Workbook
Name \a: #REF!
Name \b: #REF!
Name \c: #N/A
Name \g: #REF!
Name \O: [1]Sheet1!#REF!
Name \p: #REF!
Name \q: [2]ROCHE!#REF!
Name \r: [3]Sheet1!#REF!
Name \r: [3]Sheet1!#REF!
Name \r: [3]Sheet1!#REF!
Name \r: [3]Sheet1!#REF!
Name \r: #REF!
Name \s: [2]ROCHE!#REF!
Name \T: '[4]Noncurrent Assets'!#REF!
Name \T: '[4]Noncurrent Assets'!#REF!
Name \T: #REF!
Name \T: #REF!
Name \T: #REF!
Name \T: '[4]Noncurrent Assets'!#REF!
Name \T: '[4]Noncurrent Assets'!#REF!
Name \T: #REF!
Name \u: [2]ROCHE!#REF!
Name \v: [2]ROCHE!#REF!
Name \x: #N/A
Name \z: #N/A
Name ______DAT1: '[5]Uti per course DK'!#REF!
Name ______DAT1: '[5]Uti per course DK'!#REF!
Name ______DAT1: '[5]Uti per course DK'!#REF!
Name ______DAT1: '[5]Uti per course DK'!#REF!
Name ______DAT1: #REF!
Name ______DAT2: '[5]Uti per course DK'!#REF!
Name ______DAT2: '[5]Uti per course DK'!#REF!
Name ______DAT2: '[5]Uti per course DK'!#REF!
Name ______DAT2: '[5]Uti per course DK'!#REF!
Name ______DAT2: #REF!
Name ______EPS94: #REF!
Name ______EPS95: #REF!
Name ______EPS96: #REF!
Name ______Inc94: #REF!
Name ______Inc96: #REF!
Name ______Inc97: #REF!
Name ______Inc98: #REF!
Name ______Inc99: #REF!
Name _____Epo98: [6]Amgen!#REF!
Name _____Epo98: [6]Amgen!#REF!
Name _____Epo98: [6]Amgen!#REF!
Name _____Epo98: [6]Amgen!#REF!
Name _____Epo98: #REF!
Name _____EPS2000: [3]Sheet1!#REF!
Name _____EPS2000: [3]Sheet1!#REF!
Name _____EPS2000: [3]Sheet1!#REF!
Name _____EPS2000: [3]Sheet1!#REF!
Name _____EPS2000: #REF!
Name _____EPS93: [3]Sheet1!#REF!
Name _____EPS93: [3]Sheet1!#REF!
Name _____EPS93: [3]Sheet1!#REF!
Name _____EPS93: [3]Sheet1!#REF!
Name _____EPS93: #REF!
Name _____EPS97: [7]I!#REF!
Name _____EPS97: [7]I!#REF!

Sheet __FDSCACHE__
B1: This sheet contains FactSet XML data for use with this workbook's =FDS codes. Modifying the worksheet's contents may damage the workbook's =FDS functionality.

Sheet Income
B1: =IS!B1 -> Maplight Therapeutics, Inc. | W1: Andrew Tsai
B2: Annual and Quarterly Income Statement | W2: (415) 229-1566
W3: atsai@jefferies.com
B5: =IS!B5 -> Fiscal Year (Ending in December) | D5: =IS!D5 -> FY23 | E5: =IS!E5 -> 1Q24 | F5: =IS!F5 -> 2Q24 | G5: =IS!G5 -> 3Q24 | H5: =IS!H5 -> 4Q24 | I5: =IS!I5 -> FY24 | J5: =IS!J5 -> 1Q25 | K5: =IS!K5 -> 2Q25 | ... W5: =IS!W5 -> FY30E
B6: =IS!B6 -> ($ figures in MM, except per share) | D6: =IS!D6 -> 0 | E6: =IS!E6 -> 45352 | F6: =IS!F6 -> 45444 | G6: =IS!G6 -> 45536 | H6: =IS!H6 -> 45627 | I6: =IS!I6 -> 0 | J6: =IS!J6 -> 45717 | K6: =IS!K6 -> 45809 | ... W6: =IS!W6 -> 0
B7: =IS!B7 -> GAAP Income Statement
B8: =IS!B8 -> Revenue
B9: =IS!B9 -> Net Product Revenue | D9: =IS!D9 -> 0 | E9: =IS!E9 -> 0 | F9: =IS!F9 -> 0 | G9: =IS!G9 -> 0 | H9: =IS!H9 -> 0 | I9: =IS!I9 -> 0 | J9: =IS!J9 -> 0 | K9: =IS!K9 -> 0 | ... W9: =IS!W9 -> 35
B10: =IS!B10 -> ML-007C-MA - Total | D10: =IS!D10 -> 0 | E10: =IS!E10 -> 0 | F10: =IS!F10 -> 0 | G10: =IS!G10 -> 0 | H10: =IS!H10 -> 0 | I10: =IS!I10 -> 0 | J10: =IS!J10 -> 0 | K10: =IS!K10 -> 0 | ... W10: =IS!W10 -> 35
B11: =IS!B11 -> Schizophrenia | D11: =IS!D11 -> 0 | E11: =IS!E11 -> 0 | F11: =IS!F11 -> 0 | G11: =IS!G11 -> 0 | H11: =IS!H11 -> 0 | I11: =IS!I11 -> 0 | J11: =IS!J11 -> 0 | K11: =IS!K11 -> 0 | ... W11: =IS!W11 -> 35
B12: =IS!B12 -> Alzheimer's Disease Psychosis | D12: =IS!D12 -> 0 | E12: =IS!E12 -> 0 | F12: =IS!F12 -> 0 | G12: =IS!G12 -> 0 | H12: =IS!H12 -> 0 | I12: =IS!I12 -> 0 | J12: =IS!J12 -> 0 | K12: =IS!K12 -> 0 | ... W12: =IS!W12 -> 0
B13: =IS!B13 -> ML-004 - Autism Spectrum Disorder | D13: =IS!D13 -> 0 | E13: =IS!E13 -> 0 | F13: =IS!F13 -> 0 | G13: =IS!G13 -> 0 | H13: =IS!H13 -> 0 | I13: =IS!I13 -> 0 | J13: =IS!J13 -> 0 | K13: =IS!K13 -> 0 | ... W13: =IS!W13 -> 0
B14: =IS!B14 -> ML-021 - Parkinson's Disease | D14: =IS!D14 -> 0 | E14: =IS!E14 -> 0 | F14: =IS!F14 -> 0 | G14: =IS!G14 -> 0 | H14: =IS!H14 -> 0 | I14: =IS!I14 -> 0 | J14: =IS!J14 -> 0 | K14: =IS!K14 -> 0 | ... W14: =IS!W14 -> 0
B15: =IS!B15 -> ML-009 - Hyperactivity/Impulsivity
B16: =IS!B16 -> Other Revenue | D16: =IS!D16 -> 0 | E16: =IS!E16 -> 0 | F16: =IS!F16 -> 0 | G16: =IS!G16 -> 0 | H16: =IS!H16 -> 0 | I16: =IS!I16 -> 0 | J16: =IS!J16 -> 0 | K16: =IS!K16 -> 0 | ... W16: =IS!W16 -> 0
B17: =IS!B17 -> Licensing revenue | D17: =IS!D17 -> 0 | E17: =IS!E17 -> 0 | F17: =IS!F17 -> 0 | G17: =IS!G17 -> 0 | H17: =IS!H17 -> 0 | I17: =IS!I17 -> 0 | J17: =IS!J17 -> 0 | K17: =IS!K17 -> 0 | ... W17: =IS!W17 -> 0
B18: =IS!B18 -> Other revenue | D18: =IS!D18 -> 0 | E18: =IS!E18 -> 0 | F18: =IS!F18 -> 0 | G18: =IS!G18 -> 0 | H18: =IS!H18 -> 0 | I18: =IS!I18 -> 0 | J18: =IS!J18 -> 0 | K18: =IS!K18 -> 0 | ... W18: =IS!W18 -> 0
B19: =IS!B19 -> Total Revenues | D19: =IS!D19 -> 0 | E19: =IS!E19 -> 0 | F19: =IS!F19 -> 0 | G19: =IS!G19 -> 0 | H19: =IS!H19 -> 0 | I19: =IS!I19 -> 0 | J19: =IS!J19 -> 0 | K19: =IS!K19 -> 0 | ... W19: =IS!W19 -> 35
B20: =IS!B20 -> Cost of Sales | D20: =IS!D20 -> 0 | E20: =IS!E20 -> 0 | F20: =IS!F20 -> 0 | G20: =IS!G20 -> 0 | H20: =IS!H20 -> 0 | I20: =IS!I20 -> 0 | J20: =IS!J20 -> 0 | K20: =IS!K20 -> 0 | ... W20: =IS!W20 -> 1.75
B21: =IS!B21 -> % of Product Revenue | D21: =IS!D21 -> 0 | E21: =IS!E21 -> 0 | F21: =IS!F21 -> 0 | G21: =IS!G21 -> 0 | H21: =IS!H21 -> 0 | I21: =IS!I21 -> 0 | J21: =IS!J21 -> 0 | K21: =IS!K21 -> 0 | ... W21: =IS!W21 -> 0.05
B22: =IS!B22 -> Operating Expenses | D22: =IS!D22 -> 57.282 | E22: =IS!E22 -> 19.291 | F22: =IS!F22 -> 19.985 | G22: =IS!G22 -> 20.894 | H22: =IS!H22 -> 22.776 | I22: =IS!I22 -> 82.946 | J22: =IS!J22 -> 23.542 | K22: =IS!K22 -> 30.664 | ... W22: =IS!W22 -> 436.58528
B23: =IS!B23 -> Research and Development (R&D) | D23: =IS!D23 -> 49.675 | E23: =IS!E23 -> 15.347 | F23: =IS!F23 -> 15.642 | G23: =IS!G23 -> 16.814 | H23: =IS!H23 -> 20.72 | I23: =IS!I23 -> 68.523 | J23: =IS!J23 -> 19.786 | K23: =IS!K23 -> 26.847 | ... W23: =IS!W23 -> 385.04466
B24: =IS!B24 -> Sales, General, and Administrative (SG&A) | D24: =IS!D24 -> 7.607 | E24: =IS!E24 -> 3.944 | F24: =IS!F24 -> 4.343 | G24: =IS!G24 -> 4.08 | H24: =IS!H24 -> 2.056 | I24: =IS!I24 -> 14.423 | J24: =IS!J24 -> 3.756 | K24: =IS!K24 -> 3.817 | ... W24: =IS!W24 -> 51.540614
B25: =IS!B25 -> Other Expenses | D25: =IS!D25 -> 0 | E25: =IS!E25 -> 0 | F25: =IS!F25 -> 0 | G25: =IS!G25 -> 0 | H25: =IS!H25 -> 0 | I25: =IS!I25 -> 0 | J25: =IS!J25 -> 0 | K25: =IS!K25 -> 0 | ... W25: =IS!W25 -> 0 | AK25: C
B26: =IS!B26 -> Total Expenses | D26: =IS!D26 -> 57.282 | E26: =IS!E26 -> 19.291 | F26: =IS!F26 -> 19.985 | G26: =IS!G26 -> 20.894 | H26: =IS!H26 -> 22.776 | I26: =IS!I26 -> 82.946 | J26: =IS!J26 -> 23.542 | K26: =IS!K26 -> 30.664 | ... W26: =IS!W26 -> 438.33528
B27: =IS!B27 -> Operating Income (EBIT) | D27: =IS!D27 -> -57.282 | E27: =IS!E27 -> -19.291 | F27: =IS!F27 -> -19.985 | G27: =IS!G27 -> -20.894 | H27: =IS!H27 -> -22.776 | I27: =IS!I27 -> -82.946 | J27: =IS!J27 -> -23.542 | K27: =IS!K27 -> -30.664 | ... W27: =IS!W27 -> -403.33528
B28: =IS!B28 -> Total Other Income | D28: =IS!D28 -> 1.573 | E28: =IS!E28 -> 0.356 | F28: =IS!F28 -> 1.585 | G28: =IS!G28 -> 1.878 | H28: =IS!H28 -> 1.547 | I28: =IS!I28 -> 5.366 | J28: =IS!J28 -> 1.203 | K28: =IS!K28 -> 0.818 | ... W28: =IS!W28 -> 24.165851
B29: =IS!B29 -> Interest income | D29: =IS!D29 -> 1.099 | E29: =IS!E29 -> 0.89 | F29: =IS!F29 -> 1.634 | G29: =IS!G29 -> 1.081 | H29: =IS!H29 -> 0.899 | I29: =IS!I29 -> 4.504 | J29: =IS!J29 -> 0.811 | K29: =IS!K29 -> 0.688 | ... W29: =IS!W29 -> 24.165851
B30: =IS!B30 -> Interest expense | D30: =IS!D30 -> 0 | E30: =IS!E30 -> 0 | F30: =IS!F30 -> 0 | G30: =IS!G30 -> 0 | H30: =IS!H30 -> 0 | I30: =IS!I30 -> 0 | J30: =IS!J30 -> 0 | K30: =IS!K30 -> 0 | ... W30: =IS!W30 -> 0
B31: =IS!B31 -> Other income, net | D31: =IS!D31 -> 0.474 | E31: =IS!E31 -> -0.534 | F31: =IS!F31 -> -0.049 | G31: =IS!G31 -> 0.797 | H31: =IS!H31 -> 0.648 | I31: =IS!I31 -> 0.862 | J31: =IS!J31 -> 0.392 | K31: =IS!K31 -> 0.13 | ... W31: =IS!W31 -> 0
B32: =IS!B32 -> Pre-Tax Income | D32: =IS!D32 -> -55.709 | E32: =IS!E32 -> -18.935 | F32: =IS!F32 -> -18.4 | G32: =IS!G32 -> -19.016 | H32: =IS!H32 -> -21.229 | I32: =IS!I32 -> -77.58 | J32: =IS!J32 -> -22.339 | K32: =IS!K32 -> -29.846 | ... W32: =IS!W32 -> -379.16943
B33: =IS!B33 -> Provision for taxes (benefit) | D33: =IS!D33 -> 0 | E33: =IS!E33 -> 0 | F33: =IS!F33 -> 0 | G33: =IS!G33 -> 0 | H33: =IS!H33 -> 0 | I33: =IS!I33 -> 0 | J33: =IS!J33 -> 0 | K33: =IS!K33 -> 0 | ... W33: =IS!W33 -> 0
B34: =IS!B34 -> Tax rate | D34: =IS!D34 -> 0 | E34: =IS!E34 -> 0 | F34: =IS!F34 -> 0 | G34: =IS!G34 -> 0 | H34: =IS!H34 -> 0 | I34: =IS!I34 -> 0 | J34: =IS!J34 -> 0 | K34: =IS!K34 -> 0 | ... W34: =IS!W34 -> 0
B35: =IS!B35 -> Net Income | D35: =IS!D35 -> -55.709 | E35: =IS!E35 -> -18.935 | F35: =IS!F35 -> -18.4 | G35: =IS!G35 -> -19.016 | H35: =IS!H35 -> -21.229 | I35: =IS!I35 -> -77.58 | J35: =IS!J35 -> -22.339 | K35: =IS!K35 -> -29.846 | ... W35: =IS!W35 -> -379.16943
B36: =IS!B36 -> Other | D36: =IS!D36 -> 0 | E36: =IS!E36 -> 0 | F36: =IS!F36 -> 0 | G36: =IS!G36 -> 0 | H36: =IS!H36 -> 0 | I36: =IS!I36 -> 0 | J36: =IS!J36 -> 0 | K36: =IS!K36 -> 0 | ... W36: =IS!W36 -> 0
B37: =IS!B37 -> Net Income attributable to common stockholders | D37: =IS!D37 -> -55.709 | E37: =IS!E37 -> -18.935 | F37: =IS!F37 -> -18.4 | G37: =IS!G37 -> -19.016 | H37: =IS!H37 -> -21.229 | I37: =IS!I37 -> -77.58 | J37: =IS!J37 -> -22.339 | K37: =IS!K37 -> -29.846 | ... W37: =IS!W37 -> -379.16943
... B43: =IS!B43 -> Shares Outstanding - Fully Diluted + Options/Warrants, etc | D43: =IS!D43 -> 11.082459 | E43: =IS!E43 -> 3.9 | F43: =IS!F43 -> 18.089366 | G43: =IS!G43 -> 18.044291 | H43: =IS!H43 -> 18.046087 | I43: =IS!I43 -> 14.519936 | J43: =IS!J43 -> 18.056087 | K43: =IS!K43 -> 18.04934 | ... W43: =IS!W43 -> 66.915365

Sheet IS
B1: Maplight Therapeutics, Inc. | W1: Andrew Tsai
B2: Annual and Quarterly Income Statement | W2: (415) 229-1566
W3: atsai@jefferies.com
B5: Fiscal Year (Ending in December) | D5: FY23 | E5: 1Q24 | F5: 2Q24 | G5: 3Q24 | H5: 4Q24 | I5: FY24 | J5: 1Q25 | K5: 2Q25 | L5: 3Q25E | M5: 4Q25E | N5: FY25E | O5: 1Q26E | P5: 2Q26E | Q5: 3Q26E | R5: 4Q26E | S5: FY26E | T5: FY27E | U5: FY28E | V5: FY29E | W5: FY30E
B6: ($ figures in MM, except per share) | E6: 45352 | F6: 45444 | G6: 45536 | H6: 45627 | J6: 45717 | K6: 45809 | L6: 45901 | M6: 45992 | O6: 46082 | P6: 46174 | Q6: 46266 | R6: 46357
B7: GAAP Income Statement
B8: Revenue
B9: Net Product Revenue | D9: =SUM(D10,D13,D14,D15) -> 0 | E9: =SUM(E10,E13,E14,E15) -> 0 | F9: =SUM(F10,F13,F14,F15) -> 0 | G9: =SUM(G10,G13,G14,G15) -> 0 | H9: =SUM(H10,H13,H14,H15) -> 0 | I9: =SUM(I10,I13,I14,I15) -> 0 | J9: =SUM(J10,J13,J14,J15) -> 0 | K9: =SUM(K10,K13,K14,K15) -> 0 | ... W9: =SUM(W10,W13,W14,W15) -> 35
B10: ML-007C-MA - Total | D10: =D11+D12 -> 0 | E10: =E11+E12 -> 0 | F10: =F11+F12 -> 0 | G10: =G11+G12 -> 0 | H10: =H11+H12 -> 0 | I10: =I11+I12 -> 0 | J10: =J11+J12 -> 0 | K10: =K11+K12 -> 0 | ... W10: =W11+W12 -> 35
B11: Schizophrenia | D11: 0 | E11: 0 | F11: 0 | G11: 0 | H11: 0 | I11: =SUM(E11:H11) -> 0 | J11: 0 | K11: 0 | L11: 0 | M11: 0 | N11: =SUM(J11:M11) -> 0 | O11: 0 | P11: 0 | Q11: 0 | R11: 0 | S11: =SUM(O11:R11) -> 0 | T11: 0 | U11: 0 | V11: 0 | W11: 35
B12: Alzheimer's Disease Psychosis | D12: 0 | E12: 0 | F12: 0 | G12: 0 | H12: 0 | I12: =SUM(E12:H12) -> 0 | J12: 0 | K12: 0 | L12: 0 | M12: 0 | N12: =SUM(J12:M12) -> 0 | O12: 0 | P12: 0 | Q12: 0 | R12: 0 | S12: =SUM(O12:R12) -> 0 | T12: 0 | U12: 0 | V12: 0 | W12: 0
B13: ML-004 - Autism Spectrum Disorder | D13: 0 | E13: 0 | F13: 0 | G13: 0 | H13: 0 | I13: =SUM(E13:H13) -> 0 | J13: 0 | K13: 0 | L13: 0 | M13: 0 | N13: =SUM(J13:M13) -> 0 | O13: 0 | P13: 0 | Q13: 0 | R13: 0 | S13: =SUM(O13:R13) -> 0 | T13: 0 | U13: 0 | V13: 0 | W13: 0
B14: ML-021 - Parkinson's Disease | D14: 0 | E14: 0 | F14: 0 | G14: 0 | H14: 0 | I14: =SUM(E14:H14) -> 0 | J14: 0 | K14: 0 | L14: 0 | M14: 0 | N14: =SUM(J14:M14) -> 0 | O14: 0 | P14: 0 | Q14: 0 | R14: 0 | S14: =SUM(O14:R14) -> 0 | T14: 0 | U14: 0 | V14: 0 | W14: 0
B15: ML-009 - Hyperactivity/Impulsivity | D15: 0 | E15: 0 | F15: 0 | G15: 0 | H15: 0 | I15: =SUM(E15:H15) -> 0 | J15: 0 | K15: 0 | L15: 0 | M15: 0 | N15: =SUM(J15:M15) -> 0 | O15: 0 | P15: 0 | Q15: 0 | R15: 0 | S15: =SUM(O15:R15) -> 0
B16: Other Revenue | D16: =SUM(D17:D18) -> 0 | E16: =SUM(E17:E18) -> 0 | F16: =SUM(F17:F18) -> 0 | G16: =SUM(G17:G18) -> 0 | H16: =SUM(H17:H18) -> 0 | I16: =SUM(I17:I18) -> 0 | J16: =SUM(J17:J18) -> 0 | K16: =SUM(K17:K18) -> 0 | ... W16: =SUM(W17:W18) -> 0
B17: Licensing revenue | D17: 0 | E17: 0 | F17: 0 | G17: 0 | H17: 0 | I17: =SUM(E17:H17) -> 0 | J17: 0 | K17: 0 | L17: 0 | M17: 0 | N17: =SUM(J17:M17) -> 0 | O17: 0 | P17: 0 | Q17: 0 | R17: 0 | S17: =SUM(O17:R17) -> 0 | T17: 0 | U17: 0 | V17: 0 | W17: 0
B18: Other revenue | D18: 0 | E18: 0 | F18: 0 | G18: 0 | H18: 0 | I18: =SUM(E18:H18) -> 0 | J18: 0 | K18: 0 | L18: 0 | M18: 0 | N18: =SUM(J18:M18) -> 0 | O18: 0 | P18: 0 | Q18: 0 | R18: 0 | S18: =SUM(O18:R18) -> 0 | T18: 0 | U18: 0 | V18: 0 | W18: 0
B19: Total Revenues | D19: =D9+D16 -> 0 | E19: =E9+E16 -> 0 | F19: =F9+F16 -> 0 | G19: =G9+G16 -> 0 | H19: =H9+H16 -> 0 | I19: =I9+I16 -> 0 | J19: =J9+J16 -> 0 | K19: =K9+K16 -> 0 | ... W19: =W9+W16 -> 35
B20: Cost of Sales | D20: 0 | E20: 0 | F20: =F21*F9 -> 0 | G20: =G21*G9 -> 0 | H20: =H21*H9 -> 0 | I20: =SUM(E20:H20) -> 0 | J20: =J21*J9 -> 0 | K20: =K21*K9 -> 0 | L20: =L21*L9 -> 0 | M20: =M21*M9 -> 0 | N20: =SUM(J20:M20) -> 0 | O20: =O21*O9 -> 0 | P20: =P21*P9 -> 0 | Q20: =Q21*Q9 -> 0 | R20: =R21*R9 -> 0 | S20: =SUM(O20:R20) -> 0 | T20: =T21*T9 -> 0 | U20: =U21*U9 -> 0 | V20: =V21*V9 -> 0 | W20: =W21*W9 -> 1.75
B21: % of Product Revenue | D21: =IFERROR(D20/D9,0) -> 0 | E21: =IFERROR(E20/E9,0) -> 0 | F21: 0 | G21: 0 | H21: 0 | I21: =IFERROR(I20/I9,0) -> 0 | J21: 0 | K21: 0 | L21: 0 | M21: =IF(M9>0,5%,0%) -> 0 | N21: =IFERROR(N20/N9,0) -> 0 | O21: =IF(O9>0,5%,0%) -> 0 | P21: =IF(P9>0,5%,0%) -> 0 | Q21: =IF(Q9>0,5%,0%) -> 0 | R21: =IF(R9>0,5%,0%) -> 0 | S21: =IFERROR(S20/S9,0) -> 0 | T21: =IF(T9>0,5%,0%) -> 0 | U21: =IF(U9>0,5%,0%) -> 0 | V21: =IF(V9>0,5%,0%) -> 0 | W21: =IF(W9>0,5%,0%) -> 0.05
B22: Operating Expenses | D22: =SUM(D23:D25) -> 57.282 | E22: =SUM(E23:E25) -> 19.291 | F22: =SUM(F23:F25) -> 19.985 | G22: =SUM(G23:G25) -> 20.894 | H22: =SUM(H23:H25) -> 22.776 | I22: =SUM(I23:I25) -> 82.946 | J22: =SUM(J23:J25) -> 23.542 | K22: =SUM(K23:K25) -> 30.664 | ... W22: =SUM(W23:W25) -> 436.58528
B23: Research and Development (R&D) | D23: 49.675 | E23: 15.347 | F23: =30.989-E23 -> 15.642 | G23: 16.814 | H23: =68.523-SUM(E23:G23) -> 20.72 | I23: =SUM(E23:H23) -> 68.523 | J23: 19.786 | K23: =46.633-J23 -> 26.847 | L23: 27.094 | M23: =M75 -> 34 | N23: =SUM(J23:M23) -> 107.727 | O23: =O75 -> 38 | P23: =P75 -> 42 | Q23: =Q75 -> 47 | R23: =R75 -> 53 | S23: =SUM(O23:R23) -> 180 | T23: =T75 -> 271.9 | U23: =U75 -> 305.185 | V23: =V75 -> 342.71275 | W23: =W75 -> 385.04466
B24: Sales, General, and Administrative (SG&A) | D24: 7.607 | E24: 3.944 | F24: =8.287-E24 -> 4.343 | G24: 4.08 | H24: =14.423-SUM(E24:G24) -> 2.056 | I24: =SUM(E24:H24) -> 14.423 | J24: 3.756 | K24: =7.573-J24 -> 3.817 | L24: 4.404 | M24: =M78 -> 4.8 | N24: =SUM(J24:M24) -> 16.777 | O24: =O78 -> 5.4 | P24: =P78 -> 6 | Q24: =Q78 -> 6.6 | R24: =R78 -> 7.2 | S24: =SUM(O24:R24) -> 25.2 | T24: =T78 -> 30.13 | U24: =U78 -> 36.0295 | V24: =V78 -> 43.089925 | W24: =W78 -> 51.540614
B25: Other Expenses | D25: 0 | E25: 0 | F25: 0 | G25: 0 | H25: 0 | I25: =SUM(E25:H25) -> 0 | J25: 0 | K25: 0 | L25: 0 | M25: 0 | N25: =SUM(J25:M25) -> 0 | O25: 0 | P25: 0 | Q25: 0 | R25: 0 | S25: =SUM(O25:R25) -> 0 | T25: 0 | U25: 0 | V25: 0 | W25: 0
B26: Total Expenses | D26: =SUM(D22,D20) -> 57.282 | E26: =SUM(E22,E20) -> 19.291 | F26: =SUM(F22,F20) -> 19.985 | G26: =SUM(G22,G20) -> 20.894 | H26: =SUM(H22,H20) -> 22.776 | I26: =SUM(I22,I20) -> 82.946 | J26: =SUM(J22,J20) -> 23.542 | K26: =SUM(K22,K20) -> 30.664 | ... W26: =SUM(W22,W20) -> 438.33528
B27: Operating Income (EBIT) | D27: =SUM(-D26,D19) -> -57.282 | E27: =SUM(-E26,E19) -> -19.291 | F27: =SUM(-F26,F19) -> -19.985 | G27: =SUM(-G26,G19) -> -20.894 | H27: =SUM(-H26,H19) -> -22.776 | I27: =SUM(-I26,I19) -> -82.946 | J27: =SUM(-J26,J19) -> -23.542 | K27: =SUM(-K26,K19) -> -30.664 | ... W27: =SUM(-W26,W19) -> -403.33528
B28: Total Other Income | D28: =SUM(D29:D31) -> 1.573 | E28: =SUM(E29:E31) -> 0.356 | F28: =SUM(F29:F31) -> 1.585 | G28: =SUM(G29:G31) -> 1.878 | H28: =SUM(H29:H31) -> 1.547 | I28: =SUM(I29:I31) -> 5.366 | J28: =SUM(J29:J31) -> 1.203 | K28: =SUM(K29:K31) -> 0.818 | ... W28: =SUM(W29:W31) -> 24.165851
B29: Interest income | D29: 1.099 | E29: 0.89 | F29: =2.524-E29 -> 1.634 | G29: 1.081 | H29: =4.504-SUM(E29:G29) -> 0.899 | I29: =SUM(E29:H29) -> 4.504 | J29: 0.811 | K29: =1.499-J29 -> 0.688 | L29: 1.549 | M29: =AVERAGE(K67,L67)*5%/4 -> 1.79775 | N29: =SUM(J29:M29) -> 4.84575 | O29: =AVERAGE(M67,M59)*5%/4 -> 4.4627081 | P29: =AVERAGE(N67,O67)*5%/4 -> 5.8468332 | Q29: =AVERAGE(O67,P67)*5%/4 -> 5.3500178 | R29: =AVERAGE(P67,Q67)*5%/4 -> 6.0099981 | S29: =SUM(O29:R29) -> 21.669557 | T29: =AVERAGE(N67,S67)*5% -> 24.702504 | U29: =AVERAGE(O67,T67)*5% -> 26.070384 | V29: =AVERAGE(P67,U67)*5% -> 17.35319 | W29: =AVERAGE(Q67,V67)*5% -> 24.165851
B30: Interest expense | D30: 0 | E30: 0 | F30: 0 | G30: 0 | H30: 0 | I30: =SUM(E30:H30) -> 0 | J30: 0 | K30: 0 | L30: 0 | M30: =-M70*6.7%/4 -> 0 | N30: =SUM(J30:M30) -> 0 | O30: =-O70*6.7%/4 -> 0 | P30: =-P70*6.7%/4 -> 0 | Q30: =-Q70*6.7%/4 -> 0 | R30: =-R70*6.7%/4 -> 0 | S30: =SUM(O30:R30) -> 0 | T30: =-T70*6.7% -> 0 | U30: =-U70*6.7% -> 0 | V30: =-V70*6.7% -> 0 | W30: =-W70*6.7% -> 0
B31: Other income, net | D31: =-0.514+0.986+0.002 -> 0.474 | E31: -0.534 | F31: =0.403-0.986-E31 -> -0.049 | G31: 0.797 | H31: =SUM(1.848-0.986-SUM(E31:G31)) -> 0.648 | I31: =SUM(E31:H31) -> 0.862 | J31: 0.392 | K31: =0.522-J31 -> 0.13 | L31: 0.531 | M31: 0 | N31: =SUM(J31:M31) -> 1.053 | O31: 0 | P31: 0 | Q31: 0 | R31: 0 | S31: =SUM(O31:R31) -> 0 | T31: 0 | U31: 0 | V31: 0 | W31: 0
B32: Pre-Tax Income | D32: =D28+D27 -> -55.709 | E32: =E28+E27 -> -18.935 | F32: =F28+F27 -> -18.4 | G32: =G28+G27 -> -19.016 | H32: =H28+H27 -> -21.229 | I32: =I28+I27 -> -77.58 | J32: =J28+J27 -> -22.339 | K32: =K28+K27 -> -29.846 | ... W32: =W28+W27 -> -379.16943
B33: Provision for taxes (benefit) | D33: 0 | E33: 0 | F33: 0 | G33: 0 | H33: 0 | I33: =SUM(E33:H33) -> 0 | J33: 0 | K33: 0 | L33: 0 | M33: 0 | N33: =SUM(J33:M33) -> 0 | O33: 0 | P33: 0 | Q33: 0 | R33: 0 | S33: =SUM(O33:R33) -> 0 | T33: 0 | U33: 0 | V33: 0 | W33: 0
B34: Tax rate | D34: =IFERROR(D33/D32,0%) -> 0 | E34: =IFERROR(E33/E32,0%) -> 0 | F34: =IFERROR(F33/F32,0%) -> 0 | G34: =IFERROR(G33/G32,0%) -> 0 | H34: =IFERROR(H33/H32,0%) -> 0 | I34: =IFERROR(I33/I32,0%) -> 0 | J34: =IFERROR(J33/J32,0%) -> 0 | K34: =IFERROR(K33/K32,0%) -> 0 | ... W34: =IFERROR(W33/W32,0%) -> 0
B35: Net Income | D35: =D32-D33 -> -55.709 | E35: =E32-E33 -> -18.935 | F35: =F32-F33 -> -18.4 | G35: =G32-G33 -> -19.016 | H35: =H32-H33 -> -21.229 | I35: =I32-I33 -> -77.58 | J35: =J32-J33 -> -22.339 | K35: =K32-K33 -> -29.846 | ... W35: =W32-W33 -> -379.16943
B36: Other | D36: 0 | E36: 0 | F36: 0 | G36: 0 | H36: 0 | I36: =SUM(E36:H36) -> 0 | J36: 0 | K36: 0 | L36: 0 | M36: 0 | N36: =SUM(J36:M36) -> 0 | O36: 0 | P36: 0 | Q36: 0 | R36: 0 | S36: =SUM(O36:R36) -> 0 | T36: 0 | U36: 0 | V36: 0 | W36: 0
B37: Net Income attributable to common stockholders | D37: =D35+D36 -> -55.709 | E37: =E35+E36 -> -18.935 | F37: =F35+F36 -> -18.4 | G37: =G35+G36 -> -19.016 | H37: =H35+H36 -> -21.229 | I37: =I35+I36 -> -77.58 | J37: =J35+J36 -> -22.339 | K37: =K35+K36 -> -29.846 | ... W37: =W35+W36 -> -379.16943
B38: EPS (Basic) | D38: =D35/D40 -> -5.0267725 | E38: =E35/E40 -> -27.05 | F38: =F35/F40 -> -25.315585 | G38: =G35/G40 -> -25.080321 | H38: =H35/H40 -> -27.932895 | I38: =I35/I40 -> -105.37078 | J38: =J35/J40 -> -29.011688 | K38: =K35/K40 -> -39.532906 | ... W38: =W35/W40 -> -6.2381496
B39: EPS (Diluted, as reported) | D39: =D35/D41 -> -5.0267725 | E39: =E35/E41 -> -27.05 | F39: =F35/F41 -> -25.315585 | G39: =G35/G41 -> -25.080321 | H39: =H35/H41 -> -27.932895 | I39: =I35/I41 -> -105.37078 | J39: =J35/J41 -> -29.011688 | K39: =K35/K41 -> -39.532906 | ... W39: =W35/W41 -> -6.2381496
B40: Shares Outstanding - Basic | D40: 11.082459 | E40: 0.7 | F40: =0.728343*3-G40-E40 -> 0.726825 | G40: 0.758204 | H40: =0.76 -> 0.76 | I40: =AVERAGE(E40:H40) -> 0.73625725 | J40: 0.77 | K40: =0.772031*3-L40-J40 -> 0.754966 | L40: 0.791127 | M40: =45.373033 -> 45.373033 | N40: =AVERAGE(J40:M40) -> 11.922282 | O40: =M40*1.001+O53 -> 45.418406 | P40: =O40*1.001+P53 -> 45.463824 | Q40: =P40*1.001+Q53 -> 50.509288 | R40: =Q40*1.001+R53 -> 50.559798 | S40: =AVERAGE(O40:R40) -> 47.987829 | T40: =R40*1.001+T53 -> 55.610357 | U40: =T40*1.001+U53 -> 55.665968 | V40: =U40*1.001+V53 -> 60.721634 | W40: =V40*1.001+W53 -> 60.782355
B41: Shares Outstanding - Diluted (as reported) | D41: =D40 -> 11.082459 | E41: =IF(E37<0,E40,E40+E50) -> 0.7 | F41: =IF(F37<0,F40,F40+F50) -> 0.726825 | G41: =IF(G37<0,G40,G40+G50) -> 0.758204 | H41: =IF(H37<0,H40,H40+H50) -> 0.76 | I41: =I40 -> 0.73625725 | J41: =IF(J37<0,J40,J40+J50) -> 0.77 | K41: =IF(K37<0,K40,K40+K50) -> 0.754966 | L41: =IF(L37<0,L40,L40+L50) -> 0.791127 | M41: =IF(M37<0,M40,M40+M50) -> 45.373033 | N41: =AVERAGE(J41:M41) -> 11.922282 | O41: =IF(O37<0,O40,O40+O50) -> 45.418406 | P41: =IF(P37<0,P40,P40+P50) -> 45.463824 | Q41: =IF(Q37<0,Q40,Q40+Q50) -> 50.509288 | R41: =IF(R37<0,R40,R40+R50) -> 50.559798 | S41: =AVERAGE(O41:R41) -> 47.987829 | T41: =IF(T37<0,T40,T40+T50) -> 55.610357 | U41: =IF(U37<0,U40,U40+U50) -> 55.665968 | V41: =IF(V37<0,V40,V40+V50) -> 60.721634 | W41: =IF(W37<0,W40,W40+W50) -> 60.782355
...

Sheet BS
B1: =IS!B1 -> Maplight Therapeutics, Inc. | AB1: Andrew Tsai
B2: Annual and Quarterly Balance Sheet | AB2: (415) 229-1566
AB3: atsai@jefferies.com
B5: Fiscal Year (Ending in December) | D5: =IS!#REF! -> #REF! | E5: =IS!#REF! -> #REF! | F5: =IS!#REF! -> #REF! | G5: =IS!#REF! -> #REF! | H5: =IS!#REF! -> #REF! | I5: =IS!D5 -> FY23 | J5: =IS!E5 -> 1Q24 | K5: =IS!F5 -> 2Q24 | L5: =IS!G5 -> 3Q24 | M5: =IS!H5 -> 4Q24 | N5: =IS!I5 -> FY24 | O5: =IS!J5 -> 1Q25 | P5: =IS!K5 -> 2Q25 | ... AB5: =IS!W5 -> FY30E
B6: ($ figures in MM, except per share) | D6: =IS!#REF! -> #REF! | E6: =IS!#REF! -> #REF! | F6: =IS!#REF! -> #REF! | G6: =IS!#REF! -> #REF! | H6: =IS!#REF! -> #REF! | I6: =IS!D6 -> 0 | J6: =IS!E6 -> 45352 | K6: =IS!F6 -> 45444 | L6: =IS!G6 -> 45536 | M6: =IS!H6 -> 45627 | N6: =IS!I6 -> 0 | O6: =IS!J6 -> 45717 | P6: =IS!K6 -> 45809 | ... AB6: =IS!W6 -> 0
B7: Current assets:
B8: Cash and cash equivalents | I8: 79.769 | J8: =I8+CF!J50 -> 179.786 | K8: =J8+CF!K50 -> 38.736 | L8: =K8+CF!L50 -> 19.736 | M8: 38.253 | N8: =M8 -> 38.253 | O8: 50.156 | P8: 33.467 | Q8: 64.146 | R8: =Q8+CF!R50 -> 324.3923 | S8: =R8 -> 324.3923 | T8: =S8+CF!T50 -> 286.70401 | U8: =T8+CF!U50 -> 245.99984 | V8: =U8+CF!V50 -> 393.39886 | W8: =V8+CF!W50 -> 340.95786 | X8: =W8 -> 340.95786 | Y8: =X8+CF!Y50 -> 436.10636 | Z8: =Y8+CF!Z50 -> 130.86774 | AA8: =Z8+CF!AA50 -> 258.72018 | AB8: =AA8+CF!AB50 -> -87.493427
B9: Marketable securities | I9: 0 | J9: =I9-CF!J33-CF!J34-CF!J36 -> 0 | K9: =J9-CF!K33-CF!K34-CF!K36 -> 121.532 | L9: =K9-CF!L33-CF!L34-CF!L36 -> 121.532 | M9: 70.542 | N9: =M9 -> 70.542 | O9: 42.108 | P9: 27.005 | Q9: 163.022 | R9: =Q9-CF!R33-CF!R34-CF!R36 -> 163.022 | S9: =R9 -> 163.022 | T9: =S9-CF!T33-CF!T34-CF!T36 -> 163.022 | U9: =T9-CF!U33-CF!U34-CF!U36 -> 163.022 | V9: =U9-CF!V33-CF!V34-CF!V36 -> 163.022 | W9: =V9-CF!W33-CF!W34-CF!W36 -> 163.022 | X9: =W9 -> 163.022 | Y9: =X9-CF!Y33-CF!Y34-CF!Y36 -> 163.022 | Z9: =Y9-CF!Z33-CF!Z34-CF!Z36 -> 163.022 | AA9: =Z9-CF!AA33-CF!AA34-CF!AA36 -> 163.022 | AB9: =AA9-CF!AB33-CF!AB34-CF!AB36 -> 143.022
B10: Prepaid expenses & other current assets | I10: 3.835 | J10: =I10 -> 3.835 | K10: =J10 -> 3.835 | L10: =K10 -> 3.835 | M10: 5.807 | N10: =M10 -> 5.807 | O10: 6 | P10: 12.729 | Q10: 18.138 | R10: =Q10 -> 18.138 | S10: =R10 -> 18.138 | T10: =S10 -> 18.138 | U10: =T10 -> 18.138 | V10: =U10 -> 18.138 | W10: =V10 -> 18.138 | X10: =W10 -> 18.138 | Y10: =X10 -> 18.138 | ... AB10: =AA10 -> 18.138
B11: Restricted cash | I11: 0 | J11: 0 | K11: 0 | L11: 0 | M11: 0 | N11: =M11 -> 0 | O11: 0 | P11: 0 | Q11: 0 | R11: 0 | S11: =R11 -> 0 | T11: 0 | U11: 0 | V11: 0 | W11: 0 | X11: =W11 -> 0 | Y11: 0 | Z11: 0 | AA11: 0 | AB11: 0
B12: Accounts receivable | I12: 0 | J12: =I12 -> 0 | K12: =J12 -> 0 | L12: =K12 -> 0 | M12: 0 | N12: =M12 -> 0 | O12: 0 | P12: 0 | Q12: 0 | R12: =Q12 -> 0 | S12: =R12 -> 0 | T12: =S12 -> 0 | U12: =T12 -> 0 | V12: =U12 -> 0 | W12: =V12 -> 0 | X12: =W12 -> 0 | Y12: =X12 -> 0 | ... AB12: =AA12 -> 0
B13: Inventory | I13: 0 | J13: =I13 -> 0 | K13: =J13 -> 0 | L13: =K13 -> 0 | M13: 0 | N13: =M13 -> 0 | O13: 0 | P13: 0 | Q13: 0 | R13: =Q13 -> 0 | S13: =R13 -> 0 | T13: =S13 -> 0 | U13: =T13 -> 0 | V13: =U13 -> 0 | W13: =V13 -> 0 | X13: =W13 -> 0 | Y13: =X13 -> 0 | ... AB13: =AA13 -> 0
B14: Other current assets | I14: 0 | J14: =I14 -> 0 | K14: =J14 -> 0 | L14: =K14 -> 0 | M14: 0 | N14: =M14 -> 0 | O14: 0 | P14: 0 | Q14: 0 | R14: =Q14 -> 0 | S14: =R14 -> 0 | T14: =S14 -> 0 | U14: =T14 -> 0 | V14: =U14 -> 0 | W14: =V14 -> 0 | X14: =W14 -> 0 | Y14: =X14 -> 0 | ... AB14: =AA14 -> 0
B15: Total current assets | I15: =SUM(I8:I14) -> 83.604 | J15: =SUM(J8:J14) -> 183.621 | K15: =SUM(K8:K14) -> 164.103 | L15: =SUM(L8:L14) -> 145.103 | M15: =SUM(M8:M14) -> 114.602 | N15: =SUM(N8:N14) -> 114.602 | O15: =SUM(O8:O14) -> 98.264 | P15: =SUM(P8:P14) -> 73.201 | ... AB15: =SUM(AB8:AB14) -> 73.666573
B17: Marketable securities - long-term | I17: 0 | J17: =I17-CF!J35 -> 0.002 | K17: =J17-CF!K35 -> 0.29 | L17: =K17-CF!L35 -> 0.29 | M17: 11.38 | N17: =M17 -> 11.38 | O17: 2.493 | P17: 0 | Q17: 0 | R17: =Q17-CF!R35 -> 0 | S17: =R17 -> 0 | T17: =S17-CF!T35 -> 0 | U17: =T17-CF!U35 -> 0 | V17: =U17-CF!V35 -> 0 | W17: =V17-CF!W35 -> 0 | X17: =W17 -> 0 | Y17: =X17-CF!Y35 -> 0 | Z17: =Y17-CF!Z35 -> 0 | AA17: =Z17-CF!AA35 -> 0 | AB17: =AA17-CF!AB35 -> 0
B18: Restricted cash - long-term | I18: 0.234 | J18: =I18 -> 0.234 | K18: =J18 -> 0.234 | L18: =K18 -> 0.234 | M18: 0.207 | N18: =M18 -> 0.207 | O18: 0.207 | P18: 0.207 | Q18: 0.207 | R18: =Q18 -> 0.207 | S18: =R18 -> 0.207 | T18: =S18 -> 0.207 | U18: =T18 -> 0.207 | V18: =U18 -> 0.207 | W18: =V18 -> 0.207 | X18: =W18 -> 0.207 | Y18: =X18 -> 0.207 | ... AB18: =AA18 -> 0.207
B19: Other intangible assets (Right-of-use) | I19: 5.614 | J19: =I19 -> 5.614 | K19: =J19 -> 5.614 | L19: =K19 -> 5.614 | M19: 6.354 | N19: =M19 -> 6.354 | O19: 6.142 | P19: 5.927 | Q19: 5.71 | R19: =Q19 -> 5.71 | S19: =R19 -> 5.71 | T19: =S19 -> 5.71 | U19: =T19 -> 5.71 | V19: =U19 -> 5.71 | W19: =V19 -> 5.71 | X19: =W19 -> 5.71 | Y19: =X19 -> 5.71 | ... AB19: =AA19 -> 5.71
B20: Property and equipment, net | I20: 0.971 | J20: =I20 -> 0.971 | K20: =J20 -> 0.971 | L20: =K20 -> 0.971 | M20: 1.207 | N20: =M20 -> 1.207 | O20: 1.041 | P20: 0.971 | Q20: 0.859 | R20: =Q20 -> 0.859 | S20: =R20 -> 0.859 | T20: =S20 -> 0.859 | U20: =T20 -> 0.859 | V20: =U20 -> 0.859 | W20: =V20 -> 0.859 | X20: =W20 -> 0.859 | Y20: =X20 -> 0.859 | ... AB20: =AA20 -> 0.859
B21: Other long-term assets | I21: 0.986 | J21: =I21 -> 0.986 | K21: =J21 -> 0.986 | L21: =K21 -> 0.986 | M21: 3.166 | N21: =M21 -> 3.166 | O21: 3.42 | P21: 3.811 | Q21: 5.14 | R21: =Q21 -> 5.14 | S21: =R21 -> 5.14 | T21: =S21 -> 5.14 | U21: =T21 -> 5.14 | V21: =U21 -> 5.14 | W21: =V21 -> 5.14 | X21: =W21 -> 5.14 | Y21: =X21 -> 5.14 | ... AB21: =AA21 -> 5.14
B22: Total assets | I22: =SUM(I17:I21)+I15 -> 91.409 | J22: =SUM(J17:J21)+J15 -> 191.428 | K22: =SUM(K17:K21)+K15 -> 172.198 | L22: =SUM(L17:L21)+L15 -> 153.198 | M22: =SUM(M17:M21)+M15 -> 136.916 | N22: =SUM(N17:N21)+N15 -> 136.916 | O22: =SUM(O17:O21)+O15 -> 111.567 | P22: =SUM(P17:P21)+P15 -> 84.117 | ... AB22: =SUM(AB17:AB21)+AB15 -> 85.582573
B24: Current liabilities:
B25: Accounts payable | I25: 3.25 | J25: =I25 -> 3.25 | K25: =J25 -> 3.25 | L25: =K25 -> 3.25 | M25: 1.912 | N25: =M25 -> 1.912 | O25: 0.862 | P25: 2.102 | Q25: 2.446 | R25: =Q25 -> 2.446 | S25: =R25 -> 2.446 | T25: =S25 -> 2.446 | U25: =T25 -> 2.446 | V25: =U25 -> 2.446 | W25: =V25 -> 2.446 | X25: =W25 -> 2.446 | Y25: =X25 -> 2.446 | ... AB25: =AA25 -> 2.446
B26: Accrued expenses | I26: 6.755 | J26: =I26 -> 6.755 | K26: =J26 -> 6.755 | L26: =K26 -> 6.755 | M26: 9.991 | N26: =M26 -> 9.991 | O26: 8.076 | P26: 9.643 | Q26: 14.048 | R26: =Q26 -> 14.048 | S26: =R26 -> 14.048 | T26: =S26 -> 14.048 | U26: =T26 -> 14.048 | V26: =U26 -> 14.048 | W26: =V26 -> 14.048 | X26: =W26 -> 14.048 | Y26: =X26 -> 14.048 | ... AB26: =AA26 -> 14.048
B27: Lease liability - current | I27: 0.495 | J27: =I27-IS!E17 -> 0.495 | K27: =J27 -> 0.495 | L27: =K27 -> 0.495 | M27: 0.778 | N27: =M27 -> 0.778 | O27: 0.805 | P27: 0.833 | Q27: 0.862 | R27: =Q27-IS!M17 -> 0.862 | S27: =R27 -> 0.862 | T27: =S27-IS!O17 -> 0.862 | U27: =T27 -> 0.862 | V27: =U27 -> 0.862 | W27: =V27 -> 0.862 | X27: =W27 -> 0.862 | Y27: =X27 -> 0.862 | Z27: =Y27 -> 0.862 | AA27: =Z27 -> 0.862 | AB27: =AA27 -> 0.862
B28: Deferred grant earnings | I28: 4.198 | J28: =I28-IS!E18 -> 4.198 | K28: =J28 -> 4.198 | L28: =K28 -> 4.198 | M28: 3.239 | N28: =M28 -> 3.239 | O28: 3.239 | P28: 2.406 | Q28: 1.206 | R28: =Q28-IS!M18 -> 1.206 | S28: =R28 -> 1.206 | T28: =S28-IS!O18 -> 1.206 | U28: =T28 -> 1.206 | V28: =U28 -> 1.206 | W28: =V28 -> 1.206 | X28: =W28 -> 1.206 | Y28: =X28 -> 1.206 | Z28: =Y28 -> 1.206 | AA28: =Z28 -> 1.206 | AB28: =AA28 -> 1.206
B29: Current portion of long-term debt | I29: 0 | J29: =I29 -> 0 | K29: =J29 -> 0 | L29: =K29 -> 0 | M29: 0 | N29: =M29 -> 0 | O29: 0 | P29: 0 | Q29: 0 | R29: =Q29 -> 0 | S29: =R29 -> 0 | T29: =S29 -> 0 | U29: =T29 -> 0 | V29: =U29 -> 0 | W29: =V29 -> 0 | X29: =W29 -> 0 | Y29: =X29 -> 0 | ... AB29: =AA29 -> 0
B30: Total current liabilities | I30: =SUM(I25:I29) -> 14.698 | J30: =SUM(J25:J29) -> 14.698 | K30: =SUM(K25:K29) -> 14.698 | L30: =SUM(L25:L29) -> 14.698 | M30: =SUM(M25:M29) -> 15.92 | N30: =SUM(N25:N29) -> 15.92 | O30: =SUM(O25:O29) -> 12.982 | P30: =SUM(P25:P29) -> 14.984 | ... AB30: =SUM(AB25:AB29) -> 18.562
B32: Deferred revenue, net of current portion | I32: 0 | J32: =I32 -> 0 | K32: =J32 -> 0 | L32: =K32 -> 0 | M32: 0 | N32: =M32 -> 0 | O32: 0 | P32: 0 | Q32: 0 | R32: =Q32 -> 0 | S32: =R32 -> 0 | T32: =S32 -> 0 | U32: =T32 -> 0 | V32: =U32 -> 0 | W32: =V32 -> 0 | X32: =W32 -> 0 | Y32: =X32 -> 0 | ... AB32: =AA32 -> 0
B33: Long-term debt | I33: 0 | J33: =I33 -> 0 | K33: =J33 -> 0 | L33: =K33 -> 0 | M33: 0 | N33: =M33 -> 0 | O33: 0 | P33: 0 | Q33: 0 | R33: =Q33 -> 0 | S33: =R33 -> 0 | T33: =S33 -> 0 | U33: =T33 -> 0 | V33: =U33 -> 0 | W33: =V33 -> 0 | X33: =W33 -> 0 | Y33: =X33 -> 0 | ... AB33: =AA33 -> 0
B34: Preferred stock warrant liability | I34: 0 | J34: =H34*1.05 -> 0 | K34: =J34*1.05 -> 0 | L34: =K34*1.05 -> 0 | M34: 0 | N34: =M34 -> 0 | O34: 0 | P34: 0 | Q34: 0 | R34: =Q34*1.05 -> 0 | S34: =R34 -> 0 | T34: =R34*1.05 -> 0 | U34: =T34*1.05 -> 0 | V34: =U34*1.05 -> 0 | W34: =V34*1.05 -> 0 | X34: =W34 -> 0 | Y34: =X34*1.2 -> 0 | Z34: =Y34*1.2 -> 0 | AA34: =Z34*1.2 -> 0 | AB34: =AA34*1.2 -> 0
B35: Deferred tax liabilities | I35: 0 | J35: 0 | K35: 0 | L35: 0 | M35: 0 | N35: =M35 -> 0 | O35: 0 | P35: 0 | Q35: 0 | R35: 0 | S35: =R35 -> 0 | T35: 0 | U35: 0 | V35: 0 | W35: 0 | X35: =W35 -> 0 | Y35: 0 | Z35: 0 | AA35: 0 | AB35: 0
B36: Other long-term liabilities | I36: 5.429 | J36: =I36 -> 5.429 | K36: =J36 -> 5.429 | L36: =K36 -> 5.429 | M36: 5.801 | N36: =M36 -> 5.801 | O36: 5.59 | P36: 5.372 | Q36: =5.144 -> 5.144 | R36: =Q36 -> 5.144 | S36: =R36 -> 5.144 | T36: =S36 -> 5.144 | U36: =T36 -> 5.144 | V36: =U36 -> 5.144 | W36: =V36 -> 5.144 | X36: =W36 -> 5.144 | Y36: =X36 -> 5.144 | ... AB36: =AA36 -> 5.144
B37: Total liabilities | I37: =SUM(I32:I36)+I30 -> 20.127 | J37: =SUM(J32:J36)+J30 -> 20.127 | K37: =SUM(K32:K36)+K30 -> 20.127 | L37: =SUM(L32:L36)+L30 -> 20.127 | M37: =SUM(M32:M36)+M30 -> 21.721 | N37: =SUM(N32:N36)+N30 -> 21.721 | O37: =SUM(O32:O36)+O30 -> 18.572 | P37: =SUM(P32:P36)+P30 -> 20.356 | ... AB37: =SUM(AB32:AB36)+AB30 -> 23.706
B39: Stockholders' Equity:
B40: Convertible preferred stock | I40: =105.036+11.981+51.094+15.963+4.793 -> 188.867 | J40: =I40 -> 188.867 | K40: =J40 -> 188.867 | L40: =K40 -> 188.867 | M40: =224.992+11.981+51.094+15.963+4.793 -> 308.823 | N40: =M40 -> 308.823 | O40: =224.992+11.981+51.094+15.963+4.793 -> 308.823 | P40: =224.992+11.981+51.094+15.963+4.793 -> 308.823 | Q40: =198.87+224.992+11.981+51.094+15.963+4.793 -> 507.693 | R40: =Q40 -> 507.693 | S40: =R40 -> 507.693 | T40: =S40 -> 507.693 | U40: =T40 -> 507.693 | V40: =U40 -> 507.693 | W40: =V40 -> 507.693 | X40: =W40 -> 507.693 | Y40: =X40 -> 507.693 | ... AB40: =AA40 -> 507.693
B41: Common stock | I41: 0 | J41: =I41 -> 0 | K41: =J41 -> 0 | L41: =K41 -> 0 | M41: 0 | N41: =M41 -> 0 | O41: 0 | P41: 0 | Q41: 0 | R41: =Q41 -> 0 | S41: =R41 -> 0 | T41: =S41 -> 0 | U41: =T41 -> 0 | V41: =U41 -> 0 | W41: =V41 -> 0 | X41: =W41 -> 0 | Y41: =X41 -> 0 | ... AB41: =AA41 -> 0
B42: Additional paid-in capital | I42: 4.203 | J42: =I42 -> 4.203 | K42: =J42 -> 4.203 | L42: =K42 -> 4.203 | M42: 5.577 | N42: =M42 -> 5.577 | O42: 5.794 | P42: =6.441 -> 6.441 | Q42: 6.794 | R42: =Q42 -> 6.794 | S42: =R42 -> 6.794 | T42: =S42 -> 6.794 | U42: =T42 -> 6.794 | V42: =U42 -> 6.794 | W42: =V42 -> 6.794 | X42: =W42 -> 6.794 | Y42: =X42 -> 6.794 | ... AB42: =AA42 -> 6.794
B43: Accumulated deficit and other | I43: -121.788 | J43: =J22-J37-J40-J41-J42-J44 -> -21.769 | K43: =K22-K37-K40-K41-K42-K44 -> -40.999 | L43: =L22-L37-L40-L41-L42-L44 -> -59.999 | M43: =-199.368+0.163 -> -199.205 | N43: =M43 -> -199.205 | O43: =0.085-221.707 -> -221.622 | P43: =0.05-251.553 -> -251.503 | Q43: -280.971 | R43: =R22-R37-R40-R41-R42-R44 -> -20.724701 | S43: =R43 -> -20.724701 | T43: =T22-T37-T40-T41-T42-T44 -> -58.412993 | U43: =U22-U37-U40-U41-U42-U44 -> -99.11716 | V43: =V22-V37-V40-V41-V42-V44 -> 48.281858 | W43: =W22-W37-W40-W41-W42-W44 -> -4.1591437 | X43: =W43 -> -4.1591437 | Y43: =Y22-Y37-Y40-Y41-Y42-Y44 -> 90.98936 | Z43: =Z22-Z37-Z40-Z41-Z42-Z44 -> -214.24926 | AA43: =AA22-AA37-AA40-AA41-AA42-AA44 -> -86.396816 | AB43: =AB22-AB37-AB40-AB41-AB42-AB44 -> -452.61043
B44: Treasury stock | I44: 0 | J44: =I44 -> 0 | K44: =J44 -> 0 | L44: =K44 -> 0 | N44: =M44 -> 0 | O44: 0 | P44: =O44 -> 0 | Q44: =P44 -> 0 | R44: =Q44 -> 0 | S44: =R44 -> 0 | T44: =S44 -> 0 | U44: =T44 -> 0 | V44: =U44 -> 0 | W44: =V44 -> 0 | ... AB44: =AA44 -> 0
B45: Total stockholders' equity | I45: =SUM(I40:I44) -> 71.282 | J45: =SUM(J40:J44) -> 171.301 | K45: =SUM(K40:K44) -> 152.071 | L45: =SUM(L40:L44) -> 133.071 | M45: =SUM(M40:M44) -> 115.195 | N45: =SUM(N40:N44) -> 115.195 | O45: =SUM(O40:O44) -> 92.995 | P45: =SUM(P40:P44) -> 63.761 | ... AB45: =SUM(AB40:AB44) -> 61.876573
...

Sheet CF
B1: =IS!B1 -> Maplight Therapeutics, Inc. | AB1: Andrew Tsai
B2: Annual and Quarterly Cash Flow Statement | AB2: (415) 229-1566
AB3: atsai@jefferies.com
B4: CF Statement
B5: Fiscal Year (Ending in December) | I5: =IS!D5 -> FY23 | J5: =IS!E5 -> 1Q24 | K5: =IS!F5 -> 2Q24 | L5: =IS!G5 -> 3Q24 | M5: =IS!H5 -> 4Q24 | N5: =IS!I5 -> FY24 | O5: =IS!J5 -> 1Q25 | P5: =IS!K5 -> 2Q25 | ... AB5: =IS!W5 -> FY30E | AC5: 1Q22 | AD5: 2Q22 | AE5: 3Q22 | AF5: 4Q22 | AH5: =E5 -> 0 | AI5: =F5 -> 0 | AJ5: =G5 -> 0 | AK5: =H5 -> 0 | AM5: =J5 -> 1Q24 | AN5: =K5 -> 2Q24 | AO5: =L5 -> 3Q24 | AP5: =M5 -> 4Q24 | AR5: =O5 -> 1Q25 | AS5: =P5 -> 2Q25 | AT5: =Q5 -> 3Q25E | AU5: =R5 -> 4Q25E
B6: ($ figures in MM, except per share) | I6: =IS!D6 -> 0 | J6: =IS!E6 -> 45352 | K6: =IS!F6 -> 45444 | L6: =IS!G6 -> 45536 | M6: =IS!H6 -> 45627 | N6: =IS!I6 -> 0 | O6: =IS!J6 -> 45717 | P6: =IS!K6 -> 45809 | ... AB6: =IS!W6 -> 0 | AC6: 44621 | AD6: 44713 | AE6: 44805 | AF6: 44896 | AH6: =E6 -> 0 | AI6: =F6 -> 0 | AJ6: =G6 -> 0 | AK6: =H6 -> 0 | AM6: =J6 -> 45352 | AN6: =K6 -> 45444 | AO6: =L6 -> 45536 | AP6: =M6 -> 45627 | AR6: =O6 -> 45717 | AS6: =P6 -> 45809 | AT6: =Q6 -> 45901 | AU6: =R6 -> 45992
B7: Cash flows from operating activities:
B8: Net income | I8: -55.709 | J8: =AM8 -> -18.935 | K8: =AN8-AM8 -> -18.4 | L8: =IS!G35 -> -19.016 | M8: =IS!H35 -> -21.229 | N8: -77.58 | O8: =AR8 -> -22.339 | P8: =AS8-AR8 -> -29.846 | Q8: =AT8-AS8 -> -29.419 | R8: =IS!M35 -> -37.00225 | S8: =SUM(O8:R8) -> -118.60625 | T8: =IS!O35 -> -38.937292 | U8: =IS!P35 -> -42.153167 | V8: =IS!Q35 -> -48.249982 | W8: =IS!R35 -> -54.190002 | X8: =SUM(T8:W8) -> -183.53044 | Y8: =IS!T35 -> -277.3275 | Z8: =IS!U35 -> -315.14412 | AA8: =IS!V35 -> -368.44949 | AB8: =IS!W35 -> -379.16943 | AM8: -18.935 | AN8: -37.335 | AR8: -22.339 | AS8: -52.185 | AT8: -81.604
B9: Adjustments to reconcile net income to net cash provided by operating activities | C9: -
B10: Depreciation and amortization | I10: 0.556 | J10: =AM10 -> 0.147 | K10: =AN10-AM10 -> -0.246 | L10: =K10 -> -0.246 | M10: =L10 -> -0.246 | N10: =0.701-1.741 -> -1.04 | O10: =AR10 -> -0.091 | P10: =AS10-AR10 -> 0.197 | Q10: =AT10-AS10 -> 0.332 | R10: =Q10 -> 0.332 | S10: =SUM(O10:R10) -> 0.77 | T10: =R10 -> 0.332 | U10: =T10 -> 0.332 | V10: =U10 -> 0.332 | W10: =V10 -> 0.332 | X10: =SUM(T10:W10) -> 1.328 | Y10: =X10 -> 1.328 | Z10: =Y10 -> 1.328 | AA10: =Z10 -> 1.328 | AB10: =AA10 -> 1.328 | AM10: =0.147+0 -> 0.147 | AN10: =0.32-0.419 -> -0.099 | AR10: =0.166+-0.257 -> -0.091 | AS10: =0.302-0.196 -> 0.106 | AT10: 0.438
B11: Non-cash lease expense | I11: 0.533 | J11: =AM11 -> 0.139 | K11: =AN11-AM11 -> 0.199 | L11: 0 | M11: 0 | N11: 0.745 | O11: =AR11 -> 0.212 | P11: =AS11-AR11 -> 0.215 | Q11: =AT11-AS11 -> 0.217 | R11: =Q11 -> 0.217 | S11: =SUM(O11:R11) -> 0.861 | T11: =R11 -> 0.217 | U11: =T11 -> 0.217 | V11: =U11 -> 0.217 | W11: =V11 -> 0.217 | X11: =SUM(T11:W11) -> 0.868 | Y11: =X11 -> 0.868 | Z11: =Y11 -> 0.868 | AA11: =Z11 -> 0.868 | AB11: =AA11 -> 0.868 | AM11: 0.139 | AN11: 0.338 | AR11: 0.212 | AS11: 0.427 | AT11: 0.644
B12: Loss (gain) from equity method investment | I12: -0.986 | J12: =AM12 -> 0.534 | K12: =AN12-AM12 -> 0.452 | L12: 0 | M12: 0 | N12: 0.986 | O12: =AR12 -> 0 | P12: =AS12-AR12 -> 0 | Q12: =AT12-AS12 -> 0 | R12: =Q12 -> 0 | S12: =SUM(O12:R12) -> 0 | T12: =R12 -> 0 | U12: =T12 -> 0 | V12: =U12 -> 0 | W12: =V12 -> 0 | X12: =SUM(T12:W12) -> 0 | Y12: =X12 -> 0 | Z12: =Y12 -> 0 | AA12: =Z12 -> 0 | AB12: =AA12 -> 0 | AM12: 0.534 | AN12: 0.986 | AR12: 0 | AS12: 0 | AT12: 0
B13: Stock-based compensation | I13: 1.045 | J13: =AM13 -> 0.267 | K13: =AN13-AM13 -> 0.245 | L13: =IS!G61 -> 0.262 | M13: =IS!H61 -> 0.306 | N13: 1.08 | O13: =AR13 -> 0.212 | P13: =AS13-AR13 -> 0.148 | Q13: =AT13-AS13 -> 0.125 | R13: =IS!M61 -> 0.5 | S13: =SUM(O13:R13) -> 0.985 | T13: =IS!O61 -> 0.7 | U13: =IS!P61 -> 0.9 | V13: =IS!Q61 -> 1.1 | W13: =IS!R61 -> 1.2 | X13: =SUM(T13:W13) -> 3.9 | Y13: =IS!T61 -> 6.53 | Z13: =IS!U61 -> 7.7095 | AA13: =IS!V61 -> 9.105925 | AB13: =IS!W61 -> 10.759814 | AM13: 0.267 | AN13: 0.512 | AR13: 0.212 | AS13: 0.36 | AT13: 0.485
B14: Loss from revaluation of preferred stock purchase right | I14: 0.514 | J14: =AM14 -> 0 | K14: =AN14-AM14 -> 0 | L14: 0 | M14: 0 | N14: 0 | O14: =AR14 -> 0 | P14: =AS14-AR14 -> 0 | Q14: =AT14-AS14 -> 0 | R14: =Q14 -> 0 | S14: =SUM(O14:R14) -> 0 | T14: =R14 -> 0 | U14: =T14 -> 0 | V14: =U14 -> 0 | W14: =V14 -> 0 | X14: =SUM(T14:W14) -> 0 | Y14: =X14 -> 0 | Z14: =Y14 -> 0 | AA14: =Z14 -> 0 | AB14: =AA14 -> 0 | AM14: 0 | AN14: 0 | AR14: 0 | AS14: 0 | AT14: 0
B15: Loss on disposal of property and equipment | I15: =SUM(E15:H15) -> 0 | J15: =AM15 -> 0 | K15: =AN15-AM15 -> 0 | L15: 0 | M15: 0 | N15: 0.059 | O15: =AR15 -> 0 | P15: =AS15-AR15 -> 0 | Q15: =AT15-AS15 -> 0 | R15: =Q15 -> 0 | S15: =SUM(O15:R15) -> 0 | T15: =R15 -> 0 | U15: =T15 -> 0 | V15: =U15 -> 0 | W15: =V15 -> 0 | X15: =SUM(T15:W15) -> 0 | Y15: =X15 -> 0 | Z15: =Y15 -> 0 | AA15: =Z15 -> 0 | AB15: =AA15 -> 0 | AM15: 0 | AN15: 0 | AR15: 0 | AS15: 0 | AT15: 0
B16: Non-cash interest expense (income) | I16: =SUM(E16:H16) -> 0 | J16: =AM16 -> 0 | K16: =AN16-AM16 -> 0 | L16: 0 | M16: 0 | N16: 0 | O16: =AR16 -> 0 | P16: =AS16-AR16 -> 0.496 | Q16: =AT16-AS16 -> -0.496 | R16: 0 | S16: =SUM(O16:R16) -> 0 | T16: =R16 -> 0 | U16: =T16 -> 0 | V16: =U16 -> 0 | W16: =V16 -> 0 | X16: =SUM(T16:W16) -> 0 | Y16: =X16 -> 0 | Z16: =Y16 -> 0 | AA16: =Z16 -> 0 | AB16: =AA16 -> 0 | AM16: 0 | AN16: 0 | AR16: 0 | AS16: 0.496 | AT16: 0
B17: Change in deferred tax, other | I17: =SUM(E17:H17) -> 0 | J17: =AM17 -> 0 | K17: =AN17-AM17 -> 0 | L17: 0 | M17: 0 | N17: 0 | O17: =AR17 -> 0 | P17: =AS17-AR17 -> 0 | Q17: =AT17-AS17 -> -0.157 | R17: 0 | S17: =SUM(O17:R17) -> -0.157 | T17: =R17 -> 0 | U17: =T17 -> 0 | V17: =U17 -> 0 | W17: =V17 -> 0 | X17: =SUM(T17:W17) -> 0 | Y17: =X17 -> 0 | Z17: =Y17 -> 0 | AA17: =Z17 -> 0 | AB17: =AA17 -> 0 | AM17: 0 | AN17: 0 | AR17: 0 | AS17: 0 | AT17: =-0.66+0.496+0.007 -> -0.157
B19: Changes in operating assets and liabilities
B20: (Increase) decrease in receivables | I20: =SUM(E20:H20) -> 0 | J20: =AM20 -> 0 | K20: =AN20-AM20 -> 0 | L20: =BS!K10-BS!L10 -> 0 | M20: =BS!L10-BS!M10 -> -1.972 | O20: =AR20 -> 0 | P20: =AS20-AR20 -> 0 | Q20: =AT20-AS20 -> 0 | R20: =BS!Q10-BS!R10 -> 0 | S20: =SUM(O20:R20) -> 0 | T20: =BS!R10-BS!T10 -> 0 | U20: =BS!T10-BS!U10 -> 0 | V20: =BS!U10-BS!V10 -> 0 | W20: =BS!V10-BS!W10 -> 0 | X20: =SUM(T20:W20) -> 0 | Y20: =BS!X10-BS!Y10 -> 0 | Z20: =BS!Y10-BS!Z10 -> 0 | AA20: =BS!Z10-BS!AA10 -> 0 | AB20: =BS!AA10-BS!AB10 -> 0
B21: Increase in inventory | I21: =SUM(E21:H21) -> 0 | J21: =AM21 -> 0 | K21: =AN21-AM21 -> 0 | L21: =BS!K13-BS!L13 -> 0 | M21: =BS!L13-BS!M13 -> 0 | N21: 0 | O21: =AR21 -> 0 | P21: =AS21-AR21 -> 0 | Q21: =AT21-AS21 -> 0 | R21: =BS!Q13-BS!R13 -> 0 | S21: =SUM(O21:R21) -> 0 | T21: =BS!S13-BS!T13 -> 0 | U21: =BS!T13-BS!U13 -> 0 | V21: =BS!U13-BS!V13 -> 0 | W21: =BS!V13-BS!W13 -> 0 | X21: =SUM(T21:W21) -> 0 | Y21: =BS!X13-BS!Y13 -> 0 | Z21: =BS!Y13-BS!Z13 -> 0 | AA21: =BS!Z13-BS!AA13 -> 0 | AB21: =BS!AA13-BS!AB13 -> 0 | AM21: 0 | AN21: 0 | AR21: 0 | AS21: 0 | AT21: 0
B22: (Increase) decrease in prepaid expenses | I22: 0.532 | J22: =AM22 -> 0.012 | K22: =AN22-AM22 -> 0.232 | L22: =BS!K10-BS!L10 -> 0 | M22: =BS!L10-BS!M10 -> -1.972 | N22: -2.277 | O22: =AR22 -> -0.193 | P22: =AS22-AR22 -> -6.673 | Q22: =AT22-AS22 -> -3.908 | R22: =BS!Q10-BS!R10 -> 0 | S22: =SUM(O22:R22) -> -10.774 | T22: =BS!S10-BS!T10 -> 0 | U22: =BS!T10-BS!U10 -> 0 | V22: =BS!U10-BS!V10 -> 0 | W22: =BS!V10-BS!W10 -> 0 | X22: =SUM(T22:W22) -> 0 | Y22: =BS!X10-BS!Y10 -> 0 | Z22: =BS!Y10-BS!Z10 -> 0 | AA22: =BS!Z10-BS!AA10 -> 0 | AB22: =BS!AA10-BS!AB10 -> 0 | AM22: 0.012 | AN22: 0.244 | AR22: -0.193 | AS22: -6.866 | AT22: -10.774
B23: (Increase) decrease in receivables | I23: =SUM(E23:H23) -> 0 | J23: =AM23 -> 0 | K23: =AN23-AM23 -> 0 | L23: =BS!K12-BS!L12 -> 0 | M23: =BS!L12-BS!M12 -> 0 | N23: 0 | O23: =AR23 -> 0 | P23: =AS23-AR23 -> 0 | Q23: =AT23-AS23 -> 0 | R23: =BS!Q12-BS!R12 -> 0 | S23: =SUM(O23:R23) -> 0 | T23: =BS!S12-BS!T12 -> 0 | U23: =BS!T12-BS!U12 -> 0 | V23: =BS!U12-BS!V12 -> 0 | W23: =BS!V12-BS!W12 -> 0 | X23: =SUM(T23:W23) -> 0 | Y23: =BS!X12-BS!Y12 -> 0 | Z23: =BS!Y12-BS!Z12 -> 0 | AA23: =BS!Z12-BS!AA12 -> 0 | AB23: =BS!AA12-BS!AB12 -> 0 | AM23: 0 | AN23: 0 | AR23: 0 | AS23: 0 | AT23: 0
B24: (Increase) decrease in other assets | I24: =SUM(E24:H24) -> 0 | J24: =AM24 -> 0 | K24: =AN24-AM24 -> 0 | L24: =BS!K14-BS!L14 -> 0 | M24: =BS!L14-BS!M14 -> 0 | N24: 0 | O24: =AR24 -> 0 | P24: =AS24-AR24 -> 0 | Q24: =AT24-AS24 -> 0 | R24: =BS!Q14-BS!R14 -> 0 | S24: =SUM(O24:R24) -> 0 | T24: =BS!S14-BS!T14 -> 0 | U24: =BS!T14-BS!U14 -> 0 | V24: =BS!U14-BS!V14 -> 0 | W24: =BS!V14-BS!W14 -> 0 | X24: =SUM(T24:W24) -> 0 | Y24: =BS!X14-BS!Y14 -> 0 | Z24: =BS!Y14-BS!Z14 -> 0 | AA24: =BS!Z14-BS!AA14 -> 0 | AB24: =BS!AA14-BS!AB14 -> 0 | AM24: 0 | AN24: 0 | AR24: 0 | AS24: 0 | AT24: 0
B25: Deferred revenue | I25: =SUM(E25:H25) -> 0 | J25: =AM25 -> 0 | K25: =AN25-AM25 -> 0 | L25: =BS!L32-BS!K32 -> 0 | M25: =BS!M32-BS!L32 -> 0 | N25: 0 | O25: =AR25 -> 0 | P25: =AS25-AR25 -> 0 | Q25: =AT25-AS25 -> 0 | R25: =BS!R32-BS!Q32 -> 0 | S25: =SUM(O25:R25) -> 0 | T25: =BS!T32-BS!S32 -> 0 | U25: =BS!U32-BS!T32 -> 0 | V25: =BS!V32-BS!U32 -> 0 | W25: =BS!W32-BS!V32 -> 0 | X25: =SUM(T25:W25) -> 0 | Y25: =BS!Y32-BS!X32 -> 0 | Z25: =BS!Z32-BS!Y32 -> 0 | AA25: =BS!AA32-BS!Z32 -> 0 | AB25: =BS!AB32-BS!AA32 -> 0 | AM25: 0 | AN25: 0 | AR25: 0 | AS25: 0 | AT25: 0
B26: Increase (decrease) in accounts payable | I26: -0.405 | J26: =AM26 -> 0.802 | K26: =AN26-AM26 -> -2.02 | L26: =BS!L25-BS!K25 -> 0 | M26: =BS!M25-BS!L25 -> -1.338 | N26: -1.345 | O26: =AR26 -> -1.05 | P26: =AS26-AR26 -> 1.24 | Q26: =AT26-AS26 -> 0.301 | R26: =BS!R25-BS!Q25 -> 0 | S26: =SUM(O26:R26) -> 0.491 | T26: =BS!T25-BS!S25 -> 0 | U26: =BS!U25-BS!T25 -> 0 | V26: =BS!V25-BS!U25 -> 0 | W26: =BS!W25-BS!V25 -> 0 | X26: =SUM(T26:W26) -> 0 | Y26: =BS!Y25-BS!X25 -> 0 | Z26: =BS!Z25-BS!Y25 -> 0 | AA26: =BS!AA25-BS!Z25 -> 0 | AB26: =BS!AB25-BS!AA25 -> 0 | AM26: 0.802 | AN26: -1.218 | AR26: -1.05 | AS26: 0.19 | AT26: 0.491
B27: Accrued expenses | I27: 3.922 | J27: =AM27 -> -2.555 | K27: =AN27-AM27 -> 2.369 | L27: =BS!L26-BS!K26 -> 0 | M27: =BS!M26-BS!L26 -> 3.236 | N27: 2.169 | O27: =AR27 -> -2.117 | P27: =AS27-AR27 -> 1.279 | Q27: =AT27-AS27 -> 2.613 | R27: =BS!R26-BS!Q26 -> 0 | S27: =SUM(O27:R27) -> 1.775 | T27: =BS!T26-BS!S26 -> 0 | U27: =BS!U26-BS!T26 -> 0 | V27: =BS!V26-BS!U26 -> 0 | W27: =BS!W26-BS!V26 -> 0 | X27: =SUM(T27:W27) -> 0 | Y27: =BS!Y26-BS!X26 -> 0 | Z27: =BS!Z26-BS!Y26 -> 0 | AA27: =BS!AA26-BS!Z26 -> 0 | AB27: =BS!AB26-BS!AA26 -> 0 | AM27: -2.555 | AN27: -0.186 | AR27: -2.117 | AS27: -0.838 | AT27: 1.775
B28: Operating lease liability | I28: -0.347 | J28: =AM28 -> -0.116 | K28: =AN28-AM28 -> -0.187 | L28: =BS!L27-BS!K27 -> 0 | M28: =BS!M27-BS!L27 -> 0.283 | N28: -0.653 | O28: =AR28 -> -0.184 | P28: =AS28-AR28 -> -0.19 | Q28: =AT28-AS28 -> -0.199 | R28: =BS!R27-BS!Q27 -> 0 | S28: =SUM(O28:R28) -> -0.573 | T28: =BS!T27-BS!S27 -> 0 | U28: =BS!U27-BS!T27 -> 0 | V28: =BS!V27-BS!U27 -> 0 | W28: =BS!W27-BS!V27 -> 0 | X28: =SUM(T28:W28) -> 0 | Y28: =BS!Y27-BS!X27 -> 0 | Z28: =BS!Z27-BS!Y27 -> 0 | AA28: =BS!AA27-BS!Z27 -> 0 | AB28: =BS!AB27-BS!AA27 -> 0 | AM28: -0.116 | AN28: -0.303 | AR28: -0.184 | AS28: -0.374 | AT28: -0.573
B29: Increase (decrease) in other liabilities | I29: -1.661 | J29: =AM29 -> -0.236 | K29: =AN29-AM29 -> -0.176 | L29: =BS!L28-BS!K28 -> 0 | M29: =BS!M28-BS!L28 -> -0.959 | N29: -0.959 | O29: =AR29 -> 0 | P29: =AS29-AR29 -> -0.833 | Q29: =AT29-AS29 -> -1.2 | R29: =BS!R28-BS!Q28 -> 0 | S29: =SUM(O29:R29) -> -2.033 | T29: =BS!T28-BS!S28 -> 0 | U29: =BS!U28-BS!T28 -> 0 | V29: =BS!V28-BS!U28 -> 0 | W29: =BS!W28-BS!V28 -> 0 | X29: =SUM(T29:W29) -> 0 | Y29: =BS!Y28-BS!X28 -> 0 | Z29: =BS!Z28-BS!Y28 -> 0 | AA29: =BS!AA28-BS!Z28 -> 0 | AB29: =BS!AB28-BS!AA28 -> 0 | AM29: -0.236 | AN29: -0.412 | AR29: 0 | AS29: -0.833 | AT29: -2.033
B30: Net cash provided by operating activities | I30: =SUM(I8:I29) -> -52.006 | J30: =SUM(J8:J29) -> -19.941 | K30: =SUM(K8:K29) -> -17.532 | L30: =SUM(L8:L29) -> -19 | M30: =SUM(M8:M29) -> -23.891 | N30: =SUM(N8:N29) -> -78.815 | O30: =SUM(O8:O29) -> -25.55 | P30: =SUM(P8:P29) -> -33.967 | ... AB30: =SUM(AB8:AB29) -> -366.21361 | AM30: =SUM(AM8:AM29) -> -19.941 | AN30: =SUM(AN8:AN29) -> -37.473 | AR30: =SUM(AR8:AR29) -> -25.55 | AS30: =SUM(AS8:AS29) -> -59.517 | AT30: =SUM(AT8:AT29) -> -91.308
K31: =AN31-AM31 -> 0
B32: Cash flows from investing activities: | K32: =AN32-AM32 -> 0
B33: Maturities/sale of marketable securities | I33: 0 | J33: =AM33 -> 0 | K33: =AN33-AM33 -> 0 | L33: 0 | M33: 0 | N33: 45 | O33: =AR33 -> 37.5 | P33: =AS33-AR33 -> 17.5 | Q33: =AT33-AS33 -> 6.5 | R33: 0 | S33: =SUM(O33:R33) -> 61.5 | T33: 0 | U33: 0 | V33: 0 | W33: 0 | X33: =SUM(T33:W33) -> 0 | Y33: 0 | Z33: 0 | AA33: 0 | AB33: 20 | AM33: 0 | AN33: 0 | AR33: 37.5 | AS33: 55 | AT33: 61.5
B34: Purchases of marketable securities | I34: 0 | J34: =AM34 -> 0 | K34: =AN34-AM34 -> -121.532 | L34: 0 | M34: 0 | N34: -125.018 | O34: =AR34 -> 0 | P34: =AS34-AR34 -> 0 | Q34: =AT34-AS34 -> -142.057 | R34: 0 | S34: =SUM(O34:R34) -> -142.057 | T34: 0 | U34: 0 | V34: 0 | W34: 0 | X34: =SUM(T34:W34) -> 0 | Y34: 0 | Z34: 0 | AA34: 0 | AB34: 0 | AM34: 0 | AN34: -121.532 | AR34: 0 | AS34: 0 | AT34: -142.057
B35: Capital expenditures | I35: -0.462 | J35: =AM35 -> -0.002 | K35: =AN35-AM35 -> -0.288 | L35: =IS!G63 -> 0 | M35: =IS!H63 -> 0 | N35: -0.77 | O35: =AR35 -> 0 | P35: =AS35-AR35 -> -0.066 | Q35: =AT35-AS35 -> -0.031 | R35: =IS!M63 -> 0 | S35: =SUM(O35:R35) -> -0.097 | T35: =IS!O63 -> 0 | U35: =IS!P63 -> 0 | V35: =IS!Q63 -> 0 | W35: =IS!R63 -> 0 | X35: =SUM(T35:W35) -> 0 | Y35: =IS!T63 -> 0 | Z35: =IS!U63 -> 0 | AA35: =IS!V63 -> 0 | AB35: =IS!W63 -> 0 | AM35: -0.002 | AN35: -0.29 | AR35: 0 | AS35: -0.066 | AT35: -0.097
B36: Purchases of other securities | I36: 0 | J36: =AM36 -> 0 | K36: =AN36-AM36 -> 0 | L36: 0 | M36: 0 | N36: =SUM(J36:M36) -> 0 | O36: =AR36 -> 0 | P36: =AS36-AR36 -> 0 | Q36: =AT36-AS36 -> 0 | R36: 0 | S36: =SUM(O36:R36) -> 0 | T36: 0 | U36: 0 | V36: 0 | W36: 0 | X36: =SUM(T36:W36) -> 0 | Y36: 0 | Z36: 0 | AA36: 0 | AB36: 0 | AM36: 0 | AN36: 0 | AR36: 0 | AS36: 0 | AT36: 0
B37: Net cash used in investing activities | I37: =SUM(I33:I36) -> -0.462 | J37: =SUM(J33:J36) -> -0.002 | K37: =SUM(K33:K36) -> -121.82 | L37: =SUM(L33:L36) -> 0 | M37: =SUM(M33:M36) -> 0 | N37: =SUM(N33:N36) -> -80.788 | O37: =SUM(O33:O36) -> 37.5 | P37: =SUM(P33:P36) -> 17.434 | ... AB37: =SUM(AB33:AB36) -> 20 | AM37: =SUM(AM33:AM36) -> -0.002 | AN37: =SUM(AN33:AN36) -> -121.822 | AR37: =SUM(AR33:AR36) -> 37.5 | AS37: =SUM(AS33:AS36) -> 54.934 | AT37: =SUM(AT33:AT36) -> -80.654
K38: =AN38-AM38 -> 0
B39: Cash flows from financing activities: | K39: =AN39-AM39 -> 0
B40: Proceeds from issuance of common stock/series D, net of fees | I40: 104.532 | J40: =AM40 -> 119.956 | K40: =AN40-AM40 -> 0 | L40: =IS!G65 -> 0 | M40: =IS!H65 -> 0 | N40: 119.956 | O40: =AR40 -> 0 | P40: =AS40-AR40 -> 0 | Q40: =AT40-AS40 -> 0 | R40: =IS!M65 -> 296.19955 | S40: =SUM(O40:R40) -> 296.19955 | T40: =IS!O65 -> 0 | U40: =IS!P65 -> 0 | V40: =IS!Q65 -> 194 | W40: =IS!R65 -> 0 | X40: =SUM(T40:W40) -> 194 | Y40: =IS!T65 -> 363.75 | Z40: =IS!U65 -> 0 | AA40: =IS!V65 -> 485 | AB40: =IS!W65 -> 0 | AM40: 119.956 | AN40: 119.956 | AR40: 0 | AS40: 0 | AT40: 0
B41: Proceeds from the exercise of stock options | I41: 0.04 | J41: =AM41 -> 0.004 | K41: =AN41-AM41 -> 0.261 | L41: 0 | M41: 0 | N41: 0.294 | O41: =AR41 -> 0.005 | P41: =AS41-AR41 -> 0.003 | Q41: =AT41-AS41 -> 0.104 | R41: 0 | S41: =SUM(O41:R41) -> 0.112 | T41: 0 | U41: 0 | V41: 0 | W41: 0 | X41: =SUM(T41:W41) -> 0 | Y41: 0 | Z41: 0 | AA41: 0 | AB41: 0 | AM41: 0.004 | AN41: 0.265 | AR41: 0.005 | AS41: 0.008 | AT41: 0.112
...

Sheet SOTP
B1: MPLT Sum-Of-The-Parts Worksheet | L1: MPLT Pipeline Analysis - NPV ($M)
B2: NPV ($M) | D2: Bear | E2: % | F2: Base | G2: % | H2: Bull | I2: % | L2: Drug | M2: Licensing Partner | N2: Indication | O2: Phase | P2: Status | Q2: Rev. Pot'l | R2: Bear PoS | S2: Base PoS | T2: Bull PoS | U2: Peak Year | V2: P/S Multiple | W2: Partner | X2: Bear | Y2: Base | Z2: Bull
D3: Case | F3: Case | H3: Case
L4: ML-007C-MA | M4: n/a | N4: Alzheimer's Disease Cognition | O4: n/a | P4: Pot'l Phase II initation H2:26 | Q4: 1000 | R4: 0 | S4: 0 | T4: 0.05 | U4: 2045 | V4: 3 | W4: 1 | X4: =(($Q4*R4*$V4)/(1+$M$11)^($U4-$M$10)/$D$38)*W4 -> 0 | Y4: =(($Q4*S4*$V4)/(1+$M$11)^($U4-$M$10)/$D$38)*W4 -> 0 | Z4: =(($Q4*T4*$V4)/(1+$M$11)^($U4-$M$10)/$D$38)*W4 -> 0.54849861
B5: ML-007C-MA - Schizophrenia | D5: ='SCZ DCF'!O96 -> 2.0644184 | E5: =D5/D$32 -> 0.35386204 | F5: ='SCZ DCF'!C99 -> 16.515347 | G5: =F5/F$32 -> 0.52708005 | H5: ='SCZ DCF'!Q96 -> 24.77302 | I5: =H5/H$32 -> 0.4859726 | L5: ML-021 | M5: n/a | N5: Parkinson's Disease | O5: Preclin. | P5: Phase II initation 2026 | Q5: 1000 | R5: 0 | S5: 0 | T5: 0.05 | U5: 2045 | V5: 3 | W5: 1 | X5: =(($Q5*R5*$V5)/(1+$M$11)^($U5-$M$10)/$D$38)*W5 -> 0 | Y5: =(($Q5*S5*$V5)/(1+$M$11)^($U5-$M$10)/$D$38)*W5 -> 0 | Z5: =(($Q5*T5*$V5)/(1+$M$11)^($U5-$M$10)/$D$38)*W5 -> 0.54849861
B6: Probability | D6: ='SCZ DCF'!O95 -> 0.05 | F6: ='SCZ DCF'!P95 -> 0.4 | H6: ='SCZ DCF'!Q95 -> 0.6 | L6: ML-009 | M6: n/a | N6: Hyperactivity/Impulsivity | O6: Preclin. | P6: IND enabling studies YE:25 | Q6: 1000 | R6: 0 | S6: 0 | T6: 0.05 | U6: 2044 | V6: 3 | W6: 1 | X6: =(($Q6*R6*$V6)/(1+$M$11)^($U6-$M$10)/$D$38)*W6 -> 0 | Y6: =(($Q6*S6*$V6)/(1+$M$11)^($U6-$M$10)/$D$38)*W6 -> 0 | Z6: =(($Q6*T6*$V6)/(1+$M$11)^($U6-$M$10)/$D$38)*W6 -> 0.59786349
B7: NPV | D7: ='SCZ DCF'!O94 -> 109.80193 | F7: ='SCZ DCF'!P94 -> 878.41545 | H7: ='SCZ DCF'!Q94 -> 1317.6232 | L7: Total | X7: =SUM(X4:X6) -> 0 | Y7: =SUM(Y4:Y6) -> 0 | Z7: =SUM(Z4:Z6) -> 1.6948607
B9: ML-007C-MA - Alzheimer's Disease Psychosis | D9: ='ADP DCF'!K98 -> 0 | E9: =D9/D$32 -> 0 | F9: ='ADP DCF'!L98 -> 9.5511695 | G9: =F9/F$32 -> 0.30482138 | H9: ='ADP DCF'!M98 -> 19.102339 | I9: =H9/H$32 -> 0.37473079
B10: Probability | D10: ='ADP DCF'!K97 -> 0 | F10: ='ADP DCF'!L97 -> 0.15 | H10: ='ADP DCF'!M97 -> 0.3 | L10: Current Year: | M10: 2026
B11: NPV | D11: ='ADP DCF'!K96 -> 0 | F11: ='ADP DCF'!L96 -> 508.00597 | H11: ='ADP DCF'!M96 -> 1016.0119 | L11: Discount Rate: | M11: 0.09
B13: =IS!B13 -> ML-004 - Autism Spectrum Disorder | D13: ='ASD DCF'!O96 -> 0 | E13: =D13/D$32 -> 0 | F13: ='ASD DCF'!P96 -> 4.324757 | G13: =F13/F$32 -> 0.13802272 | H13: ='ASD DCF'!Q96 -> 5.4059462 | I13: =H13/H$32 -> 0.1060485
B14: Probability | D14: ='ASD DCF'!O95 -> 0 | F14: ='ASD DCF'!P95 -> 0.2 | H14: ='ASD DCF'!Q95 -> 0.25
B15: NPV | D15: ='ASD DCF'!O94 -> 0 | F15: ='ASD DCF'!P94 -> 230.02443 | H15: ='ASD DCF'!Q94 -> 287.53054
B17: ML-007C-MA - Alzheimer's Disease Cognition | D17: =X4 -> 0 | E17: =D17/D$32 -> 0 | F17: =Y4 -> 0 | G17: =F17/F$32 -> 0 | H17: =Z4 -> 0.54849861 | I17: =H17/H$32 -> 0.010759903
B18: Probability | D18: =R4 -> 0 | F18: =S4 -> 0 | H18: =T4 -> 0.05
B19: NPV | D19: =D17*D38 -> 0 | F19: =F17*D38 -> 0 | H19: =H17*D38 -> 29.17345
B21: =IS!B14 -> ML-021 - Parkinson's Disease | D21: =X5 -> 0 | E21: =D21/D$32 -> 0 | F21: =Y5 -> 0 | G21: =F21/F$32 -> 0 | H21: =Z5 -> 0.54849861 | I21: =H21/H$32 -> 0.010759903
B22: Probability | D22: =R5 -> 0 | F22: =S5 -> 0 | H22: =T5 -> 0.05
B23: NPV | D23: =D21*D38 -> 0 | F23: =F21*D38 -> 0 | H23: =H21*D38 -> 29.17345
B25: =IS!B15 -> ML-009 - Hyperactivity/Impulsivity | D25: =X6 -> 0 | E25: =D25/D$32 -> 0 | F25: =Y6 -> 0 | G25: =F25/F$32 -> 0 | H25: =Z6 -> 0.59786349 | I25: =H25/H$32 -> 0.011728294
B26: Probability | D26: =R6 -> 0 | F26: =S6 -> 0 | H26: =T6 -> 0.05
B27: NPV | D27: =D25*D38 -> 0 | F27: =F25*D38 -> 0 | H27: =H25*D38 -> 31.799061
B29: Cash | D29: =D40*D30 -> 3.7695455 | E29: =D29/D$32 -> 0.64613796 | F29: =D40*F30 -> 0.94238638 | G29: =F29/F$32 -> 0.030075848 | H29: =D40*H30 -> 0 | I29: =H29/H$32 -> 0
B30: Weight | D30: 0.4 | F30: 0.1 | H30: 0
B32: $/Share | D32: =D29+D9+D13+D5+D25+D21+D17 -> 5.8339639 | F32: =F29+F9+F13+F5+F25+F21+F17 -> 31.33366 | H32: =H29+H9+H13+H5+H25+H21+H17 -> 50.976166
B33: Implied Market Cap ($M) | D33: =D32*$D38 -> 310.29587 | F33: =F32*$D38 -> 1666.5693 | H33: =H32*$D38 -> 2711.3116
B35: Upside/downside | D35: =D32/D37-1 -> -0.56102604 | F35: =F32/D37-1 -> 1.357687 | H35: =H32/D37-1 -> 2.8356784
B37: Stock Price | D37: 13.29
B38: Share Count (in M) - YE:26 | D38: =IS!S42 -> 53.187829
B39: Cash (Q4:26) | D39: =IS!S67 -> 501.23486
B40: Cash/Share | D40: =D39/D38 -> 9.4238638
B41: Debt (Q4:26) | D41: =IS!S70 -> 0
J69: =MAX(#REF!) -> #REF!

Sheet Pipeline
B1: MPLT Pipeline | M1: Sep 2025
B2: Program | C2: Target | D2: Modality | E2: Indication | F2: Designation | G2: Stage | H2: Milestone | I2: Partner | K2: IP
B3: ML-007C-MA | C3: M1/M4 Agonist | D3: Oral small molecule | E3: Schizophrenia | F3: N/A | G3: Phase II (ZEPHYR) | H3: - Phase II data expected H2:26 | I3: N/A | K3: 2045
E4: Alzheimer's Disease Psychosis (ADP) | F4: N/A | G4: Phase II (VISTA) | H4: - Phase II data expected H2:27 | I4: N/A | K4: 2045
B5: ML-004 | C5: 5-HT1B/1D Agonist | D5: Oral small molecule | E5: Autism Spectrum Disorder (ASD) | F5: N/A | G5: Phase II (IRIS) | H5: - Phase II data expected H2:26 | I5: N/A | K5: 2045
B6: ML-021 | C6: M4 Antagonist | D6: Oral small molecule | E6: Parkinson's Disease | F6: N/A | G6: Preclinical | H6: - Complete IND-enabling studies in 2026 | I6: N/A | K6: 2045
B7: ML-009 | C7: GPR52 Positive Allosteric Modulator (PAM) | D7: Oral small molecule | E7: Hyperactivity/Impulsivity | F7: N/A | G7: Preclinical | H7: - Initiate IND enabling studies in 2026 | I7: N/A | K7: 2045

Sheet Newsflow
B1: MPLT Expected Newsflow | G1: Dec 2025
B2: Timing | C2: Expected Newsflow | D2: Drug | E2: Indication
B3: H2:26 | C3: Phase II data (N=300) in schizophrenia (Study 211; ZEPHYR) | D3: ML-007C-MA (M1/M4 Agonist) | E3: Schizophrenia
B4: H2:26 | C4: Phase II data (N=160) in autism spectrum disorder (IRIS) | D4: ML-004 (5-HT1B/1D Agonist) | E4: Autism Spectrum Disorder (ASD)
B5: H2:26 | C5: Complete IND-enabling studies for ML-021 in Parkinson's | D5: ML-021 (M4 Antagonist) | E5: Parkinson's Disease
B6: 2026 | C6: Initiate IND-enabling studies for hyperactivity/agitation | D6: ML-009 (GPR52 PAM) | E6: Hyperactivity/Impulsivity
B7: H2:27 | C7: Phase II data (N=300) in ADP Alzheimer's psychosis (Study 221; VISTA) | D7: ML-007C-MA | E7: Alzheimer's Disease Psychosis (ADP)
B10: Old

Sheet SCZ DCF
B1: ML-007C-MA Model Analysis for Schizophrenia (SCZ): Change Assumptions in Blue
B3: ML-007C-MA Sales Summary ($M) | E3: 2018 | F3: =E3+1 -> 2019 | G3: =F3+1 -> 2020 | H3: =G3+1 -> 2021 | I3: =H3+1 -> 2022 | J3: =I3+1 -> 2023 | K3: =J3+1 -> 2024 | L3: =K3+1 -> 2025 | M3: =L3+1 -> 2026 | ... AF3: =AE3+1 -> 2045
B4: US | E4: =E36 -> 0 | F4: =F36 -> 0 | G4: =G36 -> 0 | H4: =H36 -> 0 | I4: =I36 -> 0 | J4: =J36 -> 0 | K4: =K36 -> 0 | L4: =L36 -> 0 | ... AF4: =AF36 -> 1335.0132
B5: EU5 (Before royalties) | E5: =E62 -> 0 | F5: =F62 -> 0 | G5: =G62 -> 0 | H5: =H62 -> 0 | I5: =I62 -> 0 | J5: =J62 -> 0 | K5: =K62 -> 0 | L5: =L62 -> 0 | ... AF5: =AF62 -> 0
B6: Total Sales ($M) | E6: =E4+E5 -> 0 | F6: =F4+F5 -> 0 | G6: =G4+G5 -> 0 | H6: =H4+H5 -> 0 | I6: =I4+I5 -> 0 | J6: =J4+J5 -> 0 | K6: =K4+K5 -> 0 | L6: =L4+L5 -> 0 | ... AF6: =AF4+AF5 -> 1335.0132
B8: ML-007C-MA Patient Summary | E8: 2018 | F8: =E8+1 -> 2019 | G8: =F8+1 -> 2020 | H8: =G8+1 -> 2021 | I8: =H8+1 -> 2022 | J8: =I8+1 -> 2023 | K8: =J8+1 -> 2024 | L8: =K8+1 -> 2025 | M8: =L8+1 -> 2026 | ... AF8: =AE8+1 -> 2045
B9: US | E9: =E29 -> 0 | F9: =F29 -> 0 | G9: =G29 -> 0 | H9: =H29 -> 0 | I9: =I29 -> 0 | J9: =J29 -> 0 | K9: =K29 -> 0 | L9: =L29 -> 0 | ... AF9: =AF29 -> 82920.073
B10: EU5 | E10: =E55 -> 0 | F10: =F55 -> 0 | G10: =G55 -> 0 | H10: =H55 -> 0 | I10: =I55 -> 0 | J10: =J55 -> 0 | K10: =K55 -> 0 | L10: =L55 -> 0 | ... AF10: =AF55 -> 0
B11: Total Patients | E11: =E9+E10 -> 0 | F11: =F9+F10 -> 0 | G11: =G9+G10 -> 0 | H11: =H9+H10 -> 0 | I11: =I9+I10 -> 0 | J11: =J9+J10 -> 0 | K11: =K9+K10 -> 0 | L11: =L9+L10 -> 0 | ... AF11: =AF9+AF10 -> 82920.073
B13: ML-007C-MA for Schizophrenia - US Market Model | E13: 2018 | F13: =E13+1 -> 2019 | G13: =F13+1 -> 2020 | H13: =G13+1 -> 2021 | I13: =H13+1 -> 2022 | J13: =I13+1 -> 2023 | K13: =J13+1 -> 2024 | L13: =K13+1 -> 2025 | M13: =L13+1 -> 2026 | ... AF13: =AE13+1 -> 2045
B14: US Population (000s) | E14: =327.2*1000 -> 327200 | F14: =E14*(1+F$15) -> 329654 | G14: =F14*(1+G$15) -> 332126.41 | H14: =G14*(1+H$15) -> 334617.35 | I14: =H14*(1+I$15) -> 337126.98 | J14: =I14*(1+J$15) -> 339655.44 | K14: =J14*(1+K$15) -> 342202.85 | L14: =K14*(1+L$15) -> 344769.37 | M14: =L14*(1+M$15) -> 347355.14 | ... AF14: =AE14*(1+AF$15) -> 400340.73
B15: Annual Growth Rate | C15: 0.0075 | E15: =C15 -> 0.0075 | F15: =E15 -> 0.0075 | G15: =F15 -> 0.0075 | H15: =G15 -> 0.0075 | I15: =H15 -> 0.0075 | J15: =I15 -> 0.0075 | K15: =J15 -> 0.0075 | L15: =K15 -> 0.0075 | M15: =L15 -> 0.0075 | ... AF15: =AE15 -> 0.0075
