Workbook
Name _1998: [1]IS!#REF!
Name _CTO05: [3]BS!$S$43
Name _DSO01: [4]BS!#REF!
Name _DSO02: [4]BS!#REF!
Name _DSO03: [4]BS!#REF!
Name _DSO04: [4]BS!#REF!
Name _dso05: [4]BS!#REF!
Name _dso98: [5]BS!$F$51
Name _dso99: [5]BS!$K$51
Name _EPS01: [5]HCA!#REF!
Name _eps02: [5]HCA!#REF!
Name _eps03: [5]HCA!#REF!
Name _eps04: [5]HCA!#REF!
Name _eps05: [5]HCA!#REF!
Name _EPS06: [6]OCR!$AO$48
Name _EPS07: [6]OCR!$AT$48
Name _EPS98: [5]HCA!#REF!
Name _EPS99: [5]HCA!#REF!
Name _Key1: [7]BMY!#REF!
Name _nd0306: [8]BS!$AP$140
Name _nd0606: [8]BS!$AQ$140
Name _nd0906: [8]BS!$AR$140
Name _ni01: [5]HCA!#REF!
Name _ni02: [5]HCA!#REF!
Name _ni03: [5]HCA!#REF!
Name _ni04: [5]HCA!#REF!
Name _ni98: [5]HCA!#REF!
Name _ni99: [5]HCA!#REF!
Name _Order1: 0
Name _rev01: [5]HCA!#REF!
Name _rev02: [5]HCA!#REF!
Name _rev03: [5]HCA!#REF!
Name _rev04: [5]HCA!#REF!
Name _rev05: [5]HCA!#REF!
Name _rev06: [6]OCR!$AO$8
Name _rev07: [6]OCR!$AT$8
Name _rev98: [5]HCA!#REF!
Name _rev99: [5]HCA!#REF!
Name _roa01: [5]BS!#REF!
Name _roa02: [5]BS!#REF!
Name _roa03: [5]BS!#REF!
Name _roa04: [5]BS!#REF!
Name _roa05: [5]BS!#REF!
Name _roa98: [5]BS!#REF!
Name _roa99: [5]BS!#REF!
Name _roe01: [5]BS!$U$46
Name _roe02: [5]BS!$Z$46
Name _roe03: [5]BS!$AE$46
Name _roe04: [5]BS!$AJ$46
Name _roe05: [5]BS!$AO$46
Name _roe98: [5]BS!$F$46
Name _roe99: [5]BS!$K$46
Name _Sort: [7]BMY!#REF!
Name admissions0302: [1]Same!$L$20
Name backlogsorders: #REF!
Name balancesheet: #REF!
Name balsheet: #REF!
Name BalShGraphs: #REF!
Name balsht1991: #REF!
Name balsht1992: #REF!

Sheet Disclaimer - READ FIRST
A5: © 2025 Stifel. This report is produced for the use of Stifel customers and may not be reproduced, re-distributed or passed to any other person or published in whole or in part for any purpose without the prior consent of Stifel.

Sheet Sources
A1: The information contained herein has been prepared from sources believed to be reliable but is not guaranteed by us and is not a complete summary or statement of all available data, nor is it considered an offer to buy or sell any securities referred to herein. The most recent research and all applicable disclosures may be accessed by accessing Research Page at www.stifel.com. Additional information available upon request.
A2: Sources for data in this workbook include:
A3: Stifel estimates
A4: Company reports

Sheet P&L
A1: MapLight Therapeutics (MPLT) - IS Data in $MM, Except EPS | B1: 2023 | C1: 2024 | D1: 1H25 | E1: 3Q25 | F1: 4Q25E | G1: 2025E | H1: 2026E | I1: 2027E | J1: 2028E | K1: 2029E | L1: 2030E | M1: 2031E | N1: 2032E | O1: 2033E | P1: 2034E | Q1: 2035E | R1: 2036E | S1: 2037E | T1: 2038E
A2: Product Revenue | B2: =Revenue!E15 -> 0 | C2: =Revenue!F15 -> 0 | D2: =Revenue!G15 -> 0 | E2: =Revenue!H15 -> 0 | F2: =Revenue!I15 -> 0 | G2: =Revenue!J15 -> 0 | H2: =Revenue!K15 -> 0 | I2: =Revenue!L15 -> 0 | ... T2: =Revenue!W15 -> 1002.836
A3: Royalty Revenue | B3: 0 | C3: 0 | D3: 0 | E3: 0 | F3: 0 | G3: 0 | H3: 0 | I3: 0 | J3: 0 | K3: 0 | L3: 0 | M3: 0 | N3: 0 | O3: 0 | P3: 0 | Q3: 0 | R3: 0 | S3: 0 | T3: 0
A4: Other Revenue | C4: 0 | D4: 0 | E4: 0 | F4: 0 | G4: 0 | H4: 0 | I4: 0 | J4: 0 | K4: 0 | L4: 0 | M4: 0 | N4: 0 | O4: 0 | P4: 0 | Q4: 0 | R4: 0 | S4: 0 | T4: 0
A5: Total revenue | B5: =SUM(B2,B4) -> 0 | C5: =SUM(C2,C4) -> 0 | D5: =SUM(D2,D4) -> 0 | E5: =SUM(E2,E4) -> 0 | F5: =SUM(F2,F4) -> 0 | G5: =SUM(G2,G4) -> 0 | H5: =SUM(H2,H4) -> 0 | I5: =SUM(I2,I4) -> 0 | ... L5: =SUM(L2,L4) -> 0 | M5: =SUM(M2:M4) -> 15.528705 | N5: =SUM(N2:N4) -> 81.048604 | O5: =SUM(O2:O4) -> 191.65084 | P5: =SUM(P2:P4) -> 348.30754 | Q5: =SUM(Q2:Q4) -> 509.27378 | R5: =SUM(R2:R4) -> 657.91866 | S5: =SUM(S2:S4) -> 851.45569 | T5: =SUM(T2:T4) -> 1002.836
A7: COGS | B7: 0 | C7: 0 | D7: 0 | E7: 0 | F7: 0 | G7: =SUM(D7:F7) -> 0 | H7: 0 | I7: 0 | J7: 0 | K7: 0 | L7: 0 | M7: =M2*M64 -> 1.2422964 | N7: =N2*N64 -> 6.4838883 | O7: =O2*O64 -> 15.332067 | P7: =P2*P64 -> 27.864603 | Q7: =Q2*Q64 -> 40.741902 | R7: =R2*R64 -> 52.633493 | S7: =S2*S64 -> 68.116455 | T7: =T2*T64 -> 80.226882
A8: R&D | B8: 49.686 | C8: 68.523 | D8: 46.633 | E8: 27.094 | F8: 30 | G8: =SUM(D8:F8) -> 103.727 | H8: 120 | I8: 120 | J8: 120 | K8: 130 | L8: 140 | M8: 90 | N8: 90 | O8: 95 | P8: =P2*P65 -> 104.49226 | Q8: =Q2*Q65 -> 91.66928 | R8: =R2*R65 -> 78.950239 | S8: =S2*S65 -> 85.145569 | T8: =T2*T65 -> 90.255242
A9: SG&A | B9: 7.607 | C9: 14.423 | D9: 7.573 | E9: 4.404 | F9: 5 | G9: =SUM(D9:F9) -> 16.977 | H9: 20 | I9: 30 | J9: 40 | K9: 50 | L9: 60 | M9: 85 | N9: 120 | O9: =O66*O2 -> 95.825418 | P9: =P66*P2 -> 104.49226 | Q9: =Q66*Q2 -> 101.85476 | R9: =R66*R2 -> 131.58373 | S9: =S66*S2 -> 170.29114 | T9: =T66*T2 -> 200.5672
A10: Other operating expenses | B10: 0 | C10: 0 | D10: 0 | E10: 0 | F10: 0 | G10: =SUM(D10:F10) -> 0 | H10: 0 | I10: 0 | J10: 0 | K10: 0 | L10: 0 | M10: 0 | N10: 0 | O10: 0 | P10: 0 | Q10: 0 | R10: 0 | S10: 0 | T10: 0
A11: Operating expenses | B11: =SUM(B9,B8,B7,B10) -> 57.293 | C11: =SUM(C9,C8,C7,C10) -> 82.946 | D11: =SUM(D9,D8,D7,D10) -> 54.206 | E11: =SUM(E9,E8,E7,E10) -> 31.498 | F11: =SUM(F9,F8,F7,F10) -> 35 | G11: =SUM(G9,G8,G7,G10) -> 120.704 | H11: =SUM(H9,H8,H7,H10) -> 140 | I11: =SUM(I9,I8,I7,I10) -> 150 | ... T11: =SUM(T9,T8,T7,T10) -> 371.04933
A13: Operating income | B13: =B5-B11 -> -57.293 | C13: =C5-C11 -> -82.946 | D13: =D5-D11 -> -54.206 | E13: =E5-E11 -> -31.498 | F13: =F5-F11 -> -35 | G13: =G5-G11 -> -120.704 | H13: =H5-H11 -> -140 | I13: =I5-I11 -> -150 | ... T13: =T5-T11 -> 631.78669
A15: Interest income | B15: 1.099 | C15: 4.504 | D15: 1.499 | E15: 1.549 | F15: 1.5 | G15: =SUM(D15:F15) -> 4.548 | H15: 0 | I15: 0 | J15: 0 | K15: 0 | L15: 0 | M15: 0 | N15: 0 | O15: 0 | P15: 0 | Q15: 0 | R15: 0 | S15: 0 | T15: 0
A16: Interest expense | B16: 0 | C16: 0 | D16: 0 | E16: 0 | F16: 0 | G16: 0 | H16: 0 | I16: 0 | J16: 0 | K16: 0 | L16: 0 | M16: 0 | N16: 0 | O16: 0 | P16: 0 | Q16: 0 | R16: 0 | S16: 0 | T16: 0
A17: Change in fair value of preferred stock purchase right | B17: -0.514 | C17: 0 | D17: 0 | E17: 0 | F17: 0 | G17: 0 | H17: 0 | I17: 0 | J17: 0 | K17: 0 | L17: 0 | M17: 0 | N17: 0 | O17: 0 | P17: 0 | Q17: 0 | R17: 0 | S17: 0 | T17: 0
A18: Gain on equity method investment | B18: 0.986 | C18: -0.986 | D18: 0 | E18: 0 | F18: 0 | G18: 0 | H18: 0 | I18: 0 | J18: 0 | K18: 0 | L18: 0 | M18: 0 | N18: 0 | O18: 0 | P18: 0 | Q18: 0 | R18: 0 | S18: 0 | T18: 0
A19: Other income (expense) | B19: 0.002 | C19: 1.848 | D19: 0.522 | E19: 0.531 | F19: 0 | G19: 0 | H19: 0 | I19: 0 | J19: 0 | K19: 0 | L19: 0 | M19: 0 | N19: 0 | O19: 0 | P19: 0 | Q19: 0 | R19: 0 | S19: 0 | T19: 0
A20: Net interest and other income | B20: =SUM(B15,B16,B19,B17,B18) -> 1.573 | C20: =SUM(C15,C16,C19,C17,C18) -> 5.366 | D20: =SUM(D15,D16,D19) -> 2.021 | E20: =SUM(E15,E16,E19) -> 2.08 | F20: =SUM(F15,F16,F19) -> 1.5 | G20: =SUM(G15,G16,G19) -> 4.548 | H20: =SUM(H15,H16,H19) -> 0 | I20: =SUM(I15,I16,I19) -> 0 | J20: =SUM(J15,J16,J19) -> 0 | K20: =SUM(K15,K16,K19) -> 0 | ... T20: =SUM(T15,T16,T19) -> 0
A22: EBIT | B22: =B13+B20 -> -55.72 | C22: =C13+C19 -> -81.098 | D22: =D13+D20 -> -52.185 | E22: =E13+E19 -> -30.967 | F22: =F13+F19 -> -35 | G22: =G13+G19 -> -120.704 | H22: =H13+H19 -> -140 | I22: =I13+I19 -> -150 | J22: =J13+J19 -> -160 | K22: =K13+K19 -> -180 | L22: =L13+L19 -> -200 | ... T22: =T13+T19 -> 631.78669
A24: Net pre-tax income | B24: =B13+B20 -> -55.72 | C24: =C13+C20 -> -77.58 | D24: =D13+D20 -> -52.185 | E24: =E13+E20 -> -29.418 | F24: =F13+F20 -> -33.5 | G24: =G13+G20 -> -116.156 | H24: =H13+H20 -> -140 | I24: =I13+I20 -> -150 | ... T24: =T13+T20 -> 631.78669
A25: Provision for income taxes | B25: 0.45 | C25: =C24*C69 -> 0 | D25: =D24*D69 -> 0 | E25: =E24*E69 -> 0 | F25: =F24*F69 -> 0 | G25: =G24*G69 -> 0 | H25: =H24*H69 -> 0 | I25: =I24*I69 -> 0 | J25: =J24*J69 -> 0 | ... T25: =T24*T69 -> 138.99307
A26: Net income (loss) | B26: =B24-B25 -> -56.17 | C26: =C24-C25 -> -77.58 | D26: =D24-D25 -> -52.185 | E26: =E24-E25 -> -29.418 | F26: =F24-F25 -> -33.5 | G26: =G24-G25 -> -116.156 | H26: =H24-H25 -> -140 | I26: =I24-I25 -> -150 | ... T26: =T24-T25 -> 492.79362
A28: Diluted earnings per share (GAAP) | B28: =IFERROR((B26)/B32,"--") -> -5.0683698 | C28: =IFERROR((C26)/C32,"--") -> -6.2725092 | D28: =IFERROR((D26)/D32,"--") -> -4.074441 | E28: =IFERROR((E26)/E32,"--") -> -37.184927 | F28: =IFERROR((F26)/F32,"--") -> -0.73832402 | G28: =IFERROR((G26)/G32,"--") -> -6.4728944 | H28: =IFERROR((H26)/H32,"--") -> -2.7792648 | I28: =IFERROR((I26)/I32,"--") -> -2.9198198 | ... T28: =IFERROR((T26)/T32,"--") -> 7.3144046
A29: Basic earnings per share (GAAP) | B29: =IFERROR(B26/B31,"--") -> -5.0683698 | C29: =IFERROR(C26/C31,"--") -> -6.2725092 | D29: =IFERROR(D26/D31,"--") -> -4.074441 | E29: =IFERROR(E26/E31,"--") -> -37.184927 | F29: =IFERROR(F26/F31,"--") -> -0.73832402 | G29: =IFERROR(G26/G31,"--") -> -6.4728944 | H29: =IFERROR(H26/H31,"--") -> -2.7792648 | I29: =IFERROR(I26/I31,"--") -> -2.9198198 | ... T29: =IFERROR(T26/T31,"--") -> 7.3144046
A31: Average shares outstanding, basic | B31: 11.082459 | C31: 12.368256 | D31: 12.807892 | E31: 0.791127 | F31: 45.373033 | G31: =(D31*2+E31+F31)/4 -> 17.944986 | H31: =F31+H55/40 -> 50.373033 | I31: =H31+1 -> 51.373033 | J31: =I31+1 -> 52.373033 | K31: =J31+1 -> 53.373033 | L31: =K31+L55/50 -> 59.373033 | M31: =L31+1 -> 60.373033 | N31: =M31+1 -> 61.373033 | O31: =N31+1 -> 62.373033 | P31: =O31+1 -> 63.373033 | Q31: =P31+1 -> 64.373033 | R31: =Q31+1 -> 65.373033 | S31: =R31+1 -> 66.373033 | T31: =S31+1 -> 67.373033
A32: Average shares outstanding, diluted | B32: =B31 -> 11.082459 | C32: =C31 -> 12.368256 | D32: =D31 -> 12.807892 | E32: =E31 -> 0.791127 | F32: =F31 -> 45.373033 | G32: =G31 -> 17.944986 | H32: =H31 -> 50.373033 | I32: =I31 -> 51.373033 | ... T32: =T31 -> 67.373033
A34: Source: Stifel estimates & company filings
A36: MapLight Therapeutics BS/CFS ($MM) | B36: =B1 -> 2023 | C36: =C1 -> 2024 | D36: =D1 -> 1H25 | E36: =E1 -> 3Q25 | F36: =F1 -> 4Q25E | G36: =G1 -> 2025E | H36: =H1 -> 2026E | I36: =I1 -> 2027E | ... T36: =T1 -> 2038E
A38: Net cash | B38: =SUM(B39,B40,B41,B42) -> 158.933 | C38: =C39-C40 -> 65.286 | D38: =D39-D40 -> 60.5 | E38: =E39-E40 -> 227.2 | F38: =F39-F40 -> 456.4 | G38: =G39-G40 -> 456.4 | H38: =H39-H40 -> 526.5 | I38: =I39-I40 -> 391.6 | J38: =J39-J40 -> 250.7 | ... T38: =T39-T40 -> 1805.5478
A39: Cash and equivalents | B39: 106.829 | C39: =B39+C42 -> 65.286 | D39: =C39+D42 -> 60.5 | E39: =D39+E42 -> 227.2 | F39: =E39+F42 -> 456.4 | G39: =C39+G42 -> 456.4 | H39: =G39+H42 -> 526.5 | I39: =H39+I42 -> 391.6 | J39: =I39+J42 -> 250.7 | K39: =J39+K42 -> 91.8 | L39: =K39+L42 -> 214.9 | M39: =L39+M42 -> 74.786409 | N39: =M39+N42 -> -36.548876 | O39: =N39+O42 -> -28.872983 | ... T39: =S39+T42 -> 1805.5478
A40: Debt | B40: 0 | C40: =B40+C56 -> 0 | D40: =C40+D56 -> 0 | E40: =D40+E56 -> 0 | F40: =E40+F56 -> 0 | G40: =C40+G56 -> 0 | H40: =G40+H56 -> 0 | I40: 0 | J40: =I40+J56 -> 0 | K40: =J40+K56 -> 0 | L40: =K40+L56 -> 0 | M40: =L40+M56 -> 0 | N40: =M40+N56 -> 0 | O40: =N40+O56 -> 0 | P40: =O40+P56 -> 0 | Q40: =P40+Q56 -> 0 | ... T40: =S40+T56 -> 0
A42: Change in cash and short term investments | B42: =SUM(B44,B50,B54) -> 52.104 | C42: =SUM(C44,C50,C54) -> -41.543 | D42: =SUM(D44,D50,D54) -> -4.786 | E42: =SUM(E44,E50,E54) -> 166.7 | F42: =SUM(F44,F50,F54) -> 229.2 | G42: =SUM(G44,G50,G54) -> 391.114 | H42: =SUM(H44,H50,H54) -> 70.1 | I42: =SUM(I44,I50,I54) -> -134.9 | ... T42: =SUM(T44,T50,T54) -> 524.97587
A44: Cash Flow From Operations | B44: =SUM(B45,B46,B47,B48) -> -52.006 | C44: =SUM(C45,C46,C47,C48) -> -78.815 | D44: =SUM(D45,D46,D47,D48) -> -59.517 | E44: =SUM(E45,E46,E47,E48) -> -31.791 | F44: =SUM(F45,F46,F47,F48) -> -33 | G44: =SUM(G45,G46,G47,G48) -> -124.308 | H44: =SUM(H45,H46,H47,H48) -> -130.1 | I44: =SUM(I45,I46,I47,I48) -> -135.1 | ... T44: =SUM(T45,T46,T47,T48) -> 524.77587
A45: Net income | B45: =B26 -> -56.17 | C45: =C26 -> -77.58 | D45: =D26 -> -52.185 | E45: =E26 -> -29.418 | F45: =F26 -> -33.5 | G45: =SUM(D45:F45) -> -115.103 | H45: =H26 -> -140 | I45: =I26 -> -150 | J45: =J26 -> -160 | K45: =K26 -> -180 | L45: =L26 -> -200 | M45: =M26 -> -160.71359 | N45: =N26 -> -135.43528 | O45: =O26 -> -14.506649 | ... T45: =T26 -> 492.79362
A46: SOE | B46: 1.045 | C46: 1.08 | D46: 0.36 | E46: =0.485-D46 -> 0.125 | F46: =F67*SUM(F8,F9) -> 0.35 | G46: =SUM(D46:F46) -> 0.835 | H46: =H67*SUM(H8,H9) -> 7 | I46: =I67*SUM(I8,I9) -> 12 | J46: =J67*SUM(J8,J9) -> 16 | K46: =K67*SUM(K8,K9) -> 18 | L46: =L67*SUM(L8,L9) -> 20 | M46: =M67*SUM(M8,M9) -> 17.5 | N46: =N67*SUM(N8,N9) -> 21 | O46: =O67*SUM(O8,O9) -> 19.082542 | ... T46: =T67*SUM(T8,T9) -> 29.082245
A47: D&A | B47: 0.556 | C47: 0.701 | D47: 0.302 | E47: =0.438-D47 -> 0.136 | F47: =0.6/4 -> 0.15 | G47: =SUM(D47:F47) -> 0.588 | H47: 2.9 | I47: =H47 -> 2.9 | J47: =I47 -> 2.9 | K47: =J47 -> 2.9 | L47: =K47 -> 2.9 | M47: =L47 -> 2.9 | N47: =M47 -> 2.9 | O47: =N47 -> 2.9 | P47: =O47 -> 2.9 | ... T47: =S47 -> 2.9
A48: Other | B48: 2.563 | C48: -3.016 | D48: -7.994 | E48: -2.634 | F48: 0 | G48: =SUM(D48:F48) -> -10.628 | H48: 0 | I48: 0 | J48: 0 | K48: 0 | L48: 0 | M48: 0 | N48: 0 | O48: 0 | P48: 0 | Q48: 0 | R48: 0 | S48: 0 | T48: 0
A50: Cash Flow From Investing | B50: =SUM(B51,B52) -> -0.462 | C50: =SUM(C51,C52) -> -80.788 | D50: =SUM(D51,D52) -> 54.934 | E50: =SUM(E51,E52) -> 0.433 | F50: =SUM(F51,F52) -> -0.1 | G50: =SUM(G51,G52) -> 55.267 | H50: =SUM(H51,H52) -> 0.2 | I50: =SUM(I51,I52) -> 0.2 | ... T50: =SUM(T51,T52) -> 0.2
A51: Purchase of PP&E | B51: -0.462 | C51: -0.77 | D51: -0.066 | E51: =-0.097-D51 -> -0.031 | F51: -0.1 | G51: =SUM(D51:F51) -> -0.197 | H51: 0.2 | I51: =H51 -> 0.2 | J51: =I51 -> 0.2 | K51: =J51 -> 0.2 | L51: =K51 -> 0.2 | M51: =L51 -> 0.2 | N51: =M51 -> 0.2 | O51: =N51 -> 0.2 | P51: =O51 -> 0.2 | ... T51: =S51 -> 0.2
A52: Other | B52: 0 | C52: =45-125.018 -> -80.018 | D52: 55 | E52: 0.464 | F52: 0 | G52: =SUM(D52:F52) -> 55.464 | H52: 0 | I52: 0 | J52: 0 | K52: 0 | L52: 0 | M52: 0 | N52: 0 | O52: 0 | P52: 0 | Q52: 0 | R52: 0 | S52: 0 | T52: 0
A54: Cash Flow From Financing | B54: =SUM(B56,B57,B58,B55) -> 104.572 | C54: =SUM(C56,C57,C58,C55) -> 118.06 | D54: =SUM(D56,D57,D58,D55) -> -0.203 | E54: =SUM(E56,E57,E58,E55) -> 198.058 | F54: =SUM(F56,F57,F58,F55) -> 262.3 | G54: =SUM(G56,G57,G58,G55) -> 460.155 | H54: =SUM(H56,H57,H58,H55) -> 200 | I54: =SUM(I56,I57,I58,I55) -> 0 | ... T54: =SUM(T56,T57,T58,T55) -> 0
...

Sheet Valuation
A1: MPLT DCF - $MM | D1: ='P&L'!G1 -> 2025E | E1: ='P&L'!H1 -> 2026E | F1: ='P&L'!I1 -> 2027E | G1: ='P&L'!J1 -> 2028E | H1: ='P&L'!K1 -> 2029E | I1: ='P&L'!L1 -> 2030E | J1: ='P&L'!M1 -> 2031E | K1: ='P&L'!N1 -> 2032E | ... P1: ='P&L'!S1 -> 2037E | Q1: 2038E | R1: TV
A3: CFO | D3: ='P&L'!G44 -> -124.308 | E3: ='P&L'!H44 -> -130.1 | F3: ='P&L'!I44 -> -135.1 | G3: ='P&L'!J44 -> -141.1 | H3: ='P&L'!K44 -> -159.1 | I3: ='P&L'!L44 -> -177.1 | J3: ='P&L'!M44 -> -140.31359 | K3: ='P&L'!N44 -> -111.53528 | ... Q3: ='P&L'!T44 -> 524.77587
A4: CFI | D4: ='P&L'!G50 -> 55.267 | E4: ='P&L'!H50 -> 0.2 | F4: ='P&L'!I50 -> 0.2 | G4: ='P&L'!J50 -> 0.2 | H4: ='P&L'!K50 -> 0.2 | I4: ='P&L'!L50 -> 0.2 | J4: ='P&L'!M50 -> 0.2 | K4: ='P&L'!N50 -> 0.2 | ... Q4: ='P&L'!T50 -> 0.2
A5: Net Borrowing | D5: ='P&L'!G56 -> 0 | E5: ='P&L'!H56 -> 0 | F5: ='P&L'!I56 -> 0 | G5: ='P&L'!J56 -> 0 | H5: ='P&L'!K56 -> 0 | I5: ='P&L'!L56 -> 0 | J5: ='P&L'!M56 -> 0 | K5: ='P&L'!N56 -> 0 | ... Q5: ='P&L'!T56 -> 0
A7: FCF | D7: =SUM(D3:D5) -> -69.041 | E7: =SUM(E3:E5) -> -129.9 | F7: =SUM(F3:F5) -> -134.9 | G7: =SUM(G3:G5) -> -140.9 | H7: =SUM(H3:H5) -> -158.9 | I7: =SUM(I3:I5) -> -176.9 | J7: =SUM(J3:J5) -> -140.11359 | K7: =SUM(K3:K5) -> -111.33528 | ... Q7: =SUM(Q3:Q5) -> 524.97587 | R7: =Q7*(1+C20)/(C19-C20) -> 4772.5079
A9: Period | D9: 0 | E9: =D9+1 -> 1 | F9: =E9+1 -> 2 | G9: =F9+1 -> 3 | H9: =G9+1 -> 4 | I9: =H9+1 -> 5 | J9: =I9+1 -> 6 | K9: =J9+1 -> 7 | L9: =K9+1 -> 8 | ... Q9: =P9+1 -> 13
A11: PV FCF | D11: =D7/(1+$C$19)^D9 -> -69.041 | E11: =E7/(1+$C$19)^E9 -> -117.02703 | F11: =F7/(1+$C$19)^F9 -> -109.48787 | G11: =G7/(1+$C$19)^G9 -> -103.02487 | H11: =H7/(1+$C$19)^H9 -> -104.67235 | I11: =I7/(1+$C$19)^I9 -> -104.98154 | J11: =J7/(1+$C$19)^J9 -> -74.910448 | K11: =K7/(1+$C$19)^K9 -> -53.625576 | ... Q11: =Q7/(1+$C$19)^Q9 -> 135.18877 | R11: =R7/(1+$C$19)^Q9 -> 1228.9888
A13: Total FCF, PV | C13: =SUM(D11:R11) -> 1051.5503
A14: Net Cash 4Q25E | C14: ='P&L'!F39 -> 456.4
A15: Implied Market Capitalization | C15: =C13+C14 -> 1507.9503
A16: Diluted Shares Outstanding 4Q25E | C16: =45.373033+0.93301+6.212236+0.727405+0.035476 -> 53.28116
A17: NPV Per Share | C17: =C15/C16 -> 28.301753
A19: Discount Rate | C19: 0.11
A20: Terminal Growth Rate | C20: 0
A21: Source: Company Filings, Stifel estimates. Note: Diluted share count includes options and RSUs.

Sheet Revenue
A1: Product Revenues & Royalties ($MM) | D1: 2022 | E1: ='P&L'!B1 -> 2023 | F1: ='P&L'!C1 -> 2024 | G1: 1H25 | H1: 3Q25E | I1: 4Q25E | J1: ='P&L'!G1 -> 2025E | K1: ='P&L'!H1 -> 2026E | L1: ='P&L'!I1 -> 2027E | M1: ='P&L'!J1 -> 2028E | N1: ='P&L'!K1 -> 2029E | O1: ='P&L'!L1 -> 2030E | P1: ='P&L'!M1 -> 2031E | Q1: ='P&L'!N1 -> 2032E | ... W1: ='P&L'!T1 -> 2038E
A3: ML-007C-MA, Schizophrenia - WW Gross Revenues | D3: =Schizophrenia!C36 -> 0 | E3: =Schizophrenia!D36 -> 0 | F3: =Schizophrenia!E42 -> 0 | G3: 0 | H3: 0 | I3: 0 | J3: =Schizophrenia!F42 -> 0 | K3: =Schizophrenia!G42 -> 0 | L3: =Schizophrenia!H42 -> 0 | M3: =Schizophrenia!I42 -> 0 | N3: =Schizophrenia!J42 -> 0 | O3: =Schizophrenia!K42 -> 0 | P3: =Schizophrenia!L42 -> 31.05741 | Q3: =Schizophrenia!M42 -> 107.9617 | ... W3: =Schizophrenia!S42 -> 1225.8719
A4: ML-007C-MA, Schizophrenia - WW Risk-Adjusted Revenues | B4: =Schizophrenia!B35 -> 0.5 | D4: =Schizophrenia!C43 -> 0 | E4: =Schizophrenia!D43 -> 0 | F4: =Schizophrenia!E43 -> 0 | G4: 0 | H4: 0 | I4: 0 | J4: =Schizophrenia!F43 -> 0 | K4: =Schizophrenia!G43 -> 0 | L4: =Schizophrenia!H43 -> 0 | M4: =Schizophrenia!I43 -> 0 | N4: =Schizophrenia!J43 -> 0 | O4: =Schizophrenia!K43 -> 0 | P4: =Schizophrenia!L43 -> 15.528705 | Q4: =Schizophrenia!M43 -> 53.98085 | ... W4: =Schizophrenia!S43 -> 612.93593
A6: ML-007C-MA, Alzheimer's Disease Psychosis - WW Gross Revenues | D6: =ADP!C33 -> 0 | E6: =ADP!D33 -> 0 | F6: =ADP!E33 -> 0 | G6: 0 | H6: 0 | I6: 0 | J6: =ADP!F33 -> 0 | K6: =ADP!G33 -> 0 | L6: =ADP!H33 -> 0 | M6: =ADP!I33 -> 0 | N6: =ADP!J33 -> 0 | O6: =ADP!K33 -> 0 | P6: =ADP!L33 -> 0 | Q6: =ADP!M33 -> 127.83877 | ... W6: =ADP!S33 -> 1864.5005
A7: ML-007C-MA, Alzheimer's Disease Psychosis - WW Risk-Adjusted Revenues | B7: 0.15 | D7: =ADP!C34 -> 0 | E7: =ADP!D34 -> 0 | F7: =ADP!E34 -> 0 | G7: =G6*$B7 -> 0 | H7: =H6*$B7 -> 0 | I7: =I6*$B7 -> 0 | J7: =ADP!F34 -> 0 | K7: =ADP!G34 -> 0 | L7: =ADP!H34 -> 0 | M7: =ADP!I34 -> 0 | N7: =ADP!J34 -> 0 | O7: =ADP!K34 -> 0 | P7: =ADP!L34 -> 0 | Q7: =ADP!M34 -> 25.567755 | ... W7: =ADP!S34 -> 372.90009
A9: ML-004, Autism Spectrum Disorder - WW Gross Revenues | D9: 0 | E9: 0 | F9: 0 | G9: 0 | H9: 0 | I9: 0 | J9: 0 | K9: 0 | L9: 0 | M9: 0 | N9: 0 | O9: 0 | P9: 0 | Q9: 30 | R9: 120 | S9: 180 | T9: 220 | U9: 260 | V9: 300 | W9: 340
A10: ML-004, Autism Spectrum Disorder - WW Risk-Adjusted Revenues | B10: 0.05 | D10: =D9*$B10 -> 0 | E10: =E9*$B10 -> 0 | F10: 0 | G10: =G9*$B10 -> 0 | H10: =H9*$B10 -> 0 | I10: =I9*$B10 -> 0 | J10: 0 | K10: 0 | L10: 0 | M10: 0 | N10: 0 | O10: 0 | P10: =P9*$B10 -> 0 | Q10: =Q9*$B10 -> 1.5 | R10: =R9*$B10 -> 6 | S10: =S9*$B10 -> 9 | T10: =T9*$B10 -> 11 | U10: =U9*$B10 -> 13 | V10: =V9*$B10 -> 15 | W10: =W9*$B10 -> 17
A12: Other Pipeline (i.e., ML-021, ML-009) | B12: 0 | D12: 0 | E12: 0 | F12: 0 | G12: 0 | H12: 0 | I12: 0 | J12: 0 | K12: 0 | L12: 0 | M12: 0 | N12: 0 | O12: 0 | P12: 0 | Q12: 0 | R12: 0 | S12: 0 | T12: 0 | U12: 0 | V12: 0 | W12: 0
A14: Total Product Revenues - WW Gross Revenues | D14: =SUM(D$12,D6,D3) -> 0 | E14: =SUM(E$12,E6,E3) -> 0 | F14: =SUM(F$12,F6,F3) -> 0 | G14: =SUM(G$12,G6,G3) -> 0 | H14: =SUM(H$12,H6,H3) -> 0 | I14: =SUM(I$12,I6,I3) -> 0 | J14: =SUM(J$12,J6,J3) -> 0 | K14: =SUM(K$12,K6,K3) -> 0 | ... O14: =SUM(O$12,O6,O3) -> 0 | P14: =SUM(P$12,P9,P6,P3) -> 31.05741 | Q14: =SUM(Q$12,Q9,Q6,Q3) -> 265.80047 | R14: =SUM(R$12,R9,R6,R3) -> 730.7079 | S14: =SUM(S$12,S9,S6,S3) -> 1277.8968 | T14: =SUM(T$12,T9,T6,T3) -> 1800.4786 | U14: =SUM(U$12,U9,U6,U3) -> 2277.7851 | V14: =SUM(V$12,V9,V6,V3) -> 2863.0395 | W14: =SUM(W$12,W9,W6,W3) -> 3430.3723
A15: Total Product Revenues - WW Risk-Adjusted Revenues | D15: =SUM(D7,D4,D12) -> 0 | E15: =SUM(E7,E4,E12) -> 0 | F15: =SUM(F7,F4,F12) -> 0 | G15: =SUM(G7,G4,G12) -> 0 | H15: =SUM(H7,H4,H12) -> 0 | I15: =SUM(I7,I4,I12) -> 0 | J15: =SUM(J7,J4,J12) -> 0 | K15: =SUM(K7,K4,K12) -> 0 | ... O15: =SUM(O7,O4,O12) -> 0 | P15: =SUM(P7,P4,P10,P12) -> 15.528705 | Q15: =SUM(Q7,Q4,Q10,Q12) -> 81.048604 | R15: =SUM(R7,R4,R10,R12) -> 191.65084 | S15: =SUM(S7,S4,S10,S12) -> 348.30754 | T15: =SUM(T7,T4,T10,T12) -> 509.27378 | U15: =SUM(U7,U4,U10,U12) -> 657.91866 | V15: =SUM(V7,V4,V10,V12) -> 851.45569 | W15: =SUM(W7,W4,W10,W12) -> 1002.836
A18: Source: Stifel Estimates & Company Filings

Sheet Schizophrenia
A1: MPLT Schizophrenia Revenue Model | C1: 2022 | D1: ='P&L'!B1 -> 2023 | E1: ='P&L'!C1 -> 2024 | F1: ='P&L'!G1 -> 2025E | G1: ='P&L'!H1 -> 2026E | H1: ='P&L'!I1 -> 2027E | I1: ='P&L'!J1 -> 2028E | J1: ='P&L'!K1 -> 2029E | K1: ='P&L'!L1 -> 2030E | L1: ='P&L'!M1 -> 2031E | M1: ='P&L'!N1 -> 2032E | ... P1: ='P&L'!Q1 -> 2035E | Q1: 2036E | R1: 2037E | S1: 2038E
A3: Schizophrenia Model: U.S.
A5: US Schizophrenia Patients - Adults | B5: 2900000 | C5: =B5*(1+B6) -> 2905800 | D5: =C5*(1+C6) -> 2911611.6 | E5: =D5*(1+D6) -> 2917434.8 | F5: =E5*(1+E6) -> 2923269.7 | G5: =F5*(1+F6) -> 2929116.2 | H5: =G5*(1+G6) -> 2934974.5 | I5: =H5*(1+H6) -> 2940844.4 | J5: =I5*(1+I6) -> 2946726.1 | ... S5: =R5*(1+R6) -> 3000193.5
A6: y/y growth rate | B6: 0.002 | C6: =B6 -> 0.002 | D6: =C6 -> 0.002 | E6: =D6 -> 0.002 | F6: =E6 -> 0.002 | G6: =F6 -> 0.002 | H6: =G6 -> 0.002 | I6: =H6 -> 0.002 | J6: =I6 -> 0.002 | ... S6: =R6 -> 0.002
A7: 1st / 2nd/3rd Line Tx Success | B7: =1-B8 -> 0.55 | C7: =C$5*$B7 -> 1598190 | D7: =D$5*$B7 -> 1601386.4 | E7: =E$5*$B7 -> 1604589.2 | F7: =F$5*$B7 -> 1607798.3 | G7: =G$5*$B7 -> 1611013.9 | H7: =H$5*$B7 -> 1614236 | I7: =I$5*$B7 -> 1617464.4 | J7: =J$5*$B7 -> 1620699.4 | ... S7: =S$5*$B7 -> 1650106.4
A8: Treatment Resistant - Physician Survey | B8: 0.45 | C8: =C$5*$B8 -> 1307610 | D8: =D$5*$B8 -> 1310225.2 | E8: =E$5*$B8 -> 1312845.7 | F8: =F$5*$B8 -> 1315471.4 | G8: =G$5*$B8 -> 1318102.3 | H8: =H$5*$B8 -> 1320738.5 | I8: =I$5*$B8 -> 1323380 | J8: =J$5*$B8 -> 1326026.7 | ... S8: =S$5*$B8 -> 1350087.1
A10: Muscarinic Penetration
A11: 1st / 2nd/3rd Line Tx | C11: 0 | D11: 0 | E11: 0 | F11: 0 | G11: 0 | H11: 0 | I11: 0 | J11: 0 | K11: 0 | L11: 0 | M11: 0.005 | N11: 0.02 | O11: 0.02 | P11: 0.03 | Q11: 0.03 | R11: 0.04 | S11: 0.04
A12: Treatment Resistant | C12: 0 | D12: 0 | E12: 0.001 | F12: 0.02 | G12: 0.05 | H12: 0.1 | I12: 0.15 | J12: 0.2 | K12: 0.24 | L12: 0.27 | M12: 0.3 | N12: 0.3 | O12: 0.3 | P12: 0.3 | Q12: 0.3 | R12: 0.3 | S12: 0.3
A14: ML-007C-MA (M1/M4 Agonist + PAC) | C14: 0 | D14: 0 | E14: 0 | F14: 0 | G14: 0 | H14: 0 | I14: 0 | J14: 0 | K14: 0 | L14: 0.01 | M14: 0.03 | N14: 0.05 | O14: 0.09 | P14: 0.12 | Q14: 0.15 | R14: 0.18 | S14: 0.2
A15: KarXT (M1/M4-Preferring Agonist + Trospium) | C15: 0 | D15: 0 | E15: 1 | F15: 1 | G15: 1 | H15: 1 | I15: 1 | J15: 0.99 | K15: 0.97 | L15: 0.94 | M15: 0.89 | N15: 0.84 | O15: 0.77 | P15: 0.7 | Q15: 0.63 | R15: 0.56 | S15: 0.5
A16: Other | C16: 0 | D16: 0 | E16: 0 | F16: 0 | G16: 0 | H16: 0 | I16: 0 | J16: 0.01 | K16: 0.03 | L16: 0.05 | M16: 0.08 | N16: 0.11 | O16: 0.14 | P16: 0.18 | Q16: 0.22 | R16: 0.26 | S16: 0.3
A17: SUM | C17: =SUM(C14:C16) -> 0 | D17: =SUM(D14:D16) -> 0 | E17: =SUM(E14:E16) -> 1 | F17: =SUM(F14:F16) -> 1 | G17: =SUM(G14:G16) -> 1 | H17: =SUM(H14:H16) -> 1 | I17: =SUM(I14:I16) -> 1 | J17: =SUM(J14:J16) -> 1 | ... S17: =SUM(S14:S16) -> 1
A19: ML-007C-MA US Patients
A20: 1st / 2nd/3rd Line Tx | C20: =C7*C11*C14 -> 0 | D20: =D7*D11*D14 -> 0 | E20: =E7*E11*E14 -> 0 | F20: =F7*F11*F14 -> 0 | G20: =G7*G11*G14 -> 0 | H20: =H7*H11*H14 -> 0 | I20: =I7*I11*I14 -> 0 | J20: =J7*J11*J14 -> 0 | ... S20: =S7*S11*S14 -> 13200.851
A21: Treatment Resistant | C21: =C12*C8*C14 -> 0 | D21: =D12*D8*D14 -> 0 | E21: =E12*E8*E14 -> 0 | F21: =F12*F8*F14 -> 0 | G21: =G12*G8*G14 -> 0 | H21: =H12*H8*H14 -> 0 | I21: =I12*I8*I14 -> 0 | J21: =J12*J8*J14 -> 0 | ... L21: =L12*L8*L14 -> 3594.6076 | M21: =(M12*M8*M14) -> 12005.989 | N21: =(N12*N8*N14) + (N7*N11*N14) -> 21683.706 | O21: =(O12*O8*O14) + (O7*O11*O14) -> 39108.733 | P21: =(P12*P8*P14) + (P7*P11*P14) -> 54217.561 | Q21: =(Q12*Q8*Q14) + (Q7*Q11*Q14) -> 67907.495 | R21: =(R12*R8*R14) + (R7*R11*R14) -> 84616.235 | S21: =(S12*S8*S14) + (S7*S11*S14) -> 94206.075
A22: Total Patients on ML-007C-MA | C22: =SUM(C20:C21) -> 0 | D22: =SUM(D20:D21) -> 0 | E22: =SUM(E20:E21) -> 0 | F22: =SUM(F20:F21) -> 0 | G22: =SUM(G20:G21) -> 0 | H22: =SUM(H20:H21) -> 0 | I22: =SUM(I20:I21) -> 0 | J22: =SUM(J20:J21) -> 0 | ... S22: =SUM(S20:S21) -> 107406.93
A23: Total Muscarinic Penetration in Schizophrenia | E23: =(E7*E11)+(E8*E12) -> 1312.8457 | F23: =(F7*F11)+(F8*F12) -> 26309.427 | G23: =(G7*G11)+(G8*G12) -> 65905.115 | H23: =(H7*H11)+(H8*H12) -> 132073.85 | I23: =(I7*I11)+(I8*I12) -> 198507 | J23: =(J7*J11)+(J8*J12) -> 265205.35 | K23: =(K7*K11)+(K8*K12) -> 318882.91 | L23: =(L7*L11)+(L8*L12) -> 359460.76 | ... S23: =(S7*S11)+(S8*S12) -> 471030.38
A26: ML-007C-MA Gross Annual Cost | B26: =B49 -> 24000 | L26: =$B$26 -> 24000 | M26: =L26*(1+M27) -> 24480 | N26: =M26*(1+N27) -> 24969.6 | O26: =N26*(1+O27) -> 25468.992 | P26: =O26*(1+P27) -> 25978.372 | Q26: =P26*(1+Q27) -> 26497.939 | R26: =Q26*(1+R27) -> 27027.898 | S26: =R26*(1+S27) -> 27568.456
A27: y/y price growth | B27: =B50 -> 0.02 | L27: =B27 -> 0.02 | M27: =L27 -> 0.02 | N27: =M27 -> 0.02 | O27: =N27 -> 0.02 | P27: =O27 -> 0.02 | Q27: =P27 -> 0.02 | R27: =Q27 -> 0.02 | S27: =R27 -> 0.02
A28: Gross to Net Adjustment | B28: =B51 -> 0.4 | C28: =B28 -> 0.4 | D28: =C28 -> 0.4 | E28: =D28 -> 0.4 | F28: =E28 -> 0.4 | G28: =F28 -> 0.4 | H28: =G28 -> 0.4 | I28: =H28 -> 0.4 | J28: =I28 -> 0.4 | ... S28: =R28 -> 0.4
A29: Annual Net Cost | L29: =L26*(1-L28) -> 14400 | M29: =M26*(1-M28) -> 14688 | N29: =N26*(1-N28) -> 14981.76 | O29: =O26*(1-O28) -> 15281.395 | P29: =P26*(1-P28) -> 15587.023 | Q29: =Q26*(1-Q28) -> 15898.764 | R29: =R26*(1-R28) -> 16216.739 | S29: =S26*(1-S28) -> 16541.074
A30: Compliance Rate | B30: 0.6 | C30: =B30 -> 0.6 | D30: =C30 -> 0.6 | E30: =D30 -> 0.6 | F30: =E30 -> 0.6 | G30: =F30 -> 0.6 | H30: =G30 -> 0.6 | I30: =H30 -> 0.6 | J30: =I30 -> 0.6 | ... S30: =R30 -> 0.6
A34: ML-007C-MA U.S. Schizophrenia ($MM), gross | C34: =C22*C29*C30/1000000 -> 0 | D34: =D22*D29*D30/1000000 -> 0 | E34: =E22*E29*E30/1000000 -> 0 | F34: =F22*F29*F30/1000000 -> 0 | G34: =G22*G29*G30/1000000 -> 0 | H34: =H22*H29*H30/1000000 -> 0 | I34: =I22*I29*I30/1000000 -> 0 | J34: =J22*J29*J30/1000000 -> 0 | ... S34: =S22*S29*S30/1000000 -> 1065.9755
A35: Probability-of-success | B35: =B48 -> 0.5 | C35: =B35 -> 0.5 | D35: =C35 -> 0.5 | E35: =D35 -> 0.5 | F35: =E35 -> 0.5 | G35: =F35 -> 0.5 | H35: =G35 -> 0.5 | I35: =H35 -> 0.5 | J35: =I35 -> 0.5 | ... S35: =R35 -> 0.5
A36: Risk-Adjusted ML-007C-MA U.S. Schizophrenia Sales ($MM) | C36: =+C35*C34 -> 0 | D36: =+D35*D34 -> 0 | E36: =+E35*E34 -> 0 | F36: =+F35*F34 -> 0 | G36: =+G35*G34 -> 0 | H36: =+H35*H34 -> 0 | I36: =+I35*I34 -> 0 | J36: =+J35*J34 -> 0 | ... S36: =+S35*S34 -> 532.98777
A38: ROW as a % of US | C38: 0 | D38: 0 | E38: 0 | F38: 0 | G38: 0 | H38: 0 | I38: 0 | J38: 0 | K38: 0 | L38: 0 | M38: 0 | N38: 0.01 | O38: 0.035 | P38: 0.08 | Q38: 0.12 | R38: 0.15 | S38: 0.15
A39: Gross ML-007C-MA ROW Schizophrenia ($MM) | C39: =+C38*C34 -> 0 | D39: =+D38*D34 -> 0 | E39: =+E38*E34 -> 0 | F39: =+F38*F34 -> 0 | G39: =+G38*G34 -> 0 | H39: =+H38*H34 -> 0 | I39: =+I38*I34 -> 0 | J39: =+J38*J34 -> 0 | ... S39: =+S38*S34 -> 159.89633
A40: Risk-Adjusted ML-007C-MA ROW Schizophrenia ($MM) | C40: =+C39*C35 -> 0 | D40: =+D39*D35 -> 0 | E40: =+E39*E35 -> 0 | F40: =+F39*F35 -> 0 | G40: =G38*G36 -> 0 | H40: =H38*H36 -> 0 | I40: =I38*I36 -> 0 | J40: =J38*J36 -> 0 | K40: =K38*K36 -> 0 | L40: =L38*L36 -> 0 | M40: =M38*M36 -> 0 | N40: =N38*N36 -> 1.0480075 | ... S40: =S38*S36 -> 79.948165
A42: Gross ML-007C-MA Schizophrenia Sales ($MM) | C42: =+C39+C34 -> 0 | D42: =+D39+D34 -> 0 | E42: =+E39+E34 -> 0 | F42: =+F39+F34 -> 0 | G42: =+G39+G34 -> 0 | H42: =+H39+H34 -> 0 | I42: =+I39+I34 -> 0 | J42: =+J39+J34 -> 0 | ... S42: =+S39+S34 -> 1225.8719
A43: Risk-Adjusted WW ML-007C-MA Schizophrenia Sales ($MM) | C43: =+C40+C36 -> 0 | D43: =+D40+D36 -> 0 | E43: =+E40+E36 -> 0 | F43: =+F40+F36 -> 0 | G43: =G40+G36 -> 0 | H43: =H40+H36 -> 0 | I43: =I40+I36 -> 0 | J43: =J40+J36 -> 0 | K43: =K40+K36 -> 0 | L43: =L40+L36 -> 15.528705 | M43: =M40+M36 -> 53.98085 | N43: =N40+N36 -> 105.84876 | ... S43: =S40+S36 -> 612.93593
A47: Key Assumptions
A48: Probability of Success | B48: 0.5
A49: ML-007C-MA Gross Annual WAC | B49: 24000
A50: Annual price increase, US | B50: 0.02
A51: Gross/net discount | B51: 0.4

Sheet ADP
A1: MPLT Schizophrenia Revenue Model | C1: 2022 | D1: ='P&L'!B1 -> 2023 | E1: ='P&L'!C1 -> 2024 | F1: ='P&L'!G1 -> 2025E | G1: ='P&L'!H1 -> 2026E | H1: ='P&L'!I1 -> 2027E | I1: ='P&L'!J1 -> 2028E | J1: ='P&L'!K1 -> 2029E | K1: ='P&L'!L1 -> 2030E | L1: ='P&L'!M1 -> 2031E | M1: ='P&L'!N1 -> 2032E | ... P1: ='P&L'!Q1 -> 2035E | Q1: 2036E | R1: 2037E | S1: 2038E
A3: Alzheimer's Model: U.S.
A5: US Dementia Patients | B5: 8500000 | C5: =B5*(1+B6) -> 8670000 | D5: =C5*(1+C6) -> 8843400 | E5: =D5*(1+D6) -> 9020268 | F5: =E5*(1+E6) -> 9200673.4 | G5: =F5*(1+F6) -> 9384686.8 | H5: =G5*(1+G6) -> 9572380.6 | I5: =H5*(1+H6) -> 9763828.2 | J5: =I5*(1+I6) -> 9959104.7 | ... S5: =R5*(1+R6) -> 11902052
A6: y/y growth rate | B6: 0.02 | C6: =B6 -> 0.02 | D6: =C6 -> 0.02 | E6: =D6 -> 0.02 | F6: =E6 -> 0.02 | G6: =F6 -> 0.02 | H6: =G6 -> 0.02 | I6: =H6 -> 0.02 | J6: =I6 -> 0.02 | ... S6: =R6 -> 0.02
A7: % with AD Dementia | B7: 0.7 | C7: =B7 -> 0.7 | D7: =C7 -> 0.7 | E7: =D7 -> 0.7 | F7: =E7 -> 0.7 | G7: =F7 -> 0.7 | H7: =G7 -> 0.7 | I7: =H7 -> 0.7 | J7: =I7 -> 0.7 | ... S7: =R7 -> 0.7
A8: % with AD Psychosis | B8: 0.2 | C8: =B8 -> 0.2 | D8: =C8 -> 0.2 | E8: =D8 -> 0.2 | F8: =E8 -> 0.2 | G8: =F8 -> 0.2 | H8: =G8 -> 0.2 | I8: =H8 -> 0.2 | J8: =I8 -> 0.2 | ... S8: =R8 -> 0.2
A9: % Diagnosed | B9: 0.5 | C9: =B9 -> 0.5 | D9: =C9 -> 0.5 | E9: =D9 -> 0.5 | F9: =E9 -> 0.5 | G9: =F9 -> 0.5 | H9: =G9 -> 0.5 | I9: =H9 -> 0.5 | J9: =I9 -> 0.5 | ... S9: =R9 -> 0.5
A10: Total ADP Patients in US | C10: =C5*C7*C8*C9 -> 606900 | D10: =D5*D7*D8*D9 -> 619038 | E10: =E5*E7*E8*E9 -> 631418.76 | F10: =F5*F7*F8*F9 -> 644047.14 | G10: =G5*G7*G8*G9 -> 656928.08 | H10: =H5*H7*H8*H9 -> 670066.64 | I10: =I5*I7*I8*I9 -> 683467.97 | J10: =J5*J7*J8*J9 -> 697137.33 | ... S10: =S5*S7*S8*S9 -> 833143.64
A12: Muscarinic Penetration
A13: ML-007C-MA (M1/M4 Agonist + PAC) | C13: 0 | D13: 0 | E13: 0 | F13: 0 | G13: 0 | H13: 0 | I13: 0 | J13: 0 | K13: 0 | L13: 0 | M13: 0.02 | N13: 0.06 | O13: 0.1 | P13: 0.13 | Q13: 0.15 | R13: 0.17 | S13: 0.2
A14: Total Patients on ML-007C-MA | M14: =M10*M13 -> 14796.154 | N14: =N10*N13 -> 45276.232 | O14: =O10*O13 -> 76969.595 | P14: =P10*P13 -> 102061.68 | Q14: =Q10*Q13 -> 120118.75 | R14: =R10*R13 -> 138857.27 | S14: =S10*S13 -> 166628.73
A17: ML-007C-MA Gross Annual Cost | B17: =B40 -> 24000 | M17: =$B$17 -> 24000 | N17: =M17*(1+N18) -> 24480 | O17: =N17*(1+O18) -> 24969.6 | P17: =O17*(1+P18) -> 25468.992 | Q17: =P17*(1+Q18) -> 25978.372 | R17: =Q17*(1+R18) -> 26497.939 | S17: =R17*(1+S18) -> 27027.898
A18: y/y price growth | B18: =B41 -> 0.02 | M18: =B18 -> 0.02 | N18: =M18 -> 0.02 | O18: =N18 -> 0.02 | P18: =O18 -> 0.02 | Q18: =P18 -> 0.02 | R18: =Q18 -> 0.02 | S18: =R18 -> 0.02
A19: Gross to Net Adjustment | B19: =B42 -> 0.4 | C19: =B19 -> 0.4 | D19: =C19 -> 0.4 | E19: =D19 -> 0.4 | F19: =E19 -> 0.4 | G19: =F19 -> 0.4 | H19: =G19 -> 0.4 | I19: =H19 -> 0.4 | J19: =I19 -> 0.4 | ... S19: =R19 -> 0.4
A20: Annual Net Cost | M20: =M17*(1-M19) -> 14400 | N20: =N17*(1-N19) -> 14688 | O20: =O17*(1-O19) -> 14981.76 | P20: =P17*(1-P19) -> 15281.395 | Q20: =Q17*(1-Q19) -> 15587.023 | R20: =R17*(1-R19) -> 15898.764 | S20: =S17*(1-S19) -> 16216.739
A21: Compliance Rate | B21: 0.6 | C21: =B21 -> 0.6 | D21: =C21 -> 0.6 | E21: =D21 -> 0.6 | F21: =E21 -> 0.6 | G21: =F21 -> 0.6 | H21: =G21 -> 0.6 | I21: =H21 -> 0.6 | J21: =I21 -> 0.6 | ... S21: =R21 -> 0.6
A25: ML-007C-MA U.S. ADP ($MM), gross | C25: =C14*C20*C21/1000000 -> 0 | D25: =D14*D20*D21/1000000 -> 0 | E25: =E14*E20*E21/1000000 -> 0 | F25: =F14*F20*F21/1000000 -> 0 | G25: =G14*G20*G21/1000000 -> 0 | H25: =H14*H20*H21/1000000 -> 0 | I25: =I14*I20*I21/1000000 -> 0 | J25: =J14*J20*J21/1000000 -> 0 | ... S25: =S14*S20*S21/1000000 -> 1621.3047
A26: Probability-of-success | B26: =B39 -> 0.2 | C26: =B26 -> 0.2 | D26: =C26 -> 0.2 | E26: =D26 -> 0.2 | F26: =E26 -> 0.2 | G26: =F26 -> 0.2 | H26: =G26 -> 0.2 | I26: =H26 -> 0.2 | J26: =I26 -> 0.2 | ... S26: =R26 -> 0.2
A27: Risk-Adjusted ML-007C-MA U.S. ADP Sales ($MM) | C27: =+C26*C25 -> 0 | D27: =+D26*D25 -> 0 | E27: =+E26*E25 -> 0 | F27: =+F26*F25 -> 0 | G27: =+G26*G25 -> 0 | H27: =+H26*H25 -> 0 | I27: =+I26*I25 -> 0 | J27: =+J26*J25 -> 0 | ... S27: =+S26*S25 -> 324.26095
A29: ROW as a % of US | C29: 0 | D29: 0 | E29: 0 | F29: 0 | G29: 0 | H29: 0 | I29: 0 | J29: 0 | K29: 0 | L29: 0 | M29: 0 | N29: 0 | O29: 0.01 | P29: 0.04 | Q29: 0.08 | R29: 0.12 | S29: 0.15
A30: Gross ML-007C-MA ROW ADP ($MM) | C30: =+C29*C25 -> 0 | D30: =+D29*D25 -> 0 | E30: =+E29*E25 -> 0 | F30: =+F29*F25 -> 0 | G30: =+G29*G25 -> 0 | H30: =+H29*H25 -> 0 | I30: =+I29*I25 -> 0 | J30: =+J29*J25 -> 0 | ... S30: =+S29*S25 -> 243.19571
A31: Risk-Adjusted ML-007C-MA ROW AD ($MM) | C31: =+C30*C26 -> 0 | D31: =+D30*D26 -> 0 | E31: =+E30*E26 -> 0 | F31: =+F30*F26 -> 0 | G31: =G29*G27 -> 0 | H31: =H29*H27 -> 0 | I31: =I29*I27 -> 0 | J31: =J29*J27 -> 0 | K31: =K29*K27 -> 0 | L31: =L29*L27 -> 0 | M31: =M29*M27 -> 0 | N31: =N29*N27 -> 0 | ... S31: =S29*S27 -> 48.639142
A33: Gross ML-007C-MA ADP Sales ($MM) | C33: =+C30+C25 -> 0 | D33: =+D30+D25 -> 0 | E33: =+E30+E25 -> 0 | F33: =+F30+F25 -> 0 | G33: =+G30+G25 -> 0 | H33: =+H30+H25 -> 0 | I33: =+I30+I25 -> 0 | J33: =+J30+J25 -> 0 | ... S33: =+S30+S25 -> 1864.5005
A34: Risk-Adjusted WW ML-007C-MA ADP Sales ($MM) | C34: =+C31+C27 -> 0 | D34: =+D31+D27 -> 0 | E34: =+E31+E27 -> 0 | F34: =+F31+F27 -> 0 | G34: =G31+G27 -> 0 | H34: =H31+H27 -> 0 | I34: =I31+I27 -> 0 | J34: =J31+J27 -> 0 | K34: =K31+K27 -> 0 | L34: =L31+L27 -> 0 | M34: =M31+M27 -> 25.567755 | N34: =N31+N27 -> 79.802076 | ... S34: =S31+S27 -> 372.90009
A38: Key Assumptions
A39: Probability of Success | B39: 0.2
A40: ML-007C-MA Gross Annual WAC | B40: 24000
A41: Annual price increase, US | B41: 0.02
A42: Gross/net discount | B42: 0.4

Sheet Multiple Sclerosis
A1: Contineum Multiple Sclerosis Revenue Model | C1: 2020 | D1: 2021 | E1: 2022 | F1: ='P&L'!B1 -> 2023 | G1: ='P&L'!C1 -> 2024 | H1: ='P&L'!G1 -> 2025E | I1: ='P&L'!H1 -> 2026E | J1: ='P&L'!I1 -> 2027E | K1: ='P&L'!J1 -> 2028E | L1: ='P&L'!K1 -> 2029E | M1: ='P&L'!L1 -> 2030E | N1: ='P&L'!M1 -> 2031E | O1: ='P&L'!N1 -> 2032E | ... R1: ='P&L'!Q1 -> 2035E | S1: 2036E | T1: 2037E | U1: 2038E
A3: Multiple Sclerosis Model: U.S.
A5: Estimated US Adults | B5: 0.022 | C5: 2.5882854e+08 | D5: =+C5*(1+$B$5) -> 2.6452277e+08 | E5: =+D5*(1+$B$5) -> 2.7034227e+08 | F5: =+E5*(1+$B$5) -> 2.762898e+08 | G5: =+F5*(1+$B$5) -> 2.8236818e+08 | H5: =+G5*(1+$B$5) -> 2.8858028e+08 | I5: =+H5*(1+$B$5) -> 2.9492904e+08 | J5: =+I5*(1+$B$5) -> 3.0141748e+08 | K5: =+J5*(1+$B$5) -> 3.0804867e+08 | ... U5: =+T5*(1+$B$5) -> 3.8293785e+08
A6: Multiple Sclerosis Prevalence | B6: 0.00125 | C6: =C5*B6 -> 323535.68 | D6: =D5*B6 -> 330653.46 | E6: =E5*B6 -> 337927.84 | F6: =F5*B6 -> 345362.25 | G6: =G5*B6 -> 352960.22 | H6: =H5*B6 -> 360725.35 | I6: =I5*B6 -> 368661.31 | J6: =J5*B6 -> 376771.85 | K6: =K5*B6 -> 385060.83 | L6: =L5*B6 -> 393532.17 | M6: =M5*B6 -> 402189.88 | N6: =N5*B6 -> 411038.06 | O6: =O5*B6 -> 420080.9 | P6: =P5*B6 -> 429322.68 | Q6: =Q5*B6 -> 438767.77 | R6: =R5*B6 -> 448420.67 | S6: =S5*B6 -> 458285.92 | T6: =T5*B6 -> 468368.21 | U6: =U5*B6 -> 478672.31
A7: Multiple Sclerosis Patient Population | C7: =C6 -> 323535.68 | D7: =D6 -> 330653.46 | E7: =E6 -> 337927.84 | F7: =F6 -> 345362.25 | G7: =G6 -> 352960.22 | H7: =H6 -> 360725.35 | I7: =I6 -> 368661.31 | J7: =J6 -> 376771.85 | ... U7: =U6 -> 478672.31
A9: RRMS Prevalence | B9: 0.55 | C9: =C7*B9 -> 177944.62 | D9: =D7*B9 -> 181859.41 | E9: =E7*B9 -> 185860.31 | F9: =F7*B9 -> 189949.24 | G9: =G7*B9 -> 194128.12 | H9: =H7*B9 -> 198398.94 | I9: =I7*B9 -> 202763.72 | J9: =J7*B9 -> 207224.52 | K9: =K7*B9 -> 211783.46 | L9: =L7*B9 -> 216442.7 | M9: =M7*B9 -> 221204.43 | N9: =N7*B9 -> 226070.93 | O9: =O7*B9 -> 231044.49 | P9: =P7*B9 -> 236127.47 | Q9: =Q7*B9 -> 241322.28 | R9: =R7*B9 -> 246631.37 | S9: =S7*B9 -> 252057.26 | T9: =T7*B9 -> 257602.52 | U9: =U7*B9 -> 263269.77
A10: SPMS Prevalence | B10: 0.3 | C10: =C7*B10 -> 97060.704 | D10: =D7*B10 -> 99196.039 | E10: =E7*B10 -> 101378.35 | F10: =F7*B10 -> 103608.68 | G10: =G7*B10 -> 105888.07 | H10: =H7*B10 -> 108217.6 | I10: =I7*B10 -> 110598.39 | J10: =J7*B10 -> 113031.56 | K10: =K7*B10 -> 115518.25 | L10: =L7*B10 -> 118059.65 | M10: =M7*B10 -> 120656.96 | N10: =N7*B10 -> 123311.42 | O10: =O7*B10 -> 126024.27 | P10: =P7*B10 -> 128796.8 | Q10: =Q7*B10 -> 131630.33 | R10: =R7*B10 -> 134526.2 | S10: =S7*B10 -> 137485.78 | T10: =T7*B10 -> 140510.46 | U10: =U7*B10 -> 143601.69
A11: PPMS Prevalence | B11: 0.15 | C11: =C7*B11 -> 48530.352 | D11: =D7*B11 -> 49598.02 | E11: =E7*B11 -> 50689.176 | F11: =F7*B11 -> 51804.338 | G11: =G7*B11 -> 52944.033 | H11: =H7*B11 -> 54108.802 | I11: =I7*B11 -> 55299.196 | J11: =J7*B11 -> 56515.778 | K11: =K7*B11 -> 57759.125 | L11: =L7*B11 -> 59029.826 | M11: =M7*B11 -> 60328.482 | N11: =N7*B11 -> 61655.709 | O11: =O7*B11 -> 63012.134 | P11: =P7*B11 -> 64398.401 | Q11: =Q7*B11 -> 65815.166 | R11: =R7*B11 -> 67263.1 | S11: =S7*B11 -> 68742.888 | T11: =T7*B11 -> 70255.232 | U11: =U7*B11 -> 71800.847
A13: Share of Addressable RRMS Patients
A14: PIPE-791
A15: Ocrevus/ocrelizumab
A16: Kesimpta/ofatumumab
A17: Tecfidera/dimethyl fumarate
A18: Vumerity/diroximel fumarate
A19: Briumvi/ublituximab-xiiy
A20: Zeposia/ozanimod
A21: Ponvory/ponesimod
A22: Tysabri/natalizumab
A23: Interferons
A26: Share of Addressable RRMS Patients
