Workbook
Name __CTO05: #REF!
Name __CTO05: #REF!
Name __DSO01: #REF!
Name __DSO01: #REF!
Name __DSO02: #REF!
Name __DSO02: #REF!
Name __DSO03: #REF!
Name __DSO03: #REF!
Name __DSO04: #REF!
Name __DSO04: #REF!
Name __dso05: #REF!
Name __dso05: #REF!
Name __dso98: #REF!
Name __dso98: #REF!
Name __dso99: #REF!
Name __dso99: #REF!
Name __EPS01: #REF!
Name __EPS01: #REF!
Name __eps02: #REF!
Name __eps02: #REF!
Name __eps03: #REF!
Name __eps03: #REF!
Name __eps04: #REF!
Name __eps04: #REF!
Name __eps05: #REF!
Name __eps05: #REF!
Name __EPS98: #REF!
Name __EPS98: #REF!
Name __EPS99: #REF!
Name __EPS99: #REF!
Name __nd0306: #REF!
Name __nd0306: #REF!
Name __nd0606: #REF!
Name __nd0606: #REF!
Name __nd0906: #REF!
Name __nd0906: #REF!
Name __ni01: #REF!
Name __ni01: #REF!
Name __ni02: #REF!
Name __ni02: #REF!
Name __ni03: #REF!
Name __ni03: #REF!
Name __ni04: #REF!
Name __ni04: #REF!
Name __ni98: #REF!
Name __ni98: #REF!
Name __ni99: #REF!
Name __ni99: #REF!
Name __rev01: #REF!
Name __rev01: #REF!
Name __rev02: #REF!
Name __rev02: #REF!
Name __rev03: #REF!
Name __rev03: #REF!
Name __rev04: #REF!
Name __rev04: #REF!
Name __rev05: #REF!
Name __rev05: #REF!
Name __rev98: #REF!
Name __rev98: #REF!

Sheet __FDSCACHE__
B1: This sheet contains FactSet XML data for use with this workbook's =FDS codes. Modifying the worksheet's contents may damage the workbook's =FDS functionality.

Sheet Disclosures
A9: MPLT
A11: Company Model
A12: Last Updated: | B12: 46108
A14: Marc Goodman
A15: (212) 277-6137
A16: marc.goodman@leerink.com
A18: Alyssa Larios, Ph.D.
A19: (212) 277-6093
A20: alyssa.larios@leerink.com
A22: Basma Radwan, Ph.D.
A23: (212) 277-6151
A24: basma.radwan@leerink.com
A26: Analyst Certification
A27: I, Marc Goodman, certify that the views expressed in this report accurately reflect my views and that no part of my compensation was, is, or will be directly related to the specific recommendation or views contained in this report.
A29: Rating Distribution as of 12/31/2025
E30: Recd Inv. Banking Serv. In
A31: Coverage Universe | B31: Count | C31: % | E31: Previous 12 months | F31: Count | G31: %
A32: Outperform (Buy) | B32: 222 | C32: 0.766 | E32: Outperform (Buy) | F32: 122 | G32: 0.55
A33: Market Perform (Hold/Neutral) | B33: 66 | C33: 0.228 | E33: Market Perform (Hold/Neutral) | F33: 15 | G33: 0.227
A34: Underperform (Sell) | B34: 2 | C34: 0.007 | E34: Underperform (Sell) | F34: 0 | G34: 0
A37: Explanation of Ratings
A38: Outperform (Buy): We expect this stock to outperform its benchmark over the next 12 months. Market Perform (Hold/Neutral): We expect this stock to perform in line with its benchmark over the next 12 months. Underperform (Sell): We expect this stock to underperform its benchmark over the next 12 months. The degree of outperformance or underperformance required to warrant an Outperform or an Underperform rating should be commensurate with the risk profile of the company. For the purposes of these definitions the relevant benchmark for "Leerink Partners" branded healthcare and life sciences equity research will be the S&P 600® Health Care Index for issuers with a market capitalization of less than $2 billion and the S&P 500® Health Care Index for issuers with a market capitalization over $2 billion.
A39: Important Disclosures
A41: This information (including, but not limited to, prices, quotes and statistics) has been obtained from sources that we believe reliable, but we do not represent that it is accurate or complete and it should not be relied upon as such. All information is subject to change without notice. The information is intended for Institutional Use Only and is not an offer to sell or a solicitation to buy any product to which this information relates. Leerink Partners LLC (“Firm”), its officers, directors, employees, proprietary accounts and affiliates may have a position, long or short, in the securities referred to in this report, and/or other related securities, and from time to time may increase or decrease the position or express a view that is contrary to that contained in this report. The Firm's research analysts, salespeople, traders and other professionals may provide oral or written market commentary or trading strategies that are contrary to opinions expressed in this report. The Firm's asset management group and proprietary accounts may make investment decisions that are inconsistent with the opinions expressed in this document. The past performance of securities does not guarantee or predict future performance. Transaction strategies described herein may not be suitable for all investors. This document may not be reproduced or circulated without Leerink Partners’ written authority. Additional information is available upon request by contacting the Editorial Department, Leerink Partners, 53 State Street, 40th Floor, Boston, MA 02109. Like all Firm employees, research analysts receive compensation that is impacted by, among other factors, overall firm profitability, which includes revenues from, among other business units, Institutional Equities, Research, and Investment Banking. Research analysts, however, are not compensated for a specific investment banking services transaction. To the extent Leerink Partners research reports are referenced in this material, they are either attached hereto or information about these companies, including prices, rating, market making status, price charts, compensation disclosures, Analyst Certifications, etc. is available on https://leerink.bluematrix.com/sellside/Disclosures.action. MEDACorp LLC, an affiliate of Leerink Partners, is a global network of independent healthcare professionals (Key Opinion Leaders and consultants) providing industry and market insights to Leerink Partners and its clients. This document may not be reproduced or circulated without our written authority. This document, and any other Leerink Partners research report may not be, in whole or in part, or in any form or manner (i) forwarded, distributed, shared, or made available to third parties, including as input to, or in connection with, any artificial intelligence or machine learning model; (ii) modified or otherwise used to create derivative works; or (iii) used to train or otherwise develop a generative artificial intelligence or machine learning model, without the express written consent of Leerink Partners. Receipt and review of this document constitutes your agreement with the aforementioned limitations in use.
A42: © 2026 Leerink Partners LLC. All Rights Reserved. Member FINRA/SIPC.

Sheet CATALYSTS
A1: MapLight- Catalysts
A3: Date | B3: Product | C3: Indication | D3: Comments | E3: Trial Name
A4: 2H26 | B4: ML-007-PAC | C4: Schizophrenia | D4: Top-line data
A5: 2H27 | B5: ML-007-PAC | C5: AD psychosis | D5: Top-line data
A6: Source: Company reports, Leerink Partners estimates

Sheet Catalyst Tracker
A1: Leerink Partners Catalyst Tracker
A2: Stock (Ticker Symbol) | B2: Lateral Impact (Other companies/stocks) | C2: Drug (Brand or chemical name) / Instrument / Area | D2: Indication / Product Class | E2: Type of Event | F2: Event or Trial Details | G2: Expected Timing | H2: Specific Event Date if known or specified | I2: Impact: H(igh) > 9% M(edium) 3 - 9% L(ow) < 2% | J2: Estimated Stock Up/Down % on Best/Worst Outcomes | K2: Leerink Partners View of Expected Outcome
A3: MPLT | C3: ML-007-PAC | D3: Schizophrenia | E3: Phase 2 Data Presentation | F3: Top-line | G3: 2H26 | I3: H
A4: MPLT | C4: ML-007-PAC | D4: Alzheimer's disease psychosis | E4: Phase 2 Data Presentation | F4: Top-line | G4: 2H27 | I4: H
A26: Source: Leerink Partners LLC Equity Research and Company Filings
A29: Type of Event | B29: Expected Timing | C29: Impact | D29: Leerink Partners View of Expected Outcome
A30: Lead Candidate Selection | B30: 1H23 | C30: H | D30: Strongly Positive
A31: First Patient Treated | B31: 2H23 | C31: M | D31: Positive
A32: IND Enabling Study | B32: 1H24 | C32: L | D32: Neutral
A33: IND Submission | B33: 2H24 | D33: Negative
A34: Phase 1 Trial Initiation | B34: 1H25 | D34: Strongly Negative
A35: Phase 1 Data Announcement | B35: 2H25
A36: Phase 1 Data Presentation | B36: 1H26
A37: Phase 2 Trial Initiation | B37: 2H26
A38: Phase 2 Data Announcement | B38: 1H27
A39: Phase 2 Data Presentation | B39: 2H27
A40: Phase 3 Trial Initiation | B40: 1H28
A41: Phase 3 Trial Full Enrollment | B41: 2H28
A42: Phase 3 Results Announcement | B42: 1Q23
A43: Phase 3 Results Presentation | B43: 2Q23
A44: Phase 4 Trial Initiation | B44: 3Q23
A45: Phase 4 Results Announcement | B45: 4Q23
A46: Phase 4 Results Presentation | B46: 1Q24
... A61: Post-market Study Data Release | B61: 4Q27
A62: PMA Approval | B62: 2023
A63: Submission of CLIA application | B63: 2024
A64: CLIA certification granted | B64: 2025
A65: Reimbursement Related | B65: 2026
A66: Product Launch | B66: 2027
A67: Assay Launch | B67: 2028

Sheet INCOME STATEMENT
A1: MapLight - Income Statement
A2: ($ Millions, except per-share data)
B3: 1Q22 | C3: 2Q22 | D3: 3Q22 | E3: 4Q22 | F3: 2022 | G3: 1Q23 | H3: 2Q23 | I3: 3Q23 | J3: 4Q23 | K3: 2023 | L3: 1Q24 | M3: 2Q24 | N3: 3Q24 | O3: 4Q24 | P3: 2024 | Q3: 1Q25 | R3: 2Q25 | S3: 3Q25 | T3: 4Q25 | U3: 2025 | V3: 1Q26E | W3: 2Q26E | X3: 3Q26E | Y3: 4Q26E | Z3: 2026E | AA3: 2027E | AB3: 2028E | AC3: 2029E | AD3: 2030E | AE3: 2031E | AF3: 2032E | AG3: 2033E | AH3: 2034E | AI3: 2035E
A5: Product Sales | G5: 0 | H5: 0 | I5: 0 | J5: 0 | K5: =SUM(G5:J5) -> 0 | P5: 0 | U5: =REVENUES!F20 -> 0 | Z5: =REVENUES!K20 -> 0 | AA5: =REVENUES!L20 -> 0 | AB5: =REVENUES!M20 -> 0 | AC5: =REVENUES!N20 -> 0 | AD5: =REVENUES!O20 -> 55 | AE5: =REVENUES!P20 -> 318.42567 | AF5: =REVENUES!Q20 -> 823.41391 | AG5: =REVENUES!R20 -> 1429.1278 | ... AI5: =REVENUES!T20 -> 2361.6666
A6: Milestones & Royalties | G6: 0 | H6: 0 | I6: 0 | J6: 0 | K6: =SUM(G6:J6) -> 0 | P6: 0 | U6: =REVENUES!F26 -> 0 | Z6: =REVENUES!K26 -> 0 | AA6: =REVENUES!L26 -> 0 | AB6: =REVENUES!M26 -> 0 | AC6: =REVENUES!N26 -> 0 | AD6: =REVENUES!O26 -> 0 | AE6: =REVENUES!P26 -> 0 | AF6: =REVENUES!Q26 -> 0 | AG6: =REVENUES!R26 -> 0 | ... AI6: =REVENUES!T26 -> 0
A7: Total Revenues | G7: 0 | H7: 0 | I7: 0 | J7: 0 | K7: =SUM(G7:J7) -> 0 | L7: 0 | M7: 0 | N7: 0 | O7: 0 | P7: 0 | Q7: 0 | R7: 0 | S7: 0 | T7: 0 | U7: =U5+U6 -> 0 | V7: 0 | W7: 0 | X7: 0 | Y7: 0 | Z7: =Z5+Z6 -> 0 | AA7: =AA5+AA6 -> 0 | AB7: =AB5+AB6 -> 0 | AC7: =AC5+AC6 -> 0 | AD7: =AD5+AD6 -> 55 | AE7: =AE5+AE6 -> 318.42567 | AF7: =AF5+AF6 -> 823.41391 | AG7: =AG5+AG6 -> 1429.1278 | ... AI7: =AI5+AI6 -> 2361.6666
A8: Consensus
A9: COGS | G9: 0 | H9: 0 | I9: 0 | J9: 0 | K9: =EXPENSES!K85 -> 0 | L9: 0 | M9: 0 | N9: 0 | O9: 0 | P9: 0 | Q9: 0 | R9: 0 | S9: 0 | T9: 0 | U9: 0 | V9: 0 | W9: 0 | X9: 0 | Y9: 0 | Z9: =EXPENSES!Z85 -> 0 | AA9: =EXPENSES!AA85 -> 0 | AB9: =EXPENSES!AB85 -> 0 | AC9: =EXPENSES!AC85 -> 0 | AD9: =EXPENSES!AD85 -> 1.65 | AE9: =EXPENSES!AE85 -> 13.10554 | AF9: =EXPENSES!AF85 -> 35.904835 | AG9: =EXPENSES!AG85 -> 62.497669 | ... AI9: =EXPENSES!AI85 -> 101.2
A10: Gross Profit | G10: 0 | H10: 0 | I10: 0 | J10: 0 | K10: =K7-K9 -> 0 | L10: =L7-L9 -> 0 | M10: =M7-M9 -> 0 | N10: =N7-N9 -> 0 | O10: =O7-O9 -> 0 | P10: =P7-P9 -> 0 | Q10: =Q7-Q9 -> 0 | R10: =R7-R9 -> 0 | ... AI10: =AI7-AI9 -> 2260.4666
A12: SG&A | K12: 7.607 | L12: 3.5 | M12: =8.287-L12 -> 4.787 | N12: 4.08 | O12: =P12-L12-M12-N12 -> 2.056 | P12: 14.423 | Q12: 3.5 | R12: =7.573-Q12 -> 4.073 | S12: 4.404 | T12: =U12-Q12-R12-S12 -> 18.757 | U12: 30.734 | V12: =EXPENSES!V67 -> 6.5 | W12: =EXPENSES!W67 -> 6.6 | X12: =EXPENSES!X67 -> 7.2 | Y12: =EXPENSES!Y67 -> 7.5 | Z12: =EXPENSES!Z67 -> 27.8 | AA12: =EXPENSES!AA67 -> 29.19 | AB12: =EXPENSES!AB67 -> 30.6495 | AC12: =EXPENSES!AC67 -> 36.415575 | ... AI12: =EXPENSES!AI67 -> 508.36416
A13: R&D | K13: 49.675 | L13: 14 | M13: =30.989-L13 -> 16.989 | N13: 16.814 | O13: =P13-L13-M13-N13 -> 20.72 | P13: 68.523 | Q13: 22 | R13: =46.633-Q13 -> 24.633 | S13: 27.094 | T13: =U13-Q13-R13-S13 -> 64.622 | U13: 138.349 | V13: =EXPENSES!V22 -> 31.25 | W13: =EXPENSES!W22 -> 33.25 | X13: =EXPENSES!X22 -> 37.25 | Y13: =EXPENSES!Y22 -> 43.25 | Z13: =EXPENSES!Z22 -> 145 | AA13: =EXPENSES!AA22 -> 175 | AB13: =EXPENSES!AB22 -> 225.032 | AC13: =EXPENSES!AC22 -> 214.99706 | ... AI13: =EXPENSES!AI22 -> 57.986754
A15: Total Expenses | K15: =K12+K13 -> 57.282 | L15: =L12+L13 -> 17.5 | M15: =M12+M13 -> 21.776 | N15: =N12+N13 -> 20.894 | O15: =O12+O13 -> 22.776 | P15: =P12+P13 -> 82.946 | Q15: =Q12+Q13 -> 25.5 | R15: =R12+R13 -> 28.706 | ... AI15: =AI12+AI13 -> 566.35092
A17: Operating Income | K17: =K10-K12-K13 -> -57.282 | L17: =L10-L12-L13 -> -17.5 | M17: =M10-M12-M13 -> -21.776 | N17: =N10-N12-N13 -> -20.894 | O17: =O10-O12-O13 -> -22.776 | P17: =P10-P12-P13 -> -82.946 | Q17: =Q10-Q12-Q13 -> -25.5 | R17: =R10-R12-R13 -> -28.706 | ... AI17: =AI10-AI12-AI13 -> 1694.1157
A19: Interest Income | K19: 1.099 | L19: 1.2 | M19: =2.524-L19 -> 1.324 | N19: 1.081 | P19: 4.504 | Q19: 0.5 | R19: =1.499-Q19 -> 0.999 | S19: 1.549 | T19: 2.471 | U19: =SUM(Q19:T19) -> 5.519 | V19: 3.4 | W19: 3.2 | X19: 2.8 | Y19: =Z19-X19-W19-V19 -> 2.6 | Z19: ='BALANCE SHEET'!H53 -> 12 | AA19: ='BALANCE SHEET'!I53 -> 12.5 | AB19: ='BALANCE SHEET'!J53 -> 10 | AC19: ='BALANCE SHEET'!K53 -> 5.5 | AD19: ='BALANCE SHEET'!L53 -> 3.5 | AE19: ='BALANCE SHEET'!M53 -> 0 | AF19: ='BALANCE SHEET'!N53 -> 0 | AG19: ='BALANCE SHEET'!O53 -> 0 | ... AI19: ='BALANCE SHEET'!Q53 -> 0
A20: Interest Expense | K20: 0 | P20: 0 | Q20: 0 | R20: 0 | S20: 0 | T20: 0 | U20: =SUM(Q20:T20) -> 0 | V20: 0 | W20: 0 | X20: 0 | Y20: 0 | Z20: 0 | AA20: 0 | AB20: 0 | AC20: 0 | AD20: 0 | AE20: 0 | AF20: 0 | AG20: 0 | AH20: 0 | AI20: 0
A21: Other Income/Expense | K21: =-0.514+0.986+0.002 -> 0.474 | L21: -0.25 | M21: =-0.989+0.403 -> -0.586 | N21: 0.797 | P21: =-0.986+1.848 -> 0.862 | Q21: 0.25 | R21: =0.522-Q21 -> 0.272 | S21: 0.531 | T21: 1.359 | U21: =SUM(Q21:T21) -> 2.412 | V21: 0 | W21: 0 | X21: 0 | Y21: 0 | Z21: 0 | AA21: 0 | AB21: 0 | AC21: 0 | AD21: 0 | AE21: 0 | AF21: 0 | AG21: 0 | AH21: 0 | AI21: 0
A22: Non-Operating Income | K22: =SUM(K19:K21) -> 1.573 | L22: =SUM(L19:L21) -> 0.95 | M22: =SUM(M19:M21) -> 0.738 | N22: =SUM(N19:N21) -> 1.878 | O22: =SUM(O19:O21) -> 0 | P22: =SUM(P19:P21) -> 5.366 | Q22: =SUM(Q19:Q21) -> 0.75 | R22: =SUM(R19:R21) -> 1.271 | ... Y22: =SUM(Y19:Y21) -> 2.6 | Z22: =V22+W22+X22+Y22 -> 12 | AA22: =SUM(AA19:AA21) -> 12.5 | AB22: =SUM(AB19:AB21) -> 10 | AC22: =SUM(AC19:AC21) -> 5.5 | AD22: =SUM(AD19:AD21) -> 3.5 | AE22: =SUM(AE19:AE21) -> 0 | AF22: =SUM(AF19:AF21) -> 0 | AG22: =SUM(AG19:AG21) -> 0 | AH22: =SUM(AH19:AH21) -> 0 | AI22: =SUM(AI19:AI21) -> 0
A24: Pretax Income | K24: =K22+K17 -> -55.709 | L24: =L17+L22 -> -16.55 | M24: =M17+M22 -> -21.038 | N24: =N17+N22 -> -19.016 | O24: =O17+O22 -> -22.776 | P24: =P17+P22 -> -77.58 | Q24: =Q17+Q22 -> -24.75 | R24: =R17+R22 -> -27.435 | S24: =S17+S22 -> -29.418 | ... Y24: =Y17+Y22 -> -48.15 | Z24: =V24+W24+X24+Y24 -> -160.8 | AA24: =AA17+AA22 -> -191.69 | AB24: =AB17+AB22 -> -245.6815 | AC24: =AC17+AC22 -> -245.91264 | AD24: =AD17+AD22 -> -331.38263 | AE24: =AE17+AE22 -> -123.93382 | AF24: =AF17+AF22 -> 244.00061 | AG24: =AG17+AG22 -> 825.72359 | AH24: =AH17+AH22 -> 1269.4068 | AI24: =AI17+AI22 -> 1694.1157
A25: Taxes | K25: =SUM(G25:J25) -> 0 | L25: =SUM(H25:K25) -> 0 | M25: =SUM(I25:L25) -> 0 | N25: =SUM(J25:M25) -> 0 | O25: =SUM(K25:N25) -> 0 | P25: =P24*P26 -> 0 | Q25: =SUM(M25:P25) -> 0 | R25: =SUM(N25:Q25) -> 0 | S25: =SUM(O25:R25) -> 0 | T25: =SUM(P25:S25) -> 0 | U25: =U24*U26 -> 0 | V25: =V24*V26 -> 0 | W25: =W24*W26 -> 0 | X25: =X24*X26 -> 0 | Y25: =Y24*Y26 -> 0 | Z25: =V25+W25+X25+Y25 -> 0 | AA25: =AA24*AA26 -> 0 | AB25: =AB24*AB26 -> 0 | AC25: =AC24*AC26 -> 0 | AD25: =AD24*AD26 -> 0 | AE25: =AE24*AE26 -> 0 | AF25: =AF24*AF26 -> 0 | AG25: =AG24*AG26 -> 0 | AH25: =AH24*AH26 -> 0 | AI25: =AI24*AI26 -> 0
A26: Tax Rate | V26: =Q26 -> 0 | W26: =R26 -> 0 | X26: =S26 -> 0 | Y26: =T26 -> 0 | Z26: =Z25/Z24 -> 0 | AA26: =Z26 -> 0 | AB26: =AA26 -> 0 | AC26: =AB26 -> 0 | AD26: =AC26 -> 0 | AE26: =AD26 -> 0 | AF26: =AE26 -> 0 | AG26: =AF26 -> 0 | AH26: 0 | AI26: 0
A27: Other | L27: =P27/4 -> 0.04075 | M27: =L27 -> 0.04075 | N27: =M27 -> 0.04075 | O27: =P27-SUM(L27:N27) -> 0.04075 | P27: 0.163
A29: Net Income | K29: =K24-K25 -> -55.709 | L29: =L24-L25+L27 -> -16.50925 | M29: =M24-M25+M27 -> -20.99725 | N29: =N24-N25+N27 -> -18.97525 | O29: =O24-O25+O27 -> -22.73525 | P29: =P24-P25+P27 -> -77.417 | Q29: =Q24-Q25 -> -24.75 | R29: =R24-R25 -> -27.435 | S29: =S24-S25 -> -29.418 | T29: =T24-T25 -> -79.549 | U29: =U24-U25 -> -161.152 | V29: =V24-V25 -> -34.35 | W29: =W24-W25 -> -36.65 | X29: =X24-X25 -> -41.65 | Y29: =Y24-Y25 -> -48.15 | Z29: =V29+W29+X29+Y29 -> -160.8 | AA29: =AA24-AA25 -> -191.69 | AB29: =AB24-AB25 -> -245.6815 | AC29: =AC24-AC25 -> -245.91264 | AD29: =AD24-AD25 -> -331.38263 | AE29: =AE24-AE25 -> -123.93382 | AF29: =AF24-AF25 -> 244.00061 | AG29: =AG24-AG25 -> 825.72359 | AH29: =AH24-AH25 -> 1269.4068 | AI29: =AI24-AI25 -> 1694.1157
A30: Shares - Basic | P30: 26.149152 | Q30: =P30+0.025 -> 26.174152 | R30: =2*26.202215-Q30 -> 26.230278 | S30: =R30 -> 26.230278 | T30: 32.148977 | U30: =AVERAGE(Q30:T30) -> 27.695921 | V30: 45 | W30: =V30+0.1 -> 45.1 | X30: =W30+0.1 -> 45.2 | Y30: =X30+0.1+('CASH FLOW'!E43*0.5) -> 50.3 | Z30: =AVERAGE(V30:Y30) -> 46.4 | AA30: =Y30+0.3+'CASH FLOW'!F43 -> 58.933333 | AB30: =AA30+0.3+'CASH FLOW'!G43 -> 59.233333 | AC30: =AB30+0.3+'CASH FLOW'!H43 -> 66.420386 | AD30: =AC30+0.3+'CASH FLOW'!I43 -> 74.546582 | AE30: =AD30+0.3+'CASH FLOW'!J43 -> 74.846582 | AF30: =AE30+0.3+'CASH FLOW'!K43 -> 75.146582 | AG30: =AF30+0.3+'CASH FLOW'!L43 -> 75.446582 | AH30: =AG30+0.3+'CASH FLOW'!M43 -> 75.746582 | AI30: =AH30+0.3+'CASH FLOW'!N43 -> 76.046582
A31: EPS - Basic | P31: =P29/P30 -> -2.9605931 | Q31: -0.95 | R31: -1.05 | S31: =S29/S30 -> -1.1215283 | T31: =T29/T30 -> -2.4743867 | U31: =Q31+R31+S31+T31 -> -5.595915 | V31: =V29/V30 -> -0.76333333 | W31: =W29/W30 -> -0.81263858 | X31: =X29/X30 -> -0.92146018 | Y31: =Y29/Y30 -> -0.95725646 | Z31: =V31+W31+X31+Y31 -> -3.4546886 | AA31: =AA29/AA30 -> -3.2526584 | AB31: =AB29/AB30 -> -4.1476899 | AC31: =AC29/AC30 -> -3.7023669 | AD31: =AD29/AD30 -> -4.4453095 | AE31: =AE29/AE30 -> -1.6558381 | AF31: =AF29/AF30 -> 3.2469955 | AG31: =AG29/AG30 -> 10.94448 | AH31: =AH29/AH30 -> 16.758602 | AI31: =AI29/AI30 -> 22.277342
A32: Shares - FD | V32: =V30+9 -> 54 | W32: =W30+9 -> 54.1 | X32: =X30+9 -> 54.2 | Y32: =Y30+9 -> 59.3 | Z32: =Z30+9 -> 55.4 | AA32: =AA30+9 -> 67.933333 | AB32: =AB30+9 -> 68.233333 | AC32: =AC30+9 -> 75.420386 | AD32: =AD30+9 -> 83.546582 | AE32: =AE30+3.87 -> 78.716582 | AF32: =AF30+11 -> 86.146582 | AG32: =AG30+11 -> 86.446582 | AH32: =AH30+11 -> 86.746582 | AI32: =AI30+11 -> 87.046582
A33: EPS - Fully Diluted | AF33: =AF29/AF32 -> 2.8323888 | AG33: =AG29/AG32 -> 9.5518362 | AH33: =AH29/AH32 -> 14.633508 | AI33: =AI29/AI32 -> 19.462174
A34: Consensus | T34: {=_xll.FDS("MPLT","FE_ESTIMATE(EPS,MEAN,QTR,2025/4F,NOW,,,'')")} -> -1.0633334 | U34: {=_xll.FDS("MPLT-US","FE_ESTIMATE(eps,MEAN,ANN,2025,NOW,,,'')")} -> -7.078 | Z34: {=_xll.FDS("MPLT-US","FE_ESTIMATE(eps,MEAN,ANN,2026,NOW,,,'')")} -> -3.666 | AA34: {=_xll.FDS("MPLT-US","FE_ESTIMATE(eps,MEAN,ANN,2027,NOW,,,'')")} -> -4.0433335 | AB34: {=_xll.FDS("MPLT-US","FE_ESTIMATE(eps,MEAN,ANN,2028,NOW,,,'')")} -> -4.515
A36: Margin Analysis | B36: =B3 -> 1Q22 | C36: =C3 -> 2Q22 | D36: =D3 -> 3Q22 | E36: =E3 -> 4Q22 | F36: =F3 -> 2022 | G36: =G3 -> 1Q23 | H36: =H3 -> 2Q23 | I36: =I3 -> 3Q23 | ... AC36: =AC3 -> 2029E | AD36: 2030E | AE36: 2030E | AF36: 2030E | AG36: 2030E | AH36: 2030E | AI36: 2030E
A38: Revenues | E38: 1 | F38: 1 | G38: 1 | H38: 1 | I38: 1 | J38: 1 | K38: 1 | L38: 1 | M38: 1 | N38: 1 | O38: 1 | AD38: 1 | AE38: =AD38 -> 1 | AF38: =AE38 -> 1 | AG38: =AF38 -> 1 | AH38: =AG38 -> 1 | AI38: =AH38 -> 1
A39: COGS | AD39: =AD9/AD$7 -> 0.03 | AE39: =AE9/AE$7 -> 0.041157298 | AF39: =AF9/AF$7 -> 0.043604843 | AG39: =AG9/AG$7 -> 0.043731336 | AH39: =AH9/AH$7 -> 0.043026541 | AI39: =AI9/AI$7 -> 0.042851093
A40: Gross Margin | AD40: =AD10/AD$7 -> 0.97 | AE40: =AE10/AE$7 -> 0.9588427 | AF40: =AF10/AF$7 -> 0.95639516 | AG40: =AG10/AG$7 -> 0.95626866 | AH40: =AH10/AH$7 -> 0.95697346 | AI40: =AI10/AI$7 -> 0.95714891
A42: SG&A | AE42: =AE12/AE$7 -> 0.87343199 | AF42: =AF12/AF$7 -> 0.56011527 | AG42: =AG12/AG$7 -> 0.33334747 | AH42: =AH12/AH$7 -> 0.25900126 | AI42: =AI12/AI$7 -> 0.21525653
A43: R&D | AE43: =AE13/AE$7 -> 0.47461872 | AF43: =AF13/AF$7 -> 0.09995187 | AG43: =AG13/AG$7 -> 0.045139711 | AH43: =AH13/AH$7 -> 0.029872241 | AI43: =AI13/AI$7 -> 0.024553319
A44: Operating Margin | AE44: =AE17/AE$7 -> -0.38920801 | AF44: =AF17/AF$7 -> 0.29632802 | AG44: =AG17/AG$7 -> 0.57778148 | AH44: =AH17/AH$7 -> 0.66809995 | AI44: =AI17/AI$7 -> 0.71733906
A46: Pretax Margin | AE46: =AE24/AE$7 -> -0.38920801 | AF46: =AF24/AF$7 -> 0.29632802 | AG46: =AG24/AG$7 -> 0.57778148 | AH46: =AH24/AH$7 -> 0.66809995 | AI46: =AI24/AI$7 -> 0.71733906
A47: Net Margin | AE47: =AE29/AE$7 -> -0.38920801 | AF47: =AF29/AF$7 -> 0.29632802 | AG47: =AG29/AG$7 -> 0.57778148 | AH47: =AH29/AH$7 -> 0.66809995 | AI47: =AI29/AI$7 -> 0.71733906
A49: % Change | B49: =B36 -> 1Q22 | C49: =C36 -> 2Q22 | D49: =D36 -> 3Q22 | E49: =E36 -> 4Q22 | F49: =F36 -> 2022 | G49: =G36 -> 1Q23 | H49: =H36 -> 2Q23 | I49: =I36 -> 3Q23 | ... U49: =U36 -> 2025 | V49: =V3 -> 1Q26E | W49: =W3 -> 2Q26E | X49: =X3 -> 3Q26E | Y49: =Y3 -> 4Q26E | Z49: =Z36 -> 2026E | AA49: =AA36 -> 2027E | AB49: =AB36 -> 2028E | AC49: =AC36 -> 2029E | AD49: 2030E | AE49: 2030E | AF49: 2030E | AG49: 2030E | AH49: 2030E | AI49: 2030E
A51: Revenues
A52: COGS
A53: Gross Profit
...

Sheet REVENUES
A1: MapLight - Revenues
A2: ($ Millions)
B3: 1Q25 | C3: 2Q25 | D3: 3Q25 | E3: 4Q25 | F3: 2025 | G3: 1Q26E | H3: 2Q26E | I3: 3Q26E | J3: 4Q26E | K3: 2026E | L3: 2027E | M3: 2028E | N3: 2029E | O3: 2030E | P3: 2031E | Q3: 2032E | R3: 2033E | S3: 2034E | T3: 2035E | U3: 2036E | V3: 2037E | W3: 2038E | X3: 2039E | Y3: 2040E | Z3: 2041E | AA3: 2042E | AB3: 2043E | AC3: 2044E | AD3: 2045E | AE3: 2046E | AF3: 2047E
A5: Product Sales
A7: ML-007-MA - Schizophrenia
A8: US - Schizophrenia | B8: 0 | C8: 0 | D8: 0 | E8: 0 | F8: =SUM(B8:E8) -> 0 | G8: 0 | H8: 0 | I8: 0 | J8: 0 | K8: 0 | L8: 0 | M8: 0 | N8: 0 | O8: 55 | P8: 200 | Q8: 350 | R8: 525 | S8: 625 | T8: =S8*1.12 -> 700 | U8: =T8*1.1 -> 770 | V8: =U8*1.08 -> 831.6 | W8: =V8*1.06 -> 881.496 | X8: =W8*1.05 -> 925.5708 | Y8: =X8*1.04 -> 962.59363 | Z8: =Y8*1.03 -> 991.47144 | AA8: =Z8*1.02 -> 1011.3009 | AB8: =AA8 -> 1011.3009 | AC8: =AB8 -> 1011.3009 | AD8: =AC8*0.65 -> 657.34557 | AE8: =AD8*0.3 -> 197.20367 | AF8: =AE8*0.3 -> 59.161101
A9: % Growth Rate | P9: =P8/O8-1 -> 2.6363636 | Q9: =Q8/P8-1 -> 0.75 | R9: =R8/Q8-1 -> 0.5 | S9: =S8/R8-1 -> 0.19047619 | T9: =T8/S8-1 -> 0.12 | U9: =U8/T8-1 -> 0.1 | V9: =V8/U8-1 -> 0.08 | W9: =W8/V8-1 -> 0.06 | ... AF9: =AF8/AE8-1 -> -0.7
A11: ML-007-MA - Alzheimer's Disease Psychosis
A12: US - ADP | B12: 0 | C12: 0 | D12: 0 | E12: 0 | F12: =SUM(B12:E12) -> 0 | G12: 0 | H12: 0 | I12: 0 | J12: 0 | K12: 0 | L12: 0 | M12: 0 | N12: ='ML-007'!G102 -> 0 | O12: ='ML-007'!H102 -> 0 | P12: ='ML-007'!I102 -> 0 | Q12: 100 | R12: 250 | S12: 450 | T12: 650 | U12: 825 | V12: 950 | W12: 1050 | X12: 1125 | Y12: =X12*1.05 -> 1181.25 | Z12: =Y12*1.05 -> 1240.3125 | AA12: =Z12*1.04 -> 1289.925 | AB12: =AA12*1.03 -> 1328.6227 | AC12: =AB12*1.03 -> 1368.4814 | AD12: =AC12*0.65 -> 889.51293 | AE12: =AD12*0.3 -> 266.85388 | AF12: =AE12*0.3 -> 80.056164
A13: % Growth Rate | R13: =R12/Q12-1 -> 1.5 | S13: =S12/R12-1 -> 0.8 | T13: =T12/S12-1 -> 0.44444444 | U13: =U12/T12-1 -> 0.26923077 | V13: =V12/U12-1 -> 0.15151515 | W13: =W12/V12-1 -> 0.10526316 | X13: =X12/W12-1 -> 0.071428571 | Y13: =Y12/X12-1 -> 0.05 | ... AF13: =AF12/AE12-1 -> -0.7
A15: Total Sales - ML-007 | B15: =B8+B12 -> 0 | C15: =C8+C12 -> 0 | D15: =D8+D12 -> 0 | E15: =E8+E12 -> 0 | F15: =F8+F12 -> 0 | G15: =G8+G12 -> 0 | H15: =H8+H12 -> 0 | I15: =I8+I12 -> 0 | ... AF15: =AF8+AF12 -> 139.21726
A17: ML-004 - ASD
A18: US - ASD | F18: ='ML-004'!C29 -> 0 | G18: 0 | H18: 0 | I18: 0 | J18: 0 | K18: ='ML-004'!D29 -> 0 | L18: ='ML-004'!E29 -> 0 | M18: ='ML-004'!F29 -> 0 | N18: ='ML-004'!G29 -> 0 | O18: ='ML-004'!H29 -> 0 | P18: ='ML-004'!I29 -> 118.42567 | Q18: ='ML-004'!J29 -> 373.41391 | R18: ='ML-004'!K29 -> 654.12782 | ... Y18: ='ML-004'!R29 -> 1946.4603 | Z18: =Y18*(1+Z19) -> 2004.8541 | AA18: =Z18*(1+AA19) -> 2064.9997 | AB18: =AA18*(1+AB19) -> 2126.9497 | AC18: =AB18*(1+AC19) -> 2190.7582 | AD18: =AC18*(1+AD19) -> 2256.481 | AE18: =AD18*(1+AE19) -> 2324.1754 | AF18: =AE18*(1+AF19) -> 2393.9007
Z19: 0.03 | AA19: 0.03 | AB19: 0.03 | AC19: 0.03 | AD19: 0.03 | AE19: 0.03 | AF19: 0.03
A20: Total Sales | B20: =B18+B15 -> 0 | C20: =C18+C15 -> 0 | D20: =D18+D15 -> 0 | E20: =E18+E15 -> 0 | F20: =SUM(B20:E20) -> 0 | G20: =G18+G15 -> 0 | H20: =H18+H15 -> 0 | I20: =I18+I15 -> 0 | J20: =J18+J15 -> 0 | K20: =K18+K15 -> 0 | L20: =L18+L15 -> 0 | M20: =M18+M15 -> 0 | N20: =N18+N15 -> 0 | ... AF20: =AF18+AF15 -> 2533.1179
A21: % Growth Rate | Q21: =Q20/P20-1 -> 1.5858905 | R21: =R20/Q20-1 -> 0.73561292 | S21: =S20/R20-1 -> 0.32949987 | T21: =T20/S20-1 -> 0.2429659 | U21: =U20/T20-1 -> 0.1899283 | V21: =V20/U20-1 -> 0.14528894 | W21: =W20/V20-1 -> 0.095433534 | X21: =X20/W20-1 -> 0.081869357 | ... AF21: =AF20/AE20-1 -> -0.091497026
A23: Royalties & Milestones
A24: Milestones/Payments | F24: 0 | K24: 0 | L24: 0 | M24: 0 | N24: 0 | O24: 0 | P24: 0 | Q24: 0 | R24: 0 | S24: 0 | T24: 0 | U24: 0 | V24: 0 | W24: 0 | X24: 0 | Y24: 0 | Z24: 0 | AA24: 0 | AB24: 0 | AC24: 0 | AD24: 0 | AE24: 0 | AF24: 0
A26: Total Royalties & Milestones | B26: 0 | C26: 0 | D26: 0 | E26: 0 | F26: =SUM(B26:E26) -> 0 | G26: 0 | H26: 0 | I26: 0 | J26: 0 | K26: =K24 -> 0 | L26: =L24 -> 0 | M26: =M24 -> 0 | N26: =N24 -> 0 | O26: =O24 -> 0 | P26: =P24 -> 0 | Q26: =Q24 -> 0 | R26: =R24 -> 0 | ... AF26: =AF24 -> 0
A28: Total Revenues | B28: =B20+B26 -> 0 | C28: =C20+C26 -> 0 | D28: =D20+D26 -> 0 | E28: =E20+E26 -> 0 | F28: =F20+F26 -> 0 | G28: =G20+G26 -> 0 | H28: =H20+H26 -> 0 | I28: =I20+I26 -> 0 | ... AF28: =AF20+AF26 -> 2533.1179
A29: % Growth Rate | Q29: =Q28/P28-1 -> 1.5858905 | R29: =R28/Q28-1 -> 0.73561292 | S29: =S28/R28-1 -> 0.32949987 | T29: =T28/S28-1 -> 0.2429659 | U29: =U28/T28-1 -> 0.1899283 | V29: =V28/U28-1 -> 0.14528894 | W29: =W28/V28-1 -> 0.095433534 | X29: =X28/W28-1 -> 0.081869357 | ... AF29: =AF28/AE28-1 -> -0.091497026
A31: Source: Company reports, Leerink Partners estimates
A33: Check | F33: ='INCOME STATEMENT'!U7-F28 -> 0 | K33: ='INCOME STATEMENT'!Z7-K28 -> 0 | L33: ='INCOME STATEMENT'!AA7-L28 -> 0 | M33: ='INCOME STATEMENT'!AB7-M28 -> 0 | N33: ='INCOME STATEMENT'!AC7-N28 -> 0 | O33: ='INCOME STATEMENT'!AD7-O28 -> 0
P51: `

Sheet EXPENSES
A1: MapLight - Expenses
B3: 1Q22 | C3: 2Q22 | D3: 3Q22 | E3: 4Q22 | F3: 2022 | G3: 1Q23 | H3: 2Q23 | I3: 3Q23 | J3: 4Q23 | K3: 2023 | L3: 1Q24 | M3: 2Q24 | N3: 3Q24 | O3: 4Q24 | P3: 2024 | Q3: 1Q25 | R3: 2Q25 | S3: 3Q25 | T3: 4Q25 | U3: 2025 | V3: 1Q26E | W3: 2Q26E | X3: 3Q26E | Y3: 4Q26E | Z3: 2026E | AA3: 2027E | AB3: 2028E | AC3: 2029E | AD3: 2030E | AE3: 2031E | AF3: 2032E | AG3: 2033E | AH3: 2034E | AI3: 2035E | AJ3: 2036E | AK3: 2037E | AL3: 2038E | AM3: 2039E | AN3: 2040E | AO3: 2041E
A5: R&D
A7: ML-007 - Schizophrenia | K7: =13.307-K8-K11 -> 9.807 | L7: 3 | M7: 2.5 | N7: 2.5 | O7: =P7-L7-M7-N7 -> 2.182 | P7: =18.182-P8-P11 -> 10.182 | Q7: 3.5 | R7: 4.5 | S7: 5 | T7: =U7-Q7-R7-S7 -> 11 | U7: 24 | V7: 7 | W7: 8 | X7: 10 | Y7: =Z7-X7-W7-V7 -> 13 | Z7: 38 | AA7: 55 | AB7: 70 | AC7: 60 | AD7: 30 | AE7: 15 | AF7: 10 | AG7: 5 | AH7: 1 | AI7: =AH7 -> 1 | AJ7: =AI7 -> 1 | AK7: =AJ7 -> 1 | AL7: =AK7 -> 1 | AM7: =AL7 -> 1 | AN7: =AM7 -> 1 | AO7: =AN7 -> 1
A8: ML-007 - ADP | K8: 3 | L8: 1.5 | M8: 1.5 | N8: 2 | O8: =P8-L8-M8-N8 -> 2 | P8: 7 | Q8: =Q9-Q7 -> 2.059 | R8: =R9-R7 -> 3.4 | S8: =S9-S7 -> 4.415 | T8: =T9-T7 -> 10.087 | U8: =SUM(Q8:T8) -> 19.961 | V8: 7 | W8: 8 | X8: 10 | Y8: =Z8-X8-W8-V8 -> 13 | Z8: 38 | AA8: 55 | AB8: 70 | AC8: 75 | AD8: 75 | AE8: 75 | AF8: 15 | AG8: 5 | AH8: 0 | AI8: =AH8 -> 0 | AJ8: =AI8 -> 0 | AK8: =AJ8 -> 0 | AL8: =AK8 -> 0 | AM8: =AL8 -> 0 | AN8: =AM8 -> 0 | AO8: =AN8 -> 0
A9: Total ML-007 | K9: =SUM(K7:K8) -> 12.807 | L9: =SUM(L7:L8) -> 4.5 | M9: =SUM(M7:M8) -> 4 | N9: =SUM(N7:N8) -> 4.5 | O9: =SUM(O7:O8) -> 4.182 | P9: =SUM(P7:P8) -> 17.182 | Q9: =Q13-Q11 -> 5.559 | R9: =R13-R11 -> 7.9 | S9: =S13-S11 -> 9.415 | T9: =T13-T11 -> 21.087 | U9: =SUM(U7:U8) -> 43.961 | V9: =SUM(V7:V8) -> 14 | W9: =SUM(W7:W8) -> 16 | X9: =SUM(X7:X8) -> 20 | Y9: =SUM(Y7:Y8) -> 26 | Z9: =SUM(Z7:Z8) -> 76 | AA9: =SUM(AA7:AA8) -> 110 | AB9: =SUM(AB7:AB8) -> 140 | ... AO9: =SUM(AO7:AO8) -> 1
A11: ML-004 - ASD | K11: 0.5 | L11: 0.1 | M11: 0.1 | N11: 0.1 | O11: =P11-N11-M11-L11 -> 0.7 | P11: 1 | Q11: 2 | R11: 2.5 | S11: 2.5 | T11: =U11-Q11-R11-S11 -> 2.5 | U11: 9.5 | V11: 2.5 | W11: 2.5 | X11: 2.5 | Y11: =Z11-X11-W11-V11 -> 2.5 | Z11: 10 | AA11: 10 | AB11: 30 | AC11: 30 | AD11: 40 | AE11: 10 | AF11: 5 | AG11: 1 | AH11: =AG11 -> 1 | AI11: =AH11 -> 1 | AJ11: =AI11 -> 1 | AK11: =AJ11 -> 1 | AL11: =AK11 -> 1 | AM11: =AL11 -> 1 | AN11: =AM11 -> 1 | AO11: =AN11 -> 1
A13: Total Clinical Expenses | Q13: =29.874-R13-S13 -> 7.559 | R13: 10.4 | S13: 11.915 | T13: =U13-Q13-R13-S13 -> 23.587 | U13: 53.461 | V13: =V9+V11 -> 16.5 | W13: =W9+W11 -> 18.5 | X13: =X9+X11 -> 22.5 | Y13: =Y9+Y11 -> 28.5 | Z13: =Z9+Z11 -> 86
A14: Preclinical | K14: 14.315 | L14: 3 | M14: 5 | N14: 4 | O14: =P14-N14-M14-L14 -> 1.972 | P14: 13.972 | Q14: =7.042-R14-S14 -> 1.75 | R14: 2.5 | S14: 2.792 | T14: =U14-S14-R14-Q14 -> 3.379 | U14: 10.421 | V14: =Z14/4 -> 3 | W14: =V14 -> 3 | X14: =W14 -> 3 | Y14: =Z14-X14-W14-V14 -> 3 | Z14: 12 | AA14: =Z14 -> 12 | AB14: =AA14 -> 12 | AC14: =AB14 -> 12 | AD14: =AC14 -> 12 | AE14: =AD14 -> 12 | AF14: =AE14 -> 12 | AG14: =AF14 -> 12 | AH14: =AG14 -> 12 | ... AO14: =AN14 -> 12
A16: CMC and formulation | K16: 7.709 | L16: 2 | M16: 3 | N16: 3 | O16: =P16-N16-M16-L16 -> 3.473 | P16: 11.473 | Q16: =11.728-R16-S16 -> 3.553 | R16: 4 | S16: 4.175 | T16: =U16-Q16-R16-S16 -> 6.538 | U16: 18.266 | V16: =Z16/4 -> 3.75 | W16: =V16 -> 3.75 | X16: =W16 -> 3.75 | Y16: =Z16-X16-W16-V16 -> 3.75 | Z16: 15 | AA16: 7 | AB16: 5 | AC16: 0 | AD16: 0 | AE16: 0 | AF16: 0 | AG16: 0 | AH16: 0 | AI16: 0 | AJ16: 0 | AK16: 0 | AL16: 0 | AM16: 0 | AN16: 0 | AO16: 0
A18: People | K18: =11.867-K20 -> 11.522 | L18: 4 | M18: 4.2 | N18: 5.5 | O18: =P18-L18-M18-N18 -> 7.04 | P18: =21.337-P20 -> 20.74 | Q18: =21.05-R18-S18 -> 7.091 | R18: 7 | S18: =7.043-S20 -> 6.959 | T18: =U18-Q18-R18-S18 -> 7.816 | U18: =51.062-U20 -> 28.866 | V18: 7.5 | W18: 7.5 | X18: 7.5 | Y18: =Z18-X18-W18-V18 -> 7.5 | Z18: 30 | AA18: =Z18*1.03 -> 30.9 | AB18: =AA18*1.03 -> 31.827 | AC18: =AB18*1.03 -> 32.78181 | AD18: =AC18*1.03 -> 33.765264 | AE18: =AD18*1.03 -> 34.778222 | AF18: =AE18*1.03 -> 35.821569 | AG18: =AF18*1.03 -> 36.896216 | AH18: =AG18*1.03 -> 38.003102 | ... AO18: =AN18*1.03 -> 46.739022
A19: Other | K19: 2.477 | L19: =L22-L9-L11-L14-L16-L18-L20 -> 0.15 | M19: =M22-M9-M11-M14-M16-M18-M20 -> 0.439 | N19: 0.5 | O19: =P19-L19-M19-N19 -> 2.472 | P19: 3.561 | Q19: =Q22-Q20-Q18-Q16-Q14-Q11-Q9 -> 1.923 | R19: =R22-R20-R18-R16-R14-R11-R9 -> 0.61 | S19: =S22-S20-S18-S16-S14-S11-S9 -> 1.169 | T19: =T22-T20-T18-T16-T14-T11-T9 -> 1.437 | U19: =SUM(Q19:T19) -> 5.139 | V19: 0 | W19: 0 | X19: 0 | Y19: =Z19-X19-W19-V19 -> 0 | Z19: 0 | AA19: 3 | AB19: 4 | AC19: 2.9 | AD19: 1.8 | AE19: =AD19 -> 1.8 | AF19: =AE19 -> 1.8 | AG19: =AF19 -> 1.8 | AH19: =AG19 -> 1.8 | AI19: =AH19 -> 1.8 | AJ19: =AI19 -> 1.8 | AK19: =AJ19 -> 1.8 | AL19: =AK19 -> 1.8 | ... AO19: =AN19 -> 1.8
A20: Stock-Based Compensation | K20: =1.045-K34 -> 0.345 | L20: 0.25 | M20: 0.25 | N20: 0.25 | O20: =P20-L20-M20-N20 -> -0.153 | P20: =1.08-P34 -> 0.597 | Q20: 0.124 | R20: 0.123 | S20: 0.084 | T20: =U20-Q20-R20-S20 -> 21.865 | U20: 22.196 | V20: 0.5 | W20: =V20 -> 0.5 | X20: =W20 -> 0.5 | Y20: =Z20-X20-W20-V20 -> 0.5 | Z20: 2 | AA20: =Z20*(1+5%) -> 2.1 | AB20: =AA20*(1+5%) -> 2.205 | AC20: =AB20*(1+5%) -> 2.31525 | AD20: =AC20*(1+5%) -> 2.4310125 | AE20: =AD20*(1+5%) -> 2.5525631 | AF20: =AE20*(1+5%) -> 2.6801913 | AG20: =AF20*(1+5%) -> 2.8142008 | AH20: =AG20*(1+5%) -> 2.9549109 | AI20: =AH20*1.03 -> 3.0435582 | AJ20: =AI20*1.03 -> 3.134865 | AK20: =AJ20*1.03 -> 3.2289109 | AL20: =AK20*1.03 -> 3.3257782 | AM20: =AL20*1.03 -> 3.4255516 | AN20: =AM20*1.03 -> 3.5283181 | AO20: =AN20*1.03 -> 3.6341677
A22: Total R&D | K22: ='INCOME STATEMENT'!K13 -> 49.675 | L22: ='INCOME STATEMENT'!L13 -> 14 | M22: ='INCOME STATEMENT'!M13 -> 16.989 | N22: =SUM(N9+N11+N14+N18+N19+N20+N16) -> 17.85 | O22: =SUM(O9+O11+O14+O18+O19+O20+O16) -> 19.686 | P22: ='INCOME STATEMENT'!P13 -> 68.523 | Q22: ='INCOME STATEMENT'!Q13 -> 22 | R22: ='INCOME STATEMENT'!R13 -> 24.633 | S22: ='INCOME STATEMENT'!S13 -> 27.094 | T22: ='INCOME STATEMENT'!T13 -> 64.622 | U22: =SUM(Q22:T22) -> 138.349 | V22: =(V9+V11+V14+V18+V19+V20+V16) -> 31.25 | W22: =(W9+W11+W14+W18+W19+W20+W16) -> 33.25 | X22: =(X9+X11+X14+X18+X19+X20+X16) -> 37.25 | Y22: =(Y9+Y11+Y14+Y18+Y19+Y20+Y16) -> 43.25 | Z22: =SUM(V22:Y22) -> 145 | AA22: =SUM(AA9+AA11+AA14+AA18+AA19+AA20+AA16) -> 175 | AB22: =SUM(AB9+AB11+AB14+AB18+AB19+AB20+AB16) -> 225.032 | AC22: =SUM(AC9+AC11+AC14+AC18+AC19+AC20+AC16) -> 214.99706 | AD22: =SUM(AD9+AD11+AD14+AD18+AD19+AD20+AD16) -> 194.99628 | AE22: =SUM(AE9+AE11+AE14+AE18+AE19+AE20+AE16) -> 151.13079 | AF22: =SUM(AF9+AF11+AF14+AF18+AF19+AF20+AF16) -> 82.30176 | AG22: =SUM(AG9+AG11+AG14+AG18+AG19+AG20+AG16) -> 64.510417 | AH22: =SUM(AH9+AH11+AH14+AH18+AH19+AH20+AH16) -> 56.758013 | ... AO22: =SUM(AO9+AO11+AO14+AO18+AO19+AO20+AO16) -> 66.17319
A23: % Growth | P23: =P22/K22-1 -> 0.37942627 | Q23: =Q22/L22-1 -> 0.57142857 | R23: =R22/M22-1 -> 0.4499382 | S23: =S22/N22-1 -> 0.51787115 | T23: =T22/O22-1 -> 2.2826374 | U23: =U22/P22-1 -> 1.0190155 | V23: =V22/Q22-1 -> 0.42045455 | W23: =W22/R22-1 -> 0.34981529 | ... Z23: =Z22/U22-1 -> 0.048074074 | AA23: =AA22/Z22-1 -> 0.20689655 | AB23: =AB22/AA22-1 -> 0.28589714 | AC23: =AC22/AB22-1 -> -0.044593391 | AD23: =AD22/AC22-1 -> -0.093028171 | AE23: =AE22/AD22-1 -> -0.22495553 | AF23: =AF22/AE22-1 -> -0.4554269 | AG23: =AG22/AF22-1 -> -0.21617209 | AH23: =AH22/AG22-1 -> -0.12017289 | ... AO23: =AO22/AN22-1 -> 0.02267456
B26: =B3 -> 1Q22 | C26: =C3 -> 2Q22 | D26: =D3 -> 3Q22 | E26: =E3 -> 4Q22 | F26: =F3 -> 2022 | G26: =G3 -> 1Q23 | H26: =H3 -> 2Q23 | I26: =I3 -> 3Q23 | ... AO26: =AO3 -> 2041E
A28: G&A
A30: People | K30: =3.863-K34 -> 3.163 | L30: 1 | M30: 1.5 | N30: 2.1 | O30: =P30-L30-M30-N30 -> 2.374 | P30: =7.457-P34 -> 6.974 | Q30: 1.8 | R30: 1.8 | S30: 1.8 | T30: =U30-Q30-R30-S30 -> 2.478 | U30: =21.688-U34 -> 7.878 | V30: 2.5 | W30: 2.6 | X30: 2.7 | Y30: 3 | Z30: =V30+W30+X30+Y30 -> 10.8 | AA30: =Z30*(1+AA31) -> 11.34 | AB30: =AA30*(1+AB31) -> 11.907 | AC30: =AB30*(1+AC31) -> 13.0977 | AD30: =AC30*(1+AD31) -> 13.752585 | AE30: =AD30*(1+AE31) -> 14.440214 | AF30: =AE30*(1+AF31) -> 15.162225 | AG30: =AF30*(1+AG31) -> 15.920336 | AH30: =AG30*(1+AH31) -> 16.716353 | ... AO30: =AN30*(1+AO31) -> 23.521587
A31: % Growth | K31: =K30/F30-1 -> #DIV/0! | P31: =P30/K30-1 -> 1.2048688 | U31: =U30/P30-1 -> 0.12962432 | Z31: =Z30/U30-1 -> 0.37090632 | AA31: 0.05 | AB31: =AA31 -> 0.05 | AC31: 0.1 | AD31: 0.05 | AE31: =AD31 -> 0.05 | AF31: =AE31 -> 0.05 | AG31: =AF31 -> 0.05 | AH31: =AG31 -> 0.05 | AI31: =AH31 -> 0.05 | AJ31: =AI31 -> 0.05 | AK31: =AJ31 -> 0.05 | AL31: =AK31 -> 0.05 | ... AO31: =AN31 -> 0.05
A32: Commercial Planning/Professional Fees | K32: =3.744-K36 -> 3.744 | L32: 1 | M32: 1 | N32: 1 | O32: =P32-L32-M32-N32 -> 0.5 | P32: 3.5 | Q32: 1.6 | R32: 2.2 | S32: 2.6 | T32: =U32-Q32-R32-S32 -> 2.6 | U32: 9 | V32: 2.5 | W32: =V32 -> 2.5 | X32: 3 | Y32: 3 | Z32: =V32+W32+X32+Y32 -> 11 | AA32: =Z32*(1+AA33) -> 11.55 | AB32: =AA32*(1+AB33) -> 12.1275 | AC32: =AB32*(1+AC33) -> 16.372125 | AD32: =AC32*(1+AD33) -> 17.190731 | AE32: =AD32*(1+AE33) -> 18.050268 | AF32: =AE32*(1+AF33) -> 18.952781 | AG32: =AF32*(1+AG33) -> 19.521365 | AH32: =AG32*(1+AH33) -> 20.107006 | ... AO32: =AN32*(1+AO33) -> 24.729081
A33: % Growth | K33: 0.1 | Z33: =Z32/U32-1 -> 0.22222222 | AA33: 0.05 | AB33: 0.05 | AC33: 0.35 | AD33: 0.05 | AE33: =AD33 -> 0.05 | AF33: =AE33 -> 0.05 | AG33: 0.03 | AH33: =AG33 -> 0.03 | AI33: =AH33 -> 0.03 | AJ33: =AI33 -> 0.03 | AK33: =AJ33 -> 0.03 | AL33: =AK33 -> 0.03 | AM33: =AL33 -> 0.03 | AN33: =AM33 -> 0.03 | AO33: =AN33 -> 0.03
A34: Stock-Based Compensation | K34: 0.7 | L34: 0.15 | M34: 0.15 | N34: 0.15 | O34: =P34-L34-M34-N34 -> 0.033 | P34: 0.483 | Q34: 0.05 | R34: 0.063 | S34: 0.041 | T34: =U34-Q34-R34-S34 -> 13.656 | U34: 13.81 | V34: 1.5 | W34: =V34 -> 1.5 | X34: =W34 -> 1.5 | Y34: =Z34-X34-W34-V34 -> 1.5 | Z34: 6 | AA34: =Z34*(1+AA35) -> 6.3 | AB34: =AA34*(1+AB35) -> 6.615 | AC34: =AB34*(1+AC35) -> 6.94575 | AD34: =AC34*(1+AD35) -> 7.2930375 | AE34: =AD34*(1+AE35) -> 7.6576894 | AF34: =AE34*(1+AF35) -> 8.0405738 | AG34: =AF34*(1+AG35) -> 8.2817911 | AH34: =AG34*(1+AH35) -> 8.5302448 | ... AO34: =AN34*(1+AO35) -> 10.491125
A35: % Growth | Z35: 0.05 | AA35: 0.05 | AB35: =AA35 -> 0.05 | AC35: =AB35 -> 0.05 | AD35: =AC35 -> 0.05 | AE35: =AD35 -> 0.05 | AF35: =AE35 -> 0.05 | AG35: 0.03 | AH35: =AG35 -> 0.03 | AI35: =AH35 -> 0.03 | AJ35: =AI35 -> 0.03 | AK35: =AJ35 -> 0.03 | AL35: =AK35 -> 0.03 | AM35: =AL35 -> 0.03 | AN35: =AM35 -> 0.03 | AO35: =AN35 -> 0.03
A36: Other | K36: 0 | L36: =L38-L30-L32-L34 -> 1.35 | M36: =M38-M30-M32-M34 -> 2.137 | N36: 0 | O36: =P36-N36-M36-L36 -> -0.021 | P36: =P38-P30-P32-P34 -> 3.466 | Q36: =Q38-Q30-Q32-Q34 -> 0.05 | R36: =R38-R30-R32-R34 -> 0.01 | S36: =S38-S30-S32-S34 -> -0.037 | T36: =T38-T30-T32-T34 -> 0.023 | U36: 0 | V36: 0 | W36: 0 | X36: 0 | Y36: =Z36-X36-W36-V36 -> 0 | Z36: =U36*1.03 -> 0 | AA36: =Z36*1.03 -> 0 | AB36: =AA36*1.03 -> 0 | AC36: =AB36*1.03 -> 0 | AD36: =AC36*1.03 -> 0 | AE36: =AD36*1.03 -> 0 | AF36: =AE36*1.03 -> 0 | AG36: =AF36*1.03 -> 0 | AH36: =AG36*1.03 -> 0 | ... AO36: =AN36*1.03 -> 0
A37: % Growth | K37: 0.1
A38: Total G&A | G38: =G30+G32+G34+G36 -> 0 | H38: =H30+H32+H34+H36 -> 0 | I38: =I30+I32+I34+I36 -> 0 | J38: =J30+J32+J34+J36 -> 0 | K38: ='INCOME STATEMENT'!K12 -> 7.607 | L38: =L67-L65 -> 3.5 | M38: =M67-M65 -> 4.787 | N38: =SUM(N30:N36) -> 3.25 | O38: =SUM(O30:O36) -> 2.886 | P38: ='INCOME STATEMENT'!P12 -> 14.423 | Q38: =Q67-Q65 -> 3.5 | R38: =R67-R65 -> 4.073 | S38: =S67-S65 -> 4.404 | T38: =T67-T65 -> 18.757 | U38: =U30+U32+U34+U36 -> 30.688 | V38: =SUM(V30,V32,V34,V36) -> 6.5 | W38: =SUM(W30,W32,W34,W36) -> 6.6 | X38: =SUM(X30,X32,X34,X36) -> 7.2 | Y38: =SUM(Y30,Y32,Y34,Y36) -> 7.5 | Z38: =Z30+Z32+Z34+Z36 -> 27.8 | AA38: =AA30+AA32+AA34+AA36 -> 29.19 | AB38: =AB30+AB32+AB34+AB36 -> 30.6495 | AC38: =AC30+AC32+AC34+AC36 -> 36.415575 | AD38: =AD30+AD32+AD34+AD36 -> 38.236354 | AE38: =AE30+AE32+AE34+AE36 -> 40.148171 | AF38: =AF30+AF32+AF34+AF36 -> 42.15558 | AG38: =AG30+AG32+AG34+AG36 -> 43.723492 | ... AO38: =AO30+AO32+AO34+AO36 -> 58.741793
A39: % Growth | P39: =P38/K38-1 -> 0.89601683 | Q39: =Q38/L38-1 -> 0 | R39: =R38/M38-1 -> -0.14915396 | S39: =S38/N38-1 -> 0.35507692 | T39: =T38/O38-1 -> 5.499307 | U39: =U38/P38-1 -> 1.1277127 | V39: =V38/Q38-1 -> 0.85714286 | W39: =W38/R38-1 -> 0.6204272 | ... Z39: =Z38/U38-1 -> -0.094108446 | AA39: =AA38/Z38-1 -> 0.05 | AB39: =AB38/AA38-1 -> 0.05 | AC39: =AC38/AB38-1 -> 0.1881295 | AD39: =AD38/AC38-1 -> 0.05 | AE39: =AE38/AD38-1 -> 0.05 | AF39: =AF38/AE38-1 -> 0.05 | AG39: =AG38/AF38-1 -> 0.03719346 | AH39: =AH38/AG38-1 -> 0.03728228 | ... AO39: =AO38/AN38-1 -> 0.037916304
A42: Sales & Marketing
A44: Salesforce/Sales Management/MSLs
A46: ML-007 - Schizophrenia - US | B46: 0 | C46: =B46 -> 0 | D46: =C46 -> 0 | E46: =D46 -> 0 | F46: =E46 -> 0 | G46: 0 | H46: =G46 -> 0 | I46: =H46 -> 0 | J46: =I46 -> 0 | K46: =F46 -> 0 | L46: 0 | M46: =L46 -> 0 | N46: 0 | O46: 0 | P46: =K46 -> 0 | Q46: 0 | R46: =Q46 -> 0 | S46: 0 | T46: 0 | U46: 0 | V46: 0 | W46: =V46 -> 0 | X46: 0 | Y46: 0 | Z46: =U46 -> 0 | AA46: =Z46 -> 0 | AB46: =AA46 -> 0 | AC46: 0 | AD46: 200 | AE46: =AD46 -> 200 | AF46: =AE46 -> 200 | AG46: =AF46 -> 200 | AH46: =AG46 -> 200 | AI46: =AH46 -> 200 | AJ46: =AI46 -> 200 | AK46: =AJ46 -> 200 | AL46: =AK46 -> 200 | ... AO46: =AN46 -> 200
A47: ML-007 - ADP - US | B47: 0 | C47: =B47 -> 0 | D47: =C47 -> 0 | E47: =D47 -> 0 | F47: =E47 -> 0 | G47: 0 | H47: =G47 -> 0 | I47: =H47 -> 0 | J47: =I47 -> 0 | K47: =F47 -> 0 | L47: 0 | M47: =L47 -> 0 | N47: =M47 -> 0 | O47: =N47 -> 0 | P47: =K47 -> 0 | Q47: 0 | R47: =Q47 -> 0 | S47: =R47 -> 0 | T47: =S47 -> 0 | U47: 0 | V47: 0 | W47: =V47 -> 0 | X47: =W47 -> 0 | Y47: =X47 -> 0 | Z47: =U47 -> 0 | AA47: =Z47 -> 0 | AB47: =AA47 -> 0 | AC47: =AB47 -> 0 | AD47: 0 | AE47: 0 | AF47: 250 | AG47: =AF47 -> 250 | AH47: =AG47 -> 250 | AI47: =AH47 -> 250 | AJ47: =AI47 -> 250 | AK47: =AJ47 -> 250 | AL47: =AK47 -> 250 | AM47: =AL47 -> 250 | AN47: =AM47 -> 250 | AO47: =AN47 -> 250
A48: ML-004 - ASD - US | B48: 0 | C48: 0 | D48: 0 | E48: 0 | F48: 0 | G48: 0 | H48: 0 | I48: 0 | J48: 0 | K48: 0 | L48: 0 | M48: 0 | N48: 0 | O48: 0 | P48: 0 | Q48: 0 | R48: 0 | S48: 0 | T48: 0 | U48: 0 | V48: 0 | W48: 0 | X48: 0 | Y48: 0 | Z48: 0 | AA48: 0 | AB48: 0 | AC48: 0 | AD48: 0 | AE48: 100 | AF48: =AE48 -> 100 | AG48: =AF48 -> 100 | AH48: =AG48 -> 100 | AI48: =AH48 -> 100 | AJ48: =AI48 -> 100 | AK48: =AJ48 -> 100 | AL48: =AK48 -> 100 | AM48: =AL48 -> 100 | ... AO48: =AN48 -> 100
A49: Total Reps | B49: =SUM(B46:B48) -> 0 | C49: =SUM(C46:C48) -> 0 | D49: =SUM(D46:D48) -> 0 | E49: =SUM(E46:E48) -> 0 | F49: =SUM(F46:F48) -> 0 | G49: =SUM(G46:G48) -> 0 | H49: =SUM(H46:H48) -> 0 | I49: =SUM(I46:I48) -> 0 | ... AO49: =SUM(AO46:AO48) -> 550
A51: Cost per Rep per Year | B51: =B46*1.03 -> 0 | C51: =B51 -> 0 | D51: =C51 -> 0 | E51: =D51 -> 0 | F51: =E51 -> 0 | G51: =E51*1.03 -> 0 | H51: =G51 -> 0 | I51: =H51 -> 0 | J51: =I51 -> 0 | K51: =J51 -> 0 | L51: =P51 -> 0 | M51: =L51 -> 0 | N51: =M51 -> 0 | O51: =N51 -> 0 | P51: =K51*1.03 -> 0 | Q51: =U51 -> 0 | R51: =Q51 -> 0 | S51: =R51 -> 0 | T51: =S51 -> 0 | U51: =P51*1.03 -> 0 | V51: =Z51 -> 0 | W51: =V51 -> 0 | X51: =W51 -> 0 | Y51: =X51 -> 0 | Z51: =U51*1.03 -> 0 | AA51: =Z51*1.03 -> 0 | AB51: =AA51*1.03 -> 0 | AC51: 0 | AD51: 275000 | AE51: =AD51*1.03 -> 283250 | AF51: =AE51*1.03 -> 291747.5 | AG51: =AF51*1.03 -> 300499.92 | AH51: =AG51*1.03 -> 309514.92 | AI51: =AH51*1.03 -> 318800.37 | AJ51: =AI51*1.03 -> 328364.38 | AK51: =AJ51*1.03 -> 338215.31 | AL51: =AK51*1.03 -> 348361.77 | ... AO51: =AN51*1.03 -> 380664.31
A53: ML-007 - Schizophrenia -US | B53: =(B46*B$51)/1000000/4 -> 0 | C53: =(C46*C$51)/1000000/4 -> 0 | D53: =(D46*D$51)/1000000/4 -> 0 | E53: =(E46*E$51)/1000000/4 -> 0 | F53: =B53+C53+D53+E53 -> 0 | G53: =(G46*G$51)/1000000/4 -> 0 | H53: =(H46*H$51)/1000000/4 -> 0 | I53: =(I46*I$51)/1000000/4 -> 0 | J53: =(J46*J$51)/1000000/4 -> 0 | K53: =(K46*K$51)/1000000 -> 0 | L53: =(L46*L$51)/1000000/4 -> 0 | M53: =(M46*M$51)/1000000/4 -> 0 | N53: =(N46*N$51)/1000000/4 -> 0 | O53: =(O46*O$51)/1000000/4 -> 0 | P53: =SUM(L53:O53) -> 0 | Q53: =(Q46*Q$51)/1000000/4 -> 0 | R53: =(R46*R$51)/1000000/4 -> 0 | S53: =(S46*S$51)/1000000/4 -> 0 | T53: =(T46*T$51)/1000000/4 -> 0 | U53: =(U46*U$51)/1000000 -> 0 | V53: =(V46*V$51)/1000000/4 -> 0 | W53: =(W46*W$51)/1000000/4 -> 0 | X53: =(X46*X$51)/1000000/4 -> 0 | Y53: =(Y46*Y$51)/1000000/4 -> 0 | Z53: =(Z46*Z$51)/1000000 -> 0 | AA53: =(AA46*AA$51)/1000000 -> 0 | AB53: =(AB46*AB$51)/1000000 -> 0 | AC53: =(AC46*AC$51)/1000000 -> 0 | AD53: =(AD46*AD$51)/1000000 -> 55 | AE53: =(AE46*AE$51)/1000000 -> 56.65 | AF53: =(AF46*AF$51)/1000000 -> 58.3495 | AG53: =(AG46*AG$51)/1000000 -> 60.099985 | ... AO53: =(AO46*AO$51)/1000000 -> 76.132863
A54: ML-007 - ADP - US | B54: =(B47*B$51)/1000000/4 -> 0 | C54: =(C47*C$51)/1000000/4 -> 0 | D54: =(D47*D$51)/1000000/4 -> 0 | E54: =(E47*E$51)/1000000/4 -> 0 | F54: =B54+C54+D54+E54 -> 0 | G54: =(G47*G$51)/1000000/4 -> 0 | H54: =(H47*H$51)/1000000/4 -> 0 | I54: =(I47*I$51)/1000000/4 -> 0 | J54: =(J47*J$51)/1000000/4 -> 0 | K54: =(K47*K$51)/1000000 -> 0 | L54: =(L47*L$51)/1000000/4 -> 0 | M54: =(M47*M$51)/1000000/4 -> 0 | N54: =(N47*N$51)/1000000/4 -> 0 | O54: =(O47*O$51)/1000000/4 -> 0 | P54: =SUM(L54:O54) -> 0 | Q54: =(Q47*Q$51)/1000000/4 -> 0 | R54: =(R47*R$51)/1000000/4 -> 0 | S54: =(S47*S$51)/1000000/4 -> 0 | T54: =(T47*T$51)/1000000/4 -> 0 | U54: =(U47*U$51)/1000000 -> 0 | V54: =(V47*V$51)/1000000/4 -> 0 | W54: =(W47*W$51)/1000000/4 -> 0 | X54: =(X47*X$51)/1000000/4 -> 0 | Y54: =(Y47*Y$51)/1000000/4 -> 0 | Z54: =(Z47*Z$51)/1000000 -> 0 | AA54: =(AA47*AA$51)/1000000 -> 0 | AB54: =(AB47*AB$51)/1000000 -> 0 | AC54: =(AC47*AC$51)/1000000 -> 0 | AD54: =(AD47*AD$51)/1000000 -> 0 | AE54: =(AE47*AE$51)/1000000 -> 0 | AF54: =(AF47*AF$51)/1000000 -> 72.936875 | AG54: =(AG47*AG$51)/1000000 -> 75.124981 | ... AO54: =(AO47*AO$51)/1000000 -> 95.166079
A55: ML-004 - ASD - US | B55: =(B48*B$51)/1000000/4 -> 0 | C55: =(C48*C$51)/1000000/4 -> 0 | D55: =(D48*D$51)/1000000/4 -> 0 | E55: =(E48*E$51)/1000000/4 -> 0 | F55: =B55+C55+D55+E55 -> 0 | G55: =(G48*G$51)/1000000/4 -> 0 | H55: =(H48*H$51)/1000000/4 -> 0 | I55: =(I48*I$51)/1000000/4 -> 0 | J55: =(J48*J$51)/1000000/4 -> 0 | K55: =(K48*K$51)/1000000 -> 0 | L55: =(L48*L$51)/1000000/4 -> 0 | M55: =(M48*M$51)/1000000/4 -> 0 | N55: =(N48*N$51)/1000000/4 -> 0 | O55: =(O48*O$51)/1000000/4 -> 0 | P55: =(P48*P$51)/1000000 -> 0 | Q55: =(Q48*Q$51)/1000000/4 -> 0 | R55: =(R48*R$51)/1000000/4 -> 0 | S55: =(S48*S$51)/1000000/4 -> 0 | T55: =(T48*T$51)/1000000/4 -> 0 | U55: =(U48*U$51)/1000000 -> 0 | V55: =(V48*V$51)/1000000/4 -> 0 | W55: =(W48*W$51)/1000000/4 -> 0 | X55: =(X48*X$51)/1000000/4 -> 0 | Y55: =(Y48*Y$51)/1000000/4 -> 0 | Z55: =(Z48*Z$51)/1000000 -> 0 | AA55: =(AA48*AA$51)/1000000 -> 0 | AB55: =(AB48*AB$51)/1000000 -> 0 | AC55: =(AC48*AC$51)/1000000 -> 0 | AD55: =(AD48*AD$51)/1000000 -> 0 | AE55: =(AE48*AE$51)/1000000 -> 28.325 | AF55: =(AF48*AF$51)/1000000 -> 29.17475 | AG55: =(AG48*AG$51)/1000000 -> 30.049992 | ... AO55: =(AO48*AO$51)/1000000 -> 38.066431
A56: Total Salesforce Cost | B56: =SUM(B53:B54) -> 0 | C56: =SUM(C53:C54) -> 0 | D56: =SUM(D53:D54) -> 0 | E56: =SUM(E53:E54) -> 0 | F56: =B56+C56+D56+E56 -> 0 | G56: =SUM(G53:G54) -> 0 | H56: =SUM(H53:H54) -> 0 | I56: =SUM(I53:I54) -> 0 | J56: =SUM(J53:J54) -> 0 | K56: =SUM(K53:K55) -> 0 | L56: =SUM(L53:L54) -> 0 | M56: =SUM(M53:M54) -> 0 | N56: =SUM(N53:N54) -> 0 | O56: =SUM(O53:O54) -> 0 | P56: =SUM(P53:P55) -> 0 | Q56: =SUM(Q53:Q54) -> 0 | R56: =SUM(R53:R54) -> 0 | S56: =SUM(S53:S54) -> 0 | T56: =SUM(T53:T54) -> 0 | U56: =SUM(U53:U55) -> 0 | Z56: =SUM(Z53:Z55) -> 0 | AA56: =SUM(AA53:AA55) -> 0 | AB56: =SUM(AB53:AB55) -> 0 | AC56: =SUM(AC53:AC55) -> 0 | AD56: =SUM(AD53:AD55) -> 55 | AE56: =SUM(AE53:AE55) -> 84.975 | AF56: =SUM(AF53:AF55) -> 160.46112 | AG56: =SUM(AG53:AG55) -> 165.27496 | ... AO56: =SUM(AO53:AO55) -> 209.36537
A58: A&P
A60: ML-007 - Schizophrenia -US | B60: 0 | C60: 0 | D60: 0 | E60: =F60-B60-C60-D60 -> 0 | F60: 0 | G60: 0 | H60: 0 | I60: 0 | J60: =K60-G60-H60-I60 -> 0 | K60: 0 | L60: 0 | M60: 0 | N60: 0 | O60: 0 | P60: =L60+M60+N60+O60 -> 0 | Q60: 0 | R60: 0 | S60: 0 | T60: 0 | U60: 0 | V60: 0 | W60: 0 | X60: 0 | Y60: 0 | Z60: =U60*1.03 -> 0 | AA60: =Z60*1.03 -> 0 | AB60: =AA60*1.03 -> 0 | AC60: 0 | AD60: 100 | AE60: =AD60*1.03 -> 103 | AF60: =AE60*1.03 -> 106.09 | AG60: =AF60*1.03 -> 109.2727 | AH60: =AG60*1.03 -> 112.55088 | AI60: =AH60*1.03 -> 115.92741 | AJ60: =AI60*1.03 -> 119.40523 | AK60: =AJ60*1.03 -> 122.98739 | AL60: =AK60*1.03 -> 126.67701 | ... AO60: =AN60*1.03 -> 138.42339
...

Sheet ML-007
A2: ML-007 - US - Dyskinesia | B2: 2024E | C2: 2025E | D2: 2026E | E2: 2027E | F2: 2028E | G2: 2029E | H2: 2030E | I2: 2031E | J2: 2032E | K2: 2033E | L2: 2034E | M2: 2035E | N2: 2036E | O2: 2037E | P2: 2038E | Q2: 2039E | R2: 2040E
A4: Patients on Antipsychotics | B4: 6000000 | C4: =B4*(1+C5) -> 6006000 | D4: =C4*(1+D5) -> 6012006 | E4: =D4*(1+E5) -> 6018018 | F4: =E4*(1+F5) -> 6024036 | G4: =F4*(1+G5) -> 6030060.1 | H4: =G4*(1+H5) -> 6036090.1 | I4: =H4*(1+I5) -> 6042126.2 | J4: =I4*(1+J5) -> 6048168.3 | ... R4: =Q4*(1+R5) -> 6096723.4
A5: % Growth | C5: 0.001 | D5: 0.001 | E5: 0.001 | F5: 0.001 | G5: 0.001 | H5: 0.001 | I5: 0.001 | J5: 0.001 | K5: 0.001 | L5: 0.001 | M5: 0.001 | N5: 0.001 | O5: 0.001 | P5: 0.001 | Q5: 0.001 | R5: 0.001
A7: % on atypical antipsychotics | B7: 0.95 | C7: =B7 -> 0.95 | D7: =C7 -> 0.95 | E7: =D7 -> 0.95 | F7: =E7 -> 0.95 | G7: =F7 -> 0.95 | H7: =G7 -> 0.95 | I7: =H7 -> 0.95 | J7: =I7 -> 0.95 | ... R7: =Q7 -> 0.95
A8: Patients on atypical antipsychotics | B8: =B4*B7 -> 5700000 | C8: =C4*C7 -> 5705700 | D8: =D4*D7 -> 5711405.7 | E8: =E4*E7 -> 5717117.1 | F8: =F4*F7 -> 5722834.2 | G8: =G4*G7 -> 5728557.1 | H8: =H4*H7 -> 5734285.6 | I8: =I4*I7 -> 5740019.9 | ... R8: =R4*R7 -> 5791887.2
A10: % of atypical patients who get TD | B10: 0.09 | C10: =B10 -> 0.09 | D10: =C10 -> 0.09 | E10: =D10 -> 0.09 | F10: =E10 -> 0.09 | G10: =F10 -> 0.09 | H10: =G10 -> 0.09 | I10: =H10 -> 0.09 | J10: =I10 -> 0.09 | ... R10: =Q10 -> 0.09
A11: % of atypical patients who get TD (A) | B11: =B8*B10 -> 513000 | C11: =C8*C10 -> 513513 | D11: =D8*D10 -> 514026.51 | E11: =E8*E10 -> 514540.54 | F11: =F8*F10 -> 515055.08 | G11: =G8*G10 -> 515570.14 | H11: =H8*H10 -> 516085.71 | I11: =I8*I10 -> 516601.79 | ... R11: =R8*R10 -> 521269.85
A13: % on typical antipsychotics | B13: 0.05 | C13: =B13 -> 0.05 | D13: =C13 -> 0.05 | E13: =D13 -> 0.05 | F13: =E13 -> 0.05 | G13: =F13 -> 0.05 | H13: =G13 -> 0.05 | I13: =H13 -> 0.05 | J13: =I13 -> 0.05 | ... R13: =Q13 -> 0.05
A14: Patients on typical antipsychotics | B14: =B4*B13 -> 300000 | C14: =C4*C13 -> 300300 | D14: =D4*D13 -> 300600.3 | E14: =E4*E13 -> 300900.9 | F14: =F4*F13 -> 301201.8 | G14: =G4*G13 -> 301503 | H14: =H4*H13 -> 301804.51 | I14: =I4*I13 -> 302106.31 | ... R14: =R4*R13 -> 304836.17
A16: % of typical patients who get TD | B16: 0.189 | C16: =B16 -> 0.189 | D16: =C16 -> 0.189 | E16: =D16 -> 0.189 | F16: =E16 -> 0.189 | G16: =F16 -> 0.189 | H16: =G16 -> 0.189 | I16: =H16 -> 0.189 | J16: =I16 -> 0.189 | ... R16: =Q16 -> 0.189
A17: % of typical patients who get TD (B) | B17: =B14*B16 -> 56700 | C17: =C14*C16 -> 56756.7 | D17: =D14*D16 -> 56813.457 | E17: =E14*E16 -> 56870.27 | F17: =F14*F16 -> 56927.14 | G17: =G14*G16 -> 56984.068 | H17: =H14*H16 -> 57041.052 | I17: =I14*I16 -> 57098.093 | ... R17: =R14*R16 -> 57614.036
A19: Total TD Patients (A + B) | B19: =B11+B17 -> 569700 | C19: =C11+C17 -> 570269.7 | D19: =D11+D17 -> 570839.97 | E19: =E11+E17 -> 571410.81 | F19: =F11+F17 -> 571982.22 | G19: =G11+G17 -> 572554.2 | H19: =H11+H17 -> 573126.76 | I19: =I11+I17 -> 573699.88 | ... R19: =R11+R17 -> 578883.88
A21: % patients not with mild TD/ requiring therapy | B21: 0.3 | C21: =B21 -> 0.3 | D21: =C21 -> 0.3 | E21: =D21 -> 0.3 | F21: =E21 -> 0.3 | G21: =F21 -> 0.3 | H21: =G21 -> 0.3 | I21: =H21 -> 0.3 | J21: =I21 -> 0.3 | ... R21: =Q21 -> 0.3
A22: patients requiring therapy | B22: =B19*B21 -> 170910 | C22: =C19*C21 -> 171080.91 | D22: =D19*D21 -> 171251.99 | E22: =E19*E21 -> 171423.24 | F22: =F19*F21 -> 171594.67 | G22: =G19*G21 -> 171766.26 | H22: =H19*H21 -> 171938.03 | I22: =I19*I21 -> 172109.97 | ... R22: =R19*R21 -> 173665.17
A24: ML-007
A25: % Penetration among TD patients | I25: 0.04 | J25: 0.07 | K25: 0.1 | L25: 0.14 | M25: 0.17 | N25: 0.18 | O25: 0.19 | P25: 0.2 | Q25: 0.2 | R25: 0.2
A27: TD patients receiving therapy | I27: =I25*I22 -> 6884.3986 | J27: =J25*J22 -> 12059.745 | K27: =K25*K22 -> 17245.436 | L27: =L25*L22 -> 24167.754 | M27: =M25*M22 -> 29375.905 | N27: =N25*N22 -> 31135.003 | O27: =O25*O22 -> 32897.59 | P27: =P25*P22 -> 34663.671 | ... R27: =R25*R22 -> 34733.033
A29: Gross Cost per Rx | I29: 1700 | J29: =I29*(1+J30) -> 1785 | K29: =J29*(1+K30) -> 1874.25 | L29: =K29*(1+L30) -> 1967.9625 | M29: =L29*(1+M30) -> 2066.3606 | N29: =M29*(1+N30) -> 2169.6787 | O29: =N29*(1+O30) -> 2278.1626 | P29: =O29*(1+P30) -> 2392.0707 | Q29: =P29*(1+Q30) -> 2511.6743 | R29: =Q29*(1+R30) -> 2637.258
A30: % Change in Price - YOY | J30: 0.05 | K30: =J30 -> 0.05 | L30: =K30 -> 0.05 | M30: =L30 -> 0.05 | N30: =M30 -> 0.05 | O30: =N30 -> 0.05 | P30: =O30 -> 0.05 | Q30: =P30 -> 0.05 | R30: =Q30 -> 0.05
A33: TRxs per Period | I33: 12 | J33: =I33 -> 12 | K33: =J33 -> 12 | L33: =K33 -> 12 | M33: =L33 -> 12 | N33: =M33 -> 12 | O33: =N33 -> 12 | P33: =O33 -> 12 | Q33: =P33 -> 12 | R33: =Q33 -> 12
A34: Gross Cost per Period | I34: =I33*I29 -> 20400 | J34: =J33*J29 -> 21420 | K34: =K33*K29 -> 22491 | L34: =L33*L29 -> 23615.55 | M34: =M33*M29 -> 24796.328 | N34: =N33*N29 -> 26036.144 | O34: =O33*O29 -> 27337.951 | P34: =P33*P29 -> 28704.849 | ... R34: =R33*R29 -> 31647.096
A35: Gross to Net Adjustment | I35: 0.4 | J35: =I35 -> 0.4 | K35: =J35 -> 0.4 | L35: =K35 -> 0.4 | M35: =L35 -> 0.4 | N35: =M35 -> 0.4 | O35: =N35 -> 0.4 | P35: =O35 -> 0.4 | Q35: =P35 -> 0.4 | R35: =Q35 -> 0.4
A36: Net Cost per Period | I36: =I34*(1-I35) -> 12240 | J36: =J34*(1-J35) -> 12852 | K36: =K34*(1-K35) -> 13494.6 | L36: =L34*(1-L35) -> 14169.33 | M36: =M34*(1-M35) -> 14877.797 | N36: =N34*(1-N35) -> 15621.686 | O36: =O34*(1-O35) -> 16402.771 | P36: =P34*(1-P35) -> 17222.909 | ... R36: =R34*(1-R35) -> 18988.257
A38: Sales $ millions | I38: =(I36*I27)/1000000 -> 84.265039 | J38: =(J36*J27)/1000000 -> 154.99185 | K38: =(K36*K27)/1000000 -> 232.72026 | L38: =(L36*L27)/1000000 -> 342.44088 | M38: =(M36*M27)/1000000 -> 437.04873 | N38: =(N36*N27)/1000000 -> 486.38125 | O38: =(O36*O27)/1000000 -> 539.61162 | P38: =(P36*P27)/1000000 -> 597.00926 | ... R38: =(R36*R27)/1000000 -> 659.51977
A39: % Growth Rate | N39: =N38/M38-1 -> 0.11287647 | O39: =O38/N38-1 -> 0.10944167 | P39: =P38/O38-1 -> 0.10636842 | Q39: =Q38/P38-1 -> 0.05105 | R39: =R38/Q38-1 -> 0.05105
A44: ML-007- US - Parkinson's disease psychosis | B44: 2024E | C44: 2025E | D44: 2026E | E44: 2027E | F44: 2028E | G44: 2029E | H44: 2030E | I44: 2031E | J44: 2032E | K44: 2033E | L44: 2034E | M44: 2035E | N44: 2036E | O44: 2037E | P44: 2038E | Q44: 2039E | R44: 2040E
A45: Parkinson's Patients | B45: 1000000 | C45: =B45*(1+C46) -> 1001000 | D45: =C45*(1+D46) -> 1002001 | E45: =D45*(1+E46) -> 1003003 | F45: =E45*(1+F46) -> 1004006 | G45: =F45*(1+G46) -> 1005010 | H45: =G45*(1+H46) -> 1006015 | I45: =H45*(1+I46) -> 1007021 | J45: =I45*(1+J46) -> 1008028.1 | ... R45: =Q45*(1+R46) -> 1016120.6
A46: % Growth | C46: 0.001 | D46: 0.001 | E46: 0.001 | F46: 0.001 | G46: 0.001 | H46: 0.001 | I46: 0.001 | J46: 0.001 | K46: 0.001 | L46: 0.001 | M46: 0.001 | N46: 0.001 | O46: 0.001 | P46: 0.001 | Q46: 0.001 | R46: 0.001
A48: '% of Patients with Psychosis | B48: 0.5 | C48: =B48 -> 0.5 | D48: =C48 -> 0.5 | E48: =D48 -> 0.5 | F48: =E48 -> 0.5 | G48: =F48 -> 0.5 | H48: =G48 -> 0.5 | I48: =H48 -> 0.5 | J48: =I48 -> 0.5 | ... R48: =Q48 -> 0.5
A49: PDP Patients | B49: =B45*B48 -> 500000 | C49: =C45*C48 -> 500500 | D49: =D45*D48 -> 501000.5 | E49: =E45*E48 -> 501501.5 | F49: =F45*F48 -> 502003 | G49: =G45*G48 -> 502505.01 | H49: =H45*H48 -> 503007.51 | I49: =I45*I48 -> 503510.52 | ... R49: =R45*R48 -> 508060.28
A51: '% Patients Treated for Psychosis | B51: 0.25 | C51: =B51 -> 0.25 | D51: =C51 -> 0.25 | E51: =D51 -> 0.25 | F51: =E51 -> 0.25 | G51: =F51 -> 0.25 | H51: =G51 -> 0.25 | I51: =H51 -> 0.25 | J51: =I51 -> 0.25 | ... R51: =Q51 -> 0.25
A52: Patients | B52: =B51*B49 -> 125000 | C52: =C51*C49 -> 125125 | D52: =D51*D49 -> 125250.12 | E52: =E51*E49 -> 125375.38 | F52: =F51*F49 -> 125500.75 | G52: =G51*G49 -> 125626.25 | H52: =H51*H49 -> 125751.88 | I52: =I51*I49 -> 125877.63 | ... R52: =R51*R49 -> 127015.07
A54: ML-007
A55: % Penetration among PD patients | J55: 0.04 | K55: 0.06 | L55: 0.08 | M55: 0.1 | N55: 0.12 | O55: 0.14 | P55: 0.15 | Q55: 0.16 | R55: 0.16
A56: Patients treated | J56: =J52*J55 -> 5040.1403 | K56: =K52*K55 -> 7567.7706 | L56: =L52*L55 -> 10100.451 | M56: =M52*M55 -> 12638.19 | N56: =N52*N55 -> 15180.993 | O56: =O52*O55 -> 17728.87 | P56: =P52*P55 -> 19014.213 | Q56: =Q52*Q55 -> 20302.109 | R56: =R52*R55 -> 20322.411
A59: Gross Cost per Rx | I59: =I29 -> 1700 | J59: =J29 -> 1785 | K59: =K29 -> 1874.25 | L59: =L29 -> 1967.9625 | M59: =M29 -> 2066.3606 | N59: =N29 -> 2169.6787 | O59: =O29 -> 2278.1626 | P59: =P29 -> 2392.0707 | ... R59: =R29 -> 2637.258
A60: % Change in Price - YOY
A63: TRxs per Period | J63: 12 | K63: =J63 -> 12 | L63: =K63 -> 12 | M63: =L63 -> 12 | N63: =M63 -> 12 | O63: =N63 -> 12 | P63: =O63 -> 12 | Q63: =P63 -> 12 | R63: =Q63 -> 12
A64: Gross Cost per Period | J64: =J59*J63 -> 21420 | K64: =K59*K63 -> 22491 | L64: =L59*L63 -> 23615.55 | M64: =M59*M63 -> 24796.328 | N64: =N59*N63 -> 26036.144 | O64: =O59*O63 -> 27337.951 | P64: =P59*P63 -> 28704.849 | Q64: =Q59*Q63 -> 30140.091 | R64: =R59*R63 -> 31647.096
A65: Gross to Net Adjustment | J65: 0.3 | K65: 0.3 | L65: =K65 -> 0.3 | M65: =L65 -> 0.3 | N65: =M65 -> 0.3 | O65: =N65 -> 0.3 | P65: =O65 -> 0.3 | Q65: =P65 -> 0.3 | R65: =Q65 -> 0.3
...

Sheet ML-004
A2: ML-004 - US - Autism Spectrum Disorder | B2: 2024E | C2: 2025E | D2: 2026E | E2: 2027E | F2: 2028E | G2: 2029E | H2: 2030E | I2: 2031E | J2: 2032E | K2: 2033E | L2: 2034E | M2: 2035E | N2: 2036E | O2: 2037E | P2: 2038E | Q2: 2039E | R2: 2040E
A4: Children with ASD | B4: 1000000 | C4: =B4*(1+C5) -> 1001000 | D4: =C4*(1+D5) -> 1002001 | E4: =D4*(1+E5) -> 1003003 | F4: =E4*(1+F5) -> 1004006 | G4: =F4*(1+G5) -> 1005010 | H4: =G4*(1+H5) -> 1006015 | I4: =H4*(1+I5) -> 1007021 | J4: =I4*(1+J5) -> 1008028.1 | ... R4: =Q4*(1+R5) -> 1016120.6
A5: (3-18 years old) | C5: 0.001 | D5: 0.001 | E5: 0.001 | F5: 0.001 | G5: 0.001 | H5: 0.001 | I5: 0.001 | J5: 0.001 | K5: 0.001 | L5: 0.001 | M5: 0.001 | N5: 0.001 | O5: 0.001 | P5: 0.001 | Q5: 0.001 | R5: 0.001
A6: Adults with ASD | B6: 3000000 | C6: =B6*(1+C7) -> 3003000 | D6: =C6*(1+D7) -> 3006003 | E6: =D6*(1+E7) -> 3009009 | F6: =E6*(1+F7) -> 3012018 | G6: =F6*(1+G7) -> 3015030 | H6: =G6*(1+H7) -> 3018045.1 | I6: =H6*(1+I7) -> 3021063.1 | J6: =I6*(1+J7) -> 3024084.2 | ... R6: =Q6*(1+R7) -> 3048361.7
C7: 0.001 | D7: 0.001 | E7: 0.001 | F7: 0.001 | G7: 0.001 | H7: 0.001 | I7: 0.001 | J7: 0.001 | K7: 0.001 | L7: 0.001 | M7: 0.001 | N7: 0.001 | O7: 0.001 | P7: 0.001 | Q7: 0.001 | R7: 0.001
A9: Total ASD population | B9: =B4+B6 -> 4000000 | C9: =C4+C6 -> 4004000 | D9: =D4+D6 -> 4008004 | E9: =E4+E6 -> 4012012 | F9: =F4+F6 -> 4016024 | G9: =G4+G6 -> 4020040 | H9: =H4+H6 -> 4024060.1 | I9: =I4+I6 -> 4028084.1 | ... R9: =R4+R6 -> 4064482.2
A10: % ASD patients with significant social deficit | B10: 0.2 | C10: =B10 -> 0.2 | D10: =C10 -> 0.2 | E10: =D10 -> 0.2 | F10: =E10 -> 0.2 | G10: =F10 -> 0.2 | H10: =G10 -> 0.2 | I10: =H10 -> 0.2 | J10: =I10 -> 0.2 | ... R10: =Q10 -> 0.2
A11: ASD patients with significant social deficit | B11: =B9*B10 -> 800000 | C11: =C9*C10 -> 800800 | D11: =D9*D10 -> 801600.8 | E11: =E9*E10 -> 802402.4 | F11: =F9*F10 -> 803204.8 | G11: =G9*G10 -> 804008.01 | H11: =H9*H10 -> 804812.02 | I11: =I9*I10 -> 805616.83 | ... R11: =R9*R10 -> 812896.45
A12: % ASD patients with irritability | B12: 0.15 | C12: =B12 -> 0.15 | D12: =C12 -> 0.15 | E12: =D12 -> 0.15 | F12: =E12 -> 0.15 | G12: =F12 -> 0.15 | H12: =G12 -> 0.15 | I12: =H12 -> 0.15 | J12: =I12 -> 0.15 | ... R12: =Q12 -> 0.15
A13: ASD patients with irritability | B13: =B12*B9 -> 600000 | C13: =C12*C9 -> 600600 | D13: =D12*D9 -> 601200.6 | E13: =E12*E9 -> 601801.8 | F13: =F12*F9 -> 602403.6 | G13: =G12*G9 -> 603006.01 | H13: =H12*H9 -> 603609.01 | I13: =I12*I9 -> 604212.62 | ... R13: =R12*R9 -> 609672.34
A15: ML-004
A16: % Penetration among ASD social deficit market | I16: 0.01 | J16: 0.03 | K16: 0.05 | L16: 0.06 | M16: 0.07 | N16: 0.08 | O16: 0.09 | P16: =O16+0.005 -> 0.095 | Q16: =P16+0.005 -> 0.1 | R16: =Q16+0.005 -> 0.105
A17: % Penetration among ASD irritability market | I17: =I16 -> 0.01 | J17: =J16 -> 0.03 | K17: =K16 -> 0.05 | L17: =L16 -> 0.06 | M17: =M16 -> 0.07 | N17: =N16 -> 0.08 | O17: =O16 -> 0.09 | P17: =P16 -> 0.095 | ... R17: =R16 -> 0.105
