Workbook
Name IPS: #REF!
Name NDTI: #REF!
Name Notes: ML007MA_ME!$C$62,ML007MA_ME!$C$63:$C$65
Name Notes: '[3]VA Consensus'!$C$172,'[3]VA Consensus'!$C$173:$C$175
Name NPA: #REF!
Name RP_PP: #REF!

Sheet __FDSCACHE__
B1: This sheet contains FactSet XML data for use with this workbook's =FDS codes. Modifying the worksheet's contents may damage the workbook's =FDS functionality.

Sheet Variance
A1: COGT Variance Analysis
B3: 3Q24A | C3: 3Q25E | E3: 3Q25A | N3: 44768
B4: Value | C4: Amount | D4: % Change | E4: Amount | F4: % Change | G4: Variance | I4: Consensus | J4: Actual vs Cons | N4: Consensus
A5: Products
A6: Royalties and Contract Revenue | B6: 0 | C6: 0 | D6: =IFERROR(C6/B6-1,"NA") -> NA | E6: 0 | F6: =IFERROR(E6/B6-1,"NA") -> NA | G6: =E6-C6 -> 0
A7: Total Revenues | B7: =B6 -> 0 | C7: =C6 -> 0 | D7: =IFERROR(C7/B7-1,"NA") -> NA | E7: =E6 -> 0 | F7: =IFERROR(E7/B7-1,"NA") -> NA | G7: =E7-C7 -> 0 | I7: =FactSet!#REF! -> #REF! | J7: =E7-I7 -> #REF! | N7: 10.191705
A9: COGS | B9: 0 | C9: 0 | D9: =IFERROR(C9/B9-1,"NA") -> NA | E9: 0 | F9: =IFERROR(E9/B9-1,"NA") -> NA | G9: =-(E9-C9) -> 0 | N9: 0
A10: Gross Profit | B10: =B7-B9 -> 0 | C10: =C7-C9 -> 0 | D10: =IFERROR(C10/B10-1,"NA") -> NA | E10: =E7-E9 -> 0 | F10: =IFERROR(E10/B10-1,"NA") -> NA | G10: =E10-C10 -> 0
A11: SG&A | B11: 11.8 | C11: 13.5 | D11: =IFERROR(C11/B11-1,"NA") -> 0.1440678 | E11: 14.366 | F11: =IFERROR(E11/B11-1,"NA") -> 0.21745763 | G11: =-(E11-C11) -> -0.866 | I11: =FactSet!#REF! -> #REF! | J11: =-(E11-I11) -> #REF! | N11: 12.76223
A12: R&D | B12: 63.614 | C12: 65.604709 | D12: =IFERROR(C12/B12-1,"NA") -> 0.031293565 | E12: 68.989 | F12: =IFERROR(E12/B12-1,"NA") -> 0.084493979 | G12: =-(E12-C12) -> -3.3842911 | I12: =FactSet!#REF! -> #REF! | J12: =-(E12-I12) -> #REF! | N12: 26.507185
A13: Operating Income | B13: =B10-B11-B12 -> -75.414 | C13: =C10-C11-C12 -> -79.104709 | D13: =IFERROR(C13/B13-1,"NA") -> 0.048939307 | E13: =E10-E11-E12 -> -83.355 | F13: =IFERROR(E13/B13-1,"NA") -> 0.10529875 | G13: =E13-C13 -> -4.2502911 | I13: =FactSet!#REF! -> #REF! | J13: =E13-I13 -> #REF! | N13: -28.511639
A15: Interest income | B15: 4.779 | C15: 4 | D15: =IFERROR(C15/B15-1,"NA") -> -0.16300481 | E15: 3.887 | F15: =IFERROR(E15/B15-1,"NA") -> -0.18664993 | G15: =E15-C15 -> -0.113
A16: Gain on disposal of long-lived assets | B16: 0 | C16: 0 | D16: =IFERROR(C16/B16-1,"NA") -> NA | E16: 0
A17: Other income, net | B17: 0.044 | C17: 1.5687931 | D17: =IFERROR(C17/B17-1,"NA") -> 34.65439 | E17: =-1.459-0.003 -> -1.462 | F17: =IFERROR(E17/B17-1,"NA") -> -34.227273 | G17: =E17-C17 -> -3.0307931
A18: Non-Operating Items | B18: =SUM(B15:B17) -> 4.823 | C18: =SUM(C15:C17) -> 5.5687931 | D18: =IFERROR(C18/B18-1,"NA") -> 0.15463262 | E18: =SUM(E15:E17) -> 2.425 | F18: =IFERROR(E18/B18-1,"NA") -> -0.49720091 | G18: =E18-C18 -> -3.1437931
A19: Pre-tax Income | B19: =B13+B18 -> -70.591 | C19: =C13+C18 -> -73.535916 | D19: =IFERROR(C19/B19-1,"NA") -> 0.041718005 | E19: =E13+E18 -> -80.93 | F19: =IFERROR(E19/B19-1,"NA") -> 0.14646343 | G19: =E19-C19 -> -7.3940843
A20: Tax Rate | B20: =B21/B19 -> 0 | C20: =C21/C19 -> 0 | D20: =IFERROR(C20/B20-1,"NA") -> NA | E20: =E21/E19 -> 0 | F20: =IFERROR(E20/B20-1,"NA") -> NA | G20: =E20-C20 -> 0
A21: Taxes | B21: 0 | C21: 0 | D21: =IFERROR(C21/B21-1,"NA") -> NA | E21: 0 | F21: =IFERROR(E21/B21-1,"NA") -> NA | G21: =-(E21-C21) -> 0 | N21: -0.033018783
A23: Net Income (GAAP) | B23: =B19-B21 -> -70.591 | C23: =C19-C21 -> -73.535916 | D23: =IFERROR(C23/B23-1,"NA") -> 0.041718005 | E23: =E19-E21 -> -80.93 | F23: =IFERROR(E23/B23-1,"NA") -> 0.14646343 | G23: =E23-C23 -> -7.3940843 | I23: =FactSet!#REF! -> #REF! | J23: =E23-I23 -> #REF! | N23: -27.79529
A25: Average Basic & Diluted Shares | B25: 99.24003 | C25: 113.80794 | D25: =IFERROR(C25/B25-1,"NA") -> 0.1467947 | E25: 114.46608 | F25: =IFERROR(E25/B25-1,"NA") -> 0.1534265 | G25: =E25-C25 -> 0.65814
A26: GAAP EPS | B26: =B23/B25 -> -0.71131579 | C26: =C23/C25 -> -0.64614047 | D26: =IFERROR(C26/B26-1,"NA") -> -0.091626418 | E26: =E23/E25 -> -0.70702168 | F26: =IFERROR(E26/B26-1,"NA") -> -0.0060368521 | G26: =E26-C26 -> -0.060881209 | I26: =FactSet!#REF! -> #REF! | J26: =E26-I26 -> #REF! | N26: -0.6016666
A27: Source: Company reports; Team Research estimates

Sheet IS
A1: MapLight Therapeutics | AU1: =SOTP!R14 -> 37.175346
A2: Income Statement
A3: ($ Millions, except EPS)
B4: 1Q19A | C4: 2Q19A | D4: 3Q19A | E4: 4Q19A | F4: 2019A | G4: 1Q20A | H4: 2Q20A | I4: 3Q20A | J4: 4Q20A | K4: 2020A | L4: 1Q21A | M4: 2Q21A | N4: 3Q21A | O4: 4Q21A | P4: 2021A | Q4: 1Q22A | R4: 2Q22A | S4: 3Q22A | T4: 4Q22A | U4: 2022A | V4: 1Q23A | W4: 2Q23A | X4: 3Q23A | Y4: 4Q23A | Z4: 2023A | AA4: 1Q25A | AB4: 2Q25A | AC4: 3Q25A | AD4: 4Q25A | AE4: 2025A | AF4: 1Q26E | AG4: 2Q26E | AH4: 3Q26E | AI4: 4Q26E | AJ4: 2026E | AK4: 2027E | AL4: 2028E | AM4: 2029E | AN4: 2030E | AO4: 2031E | AP4: 2032E | AQ4: 2033E | AR4: 2034E | AS4: 2035E | AV4: Check
A6: Product Revenue | F6: 0 | G6: 0 | H6: 0 | I6: 0 | J6: =K6-SUM(G6:I6) -> 0 | K6: 0 | L6: 0 | M6: 0 | N6: 0 | O6: =P6-SUM(L6:N6) -> 0 | P6: 0 | Q6: 0 | R6: 0 | S6: 0 | T6: 0 | U6: =SUM(Q6:T6) -> 0 | V6: 0 | W6: 0 | X6: 0 | Y6: 0 | Z6: =REVENUE!Z19 -> #REF! | AC6: 0 | AD6: =REVENUE!AH19 -> 0 | AE6: =REVENUE!AI19 -> 0 | AF6: =REVENUE!AJ19 -> 0 | AG6: =REVENUE!AK19 -> 0 | AH6: =REVENUE!AL19 -> 0 | AI6: =REVENUE!AM19 -> 0 | AJ6: =REVENUE!AN19 -> 0 | AK6: =REVENUE!AO19 -> 0 | AL6: =REVENUE!AP19 -> 0 | AM6: =REVENUE!AQ19+REVENUE!AQ25 -> 16.880566 | AN6: =REVENUE!AR19+REVENUE!AR25 -> 128.13327 | AO6: =REVENUE!AS19+REVENUE!AS25 -> 348.00111 | AP6: =REVENUE!AT19+REVENUE!AT25 -> 670.96672 | AQ6: =REVENUE!AU19+REVENUE!AU25 -> 969.33752 | AR6: =REVENUE!AV19+REVENUE!AV25 -> 1235.6197 | AS6: =REVENUE!AW19+REVENUE!AW25 -> 1475.7246
A7: Collaboration revenue | F7: 22.499 | G7: 7.031 | H7: 0.528 | I7: 0.312 | J7: =K7-SUM(G7:I7) -> 0 | K7: 7.871 | L7: 0 | M7: 0 | N7: 0 | O7: =P7-SUM(L7:N7) -> 0 | P7: 0 | Q7: 0 | R7: 0 | S7: 0 | T7: 0 | U7: =SUM(Q7:T7) -> 0 | V7: 0 | W7: 0 | X7: 0 | Y7: 0 | Z7: =REVENUE!Z34 -> 0 | AC7: 0 | AD7: =REVENUE!AH34 -> 0 | AE7: =REVENUE!AI34 -> 0 | AF7: =REVENUE!AJ34 -> 0 | AG7: =REVENUE!AK34 -> 0 | AH7: =REVENUE!AL34 -> 0 | AI7: =REVENUE!AM34 -> 0 | AJ7: =REVENUE!AN34 -> 0 | AK7: =REVENUE!AO34 -> 0 | ... AS7: =REVENUE!AW34 -> 0
A8: Total Revenues | F8: =SUM(F6:F7) -> 22.499 | G8: =SUM(G6:G7) -> 7.031 | H8: =SUM(H6:H7) -> 0.528 | I8: =SUM(I6:I7) -> 0.312 | J8: =SUM(J6:J7) -> 0 | K8: =SUM(K6:K7) -> 7.871 | L8: =SUM(L6:L7) -> 0 | M8: =SUM(M6:M7) -> 0 | ... Z8: =SUM(Z6:Z7) -> #REF! | AC8: =SUM(AC6:AC7) -> 0 | AD8: =SUM(AD6:AD7) -> 0 | AE8: =SUM(AE6:AE7) -> 0 | AF8: =SUM(AF6:AF7) -> 0 | AG8: =SUM(AG6:AG7) -> 0 | AH8: =SUM(AH6:AH7) -> 0 | AI8: =SUM(AI6:AI7) -> 0 | AJ8: =SUM(AJ6:AJ7) -> 0 | ... AS8: =SUM(AS6:AS7) -> 1475.7246 | AV8: =AJ8-SUM(AF8:AI8) -> 0
A9: Consensus | Y9: =FactSet!#REF! -> #REF! | Z9: =FactSet!#REF! -> #REF! | AC9: =FactSet!P17 -> 0 | AD9: =FactSet!Q17 -> 0 | AE9: =FactSet!R17 -> 0 | AF9: =FactSet!S17 -> 0 | AG9: =FactSet!T17 -> 0 | AH9: =FactSet!U17 -> 0 | AI9: =FactSet!V17 -> 0 | AJ9: =FactSet!W17 -> 0 | AK9: =FactSet!X17 -> 0
A13: COGS | F13: 0 | G13: 0 | H13: 0 | I13: 0 | J13: =K13-SUM(G13:I13) -> 0 | K13: 0 | L13: 0 | M13: 0 | N13: 0 | O13: =P13-SUM(L13:N13) -> 0 | P13: 0 | Q13: 0 | R13: 0 | S13: 0 | T13: 0 | U13: =SUM(Q13:T13) -> 0 | V13: 0 | W13: 0 | X13: 0 | Y13: 0 | Z13: =OPEX!#REF! -> #REF! | AC13: 0 | AD13: 0 | AE13: =OPEX!O94 -> 0 | AF13: =OPEX!P94 -> 0 | AG13: =OPEX!Q94 -> 0 | AH13: =OPEX!R94 -> 0 | AI13: =OPEX!S94 -> 0 | AJ13: =OPEX!T94 -> 0 | AK13: =OPEX!U94 -> 0 | AL13: =OPEX!V94 -> 0 | ... AS13: =OPEX!AC94 -> 110.67934 | AV13: =AJ13-SUM(AF13:AI13) -> 0
A14: Gross Profit | F14: =F8-F13 -> 22.499 | G14: =G8-G13 -> 7.031 | H14: =H8-H13 -> 0.528 | I14: =I8-I13 -> 0.312 | J14: =J8-J13 -> 0 | K14: =K8-K13 -> 7.871 | L14: =L8-L13 -> 0 | M14: =M8-M13 -> 0 | ... Z14: =Z8-Z13 -> #REF! | AC14: =AC8-AC13 -> 0 | AD14: =AD8-AD13 -> 0 | AE14: =AE8-AE13 -> 0 | AF14: =AF8-AF13 -> 0 | AG14: =AG8-AG13 -> 0 | AH14: =AH8-AH13 -> 0 | AI14: =AI8-AI13 -> 0 | AJ14: =AJ8-AJ13 -> 0 | ... AS14: =AS8-AS13 -> 1365.0453
A16: SG&A | F16: 10.968 | G16: 3.674 | H16: 2.802 | I16: 5.598 | J16: =K16-SUM(G16:I16) -> 5.348 | K16: 17.422 | L16: 4.587 | M16: 4.904 | N16: 5.021 | O16: =P16-SUM(L16:N16) -> 5.126 | P16: 19.638 | Q16: 5.948 | R16: 6.376 | S16: 6.885 | T16: 7.003 | U16: =SUM(Q16:T16) -> 26.212 | V16: 7.199 | W16: 8.214 | X16: 9.453 | Y16: 9.508 | Z16: =OPEX!#REF! -> #REF! | AC16: 4.404 | AD16: 18.755 | AE16: 30.734 | AF16: =OPEX!P68 -> 13 | AG16: =OPEX!Q68 -> 14.1 | AH16: =OPEX!R68 -> 15 | AI16: =OPEX!S68 -> 15.2 | AJ16: =OPEX!T68 -> 57.3 | AK16: =OPEX!U68 -> 59.019 | AL16: =OPEX!V68 -> 81.646819 | AM16: =OPEX!W68 -> 116.54432 | ... AS16: =OPEX!AC68 -> 183.35219 | AV16: =AJ16-SUM(AF16:AI16) -> 0
A17: Consensus | Y17: =FactSet!#REF! -> #REF! | Z17: =FactSet!#REF! -> #REF! | AC17: =FactSet!P20 -> 4.4 | AD17: =FactSet!Q20 -> 18.8 | AE17: =FactSet!R20 -> 30.7 | AF17: =FactSet!S20 -> 8.5 | AG17: =FactSet!T20 -> 9.033334 | AH17: =FactSet!U20 -> 9.733334 | AI17: =FactSet!V20 -> 10.166667 | AJ17: =FactSet!W20 -> 37.433334 | AK17: =FactSet!X20 -> 42.1
A18: R&D | F18: 43.709 | G18: 9.498 | H18: 5.129 | I18: 5.003 | J18: =K18-SUM(G18:I18) -> 6.108 | K18: 25.738 | L18: 8.213 | M18: 12.388 | N18: 14.798 | O18: =P18-SUM(L18:N18) -> 20.514 | P18: 55.913 | Q18: 25.47 | R18: 29.479 | S18: 29.936 | T18: 36.742 | U18: =SUM(Q18:T18) -> 121.627 | V18: 36.038 | W18: 38.871 | X18: 50.127 | Y18: 48.719 | Z18: =OPEX!#REF! -> #REF! | AC18: 27.094 | AD18: 64.623 | AE18: 138.349 | AF18: =OPEX!P13 -> 42 | AG18: =OPEX!Q13 -> 40.5 | AH18: =OPEX!R13 -> 37.05 | AI18: =OPEX!S13 -> 39.55 | AJ18: =OPEX!T13 -> 159.1 | AK18: =OPEX!U13 -> 165.373 | AL18: =OPEX!V13 -> 182.04209 | AM18: =OPEX!W13 -> 164.86335 | ... AS18: =OPEX!AC13 -> 158.65991 | AV18: =AJ18-SUM(AF18:AI18) -> 0
A19: Consensus | Y19: =FactSet!#REF! -> #REF! | Z19: =FactSet!#REF! -> #REF! | AC19: =FactSet!P21 -> 27.1 | AD19: =FactSet!Q21 -> 64.6 | AE19: =FactSet!R21 -> 138.3 | AF19: =FactSet!S21 -> 35.1 | AG19: =FactSet!T21 -> 36.766666 | AH19: =FactSet!U21 -> 38.1 | AI19: =FactSet!V21 -> 40.766666 | AJ19: =FactSet!W21 -> 150.66667
A20: Acquired in-process research and development | F20: 0 | G20: 0 | H20: 0 | I20: 46.91 | J20: =K20-SUM(G20:I20) -> 0 | K20: 46.91 | L20: 0 | M20: 0 | N20: 0 | O20: =P20-SUM(L20:N20) -> 0 | P20: 0 | Q20: 0 | R20: 0 | S20: 0 | T20: 0 | U20: =SUM(Q20:T20) -> 0 | V20: 0 | W20: 0 | X20: 0 | Y20: =Z20-SUM(V20:X20) -> 0 | Z20: 0 | AC20: 0 | AD20: 0 | AE20: 0 | AF20: 0 | AG20: 0 | AH20: 0 | AI20: =AJ20-SUM(AF20:AH20) -> 0 | AJ20: 0 | AK20: 0 | AL20: =AK20 -> 0 | AM20: =AL20 -> 0 | AN20: =AM20 -> 0 | AO20: =AN20 -> 0 | AP20: =AO20 -> 0 | AQ20: =AP20 -> 0 | AR20: =AQ20 -> 0 | AS20: =AR20 -> 0
A22: Total Expenses | F22: =F16+F18+F20 -> 54.677 | G22: =G16+G18+G20 -> 13.172 | H22: =H16+H18+H20 -> 7.931 | I22: =I16+I18+I20 -> 57.511 | J22: =J16+J18+J20 -> 11.456 | K22: =K16+K18+K20 -> 90.07 | L22: =L16+L18+L20 -> 12.8 | M22: =M16+M18+M20 -> 17.292 | ... Z22: =Z16+Z18+Z20 -> #REF! | AC22: =AC16+AC18+AC20 -> 31.498 | AD22: =AD16+AD18+AD20 -> 83.378 | AE22: =AE16+AE18+AE20 -> 169.083 | AF22: =AF16+AF18+AF20 -> 55 | AG22: =AG16+AG18+AG20 -> 54.6 | AH22: =AH16+AH18+AH20 -> 52.05 | AI22: =AI16+AI18+AI20 -> 54.75 | AJ22: =AJ16+AJ18+AJ20 -> 216.4 | ... AS22: =AS16+AS18+AS20 -> 342.01209 | AV22: =AJ22-SUM(AF22:AI22) -> 0
A24: Operating Income | F24: =F8-F13-F16-F18-F20 -> -32.178 | G24: =G8-G13-G16-G18-G20 -> -6.141 | H24: =H8-H13-H16-H18-H20 -> -7.403 | I24: =I8-I13-I16-I18-I20 -> -57.199 | J24: =J8-J13-J16-J18-J20 -> -11.456 | K24: =K8-K13-K16-K18-K20 -> -82.199 | L24: =L8-L13-L16-L18-L20 -> -12.8 | M24: =M8-M13-M16-M18-M20 -> -17.292 | ... Z24: =Z8-Z13-Z16-Z18-Z20 -> #REF! | AC24: =AC8-AC13-AC16-AC18-AC20 -> -31.498 | AD24: =AD8-AD13-AD16-AD18-AD20 -> -83.378 | AE24: =AE8-AE13-AE16-AE18-AE20 -> -169.083 | AF24: =AF8-AF13-AF16-AF18-AF20 -> -55 | AG24: =AG8-AG13-AG16-AG18-AG20 -> -54.6 | AH24: =AH8-AH13-AH16-AH18-AH20 -> -52.05 | AI24: =AI8-AI13-AI16-AI18-AI20 -> -54.75 | AJ24: =AJ8-AJ13-AJ16-AJ18-AJ20 -> -216.4 | ... AS24: =AS8-AS13-AS16-AS18-AS20 -> 1023.0332
A26: Interest income | F26: 0.267 | G26: 0.047 | H26: 0.003 | I26: 0.023 | J26: =K26-SUM(G26:I26) -> 0.071 | K26: 0.144 | L26: 0.125 | M26: 0.12 | N26: 0.115 | O26: =P26-SUM(L26:N26) -> 0.107 | P26: 0.467 | Q26: 0.107 | R26: 0.272 | S26: 1.5 | T26: 2.11 | U26: =SUM(Q26:T26) -> 3.989 | V26: 2.268 | W26: 2.741 | X26: 4.198 | Y26: 3.87 | Z26: =SUM(V26:Y26) -> 13.077 | AC26: 1.549 | AD26: 2.471 | AE26: 5.518 | AF26: 2.5 | AG26: 2.5 | AH26: 2.5 | AI26: =AJ26-AH26-AG26-AF26 -> 2.5 | AJ26: 10 | AK26: 10 | AL26: =AK26*1.03 -> 10.3 | AM26: =AL26*1.03 -> 10.609 | AN26: =AM26*1.03 -> 10.92727 | AO26: =AN26*1.03 -> 11.255088 | AP26: =AO26*1.03 -> 11.592741 | AQ26: =AP26*1.03 -> 11.940523 | AR26: =AQ26*1.03 -> 12.298739 | AS26: =AR26*1.03 -> 12.667701
A27: Loss from equity method investment | F27: 0 | G27: 0 | H27: 0.007 | I27: 0.239 | J27: =K27-SUM(G27:I27) -> 0.533 | K27: 0.779 | L27: 0.604 | M27: 0.623 | N27: 0.62 | O27: =P27-SUM(L27:N27) -> 0.621 | P27: 2.468 | Q27: 0.677 | R27: 0.656 | S27: 0.259 | T27: 0.657 | U27: =SUM(Q27:T27) -> 2.249 | V27: 0.682 | W27: 0.268 | X27: 0 | Y27: -0.007 | Z27: =SUM(V27:Y27) -> 0.943 | AC27: 0 | AD27: 0 | AE27: 0 | AF27: 0 | AG27: 0 | AH27: 0 | AI27: =AJ27-AH27-AG27-AF27 -> 0 | AJ27: 0 | AK27: 0 | AL27: =AK27*1.03 -> 0 | AM27: =AL27*1.03 -> 0 | AN27: =AM27*1.03 -> 0 | AO27: =AN27*1.03 -> 0 | AP27: =AO27*1.03 -> 0 | AQ27: =AP27*1.03 -> 0 | AR27: =AQ27*1.03 -> 0 | AS27: =AR27*1.03 -> 0
A28: Other income, net | F28: 0 | G28: 0 | H28: 0 | I28: -0.509 | J28: =K28-SUM(G28:I28) -> -0.516 | K28: -1.025 | L28: 0.343 | M28: 0 | N28: 0 | O28: =P28-SUM(L28:N28) -> 0 | P28: 0.343 | Q28: 0 | R28: 0 | S28: 0 | T28: 1.36 | U28: =SUM(Q28:T28) -> 1.36 | V28: 1.7 | W28: 0 | X28: 0 | Y28: 0 | Z28: =SUM(V28:Y28) -> 1.7 | AC28: 0.531 | AD28: 1.359 | AE28: 2.413 | AF28: 0 | AG28: 0 | AH28: 0 | AI28: =AJ28-AH28-AG28-AF28 -> 0 | AJ28: 0 | AK28: 0 | AL28: =AK28 -> 0 | AM28: =AL28 -> 0 | AN28: =AM28 -> 0 | AO28: =AN28 -> 0 | AP28: =AO28 -> 0 | AQ28: =AP28 -> 0 | AR28: =AQ28 -> 0 | AS28: =AR28 -> 0
A29: Non-Operating Income | F29: =SUM(F26:F28) -> 0.267 | G29: =SUM(G26:G28) -> 0.047 | H29: =SUM(H26:H28) -> 0.01 | I29: =SUM(I26:I28) -> -0.247 | J29: =SUM(J26:J28) -> 0.088 | K29: =SUM(K26:K28) -> -0.102 | L29: =SUM(L26:L28) -> 1.072 | M29: =SUM(M26:M28) -> 0.743 | ... Z29: =SUM(Z26:Z28) -> 15.72 | AC29: =SUM(AC26:AC28) -> 2.08 | AD29: =SUM(AD26:AD28) -> 3.83 | AE29: =SUM(AE26:AE28) -> 7.931 | AF29: =SUM(AF26:AF28) -> 2.5 | AG29: =SUM(AG26:AG28) -> 2.5 | AH29: =SUM(AH26:AH28) -> 2.5 | AI29: =SUM(AI26:AI28) -> 2.5 | AJ29: =SUM(AJ26:AJ28) -> 10 | ... AS29: =SUM(AS26:AS28) -> 12.667701
A31: Pretax Income | F31: =F24+F29 -> -31.911 | G31: =G24+G29 -> -6.094 | H31: =H24+H29 -> -7.393 | I31: =I24+I29 -> -57.446 | J31: =J24+J29 -> -11.368 | K31: =K24+K29 -> -82.301 | L31: =L24+L29 -> -11.728 | M31: =M24+M29 -> -16.549 | ... T31: =T24+T29 -> -39.618 | U31: =SUM(Q31:T31) -> -140.241 | V31: =V24+V29 -> -38.587 | W31: =W24+W29 -> -44.076 | X31: =X24+X29 -> -55.382 | Y31: =Y24+Y29 -> -54.364 | Z31: =Z24+Z29 -> #REF! | AC31: =AC24+AC29 -> -29.418 | AD31: =AD24+AD29 -> -79.548 | AE31: =AE24+AE29 -> -161.152 | AF31: =AF24+AF29 -> -52.5 | AG31: =AG24+AG29 -> -52.1 | AH31: =AH24+AH29 -> -49.55 | AI31: =AI24+AI29 -> -52.25 | AJ31: =AJ24+AJ29 -> -206.4 | ... AS31: =AS24+AS29 -> 1035.7009 | AV31: =AJ31-SUM(AF31:AI31) -> 0
A32: Taxes | F32: 0 | G32: 0 | H32: 0 | I32: 0 | J32: =K32-SUM(G32:I32) -> 0 | K32: 0 | L32: 0 | M32: 0 | N32: 0 | O32: =P32-SUM(L32:N32) -> 0 | P32: 0 | Q32: 0 | R32: 0 | S32: 0 | T32: 0 | U32: =SUM(Q32:T32) -> 0 | V32: 0 | W32: 0 | X32: 0 | Y32: 0 | Z32: =SUM(V32:Y32) -> 0 | AC32: 0 | AD32: 0 | AE32: 0 | AF32: =AF31*AF33 -> 0 | AG32: =AG31*AG33 -> 0 | AH32: =AH31*AH33 -> 0 | AI32: =AI31*AI33 -> 0 | AJ32: =SUM(AF32:AI32) -> 0 | AK32: =AK31*AK33 -> 0 | AL32: =AL31*AL33 -> 0 | AM32: =AM31*AM33 -> 0 | AN32: =AN31*AN33 -> 0 | AO32: =AO31*AO33 -> 0 | AP32: =AP31*AP33 -> 15.877365 | AQ32: =AQ31*AQ33 -> 58.508113 | AR32: =AR31*AR33 -> 172.75574 | AS32: =AS31*AS33 -> 217.49718
A33: Tax Rate | F33: =F32/F31 -> 0 | G33: =G32/G31 -> 0 | H33: =H32/H31 -> 0 | I33: =I32/I31 -> 0 | J33: =J32/J31 -> 0 | K33: =K32/K31 -> 0 | L33: =L32/L31 -> 0 | M33: =M32/M31 -> 0 | ... Z33: =Z32/Z31 -> #REF! | AC33: =AC32/AC31 -> 0 | AD33: =AD32/AD31 -> 0 | AE33: =AE32/AE31 -> 0 | AF33: 0 | AG33: 0 | AH33: 0 | AI33: 0 | AJ33: =AJ32/AJ31 -> 0 | AK33: 0 | AL33: 0 | AM33: 0 | AN33: 0 | AO33: 0 | AP33: 0.05 | AQ33: 0.1 | AR33: 0.21 | AS33: =AR33 -> 0.21
A35: Net loss | F35: =F31-F32 -> -31.911 | G35: =G31-G32 -> -6.094 | H35: =H31-H32 -> -7.393 | I35: =I31-I32 -> -57.446 | J35: =J31-J32 -> -11.368 | K35: =K31-K32 -> -82.301 | L35: =L31-L32 -> -11.728 | M35: =M31-M32 -> -16.549 | ... T35: =T31-T32 -> -39.618 | U35: =SUM(Q35:T35) -> -140.241 | V35: =V31-V32 -> -38.587 | W35: =W31-W32 -> -44.076 | X35: =X31-X32 -> -55.382 | Y35: =Y31-Y32 -> -54.364 | Z35: =Z31-Z32 -> #REF! | AC35: =AC31-AC32 -> -29.418 | AD35: =AD31-AD32 -> -79.548 | AE35: =AE31-AE32 -> -161.152 | AF35: =AF31-AF32 -> -52.5 | AG35: =AG31-AG32 -> -52.1 | AH35: =AH31-AH32 -> -49.55 | AI35: =AI31-AI32 -> -52.25 | AJ35: =AJ31-AJ32 -> -206.4 | ... AS35: =AS31-AS32 -> 818.20368
A36: Unrealized (loss) gain on available-for-sale invesments | AC36: -0.004 | AD36: 0 | AE36: -0.391
A37: Comprehensive loss | AC37: =AC35+AC36 -> -29.422 | AD37: =AD35+AD36 -> -79.548 | AE37: =AE35+AE36 -> -161.543
A39: Shares - Weighted average | F39: 7.620082 | G39: 7.534187 | H39: 7.777487 | I39: 9.85053 | J39: =K39*4-SUM(G39:I39) -> 19.162824 | K39: 11.081257 | L39: 34.879296 | M39: 38.441729 | N39: 39.848943 | O39: =P39*4-SUM(L39:N39) -> 41.753284 | P39: 38.730813 | Q39: 45.105923 | R39: 49.388936 | S39: 69.576359 | T39: 70.489607 | U39: =#REF!/U40 -> #REF! | V39: 70.73495 | W39: 74.753269 | X39: 86.165951 | Y39: 86.730309 | Z39: 79.657942 | AC39: 0.791127 | AD39: 32.148977 | AE39: 8.680741 | AF39: =AD39+0.5 -> 32.648977 | AG39: =AF39+0.5 -> 33.148977 | AH39: =AG39+0.5 -> 33.648977 | AI39: =AH39+CF!D47 -> 47.648977 | AJ39: =AVERAGE(AF39:AI39) -> 36.773977 | AK39: =AI39+2+CF!E47 -> 56.605499 | AL39: =AK39+2+CF!F47 -> 58.605499 | AM39: =AL39+2+CF!G47 -> 66.915269 | AN39: =AM39+2+CF!H47 -> 68.915269 | AO39: =AN39+2+CF!I47 -> 70.915269 | AP39: =AO39+2+CF!J47 -> 72.915269 | AQ39: =AP39+2+CF!K47 -> 74.915269 | AR39: =AQ39+2+CF!L47 -> 76.915269 | AS39: =AR39+2+CF!M47 -> 78.915269
A40: EPS - Basic & diluted | F40: =#REF!/F39 -> #REF! | G40: =#REF!/G39 -> #REF! | H40: =#REF!/H39 -> #REF! | I40: =#REF!/I39 -> #REF! | J40: =#REF!/J39 -> #REF! | K40: =SUM(G40:J40) -> #REF! | L40: =#REF!/L39 -> #REF! | M40: =#REF!/M39 -> #REF! | N40: =#REF!/N39 -> #REF! | O40: =#REF!/O39 -> #REF! | P40: =SUM(L40:O40) -> #REF! | Q40: =#REF!/Q39 -> #REF! | R40: =#REF!/R39 -> #REF! | S40: =#REF!/S39 -> #REF! | T40: =#REF!/T39 -> #REF! | U40: =SUM(Q40:T40) -> #REF! | V40: =#REF!/V39 -> #REF! | W40: =#REF!/W39 -> #REF! | X40: =#REF!/X39 -> #REF! | Y40: =#REF!/Y39 -> #REF! | Z40: =#REF!/Z39 -> #REF! | AC40: =AC35/AC39 -> -37.184927 | AD40: =AD35/AD39 -> -2.4743556 | AE40: =AE35/AE39 -> -18.564314 | AF40: =AF35/AF39 -> -1.6080136 | AG40: =AG35/AG39 -> -1.5716925 | AH40: =AH35/AH39 -> -1.4725559 | AI40: =AI35/AI39 -> -1.0965608 | AJ40: =SUM(AF40:AI40) -> -5.7488229 | AK40: =AK35/AK39 -> -3.7874766 | AL40: =AL35/AL39 -> -4.3236371 | AM40: =AM35/AM39 -> -3.8135413 | AN40: =AN35/AN39 -> -2.369021 | AO40: =AO35/AO39 -> 0.3805463 | AP40: =AP35/AP39 -> 4.1372669 | AQ40: =AQ35/AQ39 -> 7.0289144 | AR40: =AR35/AR39 -> 8.449436 | AS40: =AS35/AS39 -> 10.368129 | AV40: =AJ40-SUM(AF40:AI40) -> 0
A41: Consensus | Y41: =FactSet!#REF! -> #REF! | Z41: =FactSet!#REF! -> #REF! | AC41: =FactSet!P8 -> -37.18 | AD41: =FactSet!Q8 -> -2.47 | AE41: =FactSet!R8 -> -18.56 | AF41: =FactSet!S8 -> -0.948 | AG41: =FactSet!T8 -> -0.99 | AH41: =FactSet!U8 -> -0.98 | AI41: =FactSet!V8 -> -1.028 | AJ41: =FactSet!W8 -> -3.946 | AK41: =FactSet!X8 -> -4.1
A42: Source: Company reports; Needham & Company, LLC estimates
A45: Margin Analysis | B45: =B4 -> 1Q19A | C45: =C4 -> 2Q19A | D45: =D4 -> 3Q19A | E45: =E4 -> 4Q19A | F45: =F4 -> 2019A | G45: =G4 -> 1Q20A | H45: =H4 -> 2Q20A | I45: =I4 -> 3Q20A | ... AS45: =AS4 -> 2035E
A47: Revenues | AJ47: 1 | AK47: 1 | AL47: 1 | AM47: 1 | AN47: 1 | AO47: 1 | AP47: 1 | AQ47: 1 | AR47: 1 | AS47: 1
A48: COGS | AJ48: =IFERROR(AJ13/AJ$8,"NM") -> NM | AK48: =IFERROR(AK13/AK$8,"NM") -> NM | AL48: =IFERROR(AL13/AL$8,"NM") -> NM | AM48: =IFERROR(AM13/AM$8,"NM") -> 0.075 | AN48: =IFERROR(AN13/AN$8,"NM") -> 0.075 | AO48: =IFERROR(AO13/AO$8,"NM") -> 0.075 | AP48: =IFERROR(AP13/AP$8,"NM") -> 0.075 | AQ48: =IFERROR(AQ13/AQ$8,"NM") -> 0.075 | ... AS48: =IFERROR(AS13/AS$8,"NM") -> 0.075
A49: Gross Margin | AJ49: =IFERROR(AJ14/AJ$8,"NM") -> NM | AK49: =IFERROR(AK14/AK$8,"NM") -> NM | AL49: =IFERROR(AL14/AL$8,"NM") -> NM | AM49: =IFERROR(AM14/AM$8,"NM") -> 0.925 | AN49: =IFERROR(AN14/AN$8,"NM") -> 0.925 | AO49: =IFERROR(AO14/AO$8,"NM") -> 0.925 | AP49: =IFERROR(AP14/AP$8,"NM") -> 0.925 | AQ49: =IFERROR(AQ14/AQ$8,"NM") -> 0.925 | ... AS49: =IFERROR(AS14/AS$8,"NM") -> 0.925
A51: SG&A | AJ51: =IFERROR(AJ16/AJ$8,"NM") -> NM | AK51: =IFERROR(AK16/AK$8,"NM") -> NM | AL51: =IFERROR(AL16/AL$8,"NM") -> NM | AM51: =IFERROR(AM16/AM$8,"NM") -> 6.9040526 | AN51: =IFERROR(AN16/AN$8,"NM") -> 1.0921676 | AO51: =IFERROR(AO16/AO$8,"NM") -> 0.46093888 | AP51: =IFERROR(AP16/AP$8,"NM") -> 0.24717241 | AQ51: =IFERROR(AQ16/AQ$8,"NM") -> 0.17690024 | ... AS51: =IFERROR(AS16/AS$8,"NM") -> 0.12424553
A52: R&D | AJ52: =IFERROR(AJ18/AJ$8,"NM") -> NM | AK52: =IFERROR(AK18/AK$8,"NM") -> NM | AL52: =IFERROR(AL18/AL$8,"NM") -> NM | AM52: =IFERROR(AM18/AM$8,"NM") -> 9.7664588 | AN52: =IFERROR(AN18/AN$8,"NM") -> 1.1922684 | AO52: =IFERROR(AO18/AO$8,"NM") -> 0.41885593 | AP52: =IFERROR(AP18/AP$8,"NM") -> 0.22183694 | AQ52: =IFERROR(AQ18/AQ$8,"NM") -> 0.15682933 | ... AS52: =IFERROR(AS18/AS$8,"NM") -> 0.10751322
A53: Operating Margin | AJ53: =IFERROR(AJ24/AJ$8,"NM") -> NM | AK53: =IFERROR(AK24/AK$8,"NM") -> NM | AL53: =IFERROR(AL24/AL$8,"NM") -> NM | AM53: =IFERROR(AM24/AM$8,"NM") -> -15.745511 | AN53: =IFERROR(AN24/AN$8,"NM") -> -1.359436 | AO53: =IFERROR(AO24/AO$8,"NM") -> 0.045205186 | AP53: =IFERROR(AP24/AP$8,"NM") -> 0.45599065 | AQ53: =IFERROR(AQ24/AQ$8,"NM") -> 0.59127042 | ... AS53: =IFERROR(AS24/AS$8,"NM") -> 0.69324125
A55: Pretax Margin | AJ55: =IFERROR(AJ31/AJ$8, "NM") -> NM | AK55: =IFERROR(AK31/AK$8, "NM") -> NM | AL55: =IFERROR(AL31/AL$8, "NM") -> NM | AM55: =IFERROR(AM31/AM$8, "NM") -> -15.117037 | AN55: =IFERROR(AN31/AN$8, "NM") -> -1.2741555 | AO55: =IFERROR(AO31/AO$8, "NM") -> 0.077547289 | AP55: =IFERROR(AP31/AP$8, "NM") -> 0.47326832 | AQ55: =IFERROR(AQ31/AQ$8, "NM") -> 0.60358865 | ... AS55: =IFERROR(AS31/AS$8, "NM") -> 0.7018253
A56: Net Margin | AJ56: =IFERROR(AJ35/AJ$8, "NM") -> NM | AK56: =IFERROR(AK35/AK$8, "NM") -> NM | AL56: =IFERROR(AL35/AL$8, "NM") -> NM | AM56: =IFERROR(AM35/AM$8, "NM") -> -15.117037 | AN56: =IFERROR(AN35/AN$8, "NM") -> -1.2741555 | AO56: =IFERROR(AO35/AO$8, "NM") -> 0.077547289 | AP56: =IFERROR(AP35/AP$8, "NM") -> 0.44960491 | AQ56: =IFERROR(AQ35/AQ$8, "NM") -> 0.54322979 | ... AS56: =IFERROR(AS35/AS$8, "NM") -> 0.55444199
...

Sheet OPEX
A1: MapLight Therapeutics - Operating Cost | AE1: =SOTP!R14 -> 37.175346
A2: ($ Millions, except EPS)
B3: =IS!B4 -> 1Q19A | C3: =IS!C4 -> 2Q19A | D3: =IS!D4 -> 3Q19A | E3: =IS!E4 -> 4Q19A | F3: =IS!F4 -> 2019A | G3: =IS!G4 -> 1Q20A | H3: =IS!H4 -> 2Q20A | I3: =IS!I4 -> 3Q20A | J3: =IS!J4 -> 4Q20A | K3: =IS!AA4 -> 1Q25A | L3: =IS!AB4 -> 2Q25A | M3: =IS!AC4 -> 3Q25A | N3: =IS!AD4 -> 4Q25A | O3: =IS!AE4 -> 2025A | P3: =IS!AF4 -> 1Q26E | Q3: =IS!AG4 -> 2Q26E | R3: =IS!AH4 -> 3Q26E | ... AC3: =IS!AS4 -> 2035E
A5: R&D - GAAP
A7: Clinical trial expenses | F7: 13.895 | G7: 1.668 | H7: 1.728 | I7: 0.794 | J7: 1.3 | M7: 11.915 | N7: 20 | O7: 53.461 | P7: 15 | Q7: 16 | R7: 18 | S7: 20 | T7: =SUM(P7:S7) -> 69 | U7: =T7*1.03 -> 71.07 | V7: 85 | W7: 65 | X7: 50 | Y7: 40 | Z7: =Y7 -> 40 | AA7: =Z7 -> 40 | AB7: =AA7 -> 40 | AC7: =AB7 -> 40
A8: Formulation and CMC expenses | F8: =F7-#REF!-#REF! -> #REF! | G8: =G7-#REF!-#REF! -> #REF! | H8: =H7-#REF!-#REF! -> #REF! | I8: =I7-#REF!-#REF! -> #REF! | J8: =J7-#REF!-#REF! -> #REF! | M8: 4.175 | N8: 8 | O8: 18.266 | P8: 5 | Q8: 4 | R8: 3 | S8: 3 | T8: =SUM(P8:S8) -> 15 | U8: 3 | V8: 3 | W8: =V8 -> 3 | X8: =W8 -> 3 | Y8: =X8 -> 3 | Z8: =Y8 -> 3 | AA8: =Z8 -> 3 | AB8: =AA8 -> 3 | AC8: =AB8 -> 3
A9: Preclinical research and discovery | F9: 2.443 | G9: 0.505 | H9: 0.351 | I9: -0.444 | J9: 0.3 | M9: 2.792 | N9: 5 | O9: 10.421 | P9: 12 | Q9: 10 | R9: 5 | S9: 5 | T9: =SUM(P9:S9) -> 32 | U9: =S9*4*1.03 -> 20.6 | V9: =U9*1.03 -> 21.218 | W9: =V9*1.03 -> 21.85454 | X9: =W9*1.03 -> 22.510176 | Y9: =X9*1.03 -> 23.185481 | Z9: =Y9*1.03 -> 23.881046 | AA9: =Z9*1.03 -> 24.597477 | AB9: =AA9*1.03 -> 25.335402 | AC9: =AB9*1.03 -> 26.095464
A11: Employee related expenses | G11: 0.237 | H11: 0.466 | I11: 1.876 | J11: =#REF!-G11-H11-I11 -> #REF! | M11: 7.043 | N11: 30 | O11: 51.062 | P11: 5 | Q11: 5 | R11: 5.05 | S11: 5.05 | T11: =SUM(P11:S11) -> 20.1 | U11: =T11*1.03 -> 20.703 | V11: =U11*1.03 -> 21.32409 | W11: =V11*1.03 -> 21.963813 | X11: =W11*1.03 -> 22.622727 | Y11: =X11*1.03 -> 23.301409 | Z11: =Y11*1.03 -> 24.000451 | AA11: =Z11*1.03 -> 24.720465 | AB11: =AA11*1.03 -> 25.462079 | AC11: =AB11*1.03 -> 26.225941
A12: Other expenses | F12: 12.197 | G12: 2.736 | H12: 1.102 | I12: 0.975 | J12: 1.2 | M12: 1.169 | N12: =N13-SUM(N7:N11) -> 1.623 | O12: 5.139 | P12: 5 | Q12: 5.5 | R12: 6 | S12: 6.5 | T12: =SUM(P12:S12) -> 23 | U12: 50 | V12: =U12*1.03 -> 51.5 | W12: =V12*1.03 -> 53.045 | X12: =W12*1.03 -> 54.63635 | Y12: =X12*1.03 -> 56.275441 | Z12: =Y12*1.03 -> 57.963704 | AA12: =Z12*1.03 -> 59.702615 | AB12: =AA12*1.03 -> 61.493693 | AC12: =AB12*1.03 -> 63.338504
A13: Total R&D - GAAP per IS | B13: =IS!B18 -> 0 | C13: =IS!C18 -> 0 | D13: =IS!D18 -> 0 | E13: =IS!E18 -> 0 | F13: =IS!F18 -> 43.709 | G13: =IS!G18 -> 9.498 | H13: =IS!H18 -> 5.129 | I13: =IS!I18 -> 5.003 | J13: =IS!J18 -> 6.108 | M13: =SUM(M7,M8,M9,M11:M12) -> 27.094 | N13: =IS!AD18 -> 64.623 | O13: =SUM(O7,O8,O9,O11:O12) -> 138.349 | P13: =SUM(P7,P8,P9,P11:P12) -> 42 | Q13: =SUM(Q7,Q8,Q9,Q11:Q12) -> 40.5 | R13: =SUM(R7,R8,R9,R11:R12) -> 37.05 | S13: =SUM(S7,S8,S9,S11:S12) -> 39.55 | T13: =SUM(T7,T8,T9,T11:T12) -> 159.1 | U13: =SUM(U7,U8,U9,U11:U12) -> 165.373 | V13: =SUM(V7,V8,V9,V11:V12) -> 182.04209 | ... AC13: =SUM(AC7,AC8,AC9,AC11:AC12) -> 158.65991
A14: Consensus | M14: =FactSet!P21 -> 27.1 | N14: =FactSet!Q21 -> 64.6 | O14: =FactSet!R21 -> 138.3 | P14: =FactSet!S21 -> 35.1 | Q14: =FactSet!T21 -> 36.766666 | R14: =FactSet!U21 -> 38.1 | S14: =FactSet!V21 -> 40.766666 | T14: =FactSet!W21 -> 150.66667 | U14: =FactSet!X21 -> 175
A15: Check | F15: =SUM(F7,F9,F11,#REF!,F12) - F13 -> #REF! | G15: =SUM(G7,G9,G11,#REF!,G12) - G13 -> #REF! | H15: =SUM(H7,H9,H11,#REF!,H12) - H13 -> #REF! | I15: =SUM(I7,I9,I11,#REF!,I12) - I13 -> #REF! | J15: =SUM(J7,J9,J11,#REF!,J12) - J13 -> #REF! | M15: =SUM(M7,M9,M11,M8,M12) - M13 -> 0 | N15: =SUM(N7,N9,N11,N8,N12) - N13 -> 0 | O15: =SUM(O7,O9,O11,O8,O12) - O13 -> 0 | P15: =SUM(P7,P9,P11,P8,P12) - P13 -> 0 | Q15: =SUM(Q7,Q9,Q11,Q8,Q12) - Q13 -> 0 | R15: =SUM(R7,R9,R11,R8,R12) - R13 -> 0 | S15: =SUM(S7,S9,S11,S8,S12) - S13 -> 0 | T15: =SUM(T7,T9,T11,T8,T12) - T13 -> 0 | ... AC15: =SUM(AC7,AC9,AC11,AC8,AC12) - AC13 -> 0
A17: Rep - Sales - ML-007 - Schizophrenia | P17: 0.55 | Q17: =P17 -> 0.55 | R17: =Q17 -> 0.55 | S17: =R17 -> 0.55 | U17: 0.45 | V17: =U17 -> 0.45 | W17: 0.2 | X17: =W17 -> 0.2 | Y17: =X17 -> 0.2 | Z17: =Y17 -> 0.2 | AA17: =Z17 -> 0.2 | AB17: =AA17 -> 0.2 | AC17: =AB17 -> 0.2
A18: Rep - Sales - ML-007 - AD Psychosis | P18: 0.35 | Q18: =P18 -> 0.35 | R18: =Q18 -> 0.35 | S18: =R18 -> 0.35 | U18: 0.45 | V18: =U18 -> 0.45 | W18: 0.55 | X18: =W18 -> 0.55 | Y18: =X18 -> 0.55 | Z18: =Y18 -> 0.55 | AA18: =Z18 -> 0.55 | AB18: =AA18 -> 0.55 | AC18: =AB18 -> 0.55
A19: Rep - Sales - ML-004- ASD | P19: =P20-P18-P17 -> 0.1 | Q19: =Q20-Q18-Q17 -> 0.1 | R19: =R20-R18-R17 -> 0.1 | S19: =S20-S18-S17 -> 0.1 | U19: =U20-U18-U17 -> 0.1 | V19: =V20-V18-V17 -> 0.1 | W19: =W20-W18-W17 -> 0.25 | X19: =X20-X18-X17 -> 0.25 | Y19: =Y20-Y18-Y17 -> 0.25 | Z19: =Z20-Z18-Z17 -> 0.25 | AA19: =AA20-AA18-AA17 -> 0.25 | AB19: =AB20-AB18-AB17 -> 0.25 | AC19: =AC20-AC18-AC17 -> 0.25
P20: 1 | Q20: 1 | R20: 1 | S20: 1 | U20: 1 | V20: 1 | W20: 1 | X20: 1 | Y20: 1 | Z20: 1 | AA20: 1 | AB20: 1 | AC20: 1
A22: Rep - Sales - ML-007 - Schizophrenia | P22: =P17*P$7 -> 8.25 | Q22: =Q17*Q$7 -> 8.8 | R22: =R17*R$7 -> 9.9 | S22: =S17*S$7 -> 11 | T22: =SUM(P22:S22) -> 37.95 | U22: =U17*U$7 -> 31.9815 | V22: =V17*V$7 -> 38.25 | W22: =W17*W$7 -> 13 | X22: =X17*X$7 -> 10 | Y22: =Y17*Y$7 -> 8 | Z22: =Z17*Z$7 -> 8 | AA22: =AA17*AA$7 -> 8 | AB22: =AB17*AB$7 -> 8 | AC22: =AC17*AC$7 -> 8
A23: Rep - Sales - ML-007 - AD Psychosis | P23: =P18*P$7 -> 5.25 | Q23: =Q18*Q$7 -> 5.6 | R23: =R18*R$7 -> 6.3 | S23: =S18*S$7 -> 7 | T23: =SUM(P23:S23) -> 24.15 | U23: =U18*U$7 -> 31.9815 | V23: =V18*V$7 -> 38.25 | W23: =W18*W$7 -> 35.75 | X23: =X18*X$7 -> 27.5 | Y23: =Y18*Y$7 -> 22 | Z23: =Z18*Z$7 -> 22 | AA23: =AA18*AA$7 -> 22 | AB23: =AB18*AB$7 -> 22 | AC23: =AC18*AC$7 -> 22
A24: Rep - Sales - ML-004- ASD | P24: =P19*P$7 -> 1.5 | Q24: =Q19*Q$7 -> 1.6 | R24: =R19*R$7 -> 1.8 | S24: =S19*S$7 -> 2 | T24: =SUM(P24:S24) -> 6.9 | U24: =U19*U$7 -> 7.107 | V24: =V19*V$7 -> 8.5 | W24: =W19*W$7 -> 16.25 | X24: =X19*X$7 -> 12.5 | Y24: =Y19*Y$7 -> 10 | Z24: =Z19*Z$7 -> 10 | AA24: =AA19*AA$7 -> 10 | AB24: =AB19*AB$7 -> 10 | AC24: =AC19*AC$7 -> 10
P25: =SUM(P22:P24) -> 15 | Q25: =SUM(Q22:Q24) -> 16 | R25: =SUM(R22:R24) -> 18 | S25: =SUM(S22:S24) -> 20 | T25: =SUM(T22:T24) -> 69 | U25: =SUM(U22:U24) -> 71.07 | V25: =SUM(V22:V24) -> 85 | W25: =SUM(W22:W24) -> 65 | ... AC25: =SUM(AC22:AC24) -> 40
B27: =B3 -> 1Q19A | C27: =C3 -> 2Q19A | D27: =D3 -> 3Q19A | E27: =E3 -> 4Q19A | F27: =F3 -> 2019A | G27: =G3 -> 1Q20A | H27: =H3 -> 2Q20A | I27: =I3 -> 3Q20A | J27: =J3 -> 4Q20A | M27: =M3 -> 3Q25A | N27: =N3 -> 4Q25A | O27: =O3 -> 2025A | P27: =P3 -> 1Q26E | Q27: =Q3 -> 2Q26E | R27: =R3 -> 3Q26E | S27: =S3 -> 4Q26E | T27: =T3 -> 2026E | ... AC27: =AC3 -> 2035E
A29: G&A - GAAP
A31: Professional and other fees | B31: =B33-B32 -> -0.432 | C31: =C33-C32 -> -1.103 | D31: =D33-D32 -> -1.302 | E31: =E33-E32 -> 2.837 | G31: =G33-G32 -> 3.142 | H31: =H33-H32 -> 2.398 | I31: =I33-I32 -> 3.962 | J31: =J33-J32 -> #REF! | M31: 2 | N31: 7 | O31: 9.046 | P31: 8 | Q31: 9 | R31: 10 | S31: 10 | T31: =SUM(P31:S31) -> 37 | U31: =T31*1.03 -> 38.11 | V31: =U31*1.03 -> 39.2533 | W31: =V31*1.03 -> 40.430899 | X31: =W31*1.03 -> 41.643826 | Y31: =X31*1.03 -> 42.893141 | Z31: =Y31*1.03 -> 44.179935 | AA31: =Z31*1.03 -> 45.505333 | AB31: =AA31*1.03 -> 46.870493 | AC31: =AB31*1.03 -> 48.276608
A32: Employee related expenses | B32: 0.432 | C32: 1.103 | D32: 1.302 | E32: =F32-D32-C32-B32 -> -2.837 | G32: 0.532 | H32: 0.404 | I32: 1.636 | J32: =#REF!-G32-H32-I32 -> #REF! | M32: 1.904 | N32: =N33-N31 -> 11.755 | O32: 21.688 | P32: 5 | Q32: 5.1 | R32: 5 | S32: 5.2 | T32: =SUM(P32:S32) -> 20.3 | U32: =T32*1.03 -> 20.909 | V32: =U32*1.03 -> 21.53627 | W32: =V32*1.03 -> 22.182358 | X32: =W32*1.03 -> 22.847829 | Y32: =X32*1.03 -> 23.533264 | Z32: =Y32*1.03 -> 24.239262 | AA32: =Z32*1.03 -> 24.966439 | AB32: =AA32*1.03 -> 25.715433 | AC32: =AB32*1.03 -> 26.486896
A33: Total G&A - GAAP per IS | B33: =B68-B66 -> 0 | C33: =C68-C66 -> 0 | D33: =D68-D66 -> 0 | E33: =E68-E66 -> 0 | F33: =F68-F66 -> 10.968 | G33: =G68-G66 -> 3.674 | H33: =H68-H66 -> 2.802 | I33: =I68-I66 -> 5.598 | J33: =J68-J66 -> 5.348 | M33: =M68-M66 -> 4.404 | N33: =N68 -> 18.755 | O33: =SUM(O31:O32) -> 30.734 | P33: =SUM(P31:P32) -> 13 | Q33: =SUM(Q31:Q32) -> 14.1 | R33: =SUM(R31:R32) -> 15 | S33: =SUM(S31:S32) -> 15.2 | T33: =SUM(T31:T32) -> 57.3 | U33: =SUM(U31:U32) -> 59.019 | V33: =SUM(V31:V32) -> 60.78957 | ... AC33: =SUM(AC31:AC32) -> 74.763503
A35: S&M - GAAP
A37: Sales & Marketing
A39: Rep - Sales - ML-007 - Schizophrenia | V39: 25 | W39: 60 | X39: =W39 -> 60 | Y39: =X39 -> 60 | Z39: =Y39 -> 60 | AA39: =Z39 -> 60 | AB39: =AA39 -> 60 | AC39: =AB39 -> 60
A40: Rep - Sales - ML-007 - AD Psychosis | W40: 100 | X40: 150 | Y40: 200 | Z40: =Y40 -> 200 | AA40: =Z40 -> 200 | AB40: =AA40 -> 200 | AC40: =AB40 -> 200
A41: Rep - Sales - ML-004- ASD | W41: 0 | X41: 0 | Y41: =X41 -> 0 | Z41: =Y41 -> 0 | AA41: =Z41 -> 0 | AB41: =AA41 -> 0 | AC41: =AB41 -> 0
A42: Rep - Sales - Unallocated
A43: Total Reps | O43: =SUM(O39:O42) -> 0 | U43: =SUM(U39:U42) -> 0 | V43: =SUM(V39:V42) -> 25 | W43: =SUM(W39:W42) -> 160 | X43: =SUM(X39:X42) -> 210 | Y43: =SUM(Y39:Y42) -> 260 | Z43: =SUM(Z39:Z42) -> 260 | AA43: =SUM(AA39:AA42) -> 260 | AB43: =SUM(AB39:AB42) -> 260 | AC43: =SUM(AC39:AC42) -> 260
A45: Cost per Rep | O45: 290000 | P45: =O45*1.03 -> 298700 | Q45: =P45 -> 298700 | R45: =Q45 -> 298700 | S45: =R45 -> 298700 | T45: =O45*1.03 -> 298700 | U45: =T45*1.03 -> 307661 | V45: =U45*1.03 -> 316890.83 | W45: =V45*1.03 -> 326397.55 | X45: =W45*1.03 -> 336189.48 | Y45: =X45*1.03 -> 346275.17 | Z45: =Y45*1.03 -> 356663.42 | AA45: =Z45*1.03 -> 367363.32 | AB45: =AA45*1.03 -> 378384.22 | AC45: =AB45*1.03 -> 389735.75
A47: Cost - Sales - ML-007 - Schizophrenia | O47: =O39*O$45/10^6 -> 0 | P47: =P39*P$45/10^6 -> 0 | Q47: =Q39*Q$45/10^6 -> 0 | R47: =R39*R$45/10^6 -> 0 | S47: =S39*S$45/10^6 -> 0 | T47: =SUM(P47:S47) -> 0 | U47: =U39*U$45/10^6 -> 0 | V47: =V39*V$45/10^6 -> 7.9222708 | W47: =W39*W$45/10^6 -> 19.583853 | X47: =X39*X$45/10^6 -> 20.171369 | Y47: =Y39*Y$45/10^6 -> 20.77651 | Z47: =Z39*Z$45/10^6 -> 21.399805 | AA47: =AA39*AA$45/10^6 -> 22.041799 | AB47: =AB39*AB$45/10^6 -> 22.703053 | AC47: =AC39*AC$45/10^6 -> 23.384145
A48: Cost - Sales - ML-007 - AD Psychosis | O48: =O40*O$45/10^6 -> 0 | P48: =P40*P$45/10^6 -> 0 | Q48: =Q40*Q$45/10^6 -> 0 | R48: =R40*R$45/10^6/4 -> 0 | S48: =S40*S$45/10^6/4 -> 0 | T48: =SUM(P48:S48) -> 0 | U48: =U40*U$45/10^6 -> 0 | V48: =V40*V$45/10^6 -> 0 | W48: =W40*W$45/10^6 -> 32.639755 | X48: =X40*X$45/10^6 -> 50.428422 | Y48: =Y40*Y$45/10^6 -> 69.255033 | Z48: =Z40*Z$45/10^6 -> 71.332684 | AA48: =AA40*AA$45/10^6 -> 73.472665 | AB48: =AB40*AB$45/10^6 -> 75.676845 | AC48: =AC40*AC$45/10^6 -> 77.94715
A49: Cost - Sales - ML-004 - ASD | O49: =O41*O$45/10^6 -> 0 | P49: =P41*P$45/10^6 -> 0 | Q49: =Q41*Q$45/10^6 -> 0 | R49: =R41*R$45/10^6/4 -> 0 | S49: =S41*S$45/10^6/4 -> 0 | T49: =SUM(P49:S49) -> 0 | U49: =U41*U$45/10^6 -> 0 | V49: =V41*V$45/10^6 -> 0 | W49: =W41*W$45/10^6 -> 0 | X49: =X41*X$45/10^6 -> 0 | Y49: =Y41*Y$45/10^6 -> 0 | Z49: =Z41*Z$45/10^6 -> 0 | AA49: =AA41*AA$45/10^6 -> 0 | AB49: =AB41*AB$45/10^6 -> 0 | AC49: =AC41*AC$45/10^6 -> 0
A50: Cost - Sales - Unallocated | O50: =O42*O$45 -> 0 | P50: =P42*P$45 -> 0 | Q50: =Q42*Q$45 -> 0 | R50: =R42*R$45 -> 0 | S50: =S42*S$45 -> 0 | T50: =SUM(P50:S50) -> 0 | U50: =U42*U$45 -> 0 | V50: =V42*V$45 -> 0 | W50: =W42*W$45 -> 0 | X50: =X42*X$45 -> 0 | Y50: =Y42*Y$45 -> 0 | Z50: =Z42*Z$45 -> 0 | AA50: =AA42*AA$45 -> 0 | AB50: =AB42*AB$45 -> 0 | AC50: =AC42*AC$45 -> 0
A51: Total Salesforce Costs | O51: =SUM(O47:O50) -> 0 | P51: =SUM(P47:P50) -> 0 | Q51: =SUM(Q47:Q50) -> 0 | R51: =SUM(R47:R50) -> 0 | S51: =SUM(S47:S50) -> 0 | T51: =SUM(P51:S51) -> 0 | U51: =SUM(U47:U50) -> 0 | V51: =SUM(V47:V50) -> 7.9222708 | W51: =SUM(W47:W50) -> 52.223609 | X51: =SUM(X47:X50) -> 70.599791 | Y51: =SUM(Y47:Y50) -> 90.031543 | Z51: =SUM(Z47:Z50) -> 92.732489 | AA51: =SUM(AA47:AA50) -> 95.514464 | AB51: =SUM(AB47:AB50) -> 98.379898 | AC51: =SUM(AC47:AC50) -> 101.3313
A53: A&P
A54: A&P Cost - Sales - ML-007 - Schizophrenia | V54: 30 | W54: 50 | X54: =W54+10 -> 60 | Y54: =X54*1.03 -> 61.8 | Z54: =Y54*1.03 -> 63.654 | AA54: =Z54*1.03 -> 65.56362 | AB54: =AA54*1.03 -> 67.530529 | AC54: =AB54*1.03 -> 69.556444
...

Sheet REVENUE
A1: MapLight Therapeutics - Revenue | AZ1: =SOTP!R14 -> 37.175346
A2: ($ Millions, except EPS)
B4: =IS!B4 -> 1Q19A | C4: =IS!C4 -> 2Q19A | D4: =IS!D4 -> 3Q19A | E4: =IS!E4 -> 4Q19A | F4: =IS!F4 -> 2019A | G4: =IS!G4 -> 1Q20A | H4: =IS!H4 -> 2Q20A | I4: =IS!I4 -> 3Q20A | ... Z4: =IS!Z4 -> 2023A | AA4: =IS!#REF! -> #REF! | AB4: =IS!#REF! -> #REF! | AC4: =IS!#REF! -> #REF! | AD4: =IS!#REF! -> #REF! | AE4: =IS!AA4 -> 1Q25A | AF4: =IS!AB4 -> 2Q25A | AG4: =IS!AC4 -> 3Q25A | AH4: =IS!AD4 -> 4Q25A | AI4: =IS!AE4 -> 2025A | AJ4: =IS!AF4 -> 1Q26E | AK4: =IS!AG4 -> 2Q26E | AL4: =IS!AH4 -> 3Q26E | ... AW4: =IS!AS4 -> 2035E
A6: ML-007C-MA
A7: Schizophrenia | Z7: 0 | AP7: 0 | AQ7: 30.691938 | AR7: 186.9139 | AS7: 470.40973 | AT7: 762.97567 | AU7: 1050.1175 | AV7: 1309.7538 | AW7: 1545.7081 | AY7: 0.55 | BC7: 78 | BD7: 37
A8: VA Cons. (Unadj) | AP8: =ML007MA_ME!T19 -> 0 | AQ8: =ML007MA_ME!U19 -> 29.32648 | AR8: =ML007MA_ME!V19 -> 90.24745 | AS8: =ML007MA_ME!W19 -> 196.03091 | AT8: =ML007MA_ME!X19 -> 316.81523 | AU8: =ML007MA_ME!Y19 -> 452.42737 | AV8: =ML007MA_ME!Z19 -> 590.38147 | AW8: =ML007MA_ME!AA19 -> 724.87222
A9: Schizophrenia PoS Adj. | Z9: =Z7*$AY$7 -> 0 | AP9: =AP7*$AY$7 -> 0 | AQ9: =AQ7*$AY$7 -> 16.880566 | AR9: =AR7*$AY$7 -> 102.80265 | AS9: =AS7*$AY$7 -> 258.72535 | AT9: =AT7*$AY$7 -> 419.63662 | AU9: =AU7*$AY$7 -> 577.56461 | AV9: =AV7*$AY$7 -> 720.3646 | AW9: =AW7*$AY$7 -> 850.13945 | BC9: 36 | BD9: 21
A10: VA Cons. (Adj) | AP10: =ML007MA_ME!T21 -> 0 | AQ10: =ML007MA_ME!U21 -> 17.595888 | AR10: =ML007MA_ME!V21 -> 53.153454 | AS10: =ML007MA_ME!W21 -> 135.93035 | AT10: =ML007MA_ME!X21 -> 216.23472 | AU10: =ML007MA_ME!Y21 -> 308.20364 | AV10: =ML007MA_ME!Z21 -> 398.53516 | AW10: =ML007MA_ME!AA21 -> 485.88175
A12: Alzheimer's Disease Psychosis | Z12: 0 | AP12: 0 | AQ12: 0 | AR12: 101.32251 | AS12: 345.29982 | AT12: 964.24697 | AU12: 1500.5163 | AV12: 1972.0631 | AW12: 2393.5535 | AY12: 0.25
A13: VA Cons. (Unadj) | AP13: =ML007MA_ME!T40 -> 0 | AQ13: =ML007MA_ME!U40 -> 0 | AR13: =ML007MA_ME!V40 -> 31.333005 | AS13: =ML007MA_ME!W40 -> 72.874931 | AT13: =ML007MA_ME!X40 -> 205.38141 | AU13: =ML007MA_ME!Y40 -> 388.60215 | AV13: =ML007MA_ME!Z40 -> 592.28238 | AW13: =ML007MA_ME!AA40 -> 786.41443
A14: AD Psychosis Pos Adj. | Z14: =Z12*$AY$12 -> 0 | AP14: =AP12*$AY$12 -> 0 | AQ14: =AQ12*$AY$12 -> 0 | AR14: =AR12*$AY$12 -> 25.330627 | AS14: =AS12*$AY$12 -> 86.324955 | AT14: =AT12*$AY$12 -> 241.06174 | AU14: =AU12*$AY$12 -> 375.12907 | AV14: =AV12*$AY$12 -> 493.01577 | AW14: =AW12*$AY$12 -> 598.38838
A15: VA Cons. (Adj) | AP15: =ML007MA_ME!T42 -> 0 | AQ15: =ML007MA_ME!U42 -> 0 | AR15: =ML007MA_ME!V42 -> 15.666503 | AS15: =ML007MA_ME!W42 -> 40.671555 | AT15: =ML007MA_ME!X42 -> 87.761699 | AU15: =ML007MA_ME!Y42 -> 152.24155 | AV15: =ML007MA_ME!Z42 -> 226.1123 | AW15: =ML007MA_ME!AA42 -> 298.94417
A17: ML-007C-MA (M1 / M4 agonist) - Total | Z17: =Z7+Z12+#REF! -> #REF! | AQ17: =AQ7+AQ12 -> 30.691938 | AR17: =AR7+AR12 -> 288.23641 | AS17: =AS7+AS12 -> 815.70955 | AT17: =AT7+AT12 -> 1727.2226 | AU17: =AU7+AU12 -> 2550.6337 | AV17: =AV7+AV12 -> 3281.8169 | AW17: =AW7+AW12 -> 3939.2616 | AY17: Avg:
A18: PoS (%) | AQ18: =AQ19/AQ17 -> 0.55 | AR18: =AR19/AR17 -> 0.44454229 | AS18: =AS19/AS17 -> 0.42300633 | AT18: =AT19/AT17 -> 0.38252067 | AU18: =AU19/AU17 -> 0.37351254 | AV18: =AV19/AV17 -> 0.36972824 | AW18: =AW19/AW17 -> 0.36771557 | AY18: =AVERAGE(AQ18:AW18) -> 0.4158608
A19: ML-007C-MA (M1 / M4 agonist) PoS Adj. | Z19: =Z7*$AY$7+Z12*$AY$12+#REF!*#REF! -> #REF! | AQ19: =AQ7*$AY$7+AQ12*$AY$12 -> 16.880566 | AR19: =AR7*$AY$7+AR12*$AY$12 -> 128.13327 | AS19: =AS7*$AY$7+AS12*$AY$12 -> 345.0503 | AT19: =AT7*$AY$7+AT12*$AY$12 -> 660.69836 | AU19: =AU7*$AY$7+AU12*$AY$12 -> 952.69368 | AV19: =AV7*$AY$7+AV12*$AY$12 -> 1213.3804 | AW19: =AW7*$AY$7+AW12*$AY$12 -> 1448.5278
A20: Growth | AR20: =AR19/AQ19-1 -> 6.5905793 | AS20: =AS19/AR19-1 -> 1.6929016 | AT20: =AT19/AS19-1 -> 0.91478853 | AU20: =AU19/AT19-1 -> 0.44194951 | AV20: =AV19/AU19-1 -> 0.27363117 | AW20: =AW19/AV19-1 -> 0.19379535
A21: Consensus | Z21: ='VA Consensus'!#REF! -> #REF! | AN21: ='VA Consensus'!S14 -> 0 | AO21: ='VA Consensus'!T14 -> 0 | AP21: ='VA Consensus'!U14 -> 0 | AQ21: ='VA Consensus'!V14 -> 17.595888 | AR21: ='VA Consensus'!W14 -> 65.038297 | AS21: ='VA Consensus'!X14 -> 182.01857 | AT21: ='VA Consensus'!Y14 -> 303.99642 | AU21: ='VA Consensus'!Z14 -> 445.62785 | ... AW21: ='VA Consensus'!AB14 -> 775.64772
A23: ML-004 (5-HT 1B/ID agonist)
A24: Autism Spectrum Disorder | Z24: 0 | AS24: 59.016167 | AT24: 205.36709 | AU24: 332.87683 | AV24: 444.78646 | AW24: 543.9352 | AY24: 0.05
A25: ASD PoS Adj. | Z25: =Z24*$AY$7 -> 0 | AS25: =AS24*$AY$24 -> 2.9508083 | AT25: =AT24*$AY$24 -> 10.268355 | AU25: =AU24*$AY$24 -> 16.643842 | AV25: =AV24*$AY$24 -> 22.239323 | AW25: =AW24*$AY$24 -> 27.19676
A26: Consensus | Z26: ='VA Consensus'!#REF! -> #REF! | AN26: ='VA Consensus'!S19 -> 0 | AO26: ='VA Consensus'!T19 -> 0 | AP26: ='VA Consensus'!U19 -> 0 | AQ26: ='VA Consensus'!V19 -> 0 | AR26: ='VA Consensus'!W19 -> 0 | AS26: ='VA Consensus'!X19 -> 11.587328 | AT26: ='VA Consensus'!Y19 -> 24.220121 | AU26: ='VA Consensus'!Z19 -> 38.412156 | ... AW26: ='VA Consensus'!AB19 -> 67.195105
A28: Royalties/Collaboration Revenues | AY28: PoS | AZ28: Royalty Rate
A29: Schizophrenia | Z29: 0 | AY29: =AY7 -> 0.55 | AZ29: 0.15
A30: AD Psychosis | Z30: 0 | AY30: =AY12 -> 0.25 | AZ30: 0.15
A31: ASD | Z31: 0 | AY31: =AY24 -> 0.05 | AZ31: 0.15
A32: Collaboration Revenue | F32: =F34 -> 22.499 | G32: =G34 -> 7.031 | H32: =H34 -> 0.528 | I32: =I34 -> 0.312 | J32: =J34 -> 0 | K32: =K34 -> 7.871 | Z32: =Z29*$AY$29*$AZ$29+Z30*$AY$30*$AZ$30+Z31*$AY$31*$AZ$31 -> 0 | AN32: =AN29*$AY$29*$AZ$29+AN30*$AY$30*$AZ$30+AN31*$AY$31*$AZ$31 -> 0 | AO32: =AO29*$AY$29*$AZ$29+AO30*$AY$30*$AZ$30+AO31*$AY$31*$AZ$31 -> 0 | AP32: =AP29*$AY$29*$AZ$29+AP30*$AY$30*$AZ$30+AP31*$AY$31*$AZ$31 -> 0 | AQ32: =AQ29*$AY$29*$AZ$29+AQ30*$AY$30*$AZ$30+AQ31*$AY$31*$AZ$31 -> 0 | AR32: =AR29*$AY$29*$AZ$29+AR30*$AY$30*$AZ$30+AR31*$AY$31*$AZ$31 -> 0 | AS32: =AS29*$AY$29*$AZ$29+AS30*$AY$30*$AZ$30+AS31*$AY$31*$AZ$31 -> 0 | AT32: =AT29*$AY$29*$AZ$29+AT30*$AY$30*$AZ$30+AT31*$AY$31*$AZ$31 -> 0 | AU32: =AU29*$AY$29*$AZ$29+AU30*$AY$30*$AZ$30+AU31*$AY$31*$AZ$31 -> 0 | ... AW32: =AW29*$AY$29*$AZ$29+AW30*$AY$30*$AZ$30+AW31*$AY$31*$AZ$31 -> 0
A34: Total Royalties/Collaboration Revenues | F34: =IS!F7 -> 22.499 | G34: =IS!G7 -> 7.031 | H34: =IS!H7 -> 0.528 | I34: =IS!I7 -> 0.312 | J34: =IS!J7 -> 0 | K34: =IS!K7 -> 7.871 | L34: =IS!L7 -> 0 | M34: =IS!M7 -> 0 | ... T34: =IS!T7 -> 0 | U34: =SUM(Q34:T34) -> 0 | V34: =IS!V7 -> 0 | W34: =IS!W7 -> 0 | X34: =IS!X7 -> 0 | Y34: =IS!Y7 -> 0 | Z34: =SUM(V34:Y34) -> 0 | AN34: =AN32 -> 0 | AO34: =AO32 -> 0 | AP34: =AP32 -> 0 | AQ34: =AQ32 -> 0 | AR34: =AR32 -> 0 | AS34: =AS32 -> 0 | AT34: =AT32 -> 0 | AU34: =AU32 -> 0 | ... AW34: =AW32 -> 0
A36: Total Revenues | F36: =IS!F8 -> 22.499 | G36: =IS!G8 -> 7.031 | H36: =IS!H8 -> 0.528 | I36: =IS!I8 -> 0.312 | J36: =IS!J8 -> 0 | K36: =IS!K8 -> 7.871 | L36: =IS!L8 -> 0 | M36: =IS!M8 -> 0 | ... T36: =IS!T8 -> 0 | U36: =SUM(U19,U34) -> 0 | V36: =IS!V8 -> 0 | W36: =IS!W8 -> 0 | X36: =IS!X8 -> 0 | Y36: =IS!Y8 -> 0 | Z36: =SUM(Z19,Z34) -> #REF! | AA36: =SUM(AA19,AA34) -> 0 | AB36: =SUM(AB19,AB34) -> 0 | AC36: =SUM(AC19,AC34) -> 0 | AD36: =SUM(AD19,AD34) -> 0 | AN36: =SUM(AN19,AN34,AN25) -> 0 | AO36: =SUM(AO19,AO34,AO25) -> 0 | AP36: =SUM(AP19,AP34,AP25) -> 0 | AQ36: =SUM(AQ19,AQ34,AQ25) -> 16.880566 | AR36: =SUM(AR19,AR34,AR25) -> 128.13327 | AS36: =SUM(AS19,AS34,AS25) -> 348.00111 | AT36: =SUM(AT19,AT34,AT25) -> 670.96672 | AU36: =SUM(AU19,AU34,AU25) -> 969.33752 | ... AW36: =SUM(AW19,AW34,AW25) -> 1475.7246
A37: Consensus | Z37: ='VA Consensus'!#REF! -> #REF! | AN37: ='VA Consensus'!S27 -> 0 | AO37: ='VA Consensus'!T27 -> 0 | AP37: ='VA Consensus'!U27 -> 0 | AQ37: ='VA Consensus'!V27 -> 17.595888 | AR37: ='VA Consensus'!W27 -> 75.100797 | AS37: ='VA Consensus'!X27 -> 259.33112 | AT37: ='VA Consensus'!Y27 -> 515.18785 | AU37: ='VA Consensus'!Z27 -> 809.33262 | ... AW37: ='VA Consensus'!AB27 -> 1392.2424
A38: Source: Company reports; Needham & Company, LLC estimates

Sheet ML007MA_ME
E1: =HYPERLINK("#ML007MA_ME!Notes","See the Notes for this Sheet") -> See the Notes for this Sheet
B2: Company | C2: =_xll.VADetail("Name",$C$3) -> MapLight Therapeutics, Inc.
B3: Ticker | C3: MPLT_US
B4: IMPL or Raw | C4: IMPL
B5: Data Type | C5: CD
B6: Tab | C6: ME
B7: As Of | C7: =TODAY() -> 46119
E8: 1QFY-2025 | F8: 2QFY-2025 | G8: 3QFY-2025 | H8: 4QFY-2025 | I8: FY-2025 | J8: 1QFY-2026 | K8: 2QFY-2026 | L8: 3QFY-2026 | M8: 4QFY-2026 | N8: FY-2026 | O8: 1QFY-2027 | P8: 2QFY-2027 | Q8: 3QFY-2027 | R8: 4QFY-2027 | S8: FY-2027 | T8: FY-2028 | U8: FY-2029 | V8: FY-2030 | W8: FY-2031 | X8: FY-2032 | Y8: FY-2033 | Z8: FY-2034 | AA8: FY-2035
E9: =_xll.VADetail("ActualOrEstimate",$C$3,"Consensus",E$8) -> A | F9: =_xll.VADetail("ActualOrEstimate",$C$3,"Consensus",F$8) -> A | G9: =_xll.VADetail("ActualOrEstimate",$C$3,"Consensus",G$8) -> A | H9: =_xll.VADetail("ActualOrEstimate",$C$3,"Consensus",H$8) -> A | I9: =_xll.VADetail("ActualOrEstimate",$C$3,"Consensus",I$8) -> A | J9: =_xll.VADetail("ActualOrEstimate",$C$3,"Consensus",J$8) -> E | K9: =_xll.VADetail("ActualOrEstimate",$C$3,"Consensus",K$8) -> E | L9: =_xll.VADetail("ActualOrEstimate",$C$3,"Consensus",L$8) -> E | ... AA9: =_xll.VADetail("ActualOrEstimate",$C$3,"Consensus",AA$8) -> E
B10: Item Code | C10: Line Item | D10: Units | E10: =IF(E$9="A","VA Actuals","Consensus") -> VA Actuals | F10: =IF(F$9="A","VA Actuals","Consensus") -> VA Actuals | G10: =IF(G$9="A","VA Actuals","Consensus") -> VA Actuals | H10: =IF(H$9="A","VA Actuals","Consensus") -> VA Actuals | I10: =IF(I$9="A","VA Actuals","Consensus") -> VA Actuals | J10: =IF(J$9="A","VA Actuals","Consensus") -> Consensus | K10: =IF(K$9="A","VA Actuals","Consensus") -> Consensus | L10: =IF(L$9="A","VA Actuals","Consensus") -> Consensus | ... AA10: =IF(AA$9="A","VA Actuals","Consensus") -> Consensus
B11: H | C11: ML 007-MA
B12: H | C12: ML-007-MA Schizophrenia
B13: N_15532762 | C13: Eligible patients - ML-007-MA - Schizophrenia - US | D13: # | E13: =_xll.VAData($C$3,E$8,$C13,E$10,$C$5,$C$4,$C$7) -> - | F13: =_xll.VAData($C$3,F$8,$C13,F$10,$C$5,$C$4,$C$7) -> - | G13: =_xll.VAData($C$3,G$8,$C13,G$10,$C$5,$C$4,$C$7) -> - | H13: =_xll.VAData($C$3,H$8,$C13,H$10,$C$5,$C$4,$C$7) -> - | I13: =_xll.VAData($C$3,I$8,$C13,I$10,$C$5,$C$4,$C$7) -> 659911.42 | J13: =_xll.VAData($C$3,J$8,$C13,J$10,$C$5,$C$4,$C$7) -> - | K13: =_xll.VAData($C$3,K$8,$C13,K$10,$C$5,$C$4,$C$7) -> - | L13: =_xll.VAData($C$3,L$8,$C13,L$10,$C$5,$C$4,$C$7) -> - | ... AA13: =_xll.VAData($C$3,AA$8,$C13,AA$10,$C$5,$C$4,$C$7) -> 938712.54
B14: N_15532764 | C14: Penetration - ML-007-MA - Schizophrenia -US | D14: % | E14: =_xll.VAData($C$3,E$8,$C14,E$10,$C$5,$C$4,$C$7) -> - | F14: =_xll.VAData($C$3,F$8,$C14,F$10,$C$5,$C$4,$C$7) -> - | G14: =_xll.VAData($C$3,G$8,$C14,G$10,$C$5,$C$4,$C$7) -> - | H14: =_xll.VAData($C$3,H$8,$C14,H$10,$C$5,$C$4,$C$7) -> - | I14: =_xll.VAData($C$3,I$8,$C14,I$10,$C$5,$C$4,$C$7) -> - | J14: =_xll.VAData($C$3,J$8,$C14,J$10,$C$5,$C$4,$C$7) -> - | K14: =_xll.VAData($C$3,K$8,$C14,K$10,$C$5,$C$4,$C$7) -> - | L14: =_xll.VAData($C$3,L$8,$C14,L$10,$C$5,$C$4,$C$7) -> - | ... AA14: =_xll.VAData($C$3,AA$8,$C14,AA$10,$C$5,$C$4,$C$7) -> 9.5
B15: N_15532763 | C15: Number of patients - ML 00-MA - Schizophrenia - US | D15: # | E15: =_xll.VAData($C$3,E$8,$C15,E$10,$C$5,$C$4,$C$7) -> - | F15: =_xll.VAData($C$3,F$8,$C15,F$10,$C$5,$C$4,$C$7) -> - | G15: =_xll.VAData($C$3,G$8,$C15,G$10,$C$5,$C$4,$C$7) -> - | H15: =_xll.VAData($C$3,H$8,$C15,H$10,$C$5,$C$4,$C$7) -> - | I15: =_xll.VAData($C$3,I$8,$C15,I$10,$C$5,$C$4,$C$7) -> - | J15: =_xll.VAData($C$3,J$8,$C15,J$10,$C$5,$C$4,$C$7) -> - | K15: =_xll.VAData($C$3,K$8,$C15,K$10,$C$5,$C$4,$C$7) -> - | L15: =_xll.VAData($C$3,L$8,$C15,L$10,$C$5,$C$4,$C$7) -> - | ... AA15: =_xll.VAData($C$3,AA$8,$C15,AA$10,$C$5,$C$4,$C$7) -> 50911.832
B16: N_15532765 | C16: Gross revenue per treatment - ML-007-MA - Schizophrenia - US | D16: $Abs | E16: =_xll.VAData($C$3,E$8,$C16,E$10,$C$5,$C$4,$C$7) -> - | F16: =_xll.VAData($C$3,F$8,$C16,F$10,$C$5,$C$4,$C$7) -> - | G16: =_xll.VAData($C$3,G$8,$C16,G$10,$C$5,$C$4,$C$7) -> - | H16: =_xll.VAData($C$3,H$8,$C16,H$10,$C$5,$C$4,$C$7) -> - | I16: =_xll.VAData($C$3,I$8,$C16,I$10,$C$5,$C$4,$C$7) -> - | J16: =_xll.VAData($C$3,J$8,$C16,J$10,$C$5,$C$4,$C$7) -> - | K16: =_xll.VAData($C$3,K$8,$C16,K$10,$C$5,$C$4,$C$7) -> - | L16: =_xll.VAData($C$3,L$8,$C16,L$10,$C$5,$C$4,$C$7) -> - | ... AA16: =_xll.VAData($C$3,AA$8,$C16,AA$10,$C$5,$C$4,$C$7) -> 24489.186
B17: N_15532767 | C17: Gross-to-net adjustment rate - ML-007-MA - Schizophrenia - US | D17: % | E17: =_xll.VAData($C$3,E$8,$C17,E$10,$C$5,$C$4,$C$7) -> - | F17: =_xll.VAData($C$3,F$8,$C17,F$10,$C$5,$C$4,$C$7) -> - | G17: =_xll.VAData($C$3,G$8,$C17,G$10,$C$5,$C$4,$C$7) -> - | H17: =_xll.VAData($C$3,H$8,$C17,H$10,$C$5,$C$4,$C$7) -> - | I17: =_xll.VAData($C$3,I$8,$C17,I$10,$C$5,$C$4,$C$7) -> 40 | J17: =_xll.VAData($C$3,J$8,$C17,J$10,$C$5,$C$4,$C$7) -> - | K17: =_xll.VAData($C$3,K$8,$C17,K$10,$C$5,$C$4,$C$7) -> - | L17: =_xll.VAData($C$3,L$8,$C17,L$10,$C$5,$C$4,$C$7) -> - | ... AA17: =_xll.VAData($C$3,AA$8,$C17,AA$10,$C$5,$C$4,$C$7) -> 32.666667
B18: N_15532766 | C18: Revenue per treatment - ML-007-MA - Schizophrenia - US | D18: $Abs | E18: =_xll.VAData($C$3,E$8,$C18,E$10,$C$5,$C$4,$C$7) -> - | F18: =_xll.VAData($C$3,F$8,$C18,F$10,$C$5,$C$4,$C$7) -> - | G18: =_xll.VAData($C$3,G$8,$C18,G$10,$C$5,$C$4,$C$7) -> - | H18: =_xll.VAData($C$3,H$8,$C18,H$10,$C$5,$C$4,$C$7) -> - | I18: =_xll.VAData($C$3,I$8,$C18,I$10,$C$5,$C$4,$C$7) -> - | J18: =_xll.VAData($C$3,J$8,$C18,J$10,$C$5,$C$4,$C$7) -> - | K18: =_xll.VAData($C$3,K$8,$C18,K$10,$C$5,$C$4,$C$7) -> - | L18: =_xll.VAData($C$3,L$8,$C18,L$10,$C$5,$C$4,$C$7) -> - | ... AA18: =_xll.VAData($C$3,AA$8,$C18,AA$10,$C$5,$C$4,$C$7) -> 17440.082
B19: N_15532769 | C19: ML 007-MA - Schizophrenia - US - Unadjusted | D19: $M | E19: =_xll.VAData($C$3,E$8,$C19,E$10,$C$5,$C$4,$C$7) -> - | F19: =_xll.VAData($C$3,F$8,$C19,F$10,$C$5,$C$4,$C$7) -> - | G19: =_xll.VAData($C$3,G$8,$C19,G$10,$C$5,$C$4,$C$7) -> - | H19: =_xll.VAData($C$3,H$8,$C19,H$10,$C$5,$C$4,$C$7) -> - | I19: =_xll.VAData($C$3,I$8,$C19,I$10,$C$5,$C$4,$C$7) -> 0 | J19: =_xll.VAData($C$3,J$8,$C19,J$10,$C$5,$C$4,$C$7) -> - | K19: =_xll.VAData($C$3,K$8,$C19,K$10,$C$5,$C$4,$C$7) -> - | L19: =_xll.VAData($C$3,L$8,$C19,L$10,$C$5,$C$4,$C$7) -> - | ... AA19: =_xll.VAData($C$3,AA$8,$C19,AA$10,$C$5,$C$4,$C$7) -> 724.87222
B20: N_15532770 | C20: POS - ML 007 MA - Schizophrenia - US | D20: % | E20: =_xll.VAData($C$3,E$8,$C20,E$10,$C$5,$C$4,$C$7) -> - | F20: =_xll.VAData($C$3,F$8,$C20,F$10,$C$5,$C$4,$C$7) -> - | G20: =_xll.VAData($C$3,G$8,$C20,G$10,$C$5,$C$4,$C$7) -> - | H20: =_xll.VAData($C$3,H$8,$C20,H$10,$C$5,$C$4,$C$7) -> - | I20: =_xll.VAData($C$3,I$8,$C20,I$10,$C$5,$C$4,$C$7) -> - | J20: =_xll.VAData($C$3,J$8,$C20,J$10,$C$5,$C$4,$C$7) -> 53.75 | K20: =_xll.VAData($C$3,K$8,$C20,K$10,$C$5,$C$4,$C$7) -> 53.75 | L20: =_xll.VAData($C$3,L$8,$C20,L$10,$C$5,$C$4,$C$7) -> 53.75 | ... AA20: =_xll.VAData($C$3,AA$8,$C20,AA$10,$C$5,$C$4,$C$7) -> 53.75
B21: N_15532768 | C21: ML 007-MA - Schizophrenia - US | D21: $M | E21: =_xll.VAData($C$3,E$8,$C21,E$10,$C$5,$C$4,$C$7) -> - | F21: =_xll.VAData($C$3,F$8,$C21,F$10,$C$5,$C$4,$C$7) -> - | G21: =_xll.VAData($C$3,G$8,$C21,G$10,$C$5,$C$4,$C$7) -> - | H21: =_xll.VAData($C$3,H$8,$C21,H$10,$C$5,$C$4,$C$7) -> - | I21: =_xll.VAData($C$3,I$8,$C21,I$10,$C$5,$C$4,$C$7) -> 0 | J21: =_xll.VAData($C$3,J$8,$C21,J$10,$C$5,$C$4,$C$7) -> - | K21: =_xll.VAData($C$3,K$8,$C21,K$10,$C$5,$C$4,$C$7) -> - | L21: =_xll.VAData($C$3,L$8,$C21,L$10,$C$5,$C$4,$C$7) -> - | ... AA21: =_xll.VAData($C$3,AA$8,$C21,AA$10,$C$5,$C$4,$C$7) -> 485.88175
B22: H
B23: N_15532802 | C23: ML-007-MA - Schizophrenia - International - Unadjusted | D23: $M | E23: =_xll.VAData($C$3,E$8,$C23,E$10,$C$5,$C$4,$C$7) -> - | F23: =_xll.VAData($C$3,F$8,$C23,F$10,$C$5,$C$4,$C$7) -> - | G23: =_xll.VAData($C$3,G$8,$C23,G$10,$C$5,$C$4,$C$7) -> - | H23: =_xll.VAData($C$3,H$8,$C23,H$10,$C$5,$C$4,$C$7) -> - | I23: =_xll.VAData($C$3,I$8,$C23,I$10,$C$5,$C$4,$C$7) -> 0 | J23: =_xll.VAData($C$3,J$8,$C23,J$10,$C$5,$C$4,$C$7) -> - | K23: =_xll.VAData($C$3,K$8,$C23,K$10,$C$5,$C$4,$C$7) -> - | L23: =_xll.VAData($C$3,L$8,$C23,L$10,$C$5,$C$4,$C$7) -> - | ... AA23: =_xll.VAData($C$3,AA$8,$C23,AA$10,$C$5,$C$4,$C$7) -> 44.982236
B24: N_15532772 | C24: POS - ML 007 MA - Schizophrenia - International | D24: % | E24: =_xll.VAData($C$3,E$8,$C24,E$10,$C$5,$C$4,$C$7) -> - | F24: =_xll.VAData($C$3,F$8,$C24,F$10,$C$5,$C$4,$C$7) -> - | G24: =_xll.VAData($C$3,G$8,$C24,G$10,$C$5,$C$4,$C$7) -> - | H24: =_xll.VAData($C$3,H$8,$C24,H$10,$C$5,$C$4,$C$7) -> - | I24: =_xll.VAData($C$3,I$8,$C24,I$10,$C$5,$C$4,$C$7) -> - | J24: =_xll.VAData($C$3,J$8,$C24,J$10,$C$5,$C$4,$C$7) -> 50 | K24: =_xll.VAData($C$3,K$8,$C24,K$10,$C$5,$C$4,$C$7) -> 50 | L24: =_xll.VAData($C$3,L$8,$C24,L$10,$C$5,$C$4,$C$7) -> 50 | ... AA24: =_xll.VAData($C$3,AA$8,$C24,AA$10,$C$5,$C$4,$C$7) -> 50
B25: N_15532771 | C25: ML 007-MA - Schizophrenia - International | D25: $M | E25: =_xll.VAData($C$3,E$8,$C25,E$10,$C$5,$C$4,$C$7) -> - | F25: =_xll.VAData($C$3,F$8,$C25,F$10,$C$5,$C$4,$C$7) -> - | G25: =_xll.VAData($C$3,G$8,$C25,G$10,$C$5,$C$4,$C$7) -> - | H25: =_xll.VAData($C$3,H$8,$C25,H$10,$C$5,$C$4,$C$7) -> - | I25: =_xll.VAData($C$3,I$8,$C25,I$10,$C$5,$C$4,$C$7) -> 0 | J25: =_xll.VAData($C$3,J$8,$C25,J$10,$C$5,$C$4,$C$7) -> - | K25: =_xll.VAData($C$3,K$8,$C25,K$10,$C$5,$C$4,$C$7) -> - | L25: =_xll.VAData($C$3,L$8,$C25,L$10,$C$5,$C$4,$C$7) -> - | ... AA25: =_xll.VAData($C$3,AA$8,$C25,AA$10,$C$5,$C$4,$C$7) -> 22.491118
B26: H
B27: N_15532806 | C27: ML-007-MA - Schizophrenia - Unadjusted | D27: $M | E27: =_xll.VAData($C$3,E$8,$C27,E$10,$C$5,$C$4,$C$7) -> - | F27: =_xll.VAData($C$3,F$8,$C27,F$10,$C$5,$C$4,$C$7) -> - | G27: =_xll.VAData($C$3,G$8,$C27,G$10,$C$5,$C$4,$C$7) -> 0 | H27: =_xll.VAData($C$3,H$8,$C27,H$10,$C$5,$C$4,$C$7) -> 0 | I27: =_xll.VAData($C$3,I$8,$C27,I$10,$C$5,$C$4,$C$7) -> 0 | J27: =_xll.VAData($C$3,J$8,$C27,J$10,$C$5,$C$4,$C$7) -> 0 | K27: =_xll.VAData($C$3,K$8,$C27,K$10,$C$5,$C$4,$C$7) -> 0 | L27: =_xll.VAData($C$3,L$8,$C27,L$10,$C$5,$C$4,$C$7) -> 0 | ... AA27: =_xll.VAData($C$3,AA$8,$C27,AA$10,$C$5,$C$4,$C$7) -> 736.11778
B28: N_15532810 | C28: POS - ML-007-MA - Schizophrenia | D28: % | E28: =_xll.VAData($C$3,E$8,$C28,E$10,$C$5,$C$4,$C$7) -> - | F28: =_xll.VAData($C$3,F$8,$C28,F$10,$C$5,$C$4,$C$7) -> - | G28: =_xll.VAData($C$3,G$8,$C28,G$10,$C$5,$C$4,$C$7) -> - | H28: =_xll.VAData($C$3,H$8,$C28,H$10,$C$5,$C$4,$C$7) -> - | I28: =_xll.VAData($C$3,I$8,$C28,I$10,$C$5,$C$4,$C$7) -> - | J28: =_xll.VAData($C$3,J$8,$C28,J$10,$C$5,$C$4,$C$7) -> 53.75 | K28: =_xll.VAData($C$3,K$8,$C28,K$10,$C$5,$C$4,$C$7) -> 53.75 | L28: =_xll.VAData($C$3,L$8,$C28,L$10,$C$5,$C$4,$C$7) -> 53.75 | ... AA28: =_xll.VAData($C$3,AA$8,$C28,AA$10,$C$5,$C$4,$C$7) -> 53.75
B29: N_15532805 | C29: ML-007-MA - Schizophrenia | D29: $M | E29: =_xll.VAData($C$3,E$8,$C29,E$10,$C$5,$C$4,$C$7) -> - | F29: =_xll.VAData($C$3,F$8,$C29,F$10,$C$5,$C$4,$C$7) -> - | G29: =_xll.VAData($C$3,G$8,$C29,G$10,$C$5,$C$4,$C$7) -> 0 | H29: =_xll.VAData($C$3,H$8,$C29,H$10,$C$5,$C$4,$C$7) -> 0 | I29: =_xll.VAData($C$3,I$8,$C29,I$10,$C$5,$C$4,$C$7) -> 0 | J29: =_xll.VAData($C$3,J$8,$C29,J$10,$C$5,$C$4,$C$7) -> - | K29: =_xll.VAData($C$3,K$8,$C29,K$10,$C$5,$C$4,$C$7) -> - | L29: =_xll.VAData($C$3,L$8,$C29,L$10,$C$5,$C$4,$C$7) -> - | ... AA29: =_xll.VAData($C$3,AA$8,$C29,AA$10,$C$5,$C$4,$C$7) -> 493.37879
B30: H
B31: H | C31: ML 007-MA Alzheimer's disease psychosis
B32: N_15532801 | C32: Gross number of patients - ML-007-MA - Alzheimer's disease psychosis (ADP) - US | D32: # | E32: =_xll.VAData($C$3,E$8,$C32,E$10,$C$5,$C$4,$C$7) -> - | F32: =_xll.VAData($C$3,F$8,$C32,F$10,$C$5,$C$4,$C$7) -> - | G32: =_xll.VAData($C$3,G$8,$C32,G$10,$C$5,$C$4,$C$7) -> - | H32: =_xll.VAData($C$3,H$8,$C32,H$10,$C$5,$C$4,$C$7) -> - | I32: =_xll.VAData($C$3,I$8,$C32,I$10,$C$5,$C$4,$C$7) -> 4584783.8 | J32: =_xll.VAData($C$3,J$8,$C32,J$10,$C$5,$C$4,$C$7) -> - | K32: =_xll.VAData($C$3,K$8,$C32,K$10,$C$5,$C$4,$C$7) -> - | L32: =_xll.VAData($C$3,L$8,$C32,L$10,$C$5,$C$4,$C$7) -> - | ... AA32: =_xll.VAData($C$3,AA$8,$C32,AA$10,$C$5,$C$4,$C$7) -> 4769886.9
B33: N_15532775 | C33: Prevalence rate - ML-007-MA - Alzheimer's disease psychosis (ADP) - US | D33: % | E33: =_xll.VAData($C$3,E$8,$C33,E$10,$C$5,$C$4,$C$7) -> - | F33: =_xll.VAData($C$3,F$8,$C33,F$10,$C$5,$C$4,$C$7) -> - | G33: =_xll.VAData($C$3,G$8,$C33,G$10,$C$5,$C$4,$C$7) -> - | H33: =_xll.VAData($C$3,H$8,$C33,H$10,$C$5,$C$4,$C$7) -> - | I33: =_xll.VAData($C$3,I$8,$C33,I$10,$C$5,$C$4,$C$7) -> 35 | J33: =_xll.VAData($C$3,J$8,$C33,J$10,$C$5,$C$4,$C$7) -> - | K33: =_xll.VAData($C$3,K$8,$C33,K$10,$C$5,$C$4,$C$7) -> - | L33: =_xll.VAData($C$3,L$8,$C33,L$10,$C$5,$C$4,$C$7) -> - | ... AA33: =_xll.VAData($C$3,AA$8,$C33,AA$10,$C$5,$C$4,$C$7) -> 35
B34: N_15532774 | C34: Eligible patients - ML-007-MA - Alzheimer's disease psychosis (ADP) - US | D34: # | E34: =_xll.VAData($C$3,E$8,$C34,E$10,$C$5,$C$4,$C$7) -> - | F34: =_xll.VAData($C$3,F$8,$C34,F$10,$C$5,$C$4,$C$7) -> - | G34: =_xll.VAData($C$3,G$8,$C34,G$10,$C$5,$C$4,$C$7) -> - | H34: =_xll.VAData($C$3,H$8,$C34,H$10,$C$5,$C$4,$C$7) -> - | I34: =_xll.VAData($C$3,I$8,$C34,I$10,$C$5,$C$4,$C$7) -> 1412735.8 | J34: =_xll.VAData($C$3,J$8,$C34,J$10,$C$5,$C$4,$C$7) -> - | K34: =_xll.VAData($C$3,K$8,$C34,K$10,$C$5,$C$4,$C$7) -> - | L34: =_xll.VAData($C$3,L$8,$C34,L$10,$C$5,$C$4,$C$7) -> - | ... AA34: =_xll.VAData($C$3,AA$8,$C34,AA$10,$C$5,$C$4,$C$7) -> 1547799.7
B35: N_15532777 | C35: Penetration rate - ML-007-MA - Alzheimer's disease psychosis (ADP) - US | D35: % | E35: =_xll.VAData($C$3,E$8,$C35,E$10,$C$5,$C$4,$C$7) -> - | F35: =_xll.VAData($C$3,F$8,$C35,F$10,$C$5,$C$4,$C$7) -> - | G35: =_xll.VAData($C$3,G$8,$C35,G$10,$C$5,$C$4,$C$7) -> - | H35: =_xll.VAData($C$3,H$8,$C35,H$10,$C$5,$C$4,$C$7) -> - | I35: =_xll.VAData($C$3,I$8,$C35,I$10,$C$5,$C$4,$C$7) -> - | J35: =_xll.VAData($C$3,J$8,$C35,J$10,$C$5,$C$4,$C$7) -> - | K35: =_xll.VAData($C$3,K$8,$C35,K$10,$C$5,$C$4,$C$7) -> - | L35: =_xll.VAData($C$3,L$8,$C35,L$10,$C$5,$C$4,$C$7) -> - | ... AA35: =_xll.VAData($C$3,AA$8,$C35,AA$10,$C$5,$C$4,$C$7) -> 5.5625
B36: N_15532776 | C36: Number of patients - ML-007-MA - Alzheimer's disease psychosis (ADP) - US | D36: # | E36: =_xll.VAData($C$3,E$8,$C36,E$10,$C$5,$C$4,$C$7) -> - | F36: =_xll.VAData($C$3,F$8,$C36,F$10,$C$5,$C$4,$C$7) -> - | G36: =_xll.VAData($C$3,G$8,$C36,G$10,$C$5,$C$4,$C$7) -> - | H36: =_xll.VAData($C$3,H$8,$C36,H$10,$C$5,$C$4,$C$7) -> - | I36: =_xll.VAData($C$3,I$8,$C36,I$10,$C$5,$C$4,$C$7) -> - | J36: =_xll.VAData($C$3,J$8,$C36,J$10,$C$5,$C$4,$C$7) -> - | K36: =_xll.VAData($C$3,K$8,$C36,K$10,$C$5,$C$4,$C$7) -> - | L36: =_xll.VAData($C$3,L$8,$C36,L$10,$C$5,$C$4,$C$7) -> - | ... AA36: =_xll.VAData($C$3,AA$8,$C36,AA$10,$C$5,$C$4,$C$7) -> 60970.32
B37: N_15532778 | C37: Gross revenue per treatment - ML-007-MA - Alzheimer's disease psychosis (ADP) - US | D37: $Abs | E37: =_xll.VAData($C$3,E$8,$C37,E$10,$C$5,$C$4,$C$7) -> - | F37: =_xll.VAData($C$3,F$8,$C37,F$10,$C$5,$C$4,$C$7) -> - | G37: =_xll.VAData($C$3,G$8,$C37,G$10,$C$5,$C$4,$C$7) -> - | H37: =_xll.VAData($C$3,H$8,$C37,H$10,$C$5,$C$4,$C$7) -> - | I37: =_xll.VAData($C$3,I$8,$C37,I$10,$C$5,$C$4,$C$7) -> - | J37: =_xll.VAData($C$3,J$8,$C37,J$10,$C$5,$C$4,$C$7) -> - | K37: =_xll.VAData($C$3,K$8,$C37,K$10,$C$5,$C$4,$C$7) -> - | L37: =_xll.VAData($C$3,L$8,$C37,L$10,$C$5,$C$4,$C$7) -> - | ... AA37: =_xll.VAData($C$3,AA$8,$C37,AA$10,$C$5,$C$4,$C$7) -> 27130.693
