Workbook
Name ____EPS94: '[1]Quarterly P&L'!$AL$31
Name ____EPS95: '[1]Quarterly P&L'!$AQ$31
Name ___auv01: '[2]Rev Drivers'!$BA$39
Name ___auv02: '[2]Rev Drivers'!$BB$39
Name ___cap01: '[2]Rev Drivers'!$BA$45
Name ___cap02: '[2]Rev Drivers'!$BB$45
Name ___cap03: '[2]Rev Drivers'!$BC$45
Name ___EPS94: '[1]Quarterly P&L'!$AL$31
Name ___EPS95: '[1]Quarterly P&L'!$AQ$31
Name ___ogq101: '[2]Rev Drivers'!$Z$44
Name ___ogq102: '[2]Rev Drivers'!$AD$44
Name ___ogq103: '[2]Rev Drivers'!$AH$44
Name ___ogq201: '[2]Rev Drivers'!$AA$44
Name ___ogq202: '[2]Rev Drivers'!$AE$44
Name ___ogq203: '[2]Rev Drivers'!$AI$44
Name ___ogq301: '[2]Rev Drivers'!$AB$44
Name ___ogq302: '[2]Rev Drivers'!$AF$44
Name ___ogq303: '[2]Rev Drivers'!$AJ$44
Name ___ogq401: '[2]Rev Drivers'!$AC$44
Name ___ogq402: '[2]Rev Drivers'!$AG$44
Name ___ogq403: '[2]Rev Drivers'!$AK$44
Name ___rlq101: '[2]Rev Drivers'!$Z$43
Name ___rlq102: '[2]Rev Drivers'!$AD$43
Name ___rlq103: '[2]Rev Drivers'!$AH$43
Name ___rlq201: '[2]Rev Drivers'!$AA$43
Name ___rlq202: '[2]Rev Drivers'!$AE$43
Name ___rlq203: '[2]Rev Drivers'!$AI$43
Name ___rlq301: '[2]Rev Drivers'!$AB$43
Name ___rlq302: '[2]Rev Drivers'!$AF$43
Name ___rlq303: '[2]Rev Drivers'!$AJ$43
Name ___rlq401: '[2]Rev Drivers'!$AC$43
Name ___rlq402: '[2]Rev Drivers'!$AG$43
Name ___rlq403: '[2]Rev Drivers'!$AK$43
Name __auv01: '[4]Rev Drivers'!$BA$39
Name __auv02: '[4]Rev Drivers'!$BB$39
Name __cap01: '[4]Rev Drivers'!$BA$45
Name __cap02: '[4]Rev Drivers'!$BB$45
Name __cap03: '[4]Rev Drivers'!$BC$45
Name __EPS94: '[1]Quarterly P&L'!$AL$31
Name __EPS95: '[1]Quarterly P&L'!$AQ$31
Name __FDS_UNIQUE_RANGE_ID_GENERATOR_COUNTER: 1
Name __ogq101: '[4]Rev Drivers'!$Z$44
Name __ogq102: '[4]Rev Drivers'!$AD$44
Name __ogq103: '[4]Rev Drivers'!$AH$44
Name __ogq201: '[4]Rev Drivers'!$AA$44
Name __ogq202: '[4]Rev Drivers'!$AE$44
Name __ogq203: '[4]Rev Drivers'!$AI$44
Name __ogq301: '[4]Rev Drivers'!$AB$44
Name __ogq302: '[4]Rev Drivers'!$AF$44
Name __ogq303: '[4]Rev Drivers'!$AJ$44
Name __ogq401: '[4]Rev Drivers'!$AC$44
Name __ogq402: '[4]Rev Drivers'!$AG$44
Name __ogq403: '[4]Rev Drivers'!$AK$44
Name __rev1: [6]Sheet1!$A$8:$G$103
Name __rev2: [6]Sheet1!$A$105:$G$155
Name __rev3: [6]Sheet1!$A$157:$G$197
Name __rlq101: '[4]Rev Drivers'!$Z$43
Name __rlq102: '[4]Rev Drivers'!$AD$43
Name __rlq103: '[4]Rev Drivers'!$AH$43
Name __rlq201: '[4]Rev Drivers'!$AA$43

Sheet __FDSCACHE__
B1: This sheet contains FactSet XML data for use with this workbook's =FDS codes. Modifying the worksheet's contents may damage the workbook's =FDS functionality.

Sheet iQ ML_Model_Summary
A1: Checksheet
A3: Security: | C3: =_xll.NextGen.Functions.XmlPart("urn:NextGen/PropertyType/DocumentMetadata","DocumentMetadata/Instruments/Instrument[@Type='Primary']/@Ticker") -> #NAME? | Q3: Key
Q4: percentage change data
A5: Analyst: | C5: =_xll.IQXL.Functions.iQ(Ticker,"AName") -> #NAME? | Q5: aiQ codes
Q6: aquarterly EPS logic
A7: Company: | C7: =_xll.IQXL.Functions.iQ(Ticker,"CoLongName") -> #NAME? | K7: Investment Opinion: | M7: =_xll.IQXL.Functions.iQ(Ticker,12948) -> #NAME? | Q7: CoLongName | R7: 12948
A8: Industry: | C8: =_xll.IQXL.Functions.iQ(Ticker,"ind") -> #NAME? | K8: Last Fiscal Year End: | M8: =_xll.IQXL.Functions.iQ(Ticker,"FiscalYearEnd") -> #NAME? | Q8: ind | R8: FiscalYearEnd
A9: Country: | C9: =_xll.IQXL.Functions.iQ(Ticker,"loc") -> #NAME? | K9: Price Objective: | M9: =_xll.IQXL.Functions.iQ(Ticker,12764) -> #NAME? | Q9: loc | R9: 12764
A10: Currency: | C10: =_xll.IQXL.Functions.iQ(Ticker,"REPCRNCY") -> #NAME? | K10: Date Established: | M10: =_xll.IQXL.Functions.iQ(Ticker,29013) -> #NAME? | Q10: REPCRNCY | R10: 29013
A11: Cusip: | C11: =_xll.IQXL.Functions.iQ(Ticker,"CUSIP") -> #NAME? | K11: aBase Price: | M11: =_xll.IQXL.Functions.iQ(Ticker,12765) -> #NAME? | Q11: CUSIP | R11: 12765
A12: Sedol: | C12: =_xll.IQXL.Functions.iQ(Ticker,"SEDOL") -> #NAME? | Q12: SEDOL
A14: Price Date: | C14: =_xll.IQXL.Functions.iQ(Ticker,"PriceDate") -> #NAME? | Q14: PriceDate
A15: Price: | C15: =_xll.IQXL.Functions.iQ(Ticker,"nprice") -> #NAME? | Q15: nprice
A16: Data: | C16: =_xll.IQXL.Functions.iQ(Ticker,"statusrelease") -> #NAME? | Q16: statusrelease
C17: Last Year | E17: =C18&D18 -> #NAME? | H17: Current Year | J17: =H18&I18 -> #NAME? | M17: Next Year | O17: =M18&N18 -> #NAME?
C18: =_xll.IQXL.Functions.iQ(Ticker,"year",0) -> #NAME? | D18: =_xll.IQXL.Functions.iQ(Ticker,18134,C18) -> #NAME? | H18: =_xll.IQXL.Functions.iQ(Ticker,"year","+1") -> #NAME? | I18: =_xll.IQXL.Functions.iQ(Ticker,18134,H18) -> #NAME? | M18: =_xll.IQXL.Functions.iQ(Ticker,"year","+2") -> #NAME? | N18: =_xll.IQXL.Functions.iQ(Ticker,18134,M18) -> #NAME?
C19: (model) | D19: iQ | E19: %Δ | H19: (model) | I19: iQ | J19: %Δ | M19: (model) | N19: iQ | O19: %Δ
A23: EPS: | C23: =#REF! -> #REF! | D23: =_xll.IQXL.Functions.iQ(Ticker,$Q$23,C18) -> #NAME? | E23: =IF(ISERROR(R23)=TRUE,"",R23) | H23: =#REF! -> #REF! | I23: =_xll.IQXL.Functions.iQ(Ticker,$Q$23,H18) -> #NAME? | J23: =IF(ISERROR(S23)=TRUE,"",S23) | M23: =#REF! -> #REF! | N23: =_xll.IQXL.Functions.iQ(Ticker,$Q$23,M18) -> #NAME? | O23: =IF(ISERROR(T23)=TRUE,"",T23) | Q23: 12569 | R23: =IF(NOT(AND(ISNUMBER(D23),ISNUMBER(C23))),NA(),(C23/D23-1)) -> #N/A | S23: =IF(NOT(AND(ISNUMBER(I23),ISNUMBER(H23))),NA(),(H23/I23-1)) -> #N/A | T23: =IF(NOT(AND(ISNUMBER(N23),ISNUMBER(M23))),NA(),(M23/N23-1)) -> #N/A
A24: GAAP EPS: | C24: =#REF! -> #REF! | D24: =_xll.IQXL.Functions.iQ(Ticker,12773,C18) -> #NAME? | E24: =IF(ISERROR(R24)=TRUE,"",R24) | H24: =#REF! -> #REF! | I24: =_xll.IQXL.Functions.iQ(Ticker,$Q$24,H18) -> #NAME? | J24: =IF(ISERROR(S24)=TRUE,"",S24) | M24: =#REF! -> #REF! | N24: =_xll.IQXL.Functions.iQ(Ticker,$Q$24,M18) -> #NAME? | O24: =IF(ISERROR(T24)=TRUE,"",T24) | Q24: 12773 | R24: =IF(NOT(AND(ISNUMBER(D24),ISNUMBER(C24))),NA(),(C24/D24-1)) -> #N/A | S24: =IF(NOT(AND(ISNUMBER(I24),ISNUMBER(H24))),NA(),(H24/I24-1)) -> #N/A | T24: =IF(NOT(AND(ISNUMBER(N24),ISNUMBER(M24))),NA(),(M24/N24-1)) -> #N/A
A25: CFPS: | C25: ='BAL-CF'!AK114 -> 0 | D25: =_xll.IQXL.Functions.iQ(Ticker,$Q$25,C18) -> #NAME? | E25: =IF(ISERROR(R25)=TRUE,"",R25) | H25: ='BAL-CF'!AP114 -> 0 | I25: =_xll.IQXL.Functions.iQ(Ticker,$Q$25,H18) -> #NAME? | J25: =IF(ISERROR(S25)=TRUE,"",S25) | M25: ='BAL-CF'!AU114 -> 0 | N25: =_xll.IQXL.Functions.iQ(Ticker,$Q$25,M18) -> #NAME? | O25: =IF(ISERROR(T25)=TRUE,"",T25) | Q25: 12570 | R25: =IF(NOT(AND(ISNUMBER(D25),ISNUMBER(C25))),NA(),(C25/D25-1)) -> #N/A | S25: =IF(NOT(AND(ISNUMBER(I25),ISNUMBER(H25))),NA(),(H25/I25-1)) -> #N/A | T25: =IF(NOT(AND(ISNUMBER(N25),ISNUMBER(M25))),NA(),(M25/N25-1)) -> #N/A
A26: DPS: | C26: 0 | D26: =_xll.IQXL.Functions.iQ(Ticker,$Q$26,C18) -> #NAME? | E26: =IF(ISERROR(R26)=TRUE,"",R26) | H26: 0 | I26: =_xll.IQXL.Functions.iQ(Ticker,$Q$26,H18) -> #NAME? | J26: =IF(ISERROR(S26)=TRUE,"",S26) | M26: 0 | N26: =_xll.IQXL.Functions.iQ(Ticker,$Q$26,M18) -> #NAME? | O26: =IF(ISERROR(T26)=TRUE,"",T26) | Q26: 12571 | R26: =IF(NOT(AND(ISNUMBER(D26),ISNUMBER(C26))),NA(),(C26/D26-1)) -> #N/A | S26: =IF(NOT(AND(ISNUMBER(I26),ISNUMBER(H26))),NA(),(H26/I26-1)) -> #N/A | T26: =IF(NOT(AND(ISNUMBER(N26),ISNUMBER(M26))),NA(),(M26/N26-1)) -> #N/A
F28: Est 5 Year EPS Growth Rate: | I28: =_xll.IQXL.Functions.iQ(Ticker,Q28) -> #NAME? | J28: =IF(ISERROR(R28)=TRUE,"",R28) | Q28: 12612 | R28: =IF(NOT(AND(ISNUMBER(I28),ISNUMBER(H28))),NA(),(H28/I28-1)) -> #N/A
F29: Current Qtr. EPS Est.: | H29: ='QTR-EPS'!AU32 -> 0 | I29: =VLOOKUP("E",S32:T38,2,FALSE) -> #N/A | J29: =IF(ISERROR(R29)=TRUE,"",R29) | R29: =IF(NOT(AND(ISNUMBER(I29),ISNUMBER(H29))),NA(),(H29/I29-1)) -> #N/A
F30: Curr. Qtr. Date: | H30: Q1 | I30: =Q32 -> #NAME?
Q31: Logic | S31: =_xll.IQXL.Functions.iQ(Ticker,"year","+1") -> #NAME? | T31: EPS
Q32: =IF(S32="E",R32,Q34) -> #NAME? | R32: Q1 | S32: =_xll.IQXL.Functions.iQ(Ticker,18134,S$31&$R32) -> #NAME? | T32: =_xll.IQXL.Functions.iQ(Ticker,$Q$23,S$31&$R32) -> #NAME?
Q33: =IF(S33="E",R33,Q34) -> #NAME? | R33: Q2 | S33: =_xll.IQXL.Functions.iQ(Ticker,18134,S$31&$R33) -> #NAME? | T33: =_xll.IQXL.Functions.iQ(Ticker,$Q$23,S$31&$R33) -> #NAME?
Q34: =IF(S34="E",R34,Q35) -> #NAME? | R34: Q2 | S34: =_xll.IQXL.Functions.iQ(Ticker,18134,S$31&$R34) -> #NAME? | T34: =_xll.IQXL.Functions.iQ(Ticker,$Q$23,S$31&$R34) -> #NAME?
Q35: =IF(S35="E",R35,Q36) -> #NAME? | R35: Q3 | S35: =_xll.IQXL.Functions.iQ(Ticker,18134,S$31&$R35) -> #NAME? | T35: =_xll.IQXL.Functions.iQ(Ticker,$Q$23,S$31&$R35) -> #NAME?
Q36: =IF(S36="E",R36,Q38) -> #NAME? | R36: Q4 | S36: =_xll.IQXL.Functions.iQ(Ticker,18134,S$31&$R36) -> #NAME? | T36: =_xll.IQXL.Functions.iQ(Ticker,$Q$23,S$31&$R36) -> #NAME?
S37: =_xll.IQXL.Functions.iQ(Ticker,"year","+2") -> #NAME? | T37: EPS
Q38: =IF(S38="E",R38,"NA") -> #NAME? | R38: Q1 | S38: =_xll.IQXL.Functions.iQ(Ticker,18134,S$37&$R38) -> #NAME? | T38: =_xll.IQXL.Functions.iQ(Ticker,$Q$23,S$37&$R38) -> #NAME?

Sheet Cover
A4: Company Model
B5: US Equity Research
A8: MapLight | H8: MPLT | L8: 46107
A15: Sumant Kulkarni
A16: Analyst
A17: SKulkarni@cgf.com
A18: 212.389.8037
A22: Canaccord Genuity LLC, Member FINRA (CRD# 1020) and SIPC, is a wholly owned subsidiary of Canaccord Genuity Group Inc. (together with its affiliates"Canaccord Group"). The following important disclosures and disclaimers apply to the information presented in the attached model (this "Model") and the provision of this Model by Canaccord Genuity LLC, Canaccord Group, or any of their respective affiliates, officers, directors, or employees (collectively "Canaccord Genuity") and such disclosures and disclaimers should be reviewed carefully. Models are the basis, but not substitutes, for Canaccord Genuity LLC published research reports and do not constitute research reports and should not be relied upon to make an investment decision. Models, including this Model, present a view only as of the date thereof and any opinions estimates and assumptions expressed therein are made as of the date thereof. The information contained may be subject to change or withdrawal without notice or become incorrect due to passage of time or as a result of legal, political, economic, or other changes. This Model may present non-substantive changes from a recently published model. Canaccord Genuity LLC does not assume responsibility to indicate any changes or to furnish an updated Model.
A23: This Model is intended for intended recipients who are institutional investors only and not for retail or private investors and should not be reproduced or redistributed to third parties outside of the intended recipient's organization or republished absent the prior written consent of Canaccord Genuity LLC. Any such reproduction without permission is a violation of Canaccord Genuity's copyright. This Model is provided to such institutional investors, for informational purposes only, and on the basis that any intended recipient is a sophisticated investment professional familiar with its limitations. In providing this model, Canaccord Genuity LLC is not acting as an investment adviser or fiduciary in any respect. The opinions and recommendations herein do not take into account individual client circumstances, objectives or needs and are not intended as recommendations of investment products or other financial products or strategies to particular clients. Securities, investment products, other financial products or strategies discussed herein are not suitable for all investors. The recipient of this report must make its own independent decisions regarding any securities, investment products, other financial products mentioned herein. By making this material available, Canaccord Genuity LLC is not providing investment, legal, regulatory, tax, financial, or accounting advice to the recipient of this model or any other party.
A24: This Model does not constitute an offer or solicitation to buy or sell any securities, investment products or other financial product or services. This Model does not constitute an official confirmation of any transaction. This Model is not an official statement of Canaccord Genuity and opinions expressed in this Model may differ or be contrary to opinions expressed, or actions taken by other business units, of Canaccord Genuity. Sources for the information herein are believed to be reliable, but Canaccord Genuity LLC makes no representation and gives no warranty as to the completeness or accuracy of the information contained herein, except with respect to any disclosures related to Canaccord Genuity and its research analyst's involvement with or interests in a particular issuer. Any forward looking statements incorporated herein are uncertain and may involve risks, assumptions and uncertainties. Past performance is not indicative of future results. Nothing herein shall be relied on as a representation as to future performance. No liability is accepted by Canaccord Genuity for any losses that may arise from any use of or reliance on the information contained herein. Periods beyond our published forecast are scenario analysis for the purpose of supporting our valuation framework predicated on historical trends or guidance but are not studied estimates.
A25: The preparation of this Model is subject to regulation by U.S. law. The distribution of this Model in other jurisdictions may be restricted by law, and persons into whose possession this Model comes should inform themselves about, and observe, any such restrictions. This Model has been prepared exclusively by Canaccord Genuity LLC. Although affiliates of Canaccord Genuity LLC may distribute this document ton a third-party basis, such affiliates do not provide input into its contents.
A26: This Model was last updated on the date noted above and shall constitute an addendum to, and part of, the research report published on that date which contains company-specific disclosures applicable at the time of publication and which may be obtained by visiting:
A27: https://research.canaccordgenuity.com.
A28: All conflict of interest and company-specific disclosures may be obtained at:
A29: https://canaccordgenuity.bluematrix.com/sellside/Disclosures.action
... A32: Copyright © Canaccord Genuity LLC 2026 – Member FINRA/SIPC Copyright © Canaccord Genuity Corp. 2026 – Member CIRO/Canadian Investor Protection Fund Copyright © Canaccord Genuity Limited. 2026 – Member LSE, authorized and regulated by the Financial Conduct Authority Copyright © Canaccord Genuity (Australia) Limited. 2026 – Participant of ASX Group, Cboe Australia and of the NSX. Authorized and regulated by ASIC All rights reserved. All material presented in this document, unless specifically indicated otherwise, is under copyright of Canaccord Group. None of the material, nor its content, nor any copy of it, may be altered in any way, or transmitted to or distributed to any other party, without the prior express written permission of Canaccord Group. Source: Company reports and Canaccord Genuity LLC Please contact your Canaccord Genuity LLC salesperson for a copy of the most recent research report on this company.

Sheet QTR-EPS
BJ1: `
A4: MPLT Quarterly Earnings Model
A6: ($mn) [FY - DEC] | B6: Mar-08A | C6: Jun-08A | D6: Sep-08A | E6: Dec-08A | F6: 2008A | G6: Mar-09A | H6: Jun-09A | I6: Sep-09A | J6: Dec-09A | K6: 2009A | L6: Mar-10A | M6: Jun-10A | N6: Sep-10A | O6: Dec-10A | P6: 2010A | Q6: Mar-11A | R6: Jun-11A | S6: Sep-11A | T6: Dec-11A | U6: 2011A | V6: Mar-12A | W6: Jun-12A | X6: Sep-12A | Y6: Dec-12A | Z6: 2012A | AA6: Mar-13A | AB6: Jun-13A | AC6: Sep-13A | AD6: Dec-13A | AE6: 2013A | AF6: Mar-14A | AG6: Jun-14A | AH6: Sep-14A | AI6: Dec-14A | AJ6: 2014A | AK6: Mar-15A | AL6: Jun-15A | AM6: Sep-15A | AN6: Dec-15A | AO6: 2015A | AP6: Mar-16A | AQ6: Jun-16A | AR6: Sep-16A | AS6: Dec-16A | AT6: 2016A | AU6: Mar-17A | AV6: Jun-17A | AW6: Sep-17A | AX6: Dec-17A | AY6: 2017A | AZ6: Mar-18A | BA6: Jun-18A | BB6: Sep-18A | BC6: Dec-18A | BD6: 2018A | BE6: Mar-19A | BF6: Jun-19A | BG6: Sep-19A | BH6: Dec-19A | BI6: 2019A | BJ6: Mar-20A | BK6: Jun-20A | BL6: Sep-20A | BM6: Dec-20A | BN6: 2020A | BO6: Mar-21A | BP6: Jun-21A | BQ6: Sep-21A | BR6: Dec-21A | BS6: 2021A | BT6: Mar-22A | BU6: Jun-22A | BV6: Sep-22A | BW6: Dec-22A | BX6: 2022A | BY6: Mar-23A | BZ6: Jun-23A | CA6: Sep-23A | CB6: Dec-23A | CC6: 2023A | CD6: Mar-24A | CE6: Jun-24A | CF6: Sep-24A | CG6: Dec-24A | CH6: 2024A | CI6: Mar-25A | CJ6: Jun-25A | CK6: Sep-25A | CL6: Dec-25A | CM6: 2025A | CN6: Mar-26E | CO6: Jun-26E | CP6: Sep-26E | CQ6: Dec-26E | CR6: 2026E | CS6: 2027E | CT6: 2028E | CU6: 2029E | CV6: 2030E | CW6: 2031E | CX6: 2032E | CY6: 2033E | CZ6: 2034E | DA6: 2035E | DB6: 2036E
A8: Revenue | CC8: 0 | CD8: 0 | CE8: 0 | CF8: 0 | CG8: 0 | CH8: 0 | CI8: 0 | CJ8: 0 | CK8: 0 | CL8: 0 | CM8: 0 | CN8: 0 | CO8: 0 | CP8: 0 | CQ8: 0 | CR8: 0 | CS8: 0 | CT8: 0 | CU8: 0 | CV8: 57.31451 | CW8: 374.48993 | CX8: 662.96906 | CY8: 1130.0803 | CZ8: 1958.9362 | DA8: 2876.6971 | DB8: 3716.9758
A9: COGS | CC9: 0 | CD9: 0 | CE9: 0 | CF9: 0 | CG9: 0 | CH9: 0 | CI9: 0 | CJ9: 0 | CK9: 0 | CL9: 0 | CM9: 0 | CN9: 0 | CO9: 0 | CP9: 0 | CQ9: 0 | CR9: 0 | CS9: 0 | CT9: 0 | CU9: 0 | CV9: 3.4388706 | CW9: 22.469396 | CX9: 39.778143 | CY9: 67.804821 | CZ9: 117.53617 | DA9: 172.60182 | DB9: 223.01855
A10: Gross Profit | CC10: 0 | CD10: 0 | CE10: 0 | CF10: 0 | CG10: 0 | CH10: 0 | CI10: 0 | CJ10: 0 | CK10: 0 | CL10: 0 | CM10: 0 | CN10: 0 | CO10: 0 | CP10: 0 | CQ10: 0 | CR10: 0 | CS10: 0 | CT10: 0 | CU10: 0 | CV10: 53.87564 | CW10: 352.02053 | CX10: 623.19091 | CY10: 1062.2755 | CZ10: 1841.4 | DA10: 2704.0952 | DB10: 3493.9572
A12: SG&A | CC12: 7.607 | CD12: 4.1435 | CE12: 4.1435 | CF12: 4.08 | CG12: 2.064 | CH12: 14.423 | CI12: 3.2865 | CJ12: 4.2885 | CK12: 4.404 | CL12: 18.755 | CM12: 30.734 | CN12: 11 | CO12: 12 | CP12: 13 | CQ12: 14 | CR12: 50 | CS12: 55 | CT12: 65 | CU12: 65 | CV12: 200 | CW12: 300 | CX12: 500 | CY12: 515 | CZ12: 530.45 | DA12: 546.3635 | DB12: 562.75441
A13: R&D | CC13: 49.675 | CD13: 15.4945 | CE13: 15.4945 | CF13: 16.814 | CG13: 20.714 | CH13: 68.523 | CI13: 22.3155 | CJ13: 24.3165 | CK13: 27.094 | CL13: 64.623 | CM13: 138.349 | CN13: 38 | CO13: 40 | CP13: 42 | CQ13: 44 | CR13: 164 | CS13: 175 | CT13: 200 | CU13: 200 | CV13: 100 | CW13: 50 | CX13: 50 | CY13: 50 | CZ13: 50 | DA13: 50 | DB13: 50
A14: EBITDA | CC14: -57.282 | CD14: -19.638 | CE14: -19.737 | CF14: -21.62 | CG14: -22.993 | CH14: -83.986 | CI14: -25.602 | CJ14: -28.499 | CK14: -31.826 | CL14: -84.68 | CM14: -170.607 | CN14: -48.9 | CO14: -51.9 | CP14: -54.9 | CQ14: -57.9 | CR14: -213.6 | CS14: -229.5 | CT14: -264 | CU14: -264 | CV14: -245.12436 | CW14: 3.0205348 | CX14: 74.190915 | CY14: 498.27553 | CZ14: 1261.95 | DA14: 2108.7317 | DB14: 2882.2028
A15: Depreciation | CC15: 0 | CD15: 0 | CE15: 0.32 | CF15: 0.187 | CG15: 0.194 | CH15: 0.701 | CI15: 0 | CJ15: 0.302 | CK15: 0.136 | CL15: 0.14 | CM15: 0.578 | CN15: 0.1 | CO15: 0.1 | CP15: 0.1 | CQ15: 0.1 | CR15: 0.4 | CS15: 0.5 | CT15: 1 | CU15: 1 | CV15: 1 | CW15: 1 | CX15: 1 | CY15: 1 | CZ15: 1 | DA15: 1 | DB15: 1
A16: Amortization | CC16: 0 | CD16: 0 | CE16: -0.419 | CF16: -0.913 | CG16: -0.409 | CH16: -1.741 | CI16: 0 | CJ16: -0.196 | CK16: -0.464 | CL16: -1.442 | CM16: -2.102 | CN16: 0 | CO16: 0 | CP16: 0 | CQ16: 0 | CR16: 0 | CS16: 0 | CT16: 0 | CU16: 0 | CV16: 0 | CW16: 0 | CX16: 0 | CY16: 0 | CZ16: 0 | DA16: 0 | DB16: 0
A17: Operating Income | CC17: -57.282 | CD17: -19.638 | CE17: -19.638 | CF17: -20.894 | CG17: -22.778 | CH17: -82.946 | CI17: -25.602 | CJ17: -28.605 | CK17: -31.498 | CL17: -83.378 | CM17: -169.083 | CN17: -49 | CO17: -52 | CP17: -55 | CQ17: -58 | CR17: -214 | CS17: -230 | CT17: -265 | CU17: -265 | CV17: -246.12436 | CW17: 2.0205348 | CX17: 73.190915 | CY17: 497.27553 | CZ17: 1260.95 | DA17: 2107.7317 | DB17: 2881.2028
A19: Interest Income | CC19: 1.099 | CD19: 1.2625 | CE19: 1.2625 | CF19: 1.081 | CG19: 0.899 | CH19: 4.504 | CI19: 0.698 | CJ19: 0.8 | CK19: 1.549 | CL19: 2.471 | CM19: 5.518 | CN19: 0.17605689 | CO19: 0.14584499 | CP19: 0.16062826 | CQ19: 0.17354519 | CR19: 0.65607533 | CS19: 0.58063223 | CT19: 0.47370891 | CU19: 0.35349291 | CV19: 0.28889 | CW19: 0.31654339 | CX19: 0.47072008 | CY19: 1.1867763 | CZ19: 3.1730173 | DA19: 6.6986033 | DB19: 11.738145
A20: Interest Expense | CC20: 0 | CD20: 0 | CE20: 0 | CF20: 0 | CG20: 0 | CH20: 0 | CI20: 0 | CJ20: 0 | CK20: 0 | CL20: 0 | CM20: 0 | CN20: 0 | CO20: 0 | CP20: 0 | CQ20: 0 | CR20: 0 | CS20: 0 | CT20: 0 | CU20: 0 | CV20: 0 | CW20: 0 | CX20: 0 | CY20: 0 | CZ20: 0 | DA20: 0 | DB20: 0
A21: Other | CC21: 0.474 | CD21: -0.2915 | CE21: -0.2915 | CF21: 0.797 | CG21: 0.65 | CH21: 0.862 | CI21: 0.32333333 | CJ21: 0.2 | CK21: 0.531 | CL21: 1.359 | CM21: 2.4133333 | CN21: 0 | CO21: 0 | CP21: 0 | CQ21: 0 | CR21: 0 | CS21: 0 | CT21: 0 | CU21: 0 | CV21: 0 | CW21: 0 | CX21: 0 | CY21: 0 | CZ21: 0 | DA21: 0 | DB21: 0
... A34: Adjusted Net Income | CC34: -55.709 | CD34: -18.667 | CE34: -18.667 | CF34: -19.016 | CG34: -21.229 | CH34: -77.58 | CI34: -24.580667 | CJ34: -27.605 | CK34: -29.418 | CL34: -79.548 | CM34: -161.15167 | CN34: -48.823943 | CO34: -51.854155 | CP34: -54.839372 | CQ34: -57.826455 | CR34: -213.34392 | CS34: -229.41937 | CT34: -264.52629 | CU34: -264.64651 | CV34: -245.83547 | CW34: 2.3370782 | CX34: 69.978553 | CY34: 448.61607 | CZ34: 1074.5046 | DA34: 1670.4 | DB34: 2285.4234
A35: GAAP EPS
A37: YEAR-OVER-YEAR % CHANGE
A38: Revenue | CC38: NM | CD38: NM | CE38: NM | CF38: NM | CG38: NM | CH38: NM | CI38: NM | CJ38: NM | CK38: NM | CL38: NM | CM38: NM | CN38: NM | CO38: NM | CP38: NM | CQ38: NM | CR38: NM | CS38: NM | CT38: NM | CU38: NM | CV38: NM | CW38: 5.5339463 | CX38: 0.77032546 | CY38: 0.7045748 | CZ38: 0.73344858 | DA38: 0.46849964 | DB38: 0.29209843
A39: COGS | CC39: NM | CD39: NM | CE39: NM | CF39: NM | CG39: NM | CH39: NM | CI39: NM | CJ39: NM | CK39: NM | CL39: NM | CM39: NM | CN39: NM | CO39: NM | CP39: NM | CQ39: NM | CR39: NM | CS39: NM | CT39: NM | CU39: NM | CV39: NM | CW39: NM | CX39: NM | CY39: NM | CZ39: NM | DA39: NM | DB39: NM
A40: Gross Profit | CC40: NM | CD40: NM | CE40: NM | CF40: NM | CG40: NM | CH40: NM | CI40: NM | CJ40: NM | CK40: NM | CL40: NM | CM40: NM | CN40: NM | CO40: NM | CP40: NM | CQ40: NM | CR40: NM | CS40: NM | CT40: NM | CU40: NM | CV40: NM | CW40: 5.5339463 | CX40: 0.77032546 | CY40: 0.7045748 | CZ40: 0.73344858 | DA40: 0.46849964 | DB40: 0.29209843
A41: SG&A | CC41: NM | CD41: NM | CE41: NM | CF41: NM | CG41: NM | CH41: 0.89601683 | CI41: -0.20682997 | CJ41: 0.03499457 | CK41: 0.079411765 | CL41: 8.0867248 | CM41: 1.130902 | CN41: 2.3470257 | CO41: 1.7981812 | CP41: 1.9518619 | CQ41: -0.25353239 | CR41: 0.62686276 | CS41: 0.1 | CT41: 0.18181818 | CU41: 0 | CV41: 2.0769231 | CW41: 0.5 | CX41: 0.66666667 | CY41: 0.03 | CZ41: 0.03 | DA41: 0.03 | DB41: 0.03
A42: R&D | CC42: NM | CD42: NM | CE42: NM | CF42: NM | CG42: NM | CH42: 0.37942627 | CI42: 0.44022072 | CJ42: 0.56936332 | CK42: 0.61139527 | CL42: 2.1197741 | CM42: 1.0190155 | CN42: 0.70285228 | CO42: 0.64497358 | CP42: 0.55015871 | CQ42: -0.31912786 | CR42: 0.18540792 | CS42: 0.067073171 | CT42: 0.14285714 | CU42: 0 | CV42: -0.5 | CW42: -0.5 | CX42: 0 | CY42: 0 | CZ42: 0 | DA42: 0 | DB42: 0
A43: EBITDA | CC43: NM | CD43: NM | CE43: NM | CF43: NM | CG43: NM | CH43: NM | CI43: NM | CJ43: NM | CK43: NM | CL43: NM | CM43: NM | CN43: NM | CO43: NM | CP43: NM | CQ43: NM | CR43: NM | CS43: NM | CT43: NM | CU43: NM | CV43: NM | CW43: NM | CX43: NM | CY43: NM | CZ43: 1.5326349 | DA43: 0.67101053 | DB43: 0.36679444
A44: Operating Income | CC44: NM | CD44: NM | CE44: NM | CF44: NM | CG44: NM | CH44: NM | CI44: NM | CJ44: NM | CK44: NM | CL44: NM | CM44: NM | CN44: NM | CO44: NM | CP44: NM | CQ44: NM | CR44: NM | CS44: NM | CT44: NM | CU44: NM | CV44: NM | CW44: NM | CX44: NM | CY44: NM | CZ44: 1.535717 | DA44: 0.67154267 | DB44: 0.36696846
A45: Pre-Tax Income | CC45: NM | CD45: NM | CE45: NM | CF45: NM | CG45: NM | CH45: NM | CI45: NM | CJ45: NM | CK45: NM | CL45: NM | CM45: NM | CN45: NM | CO45: NM | CP45: NM | CQ45: NM | CR45: NM | CS45: NM | CT45: NM | CU45: NM | CV45: NM | CW45: NM | CX45: NM | CY45: NM | CZ45: 1.5360454 | DA45: 0.67264602 | DB45: 0.3681893
A46: Net Income | CC46: NM | CD46: NM | CE46: NM | CF46: NM | CG46: NM | CH46: NM | CI46: NM | CJ46: NM | CK46: NM | CL46: NM | CM46: NM | CN46: NM | CO46: NM | CP46: NM | CQ46: NM | CR46: NM | CS46: NM | CT46: NM | CU46: NM | CV46: NM | CW46: NM | CX46: NM | CY46: NM | CZ46: 1.395154 | DA46: 0.55457689 | DB46: 0.3681893
A47: EPS | CC47: NM | CD47: NM | CE47: NM | CF47: NM | CG47: NM | CH47: NM | CI47: NM | CJ47: NM | CK47: NM | CL47: NM | CM47: NM | CN47: NM | CO47: NM | CP47: NM | CQ47: NM | CR47: NM | CS47: NM | CT47: NM | CU47: NM | CV47: NM | CW47: NM | CX47: NM | CY47: NM | CZ47: 1.379322 | DA47: 0.5443686 | DB47: 0.35926355
A48: GAAP EPS
A50: MARGIN ANALYSIS
A51: Gross Profit | CC51: NM | CD51: NM | CE51: NM | CF51: NM | CG51: NM | CH51: NM | CI51: NM | CJ51: NM | CK51: NM | CL51: NM | CM51: NM | CN51: NM | CO51: NM | CP51: NM | CQ51: NM | CR51: NM | CS51: NM | CT51: NM | CU51: NM | CV51: 0.94 | CW51: 0.94 | CX51: 0.94 | CY51: 0.94 | CZ51: 0.94 | DA51: 0.94 | DB51: 0.94
A52: SG&A | CC52: NM | CD52: NM | CE52: NM | CF52: NM | CG52: NM | CH52: NM | CI52: NM | CJ52: NM | CK52: NM | CL52: NM | CM52: NM | CN52: NM | CO52: NM | CP52: NM | CQ52: NM | CR52: NM | CS52: NM | CT52: NM | CU52: NM | CV52: NM | CW52: 0.80108963 | CX52: 0.75418301 | CY52: 0.45571981 | CZ52: 0.27078473 | DA52: 0.18992737 | DB52: 0.15140115
A53: R&D | CC53: NM | CD53: NM | CE53: NM | CF53: NM | CG53: NM | CH53: NM | CI53: NM | CJ53: NM | CK53: NM | CL53: NM | CM53: NM | CN53: NM | CO53: NM | CP53: NM | CQ53: NM | CR53: NM | CS53: NM | CT53: NM | CU53: NM | CV53: NM | CW53: 0.13351494 | CX53: 0.075418301 | CY53: 0.044244642 | CZ53: 0.025524058 | DA53: 0.017381045 | DB53: 0.013451796
A54: EBITDA | CC54: NM | CD54: NM | CE54: NM | CF54: NM | CG54: NM | CH54: NM | CI54: NM | CJ54: NM | CK54: NM | CL54: NM | CM54: NM | CN54: NM | CO54: NM | CP54: NM | CQ54: NM | CR54: NM | CS54: NM | CT54: NM | CU54: NM | CV54: NM | CW54: 0.0080657303 | CX54: 0.11190705 | CY54: 0.44092044 | CZ54: 0.6442017 | DA54: 0.73303921 | DB54: 0.77541609
A55: Operating Income | CC55: NM | CD55: NM | CE55: NM | CF55: NM | CG55: NM | CH55: NM | CI55: NM | CJ55: NM | CK55: NM | CL55: NM | CM55: NM | CN55: NM | CO55: NM | CP55: NM | CQ55: NM | CR55: NM | CS55: NM | CT55: NM | CU55: NM | CV55: NM | CW55: 0.0053954315 | CX55: 0.11039869 | CY55: 0.44003555 | CZ55: 0.64369121 | DA55: 0.73269159 | DB55: 0.77514705
A56: Pre-Tax Income | CC56: NM | CD56: NM | CE56: NM | CF56: NM | CG56: NM | CH56: NM | CI56: NM | CJ56: NM | CK56: NM | CL56: NM | CM56: NM | CN56: NM | CO56: NM | CP56: NM | CQ56: NM | CR56: NM | CS56: NM | CT56: NM | CU56: NM | CV56: NM | CW56: 0.0062406969 | CX56: 0.11110871 | CY56: 0.44108572 | CZ56: 0.64531098 | DA56: 0.73502016 | DB56: 0.77830504
A57: Net Income | CC57: NM | CD57: NM | CE57: NM | CF57: NM | CG57: NM | CH57: NM | CI57: NM | CJ57: NM | CK57: NM | CL57: NM | CM57: NM | CN57: NM | CO57: NM | CP57: NM | CQ57: NM | CR57: NM | CS57: NM | CT57: NM | CU57: NM | CV57: NM | CW57: 0.0062406969 | CX57: 0.10555327 | CY57: 0.39697715 | CZ57: 0.54851433 | DA57: 0.58066593 | DB57: 0.61486098
A60: Source: Company Reports and Canaccord Genuity

Sheet YR-EPS
A4: MPLT Annual Earnings Model
A6: ($mn) [FY - DEC] | B6: 2008A | C6: 2009A | D6: 2010A | E6: 2011A | F6: 2012A | G6: 2013A | H6: 2014A | I6: 2015A | J6: 2016A | K6: 2017A | L6: 2018A | M6: 2019A | N6: 2020A | O6: 2021A | P6: 2022A | Q6: 2023A | R6: 2024A | S6: 2025A | T6: 2026E | U6: 2027E | V6: 2028E | W6: 2029E | X6: 2030E | Y6: 2031E | Z6: 2032E | AA6: 2033E | AB6: 2034E | AC6: 2035E | AD6: 2036E
A8: Revenue | H8: 0 | I8: 0 | J8: 0 | K8: 0 | L8: 0 | M8: 0 | N8: 0 | O8: 0 | P8: 0 | Q8: 0 | R8: 0 | S8: 0 | T8: 0 | U8: 0 | V8: 0 | W8: 0 | X8: 57.31451 | Y8: 374.48993 | Z8: 662.96906 | AA8: 1130.0803 | AB8: 1958.9362 | AC8: 2876.6971 | AD8: 3716.9758
A9: COGS | H9: 0 | I9: 0 | J9: 0 | K9: 0 | L9: 0 | M9: 0 | N9: 0 | O9: 0 | P9: 0 | Q9: 0 | R9: 0 | S9: 0 | T9: 0 | U9: 0 | V9: 0 | W9: 0 | X9: 3.4388706 | Y9: 22.469396 | Z9: 39.778143 | AA9: 67.804821 | AB9: 117.53617 | AC9: 172.60182 | AD9: 223.01855
A10: Gross Profit | H10: 0 | I10: 0 | J10: 0 | K10: 0 | L10: 0 | M10: 0 | N10: 0 | O10: 0 | P10: 0 | Q10: 0 | R10: 0 | S10: 0 | T10: 0 | U10: 0 | V10: 0 | W10: 0 | X10: 53.87564 | Y10: 352.02053 | Z10: 623.19091 | AA10: 1062.2755 | AB10: 1841.4 | AC10: 2704.0952 | AD10: 3493.9572
A12: SG&A | H12: 0 | I12: 0 | J12: 0 | K12: 0 | L12: 0 | M12: 0 | N12: 0 | O12: 0 | P12: 0 | Q12: 7.607 | R12: 14.423 | S12: 30.734 | T12: 50 | U12: 55 | V12: 65 | W12: 65 | X12: 200 | Y12: 300 | Z12: 500 | AA12: 515 | AB12: 530.45 | AC12: 546.3635 | AD12: 562.75441
A13: R&D | H13: 0 | I13: 0 | J13: 0 | K13: 0 | L13: 0 | M13: 0 | N13: 0 | O13: 0 | P13: 0 | Q13: 49.675 | R13: 68.523 | S13: 138.349 | T13: 164 | U13: 175 | V13: 200 | W13: 200 | X13: 100 | Y13: 50 | Z13: 50 | AA13: 50 | AB13: 50 | AC13: 50 | AD13: 50
A14: EBITDA | H14: 0 | I14: 0 | J14: 0 | K14: 0 | L14: 0 | M14: 0 | N14: 0 | O14: 0 | P14: 0 | Q14: -57.282 | R14: -83.986 | S14: -170.607 | T14: -213.6 | U14: -229.5 | V14: -264 | W14: -264 | X14: -245.12436 | Y14: 3.0205348 | Z14: 74.190915 | AA14: 498.27553 | AB14: 1261.95 | AC14: 2108.7317 | AD14: 2882.2028
A15: Depreciation | H15: 0 | I15: 0 | J15: 0 | K15: 0 | L15: 0 | M15: 0 | N15: 0 | O15: 0 | P15: 0 | Q15: 0 | R15: 0.701 | S15: 0.578 | T15: 0.4 | U15: 0.5 | V15: 1 | W15: 1 | X15: 1 | Y15: 1 | Z15: 1 | AA15: 1 | AB15: 1 | AC15: 1 | AD15: 1
A16: Amortization | H16: 0 | I16: 0 | J16: 0 | K16: 0 | L16: 0 | M16: 0 | N16: 0 | O16: 0 | P16: 0 | Q16: 0 | R16: -1.741 | S16: -2.102 | T16: 0 | U16: 0 | V16: 0 | W16: 0 | X16: 0 | Y16: 0 | Z16: 0 | AA16: 0 | AB16: 0 | AC16: 0 | AD16: 0
A17: Operating Income | H17: 0 | I17: 0 | J17: 0 | K17: 0 | L17: 0 | M17: 0 | N17: 0 | O17: 0 | P17: 0 | Q17: -57.282 | R17: -82.946 | S17: -169.083 | T17: -214 | U17: -230 | V17: -265 | W17: -265 | X17: -246.12436 | Y17: 2.0205348 | Z17: 73.190915 | AA17: 497.27553 | AB17: 1260.95 | AC17: 2107.7317 | AD17: 2881.2028
A19: Interest Income | H19: 0 | I19: 0 | J19: 0 | K19: 0 | L19: 0 | M19: 0 | N19: 0 | O19: 0 | P19: 0 | Q19: 1.099 | R19: 4.504 | S19: 5.518 | T19: 0.65607533 | U19: 0.58063223 | V19: 0.47370891 | W19: 0.35349291 | X19: 0.28889 | Y19: 0.31654339 | Z19: 0.47072008 | AA19: 1.1867763 | AB19: 3.1730173 | AC19: 6.6986033 | AD19: 11.738145
A20: Interest Expense | H20: 0 | I20: 0 | J20: 0 | K20: 0 | L20: 0 | M20: 0 | N20: 0 | O20: 0 | P20: 0 | Q20: 0 | R20: 0 | S20: 0 | T20: 0 | U20: 0 | V20: 0 | W20: 0 | X20: 0 | Y20: 0 | Z20: 0 | AA20: 0 | AB20: 0 | AC20: 0 | AD20: 0
A21: Other | H21: 0 | I21: 0 | J21: 0 | K21: 0 | L21: 0 | M21: 0 | N21: 0 | O21: 0 | P21: 0 | Q21: 0.474 | R21: 0.862 | S21: 2.4133333 | T21: 0 | U21: 0 | V21: 0 | W21: 0 | X21: 0 | Y21: 0 | Z21: 0 | AA21: 0 | AB21: 0 | AC21: 0 | AD21: 0
... A35: GAAP EPS | H35: 0 | I35: 0 | J35: 0 | K35: 0 | L35: 0 | M35: 0 | N35: 0 | O35: 0 | P35: 0 | Q35: 0 | R35: 0 | S35: 0 | T35: 0 | U35: 0 | V35: 0 | W35: 0 | X35: 0 | Y35: 0 | Z35: 0 | AA35: 0 | AB35: 0 | AC35: 0 | AD35: 0
A37: YEAR-OVER-YEAR % CHANGE
A38: Revenue | H38: 0 | I38: 0 | J38: 0 | K38: 0 | L38: 0 | M38: 0 | N38: 0 | O38: 0 | P38: 0 | Q38: 0 | R38: NM | S38: NM | T38: NM | U38: NM | V38: NM | W38: NM | X38: NM | Y38: 5.5339463 | Z38: 0.77032546 | AA38: 0.7045748 | AB38: 0.73344858 | AC38: 0.46849964 | AD38: 0.29209843
A39: COGS | H39: 0 | I39: 0 | J39: 0 | K39: 0 | L39: 0 | M39: 0 | N39: 0 | O39: 0 | P39: 0 | Q39: 0 | R39: NM | S39: NM | T39: NM | U39: NM | V39: NM | W39: NM | X39: NM | Y39: NM | Z39: NM | AA39: NM | AB39: NM | AC39: NM | AD39: NM
A40: Gross Profit | H40: 0 | I40: 0 | J40: 0 | K40: 0 | L40: 0 | M40: 0 | N40: 0 | O40: 0 | P40: 0 | Q40: 0 | R40: NM | S40: NM | T40: NM | U40: NM | V40: NM | W40: NM | X40: NM | Y40: 5.5339463 | Z40: 0.77032546 | AA40: 0.7045748 | AB40: 0.73344858 | AC40: 0.46849964 | AD40: 0.29209843
A41: SG&A | H41: 0 | I41: 0 | J41: 0 | K41: 0 | L41: 0 | M41: 0 | N41: 0 | O41: 0 | P41: 0 | Q41: NM | R41: 0.89601683 | S41: 1.130902 | T41: 0.62686276 | U41: 0.1 | V41: 0.18181818 | W41: 0 | X41: 2.0769231 | Y41: 0.5 | Z41: 0.66666667 | AA41: 0.03 | AB41: 0.03 | AC41: 0.03 | AD41: 0.03
A42: R&D | H42: 0 | I42: 0 | J42: 0 | K42: 0 | L42: 0 | M42: 0 | N42: 0 | O42: 0 | P42: 0 | Q42: NM | R42: 0.37942627 | S42: 1.0190155 | T42: 0.18540792 | U42: 0.067073171 | V42: 0.14285714 | W42: 0 | X42: -0.5 | Y42: -0.5 | Z42: 0 | AA42: 0 | AB42: 0 | AC42: 0 | AD42: 0
A43: EBITDA | H43: 0 | I43: 0 | J43: 0 | K43: 0 | L43: 0 | M43: 0 | N43: 0 | O43: 0 | P43: 0 | Q43: NM | R43: NM | S43: NM | T43: NM | U43: NM | V43: NM | W43: NM | X43: NM | Y43: NM | Z43: NM | AA43: NM | AB43: 1.5326349 | AC43: 0.67101053 | AD43: 0.36679444
A44: Operating Income | H44: 0 | I44: 0 | J44: 0 | K44: 0 | L44: 0 | M44: 0 | N44: 0 | O44: 0 | P44: 0 | Q44: NM | R44: NM | S44: NM | T44: NM | U44: NM | V44: NM | W44: NM | X44: NM | Y44: NM | Z44: NM | AA44: NM | AB44: 1.535717 | AC44: 0.67154267 | AD44: 0.36696846
A45: Pre-Tax Income | H45: 0 | I45: 0 | J45: 0 | K45: 0 | L45: 0 | M45: 0 | N45: 0 | O45: 0 | P45: 0 | Q45: NM | R45: NM | S45: NM | T45: NM | U45: NM | V45: NM | W45: NM | X45: NM | Y45: NM | Z45: NM | AA45: NM | AB45: 1.5360454 | AC45: 0.67264602 | AD45: 0.3681893
A46: Net Income | H46: 0 | I46: 0 | J46: 0 | K46: 0 | L46: 0 | M46: 0 | N46: 0 | O46: 0 | P46: 0 | Q46: NM | R46: NM | S46: NM | T46: NM | U46: NM | V46: NM | W46: NM | X46: NM | Y46: NM | Z46: NM | AA46: NM | AB46: 1.395154 | AC46: 0.55457689 | AD46: 0.3681893
A47: EPS | H47: 0 | I47: 0 | J47: 0 | K47: 0 | L47: 0 | M47: 0 | N47: 0 | O47: 0 | P47: 0 | Q47: NM | R47: NM | S47: NM | T47: NM | U47: NM | V47: NM | W47: NM | X47: NM | Y47: NM | Z47: NM | AA47: NM | AB47: 1.379322 | AC47: 0.5443686 | AD47: 0.35926355
A48: GAAP EPS | H48: 0 | I48: 0 | J48: 0 | K48: 0 | L48: 0 | M48: 0 | N48: 0 | O48: 0 | P48: 0 | Q48: 0 | R48: 0 | S48: 0 | T48: 0 | U48: 0 | V48: 0 | W48: 0 | X48: 0 | Y48: 0 | Z48: 0 | AA48: 0 | AB48: 0 | AC48: 0 | AD48: 0
A50: MARGIN ANALYSIS
A51: Gross Profit | H51: 0 | I51: 0 | J51: 0 | K51: 0 | L51: 0 | M51: 0 | N51: 0 | O51: 0 | P51: 0 | Q51: NM | R51: NM | S51: NM | T51: NM | U51: NM | V51: NM | W51: NM | X51: 0.94 | Y51: 0.94 | Z51: 0.94 | AA51: 0.94 | AB51: 0.94 | AC51: 0.94 | AD51: 0.94
A52: SG&A | H52: 0 | I52: 0 | J52: 0 | K52: 0 | L52: 0 | M52: 0 | N52: 0 | O52: 0 | P52: 0 | Q52: NM | R52: NM | S52: NM | T52: NM | U52: NM | V52: NM | W52: NM | X52: NM | Y52: 0.80108963 | Z52: 0.75418301 | AA52: 0.45571981 | AB52: 0.27078473 | AC52: 0.18992737 | AD52: 0.15140115
A53: R&D | H53: 0 | I53: 0 | J53: 0 | K53: 0 | L53: 0 | M53: 0 | N53: 0 | O53: 0 | P53: 0 | Q53: NM | R53: NM | S53: NM | T53: NM | U53: NM | V53: NM | W53: NM | X53: NM | Y53: 0.13351494 | Z53: 0.075418301 | AA53: 0.044244642 | AB53: 0.025524058 | AC53: 0.017381045 | AD53: 0.013451796
A54: EBITDA | H54: 0 | I54: 0 | J54: 0 | K54: 0 | L54: 0 | M54: 0 | N54: 0 | O54: 0 | P54: 0 | Q54: NM | R54: NM | S54: NM | T54: NM | U54: NM | V54: NM | W54: NM | X54: NM | Y54: 0.0080657303 | Z54: 0.11190705 | AA54: 0.44092044 | AB54: 0.6442017 | AC54: 0.73303921 | AD54: 0.77541609
A55: Operating Income | H55: 0 | I55: 0 | J55: 0 | K55: 0 | L55: 0 | M55: 0 | N55: 0 | O55: 0 | P55: 0 | Q55: NM | R55: NM | S55: NM | T55: NM | U55: NM | V55: NM | W55: NM | X55: NM | Y55: 0.0053954315 | Z55: 0.11039869 | AA55: 0.44003555 | AB55: 0.64369121 | AC55: 0.73269159 | AD55: 0.77514705
A56: Pre-Tax Income | H56: 0 | I56: 0 | J56: 0 | K56: 0 | L56: 0 | M56: 0 | N56: 0 | O56: 0 | P56: 0 | Q56: NM | R56: NM | S56: NM | T56: NM | U56: NM | V56: NM | W56: NM | X56: NM | Y56: 0.0062406969 | Z56: 0.11110871 | AA56: 0.44108572 | AB56: 0.64531098 | AC56: 0.73502016 | AD56: 0.77830504
A57: Net Income | H57: 0 | I57: 0 | J57: 0 | K57: 0 | L57: 0 | M57: 0 | N57: 0 | O57: 0 | P57: 0 | Q57: NM | R57: NM | S57: NM | T57: NM | U57: NM | V57: NM | W57: NM | X57: NM | Y57: 0.0062406969 | Z57: 0.10555327 | AA57: 0.39697715 | AB57: 0.54851433 | AC57: 0.58066593 | AD57: 0.61486098
A60: Source: Company Reports and Canaccord Genuity

Sheet QTR-REV
A4: MPLT Quarterly Revenue and Gross Profit Model
A6: ($mn) [FY - DEC] | B6: Mar-08A | C6: Jun-08A | D6: Sep-08A | E6: Dec-08A | F6: 2008A | G6: Mar-09A | H6: Jun-09A | I6: Sep-09A | J6: Dec-09A | K6: 2009A | L6: Mar-10A | M6: Jun-10A | N6: Sep-10A | O6: Dec-10A | P6: 2010A | Q6: Mar-11A | R6: Jun-11A | S6: Sep-11A | T6: Dec-11A | U6: 2011A | V6: Mar-12A | W6: Jun-12A | X6: Sep-12A | Y6: Dec-12A | Z6: 2012A | AA6: Mar-13A | AB6: Jun-13A | AC6: Sep-13A | AD6: Dec-13A | AE6: 2013A | AF6: Mar-14A | AG6: Jun-14A | AH6: Sep-14A | AI6: Dec-14A | AJ6: 2014A | AK6: Mar-15A | AL6: Jun-15A | AM6: Sep-15A | AN6: Dec-15A | AO6: 2015A | AP6: Mar-16A | AQ6: Jun-16A | AR6: Sep-16A | AS6: Dec-16A | AT6: 2016A | AU6: Mar-17A | AV6: Jun-17A | AW6: Sep-17A | AX6: Dec-17A | AY6: 2017A | AZ6: Mar-18A | BA6: Jun-18A | BB6: Sep-18A | BC6: Dec-18A | BD6: 2018A | BE6: Mar-19A | BF6: Jun-19A | BG6: Sep-19A | BH6: Dec-19A | BI6: 2019A | BJ6: Mar-20A | BK6: Jun-20A | BL6: Sep-20A | BM6: Dec-20A | BN6: 2020A | BO6: Mar-21A | BP6: Jun-21A | BQ6: Sep-21A | BR6: Dec-21A | BS6: 2021A | BT6: Mar-22A | BU6: Jun-22A | BV6: Sep-22A | BW6: Dec-22A | BX6: 2022A | BY6: Mar-23A | BZ6: Jun-23A | CA6: Sep-23A | CB6: Dec-23A | CC6: 2023A | CD6: Mar-24A | CE6: Jun-24A | CF6: Sep-24A | CG6: Dec-24A | CH6: 2024A | CI6: Mar-25A | CJ6: Jun-25A | CK6: Sep-25A | CL6: Dec-25A | CM6: 2025A | CN6: Mar-26E | CO6: Jun-26E | CP6: Sep-26E | CQ6: Dec-26E | CR6: 2026E | CS6: 2027E | CT6: 2028E | CU6: 2029E | CV6: 2030E | CW6: 2031E | CX6: 2032E | CY6: 2033E | CZ6: 2034E | DA6: 2035E | DB6: 2036E
A8: ML-007C-MA - Schizophrenia | CC8: 0 | CD8: 0 | CE8: 0 | CF8: 0 | CG8: 0 | CH8: 0 | CI8: 0 | CJ8: 0 | CK8: 0 | CL8: 0 | CM8: 0 | CN8: 0 | CO8: 0 | CP8: 0 | CQ8: 0 | CR8: 0 | CS8: 0 | CT8: 0 | CU8: 0 | CV8: 57.31451 | CW8: 242.03918 | CX8: 383.29929 | CY8: 539.55764 | CZ8: 712.04747 | DA8: 902.09294 | DB8: 1111.1154
A9: ML-007C-MA - ADP | CC9: 0 | CD9: 0 | CE9: 0 | CF9: 0 | CG9: 0 | CH9: 0 | CI9: 0 | CJ9: 0 | CK9: 0 | CL9: 0 | CM9: 0 | CN9: 0 | CO9: 0 | CP9: 0 | CQ9: 0 | CR9: 0 | CS9: 0 | CT9: 0 | CU9: 0 | CV9: 0 | CW9: 132.45075 | CX9: 279.66977 | CY9: 590.52271 | CZ9: 1246.8887 | DA9: 1974.6041 | DB9: 2605.8604
A10: ML-004 - ASD
A11: Total Product Revenue | CC11: 0 | CD11: 0 | CE11: 0 | CF11: 0 | CG11: 0 | CH11: 0 | CI11: 0 | CJ11: 0 | CK11: 0 | CL11: 0 | CM11: 0 | CN11: 0 | CO11: 0 | CP11: 0 | CQ11: 0 | CR11: 0 | CS11: 0 | CT11: 0 | CU11: 0 | CV11: 57.31451 | CW11: 374.48993 | CX11: 662.96906 | CY11: 1130.0803 | CZ11: 1958.9362 | DA11: 2876.6971 | DB11: 3716.9758
A12: Collaboration revenue | CC12: 0 | CD12: 0 | CE12: 0 | CF12: 0 | CG12: 0 | CH12: 0 | CI12: 0 | CJ12: 0 | CK12: 0 | CL12: 0 | CM12: 0 | CN12: 0 | CO12: 0 | CP12: 0 | CQ12: 0 | CR12: 0 | CS12: 0 | CT12: 0 | CU12: 0 | CV12: 0 | CW12: 0 | CX12: 0 | CY12: 0 | CZ12: 0 | DA12: 0 | DB12: 0
A13: Other | CC13: 0 | CD13: 0 | CE13: 0 | CF13: 0 | CG13: 0 | CH13: 0 | CI13: 0 | CJ13: 0 | CK13: 0 | CL13: 0 | CM13: 0 | CN13: 0 | CO13: 0 | CP13: 0 | CQ13: 0 | CR13: 0 | CS13: 0 | CT13: 0 | CU13: 0 | CV13: 0 | CW13: 0 | CX13: 0 | CY13: 0 | CZ13: 0 | DA13: 0 | DB13: 0
A14: Total Revenue | CC14: 0 | CD14: 0 | CE14: 0 | CF14: 0 | CG14: 0 | CH14: 0 | CI14: 0 | CJ14: 0 | CK14: 0 | CL14: 0 | CM14: 0 | CN14: 0 | CO14: 0 | CP14: 0 | CQ14: 0 | CR14: 0 | CS14: 0 | CT14: 0 | CU14: 0 | CV14: 57.31451 | CW14: 374.48993 | CX14: 662.96906 | CY14: 1130.0803 | CZ14: 1958.9362 | DA14: 2876.6971 | DB14: 3716.9758
A16: YEAR-OVER-YEAR CHANGE
A17: ML-007C-MA - Schizophrenia | CC17: NM | CD17: NM | CE17: NM | CF17: NM | CG17: NM | CH17: NM | CI17: NM | CJ17: NM | CK17: NM | CL17: NM | CM17: NM | CN17: NM | CO17: NM | CP17: NM | CQ17: NM | CR17: NM | CS17: NM | CT17: NM | CU17: NM | CV17: NM | CW17: 3.223 | CX17: 0.583625 | CY17: 0.40766667 | CZ17: 0.3196875 | DA17: 0.2669 | DB17: 0.23170833
A18: ML-007C-MA - ADP | CC18: NM | CD18: NM | CE18: NM | CF18: NM | CG18: NM | CH18: NM | CI18: NM | CJ18: NM | CK18: NM | CL18: NM | CM18: NM | CN18: NM | CO18: NM | CP18: NM | CQ18: NM | CR18: NM | CS18: NM | CT18: NM | CU18: NM | CV18: NM | CW18: NM | CX18: 1.1115 | CY18: 1.1115 | CZ18: 1.1115 | DA18: 0.583625 | DB18: 0.3196875
A19: ML-004 - ASD
A20: Total Product Revenue | CC20: NM | CD20: NM | CE20: NM | CF20: NM | CG20: NM | CH20: NM | CI20: NM | CJ20: NM | CK20: NM | CL20: NM | CM20: NM | CN20: NM | CO20: NM | CP20: NM | CQ20: NM | CR20: NM | CS20: NM | CT20: NM | CU20: NM | CV20: NM | CW20: 5.5339463 | CX20: 0.77032546 | CY20: 0.7045748 | CZ20: 0.73344858 | DA20: 0.46849964 | DB20: 0.29209843
A21: Collaboration revenue | CC21: 0 | CD21: 0 | CE21: 0 | CF21: 0 | CG21: 0 | CH21: 0 | CI21: 0 | CJ21: 0 | CK21: 0 | CL21: 0 | CM21: 0 | CN21: NM | CO21: NM | CP21: NM | CQ21: NM | CR21: NM | CS21: 0 | CT21: 0 | CU21: 0 | CV21: 0 | CW21: 0 | CX21: 0 | CY21: 0 | CZ21: 0 | DA21: 0 | DB21: 0
A22: Other | CC22: 0 | CD22: NM | CE22: NM | CF22: NM | CG22: NM | CH22: 0 | CI22: NM | CJ22: NM | CK22: NM | CL22: NM | CM22: 0 | CN22: NM | CO22: NM | CP22: NM | CQ22: NM | CR22: NM | CS22: 0 | CT22: 0 | CU22: 0 | CV22: 0 | CW22: 0 | CX22: 0 | CY22: 0 | CZ22: 0 | DA22: 0 | DB22: 0
A23: Total Revenue | CC23: 0 | CD23: 0 | CE23: 0 | CF23: 0 | CG23: 0 | CH23: 0 | CI23: 0 | CJ23: 0 | CK23: 0 | CL23: 0 | CM23: 0 | CN23: NM | CO23: NM | CP23: NM | CQ23: NM | CR23: NM | CS23: 0 | CT23: 0 | CU23: 0 | CV23: 0 | CW23: 5.5339463 | CX23: 0.77032546 | CY23: 0.7045748 | CZ23: 0.73344858 | DA23: 0.46849964 | DB23: 0.29209843
A25: % OF TOTAL REVENUE
A26: ML-007C-MA - Schizophrenia | CC26: NM | CD26: NM | CE26: NM | CF26: NM | CG26: NM | CH26: NM | CI26: NM | CJ26: NM | CK26: NM | CL26: NM | CM26: NM | CN26: NM | CO26: NM | CP26: NM | CQ26: NM | CR26: NM | CS26: NM | CT26: NM | CU26: NM | CV26: 1 | CW26: 0.64631692 | CX26: 0.57815563 | CY26: 0.47745068 | CZ26: 0.36348681 | DA26: 0.31358635 | DB26: 0.29892995
A27: ML-007C-MA - ADP | CC27: NM | CD27: NM | CE27: NM | CF27: NM | CG27: NM | CH27: NM | CI27: NM | CJ27: NM | CK27: NM | CL27: NM | CM27: NM | CN27: NM | CO27: NM | CP27: NM | CQ27: NM | CR27: NM | CS27: NM | CT27: NM | CU27: NM | CV27: 0 | CW27: 0.35368308 | CX27: 0.42184437 | CY27: 0.52254932 | CZ27: 0.63651319 | DA27: 0.68641365 | DB27: 0.70107005
A28: ML-004 - ASD
A29: Total Product Revenue | CC29: NM | CD29: NM | CE29: NM | CF29: NM | CG29: NM | CH29: NM | CI29: NM | CJ29: NM | CK29: NM | CL29: NM | CM29: NM | CN29: NM | CO29: NM | CP29: NM | CQ29: NM | CR29: NM | CS29: NM | CT29: NM | CU29: NM | CV29: 1 | CW29: 1 | CX29: 1 | CY29: 1 | CZ29: 1 | DA29: 1 | DB29: 1
A30: Collaboration revenue | CC30: NM | CD30: NM | CE30: NM | CF30: NM | CG30: NM | CH30: NM | CI30: NM | CJ30: NM | CK30: NM | CL30: NM | CM30: NM | CN30: NM | CO30: NM | CP30: NM | CQ30: NM | CR30: NM | CS30: NM | CT30: NM | CU30: NM | CV30: 0 | CW30: 0 | CX30: 0 | CY30: 0 | CZ30: 0 | DA30: 0 | DB30: 0
A31: Other | CC31: NM | CD31: NM | CE31: NM | CF31: NM | CG31: NM | CH31: NM | CI31: NM | CJ31: NM | CK31: NM | CL31: NM | CM31: NM | CN31: NM | CO31: NM | CP31: NM | CQ31: NM | CR31: NM | CS31: NM | CT31: NM | CU31: NM | CV31: 0 | CW31: 0 | CX31: 0 | CY31: 0 | CZ31: 0 | DA31: 0 | DB31: 0
A32: Total Revenue | CC32: NM | CD32: NM | CE32: NM | CF32: NM | CG32: NM | CH32: NM | CI32: NM | CJ32: NM | CK32: NM | CL32: NM | CM32: NM | CN32: NM | CO32: NM | CP32: NM | CQ32: NM | CR32: NM | CS32: NM | CT32: NM | CU32: NM | CV32: 1 | CW32: 1 | CX32: 1 | CY32: 1 | CZ32: 1 | DA32: 1 | DB32: 1
A34: GROSS PROFIT
A35: ML-007C-MA - Schizophrenia | CC35: 0 | CD35: 0 | CE35: 0 | CF35: 0 | CG35: 0 | CH35: 0 | CI35: 0 | CJ35: 0 | CK35: 0 | CL35: 0 | CM35: 0 | CN35: 0 | CO35: 0 | CP35: 0 | CQ35: 0 | CR35: 0 | CS35: 0 | CT35: 0 | CU35: 0 | CV35: 53.87564 | CW35: 227.51683 | CX35: 360.30133 | CY35: 507.18418 | CZ35: 669.32462 | DA35: 847.96736 | DB35: 1044.4485
A36: ML-007C-MA - ADP | CC36: 0 | CD36: 0 | CE36: 0 | CF36: 0 | CG36: 0 | CH36: 0 | CI36: 0 | CJ36: 0 | CK36: 0 | CL36: 0 | CM36: 0 | CN36: 0 | CO36: 0 | CP36: 0 | CQ36: 0 | CR36: 0 | CS36: 0 | CT36: 0 | CU36: 0 | CV36: 0 | CW36: 124.50371 | CX36: 262.88958 | CY36: 555.09135 | CZ36: 1172.0754 | DA36: 1856.1279 | DB36: 2449.5088
A37: ML-004 - ASD
A38: Total Product Revenue | CC38: 0 | CD38: 0 | CE38: 0 | CF38: 0 | CG38: 0 | CH38: 0 | CI38: 0 | CJ38: 0 | CK38: 0 | CL38: 0 | CM38: 0 | CN38: 0 | CO38: 0 | CP38: 0 | CQ38: 0 | CR38: 0 | CS38: 0 | CT38: 0 | CU38: 0 | CV38: 53.87564 | CW38: 352.02053 | CX38: 623.19091 | CY38: 1062.2755 | CZ38: 1841.4 | DA38: 2704.0952 | DB38: 3493.9572
A39: Collaboration revenue | CC39: 0 | CD39: 0 | CE39: 0 | CF39: 0 | CG39: 0 | CH39: 0 | CI39: 0 | CJ39: 0 | CK39: 0 | CL39: 0 | CM39: 0 | CN39: 0 | CO39: 0 | CP39: 0 | CQ39: 0 | CR39: 0 | CS39: 0 | CT39: 0 | CU39: 0 | CV39: 0 | CW39: 0 | CX39: 0 | CY39: 0 | CZ39: 0 | DA39: 0 | DB39: 0
A40: Other | CC40: 0 | CD40: 0 | CE40: 0 | CF40: 0 | CG40: 0 | CH40: 0 | CI40: 0 | CJ40: 0 | CK40: 0 | CL40: 0 | CM40: 0 | CN40: 0 | CO40: 0 | CP40: 0 | CQ40: 0 | CR40: 0 | CS40: 0 | CT40: 0 | CU40: 0 | CV40: 0 | CW40: 0 | CX40: 0 | CY40: 0 | CZ40: 0 | DA40: 0 | DB40: 0
A41: Total Revenue | CC41: 0 | CD41: 0 | CE41: 0 | CF41: 0 | CG41: 0 | CH41: 0 | CI41: 0 | CJ41: 0 | CK41: 0 | CL41: 0 | CM41: 0 | CN41: 0 | CO41: 0 | CP41: 0 | CQ41: 0 | CR41: 0 | CS41: 0 | CT41: 0 | CU41: 0 | CV41: 53.87564 | CW41: 352.02053 | CX41: 623.19091 | CY41: 1062.2755 | CZ41: 1841.4 | DA41: 2704.0952 | DB41: 3493.9572
A43: GROSS MARGIN
A44: ML-007C-MA - Schizophrenia | CC44: 0 | CD44: 0 | CE44: 0 | CF44: 0 | CG44: 0 | CH44: 0 | CI44: 0 | CJ44: 0 | CK44: 0 | CL44: 0 | CM44: 0 | CN44: 0 | CO44: 0 | CP44: 0 | CQ44: 0 | CR44: 0 | CS44: 0 | CT44: 0 | CU44: 0 | CV44: 0.94 | CW44: 0.94 | CX44: 0.94 | CY44: 0.94 | CZ44: 0.94 | DA44: 0.94 | DB44: 0.94
A45: ML-007C-MA - ADP | CC45: 0 | CD45: 0 | CE45: 0 | CF45: 0 | CG45: 0 | CH45: 0 | CI45: 0 | CJ45: 0 | CK45: 0 | CL45: 0 | CM45: 0 | CN45: 0 | CO45: 0 | CP45: 0 | CQ45: 0 | CR45: 0 | CS45: 0 | CT45: 0 | CU45: 0 | CV45: 0 | CW45: 0.94 | CX45: 0.94 | CY45: 0.94 | CZ45: 0.94 | DA45: 0.94 | DB45: 0.94
A46: ML-004 - ASD
A47: Total Product Revenue | CC47: 0 | CD47: 0 | CE47: 0 | CF47: 0 | CG47: 0 | CH47: 0 | CI47: 0 | CJ47: 0 | CK47: 0 | CL47: 0 | CM47: 0 | CN47: 0 | CO47: 0 | CP47: 0 | CQ47: 0 | CR47: 0 | CS47: 0 | CT47: 0 | CU47: 0 | CV47: 0.94 | CW47: 0.94 | CX47: 0.94 | CY47: 0.94 | CZ47: 0.94 | DA47: 0.94 | DB47: 0.94
A48: Collaboration revenue | CC48: 0 | CD48: 0 | CE48: 0 | CF48: 0 | CG48: 0 | CH48: 0 | CI48: 0 | CJ48: 0 | CK48: 0 | CL48: 0 | CM48: 0 | CN48: 0 | CO48: 0 | CP48: 0 | CQ48: 0 | CR48: 0 | CS48: 0 | CT48: 0 | CU48: 0 | CV48: 0 | CW48: 0 | CX48: 0 | CY48: 0 | CZ48: 0 | DA48: 0 | DB48: 0
A49: Other | CC49: 0 | CD49: 0 | CE49: 0 | CF49: 0 | CG49: 0 | CH49: 0 | CI49: 0 | CJ49: 0 | CK49: 0 | CL49: 0 | CM49: 0 | CN49: 0 | CO49: 0 | CP49: 0 | CQ49: 0 | CR49: 0 | CS49: 0 | CT49: 0 | CU49: 0 | CV49: 0 | CW49: 0 | CX49: 0 | CY49: 0 | CZ49: 0 | DA49: 0 | DB49: 0
...

Sheet YR-REV
A4: MPLT Annual Revenue and Gross Profit Model
A6: ($mn) [FY - DEC] | B6: 2008A | C6: 2009A | D6: 2010A | E6: 2011A | F6: 2012A | G6: 2013A | H6: 2014A | I6: 2015A | J6: 2016A | K6: 2017A | L6: 2018A | M6: 2019A | N6: 2020A | O6: 2021A | P6: 2022A | Q6: 2023A | R6: 2024A | S6: 2025A | T6: 2026E | U6: 2027E | V6: 2028E | W6: 2029E | X6: 2030E | Y6: 2031E | Z6: 2032E | AA6: 2033E | AB6: 2034E | AC6: 2035E | AD6: 2036E
A8: ML-007C-MA - Schizophrenia | H8: 0 | I8: 0 | J8: 0 | K8: 0 | L8: 0 | M8: 0 | N8: 0 | O8: 0 | P8: 0 | Q8: 0 | R8: 0 | S8: 0 | T8: 0 | U8: 0 | V8: 0 | W8: 0 | X8: 57.31451 | Y8: 242.03918 | Z8: 383.29929 | AA8: 539.55764 | AB8: 712.04747 | AC8: 902.09294 | AD8: 1111.1154
A9: ML-007C-MA - ADP | H9: 0 | I9: 0 | J9: 0 | K9: 0 | L9: 0 | M9: 0 | N9: 0 | O9: 0 | P9: 0 | Q9: 0 | R9: 0 | S9: 0 | T9: 0 | U9: 0 | V9: 0 | W9: 0 | X9: 0 | Y9: 132.45075 | Z9: 279.66977 | AA9: 590.52271 | AB9: 1246.8887 | AC9: 1974.6041 | AD9: 2605.8604
A10: ML-004 - ASD | H10: 0 | I10: 0 | J10: 0 | K10: 0 | L10: 0 | M10: 0 | N10: 0 | O10: 0 | P10: 0
A11: Total Product Revenue | H11: 0 | I11: 0 | J11: 0 | K11: 0 | L11: 0 | M11: 0 | N11: 0 | O11: 0 | P11: 0 | Q11: 0 | R11: 0 | S11: 0 | T11: 0 | U11: 0 | V11: 0 | W11: 0 | X11: 57.31451 | Y11: 374.48993 | Z11: 662.96906 | AA11: 1130.0803 | AB11: 1958.9362 | AC11: 2876.6971 | AD11: 3716.9758
A12: Collaboration revenue | H12: 0 | I12: 0 | J12: 0 | K12: 0 | L12: 0 | M12: 0 | N12: 0 | O12: 0 | P12: 0 | Q12: 0 | R12: 0 | S12: 0 | T12: 0 | U12: 0 | V12: 0 | W12: 0 | X12: 0 | Y12: 0 | Z12: 0 | AA12: 0 | AB12: 0 | AC12: 0 | AD12: 0
A13: Other | H13: 0 | I13: 0 | J13: 0 | K13: 0 | L13: 0 | M13: 0 | N13: 0 | O13: 0 | P13: 0 | Q13: 0 | R13: 0 | S13: 0 | T13: 0 | U13: 0 | V13: 0 | W13: 0 | X13: 0 | Y13: 0 | Z13: 0 | AA13: 0 | AB13: 0 | AC13: 0 | AD13: 0
A14: Total Revenue | H14: 0 | I14: 0 | J14: 0 | K14: 0 | L14: 0 | M14: 0 | N14: 0 | O14: 0 | P14: 0 | Q14: 0 | R14: 0 | S14: 0 | T14: 0 | U14: 0 | V14: 0 | W14: 0 | X14: 57.31451 | Y14: 374.48993 | Z14: 662.96906 | AA14: 1130.0803 | AB14: 1958.9362 | AC14: 2876.6971 | AD14: 3716.9758
A16: YEAR-OVER-YEAR CHANGE
A17: ML-007C-MA - Schizophrenia | H17: 0 | I17: 0 | J17: 0 | K17: 0 | L17: 0 | M17: 0 | N17: 0 | O17: 0 | P17: 0 | Q17: NM | R17: NM | S17: NM | T17: NM | U17: NM | V17: NM | W17: NM | X17: NM | Y17: 3.223 | Z17: 0.583625 | AA17: 0.40766667 | AB17: 0.3196875 | AC17: 0.2669 | AD17: 0.23170833
A18: ML-007C-MA - ADP | H18: 0 | I18: 0 | J18: 0 | K18: 0 | L18: 0 | M18: 0 | N18: 0 | O18: 0 | P18: 0 | Q18: NM | R18: NM | S18: NM | T18: NM | U18: NM | V18: NM | W18: NM | X18: NM | Y18: NM | Z18: 1.1115 | AA18: 1.1115 | AB18: 1.1115 | AC18: 0.583625 | AD18: 0.3196875
A19: ML-004 - ASD | H19: 0 | I19: 0 | J19: 0 | K19: 0 | L19: 0 | M19: 0 | N19: 0 | O19: 0 | P19: 0
A20: Total Product Revenue | H20: 0 | I20: 0 | J20: 0 | K20: 0 | L20: 0 | M20: 0 | N20: 0 | O20: 0 | P20: 0 | Q20: NM | R20: NM | S20: NM | T20: NM | U20: NM | V20: NM | W20: NM | X20: NM | Y20: 5.5339463 | Z20: 0.77032546 | AA20: 0.7045748 | AB20: 0.73344858 | AC20: 0.46849964 | AD20: 0.29209843
A21: Collaboration revenue | H21: 0 | I21: 0 | J21: 0 | K21: 0 | L21: 0 | M21: 0 | N21: 0 | O21: 0 | P21: 0 | Q21: 0 | R21: 0 | S21: 0 | T21: NM | U21: 0 | V21: 0 | W21: 0 | X21: 0 | Y21: 0 | Z21: 0 | AA21: 0 | AB21: 0 | AC21: 0 | AD21: 0
A22: Other | H22: 0 | I22: 0 | J22: 0 | K22: 0 | L22: 0 | M22: 0 | N22: 0 | O22: 0 | P22: 0 | Q22: 0 | R22: 0 | S22: 0 | T22: NM | U22: 0 | V22: 0 | W22: 0 | X22: 0 | Y22: 0 | Z22: 0 | AA22: 0 | AB22: 0 | AC22: 0 | AD22: 0
A23: Total Revenue | H23: 0 | I23: 0 | J23: 0 | K23: 0 | L23: 0 | M23: 0 | N23: 0 | O23: 0 | P23: 0 | Q23: 0 | R23: 0 | S23: 0 | T23: NM | U23: 0 | V23: 0 | W23: 0 | X23: 0 | Y23: 5.5339463 | Z23: 0.77032546 | AA23: 0.7045748 | AB23: 0.73344858 | AC23: 0.46849964 | AD23: 0.29209843
A25: % OF TOTAL REVENUE
A26: ML-007C-MA - Schizophrenia | H26: 0 | I26: 0 | J26: 0 | K26: 0 | L26: 0 | M26: 0 | N26: 0 | O26: 0 | P26: 0 | Q26: NM | R26: NM | S26: NM | T26: NM | U26: NM | V26: NM | W26: NM | X26: 1 | Y26: 0.64631692 | Z26: 0.57815563 | AA26: 0.47745068 | AB26: 0.36348681 | AC26: 0.31358635 | AD26: 0.29892995
A27: ML-007C-MA - ADP | H27: 0 | I27: 0 | J27: 0 | K27: 0 | L27: 0 | M27: 0 | N27: 0 | O27: 0 | P27: 0 | Q27: NM | R27: NM | S27: NM | T27: NM | U27: NM | V27: NM | W27: NM | X27: 0 | Y27: 0.35368308 | Z27: 0.42184437 | AA27: 0.52254932 | AB27: 0.63651319 | AC27: 0.68641365 | AD27: 0.70107005
A28: ML-004 - ASD | H28: 0 | I28: 0 | J28: 0 | K28: 0 | L28: 0 | M28: 0 | N28: 0 | O28: 0 | P28: 0
A29: Total Product Revenue | H29: 0 | I29: 0 | J29: 0 | K29: 0 | L29: 0 | M29: 0 | N29: 0 | O29: 0 | P29: 0 | Q29: NM | R29: NM | S29: NM | T29: NM | U29: NM | V29: NM | W29: NM | X29: 1 | Y29: 1 | Z29: 1 | AA29: 1 | AB29: 1 | AC29: 1 | AD29: 1
A30: Collaboration revenue | H30: 0 | I30: 0 | J30: 0 | K30: 0 | L30: 0 | M30: 0 | N30: 0 | O30: 0 | P30: 0 | Q30: NM | R30: NM | S30: NM | T30: NM | U30: NM | V30: NM | W30: NM | X30: 0 | Y30: 0 | Z30: 0 | AA30: 0 | AB30: 0 | AC30: 0 | AD30: 0
A31: Other | H31: 0 | I31: 0 | J31: 0 | K31: 0 | L31: 0 | M31: 0 | N31: 0 | O31: 0 | P31: 0 | Q31: NM | R31: NM | S31: NM | T31: NM | U31: NM | V31: NM | W31: NM | X31: 0 | Y31: 0 | Z31: 0 | AA31: 0 | AB31: 0 | AC31: 0 | AD31: 0
A32: Total Revenue | H32: 0 | I32: 0 | J32: 0 | K32: 0 | L32: 0 | M32: 0 | N32: 0 | O32: 0 | P32: 0 | Q32: NM | R32: NM | S32: NM | T32: NM | U32: NM | V32: NM | W32: NM | X32: 1 | Y32: 1 | Z32: 1 | AA32: 1 | AB32: 1 | AC32: 1 | AD32: 1
A34: GROSS PROFIT
A35: ML-007C-MA - Schizophrenia | H35: 0 | I35: 0 | J35: 0 | K35: 0 | L35: 0 | M35: 0 | N35: 0 | O35: 0 | P35: 0 | Q35: 0 | R35: 0 | S35: 0 | T35: 0 | U35: 0 | V35: 0 | W35: 0 | X35: 53.87564 | Y35: 227.51683 | Z35: 360.30133 | AA35: 507.18418 | AB35: 669.32462 | AC35: 847.96736 | AD35: 1044.4485
A36: ML-007C-MA - ADP | H36: 0 | I36: 0 | J36: 0 | K36: 0 | L36: 0 | M36: 0 | N36: 0 | O36: 0 | P36: 0 | Q36: 0 | R36: 0 | S36: 0 | T36: 0 | U36: 0 | V36: 0 | W36: 0 | X36: 0 | Y36: 124.50371 | Z36: 262.88958 | AA36: 555.09135 | AB36: 1172.0754 | AC36: 1856.1279 | AD36: 2449.5088
A37: ML-004 - ASD | H37: 0 | I37: 0 | J37: 0 | K37: 0 | L37: 0 | M37: 0 | N37: 0 | O37: 0 | P37: 0
A38: Total Product Revenue | H38: 0 | I38: 0 | J38: 0 | K38: 0 | L38: 0 | M38: 0 | N38: 0 | O38: 0 | P38: 0 | Q38: 0 | R38: 0 | S38: 0 | T38: 0 | U38: 0 | V38: 0 | W38: 0 | X38: 53.87564 | Y38: 352.02053 | Z38: 623.19091 | AA38: 1062.2755 | AB38: 1841.4 | AC38: 2704.0952 | AD38: 3493.9572
A39: Collaboration revenue | H39: 0 | I39: 0 | J39: 0 | K39: 0 | L39: 0 | M39: 0 | N39: 0 | O39: 0 | P39: 0 | Q39: 0 | R39: 0 | S39: 0 | T39: 0 | U39: 0 | V39: 0 | W39: 0 | X39: 0 | Y39: 0 | Z39: 0 | AA39: 0 | AB39: 0 | AC39: 0 | AD39: 0
A40: Other | H40: 0 | I40: 0 | J40: 0 | K40: 0 | L40: 0 | M40: 0 | N40: 0 | O40: 0 | P40: 0 | Q40: 0 | R40: 0 | S40: 0 | T40: 0 | U40: 0 | V40: 0 | W40: 0 | X40: 0 | Y40: 0 | Z40: 0 | AA40: 0 | AB40: 0 | AC40: 0 | AD40: 0
A41: Total Revenue | H41: 0 | I41: 0 | J41: 0 | K41: 0 | L41: 0 | M41: 0 | N41: 0 | O41: 0 | P41: 0 | Q41: 0 | R41: 0 | S41: 0 | T41: 0 | U41: 0 | V41: 0 | W41: 0 | X41: 53.87564 | Y41: 352.02053 | Z41: 623.19091 | AA41: 1062.2755 | AB41: 1841.4 | AC41: 2704.0952 | AD41: 3493.9572
A43: GROSS MARGIN
A44: ML-007C-MA - Schizophrenia | H44: 0 | I44: 0 | J44: 0 | K44: 0 | L44: 0 | M44: 0 | N44: 0 | O44: 0 | P44: 0 | Q44: 0 | R44: 0 | S44: 0 | T44: 0 | U44: 0 | V44: 0 | W44: 0 | X44: 0.94 | Y44: 0.94 | Z44: 0.94 | AA44: 0.94 | AB44: 0.94 | AC44: 0.94 | AD44: 0.94
A45: ML-007C-MA - ADP | H45: 0 | I45: 0 | J45: 0 | K45: 0 | L45: 0 | M45: 0 | N45: 0 | O45: 0 | P45: 0 | Q45: 0 | R45: 0 | S45: 0 | T45: 0 | U45: 0 | V45: 0 | W45: 0 | X45: 0 | Y45: 0.94 | Z45: 0.94 | AA45: 0.94 | AB45: 0.94 | AC45: 0.94 | AD45: 0.94
A46: ML-004 - ASD | H46: 0 | I46: 0 | J46: 0 | K46: 0 | L46: 0 | M46: 0 | N46: 0 | O46: 0 | P46: 0
A47: Total Product Revenue | H47: 0 | I47: 0 | J47: 0 | K47: 0 | L47: 0 | M47: 0 | N47: 0 | O47: 0 | P47: 0 | Q47: 0 | R47: 0 | S47: 0 | T47: 0 | U47: 0 | V47: 0 | W47: 0 | X47: 0.94 | Y47: 0.94 | Z47: 0.94 | AA47: 0.94 | AB47: 0.94 | AC47: 0.94 | AD47: 0.94
A48: Collaboration revenue | H48: 0 | I48: 0 | J48: 0 | K48: 0 | L48: 0 | M48: 0 | N48: 0 | O48: 0 | P48: 0 | Q48: 0 | R48: 0 | S48: 0 | T48: 0 | U48: 0 | V48: 0 | W48: 0 | X48: 0 | Y48: 0 | Z48: 0 | AA48: 0 | AB48: 0 | AC48: 0 | AD48: 0
A49: Other | H49: 0 | I49: 0 | J49: 0 | K49: 0 | L49: 0 | M49: 0 | N49: 0 | O49: 0 | P49: 0 | Q49: 0 | R49: 0 | S49: 0 | T49: 0 | U49: 0 | V49: 0 | W49: 0 | X49: 0 | Y49: 0 | Z49: 0 | AA49: 0 | AB49: 0 | AC49: 0 | AD49: 0
...

Sheet Schizophrenia
A4: ML-007C-MA Schizophrenia revenue model
A6: ($mn, except patient numbers) [FY - DEC] | B6: 2017A | C6: Mar-18A | D6: Jun-18A | E6: Sep-18A | F6: Dec-18A | G6: 2018A | H6: Mar-19A | I6: Jun-19A | J6: Sep-19A | K6: Dec-19A | L6: 2019A | M6: Mar-20A | N6: Jun-20A | O6: Sep-20A | P6: Dec-20A | Q6: 2020A | R6: Mar-21A | S6: Jun-21A | T6: Sep-21A | U6: Dec-21A | V6: 2021A | W6: Mar-22A | X6: Jun-22A | Y6: Sep-22A | Z6: Dec-22A | AA6: 2022A | AB6: Mar-23A | AC6: Jun-23A | AD6: Sep-23A | AE6: Dec-23A | AF6: 2023A | AG6: Mar-24A | AH6: Jun-24A | AI6: Sep-24A | AJ6: Dec-24A | AK6: 2024A | AL6: Mar-25A | AM6: Jun-25A | AN6: Sep-25A | AO6: Dec-25A | AP6: 2025A | AQ6: Mar-26E | AR6: Jun-26E | AS6: Sep-26E | AT6: Dec-26E | AU6: 2026E | AV6: 2027E | AW6: 2028E | AX6: 2029E | AY6: 2030E | AZ6: 2031E | BA6: 2032E | BB6: 2033E | BC6: 2034E | BD6: 2035E | BE6: 2036E
A7: US Market (patients in '000)
A9: Prevalence | AK9: 3000 | AL9: 3090 | AM9: 3090 | AN9: 3090 | AO9: 3090 | AP9: 3090 | AQ9: 3182.7 | AR9: 3182.7 | AS9: 3182.7 | AT9: 3182.7 | AU9: 3182.7 | AV9: 3278.181 | AW9: 3376.5264 | AX9: 3477.8222 | AY9: 3582.1569 | AZ9: 3689.6216 | BA9: 3800.3102 | BB9: 3914.3196 | BC9: 4031.7491 | BD9: 4152.7016 | BE9: 4277.2827
A10: % growth | AK10: 0.03 | AP10: 0.03 | AU10: 0.03 | AV10: 0.03 | AW10: 0.03 | AX10: 0.03 | AY10: 0.03 | AZ10: 0.03 | BA10: 0.03 | BB10: 0.03 | BC10: 0.03 | BD10: 0.03 | BE10: 0.03
A12: Patients receiving Rx treatment | AK12: 2400 | AL12: 2472 | AM12: 2472 | AN12: 2472 | AO12: 2472 | AP12: 2472 | AQ12: 2546.16 | AR12: 2546.16 | AS12: 2546.16 | AT12: 2546.16 | AU12: 2546.16 | AV12: 2622.5448 | AW12: 2701.2211 | AX12: 2782.2578 | AY12: 2865.7255 | AZ12: 2951.6973 | BA12: 3040.2482 | BB12: 3131.4556 | BC12: 3225.3993 | BD12: 3322.1613 | BE12: 3421.8261
A13: % receiving Rx treatment | AK13: 0.8 | AL13: 0.8 | AM13: 0.8 | AN13: 0.8 | AO13: 0.8 | AP13: 0.8 | AQ13: 0.8 | AR13: 0.8 | AS13: 0.8 | AT13: 0.8 | AU13: 0.8 | AV13: 0.8 | AW13: 0.8 | AX13: 0.8 | AY13: 0.8 | AZ13: 0.8 | BA13: 0.8 | BB13: 0.8 | BC13: 0.8 | BD13: 0.8 | BE13: 0.8
A15: Annual treatment fraction % | AK15: 0.5 | AL15: 0.5 | AM15: 0.5 | AN15: 0.5 | AO15: 0.5 | AP15: 0.5 | AQ15: 0.5 | AR15: 0.5 | AS15: 0.5 | AT15: 0.5 | AU15: 0.5 | AV15: 0.5 | AW15: 0.5 | AX15: 0.5 | AY15: 0.5 | AZ15: 0.5 | BA15: 0.5 | BB15: 0.5 | BC15: 0.5 | BD15: 0.5 | BE15: 0.5
A17: Patients treated with ML-007C-MA | AY17: 3.5821569 | AZ17: 14.758486 | BA17: 22.801861 | BB17: 31.314556 | BC17: 40.317491 | BD17: 49.832419 | BE17: 59.881957
A18: % of patients receiving treatment | AY18: 0.0025 | AZ18: 0.01 | BA18: 0.015 | BB18: 0.02 | BC18: 0.025 | BD18: 0.03 | BE18: 0.035
A20: Annual cost of therapy | AY20: 16000 | AZ20: 16400 | BA20: 16810 | BB20: 17230.25 | BC20: 17661.006 | BD20: 18102.531 | BE20: 18555.095
A21: % growth | AZ21: 0.025 | BA21: 0.025 | BB21: 0.025 | BC21: 0.025 | BD21: 0.025 | BE21: 0.025
A23: Sales of ML-007C-MA in schizophrenia | AY23: 57.31451 | AZ23: 242.03918 | BA23: 383.29929 | BB23: 539.55764 | BC23: 712.04747 | BD23: 902.09294 | BE23: 1111.1154
A24: % growth | AZ24: 3.223 | BA24: 0.583625 | BB24: 0.40766667 | BC24: 0.3196875 | BD24: 0.2669 | BE24: 0.23170833
A28: Source: Company Reports and Canaccord Genuity

Sheet ADP
A4: ML-007C-MA Alzheimer's disease psychosis (ADP) revenue model
A6: ($mn, except patient numbers) [FY - DEC] | B6: 2017A | C6: Mar-18A | D6: Jun-18A | E6: Sep-18A | F6: Dec-18A | G6: 2018A | H6: Mar-19A | I6: Jun-19A | J6: Sep-19A | K6: Dec-19A | L6: 2019A | M6: Mar-20A | N6: Jun-20A | O6: Sep-20A | P6: Dec-20A | Q6: 2020A | R6: Mar-21A | S6: Jun-21A | T6: Sep-21A | U6: Dec-21A | V6: 2021A | W6: Mar-22A | X6: Jun-22A | Y6: Sep-22A | Z6: Dec-22A | AA6: 2022A | AB6: Mar-23A | AC6: Jun-23A | AD6: Sep-23A | AE6: Dec-23A | AF6: 2023A | AG6: Mar-24A | AH6: Jun-24A | AI6: Sep-24A | AJ6: Dec-24A | AK6: 2024A | AL6: Mar-25A | AM6: Jun-25A | AN6: Sep-25A | AO6: Dec-25A | AP6: 2025A | AQ6: Mar-26E | AR6: Jun-26E | AS6: Sep-26E | AT6: Dec-26E | AU6: 2026E | AV6: 2027E | AW6: 2028E | AX6: 2029E | AY6: 2030E | AZ6: 2031E | BA6: 2032E | BB6: 2033E | BC6: 2034E | BD6: 2035E | BE6: 2036E
