Workbook
Name \B: #REF!
Name \C: #REF!
Name \D: #REF!
Name \E: #REF!
Name \F: #REF!
Name \G: #REF!
Name \H: #REF!
Name \I: #REF!
Name \L: #REF!
Name \r: #REF!
Name \T: #REF!
Name ___PRT1: #REF!
Name ___PRT2: #REF!
Name ___PRT3: #REF!
Name ___PRT4: #REF!
Name ___PRT5: #REF!
Name ___PRT6: #REF!
Name ___PRT7: #REF!
Name ___PRT8: #REF!
Name ___PT5: #REF!
Name __FDS_UNIQUE_RANGE_ID_GENERATOR_COUNTER: 1
Name __PRT1: #REF!
Name __PRT2: #REF!
Name __PRT3: #REF!
Name __PRT4: #REF!
Name __PRT5: #REF!
Name __PRT6: #REF!
Name __PRT7: #REF!
Name __PRT8: #REF!
Name __PT5: #REF!
Name _1994: #REF!
Name _1995: #REF!
Name _1996: #REF!
Name _1997: #REF!
Name _1998: #REF!
Name _1999: #REF!
Name _1P: #REF!
Name _1Q94: #REF!
Name _1Q95: #REF!
Name _20_Jul_94: #REF!
Name _2Q94: #REF!
Name _2Q95: #REF!
Name _3Q94: #REF!
Name _3Q95: #REF!
Name _4Q94: #REF!
Name _4Q95: #REF!
Name _95: #REF!
Name _95: [1]quarterly!#REF!
Name _96: #REF!
Name _96: [1]quarterly!#REF!
Name _97: #REF!
Name _97: [1]quarterly!#REF!
Name _98: #REF!
Name _98: #REF!
Name _eps01: #REF!
Name _eps02: #REF!
Name _eps03: #REF!
Name _eps04: #REF!
Name _EPS2000: #REF!
Name _EPS93: #REF!

Sheet Disclosures
B5: Maplight Therapeutics (MPLT) Financial Model
B7: Joseph Thome, Ph.D.
B8: TD Cowen
B9: 1 Vanderbilt Avenue
B10: New York, NY 10017
B11: 646-562-1308 (office)
B12: 646-562-1314 (Fax)
B13: joseph.thome@tdsecurities.com
B15: Peyton Bohnsack, Ph.D.
B16: TD Cowen
B17: 1 Vanderbilt Avenue
B18: New York, NY 10017
... B26: ® The TD logo and other TD trademarks are the property of The Toronto-Dominion Bank or its subsidiaries

Sheet Quarterly
A1: Maplight Therapeutics Quarterly P&L ($MM)
B2: H1:25A | C2: Q3:25A | D2: Q4:25A | E2: 2025A | F2: Q1:26E | G2: Q2:26E | H2: Q3:26E | I2: Q4:26E | J2: 2026E | K2: 2027E | L2: 2028E | M2: 2029E | N2: 2030E | O2: 2031E
A3: ML-007C-MA Revenue | B3: 0 | C3: 0 | D3: 0 | E3: 0 | F3: 0 | G3: 0 | H3: 0 | I3: 0 | M3: =Schizophrenia!B50 -> 35.739 | N3: =Schizophrenia!C50 -> 174.69974 | O3: =Schizophrenia!D50 -> 390.21748
A4: Total Revenue | B4: =SUM(B3:B3) -> 0 | C4: =SUM(C3:C3) -> 0 | D4: =SUM(D3:D3) -> 0 | E4: =SUM(B4:D4) -> 0 | F4: =SUM(F3:F3) -> 0 | G4: =SUM(G3:G3) -> 0 | H4: =SUM(H3:H3) -> 0 | I4: =SUM(I3:I3) -> 0 | J4: =SUM(F4:I4) -> 0 | K4: =SUM(K3:K3) -> 0 | L4: =SUM(L3:L3) -> 0 | M4: =SUM(M3:M3) -> 35.739 | N4: =SUM(N3:N3) -> 174.69974 | O4: =SUM(O3:O3) -> 390.21748
A5: COGS | B5: 0 | C5: 0 | D5: 0 | E5: =SUM(B5:D5) -> 0 | F5: 0 | G5: 0 | H5: 0 | I5: 0 | J5: =SUM(F5:I5) -> 0 | K5: =K4*0.08 -> 0 | L5: =L4*0.08 -> 0 | M5: =M4*0.08 -> 2.85912 | N5: =N4*0.08 -> 13.975979 | O5: =O4*0.082 -> 31.997833
A6: Gross Margin
A7: R&D | B7: 46.633 | C7: 27.094 | D7: 64.623 | E7: =SUM(B7:D7) -> 138.35 | F7: 35 | G7: 37.5 | H7: 40 | I7: 40.5 | J7: =SUM(F7:I7) -> 153 | K7: 225 | L7: 250 | M7: 165 | N7: 125 | O7: 75
A8: R&D as % of Sales
A9: SG&A | B9: 7.573 | C9: 4.404 | D9: 18.755 | E9: =SUM(B9:D9) -> 30.732 | F9: 11 | G9: 11.5 | H9: 12 | I9: 12.5 | J9: =SUM(F9:I9) -> 47 | K9: 60 | L9: 65 | M9: 125 | N9: 250 | O9: 295
A10: SG&A as % of Sales
A11: Other | E11: =SUM(B11:D11) -> 0 | J11: =SUM(F11:I11) -> 0
A12: Operating Expenses | B12: =SUM(B5:B11) -> 54.206 | C12: =SUM(C5:C11) -> 31.498 | D12: =SUM(D5:D11) -> 83.378 | E12: =SUM(B12:D12) -> 169.082 | F12: =SUM(F5:F11) -> 46 | G12: =SUM(G5:G11) -> 49 | H12: =SUM(H5:H11) -> 52 | I12: =SUM(I5:I11) -> 53 | J12: =SUM(F12:I12) -> 200 | K12: =K5+K7+K9 -> 285 | L12: =L5+L7+L9 -> 315 | M12: =M5+M7+M9 -> 292.85912 | N12: =N5+N7+N9 -> 388.97598 | O12: =O5+O7+O9 -> 401.99783
A13: Other Income, net | B13: 0 | C13: 0 | D13: 0 | E13: =SUM(B13:D13) -> 0 | F13: 0 | G13: 0 | H13: 0 | I13: 0 | J13: =SUM(F13:I13) -> 0 | K13: 0
A14: Operating Income / (Loss) | B14: =B4-B12+B13 -> -54.206 | C14: =C4-C12+C13 -> -31.498 | D14: =D4-D12+D13 -> -83.378 | E14: =SUM(B14:D14) -> -169.082 | F14: =F4-F12+F13 -> -46 | G14: =G4-G12+G13 -> -49 | H14: =H4-H12+H13 -> -52 | I14: =I4-I12+I13 -> -53 | J14: =SUM(F14:I14) -> -200 | K14: =K4-K12 -> -285 | L14: =L4-L12 -> -315 | M14: =M4-M12 -> -257.12012 | N14: =N4-N12 -> -214.27624 | O14: =O4-O12 -> -11.780354
A15: Interest Income (Expense) | B15: 1.499 | C15: 1.549 | D15: 2.471 | E15: =SUM(B15:D15) -> 5.519 | F15: 0 | G15: 0 | H15: 0 | I15: 0 | J15: =SUM(F15:I15) -> 0 | K15: 0 | L15: 0 | M15: 0 | N15: 0 | O15: 0
A16: Other Non-Operating Income, net | B16: 0.522 | C16: 0.531 | D16: 1.359 | E16: =SUM(B16:D16) -> 2.412 | F16: 0 | G16: 0 | H16: 0 | I16: 0 | J16: =SUM(F16:I16) -> 0 | K16: 0 | L16: 0 | M16: 0 | N16: 0 | O16: 0
A17: Pretax net income | B17: =B14+B16+B15 -> -52.185 | C17: =C14+C16+C15 -> -29.418 | D17: =D14+D16+D15 -> -79.548 | E17: =SUM(B17:D17) -> -161.151 | F17: =F14+F16+F15 -> -46 | G17: =G14+G16+G15 -> -49 | H17: =H14+H16+H15 -> -52 | I17: =I14+I16+I15 -> -53 | J17: =SUM(F17:I17) -> -200 | K17: =K14+K16+K15 -> -285 | L17: =L14+L16+L15 -> -315 | M17: =M14+M16+M15 -> -257.12012 | N17: =N14+N16+N15 -> -214.27624 | O17: =O14+O16+O15 -> -11.780354
A18: Taxes | B18: 0 | C18: 0 | D18: 0 | E18: =SUM(B18:D18) -> 0 | F18: 0 | G18: 0 | H18: 0 | I18: 0 | J18: =SUM(F18:I18) -> 0 | K18: 0 | L18: 0 | M18: 0 | N18: 0 | O18: 0
A19: Tax Rate
A21: GAAP Net Income | B21: =B17-B18 -> -52.185 | C21: =C17-C18 -> -29.418 | D21: =D17-D18 -> -79.548 | E21: =SUM(B21:D21) -> -161.151 | F21: =F17-F18 -> -46 | G21: =G17-G18 -> -49 | H21: =H17-H18 -> -52 | I21: =I17-I18 -> -53 | J21: =SUM(F21:I21) -> -200 | K21: =K17-K18 -> -285 | L21: =L17-L18 -> -315 | M21: =M17-M18 -> -257.12012 | N21: =N17-N18 -> -214.27624 | O21: =O17-O18 -> -11.780354
A22: GAAP EPS | B22: =B21/B23 -> -68.455055 | C22: =C21/C23 -> -37.184927 | D22: =D21/D23 -> -2.4743556 | E22: =E21/E23 -> -18.564199 | F22: =F21/F23 -> -1.0839853 | G22: =G21/G23 -> -1.15468 | H22: =H21/H23 -> -1.1555556 | I22: =I21/I23 -> -1.1041667 | ... O22: =O21/O23 -> -0.19966702
A23: Diluted Shares Outstanding (MM) | B23: 0.762325 | C23: 0.791127 | D23: 32.148977 | E23: 8.680741 | F23: 42.436 | G23: 42.436 | H23: 45 | I23: 48 | J23: =AVERAGE(F23:I23) -> 44.468 | K23: 55.3 | L23: 57.75 | M23: 57.8 | N23: 58.7 | O23: 59
A25: cash and cash equivalents | D25: 453.096 | J25: =D25+J21+250 -> 503.096 | K25: =J25+K21+500 -> 718.096 | L25: =K25+L21 -> 403.096 | M25: =L25+M21 -> 145.97588 | N25: =M25+N21+150 -> 81.699644 | O25: =N25+O21 -> 69.91929
A26: Debt | D26: 0
A27: Net cash | D27: =D25-D26 -> 453.096
A29: Net cash/share

Sheet Annual
A1: Maplight Therapeutics Annual P&L ($MM)
B2: =Quarterly!E2 -> 2025A | C2: =Quarterly!J2 -> 2026E | D2: =Quarterly!K2 -> 2027E | E2: =Quarterly!L2 -> 2028E | F2: =Quarterly!M2 -> 2029E | G2: =Quarterly!N2 -> 2030E | H2: =Quarterly!O2 -> 2031E
A3: =Quarterly!A3 -> ML-007C-MA Revenue | B3: =Quarterly!E3 -> 0 | C3: =Quarterly!J3 -> 0 | D3: =Quarterly!K3 -> 0 | E3: =Quarterly!L3 -> 0 | F3: =Quarterly!M3 -> 35.739 | G3: =Quarterly!N3 -> 174.69974 | H3: =Quarterly!O3 -> 390.21748
A4: =Quarterly!A4 -> Total Revenue | B4: =Quarterly!E4 -> 0 | C4: =Quarterly!J4 -> 0 | D4: =Quarterly!K4 -> 0 | E4: =Quarterly!L4 -> 0 | F4: =Quarterly!M4 -> 35.739 | G4: =Quarterly!N4 -> 174.69974 | H4: =Quarterly!O4 -> 390.21748
A5: =Quarterly!A5 -> COGS | B5: =Quarterly!E5 -> 0 | C5: =Quarterly!J5 -> 0 | D5: =Quarterly!K5 -> 0 | E5: =Quarterly!L5 -> 0 | F5: =Quarterly!M5 -> 2.85912 | G5: =Quarterly!N5 -> 13.975979 | H5: =Quarterly!O5 -> 31.997833
A6: =Quarterly!A6 -> Gross Margin | B6: =Quarterly!E6 -> 0 | C6: =Quarterly!J6 -> 0 | D6: =Quarterly!K6 -> 0 | E6: =Quarterly!L6 -> 0 | F6: =Quarterly!M6 -> 0 | G6: =Quarterly!N6 -> 0 | H6: =Quarterly!O6 -> 0
A7: =Quarterly!A7 -> R&D | B7: =Quarterly!E7 -> 138.35 | C7: =Quarterly!J7 -> 153 | D7: =Quarterly!K7 -> 225 | E7: =Quarterly!L7 -> 250 | F7: =Quarterly!M7 -> 165 | G7: =Quarterly!N7 -> 125 | H7: =Quarterly!O7 -> 75
B8: =Quarterly!E8 -> 0 | C8: =Quarterly!J8 -> 0 | D8: =Quarterly!K8 -> 0 | E8: =Quarterly!L8 -> 0 | F8: =Quarterly!M8 -> 0 | G8: =Quarterly!N8 -> 0 | H8: =Quarterly!O8 -> 0
A9: =Quarterly!A9 -> SG&A | B9: =Quarterly!E9 -> 30.732 | C9: =Quarterly!J9 -> 47 | D9: =Quarterly!K9 -> 60 | E9: =Quarterly!L9 -> 65 | F9: =Quarterly!M9 -> 125 | G9: =Quarterly!N9 -> 250 | H9: =Quarterly!O9 -> 295
B10: =Quarterly!E10 -> 0 | C10: =Quarterly!J10 -> 0 | D10: =Quarterly!K10 -> 0 | E10: =Quarterly!L10 -> 0 | F10: =Quarterly!M10 -> 0 | G10: =Quarterly!N10 -> 0 | H10: =Quarterly!O10 -> 0
A11: =Quarterly!A12 -> Operating Expenses | B11: =Quarterly!E12 -> 169.082 | C11: =Quarterly!J12 -> 200 | D11: =Quarterly!K12 -> 285 | E11: =Quarterly!L12 -> 315 | F11: =Quarterly!M12 -> 292.85912 | G11: =Quarterly!N12 -> 388.97598 | H11: =Quarterly!O12 -> 401.99783
A12: =Quarterly!A13 -> Other Income, net | B12: =Quarterly!E13 -> 0 | C12: =Quarterly!J13 -> 0 | D12: =Quarterly!K13 -> 0 | E12: =Quarterly!L13 -> 0 | F12: =Quarterly!M13 -> 0 | G12: =Quarterly!N13 -> 0 | H12: =Quarterly!O13 -> 0
A13: =Quarterly!$A$14 -> Operating Income / (Loss) | B13: =Quarterly!E14 -> -169.082 | C13: =Quarterly!J14 -> -200 | D13: =Quarterly!K14 -> -285 | E13: =Quarterly!L14 -> -315 | F13: =Quarterly!M14 -> -257.12012 | G13: =Quarterly!N14 -> -214.27624 | H13: =Quarterly!O14 -> -11.780354
A14: =Quarterly!A16 -> Other Non-Operating Income, net | B14: =Quarterly!E16 -> 2.412 | C14: =Quarterly!J16 -> 0 | D14: =Quarterly!K16 -> 0 | E14: =Quarterly!L16 -> 0 | F14: =Quarterly!M16 -> 0 | G14: =Quarterly!N16 -> 0 | H14: =Quarterly!O16 -> 0
A15: =Quarterly!A17 -> Pretax net income | B15: =Quarterly!E17 -> -161.151 | C15: =Quarterly!J17 -> -200 | D15: =Quarterly!K17 -> -285 | E15: =Quarterly!L17 -> -315 | F15: =Quarterly!M17 -> -257.12012 | G15: =Quarterly!N17 -> -214.27624 | H15: =Quarterly!O17 -> -11.780354
A16: =Quarterly!A18 -> Taxes | B16: =Quarterly!E18 -> 0 | C16: =Quarterly!J18 -> 0 | D16: =Quarterly!K18 -> 0 | E16: =Quarterly!L18 -> 0 | F16: =Quarterly!M18 -> 0 | G16: =Quarterly!N18 -> 0 | H16: =Quarterly!O18 -> 0
A17: =Quarterly!A19 -> Tax Rate | B17: =Quarterly!E19 -> 0 | C17: =Quarterly!J19 -> 0 | D17: =Quarterly!K19 -> 0 | E17: =Quarterly!L19 -> 0 | F17: =Quarterly!M19 -> 0 | G17: =Quarterly!N19 -> 0 | H17: =Quarterly!O19 -> 0
A18: =Quarterly!A21 -> GAAP Net Income | B18: =Quarterly!E21 -> -161.151 | C18: =Quarterly!J21 -> -200 | D18: =Quarterly!K21 -> -285 | E18: =Quarterly!L21 -> -315 | F18: =Quarterly!M21 -> -257.12012 | G18: =Quarterly!N21 -> -214.27624 | H18: =Quarterly!O21 -> -11.780354
A19: =Quarterly!A22 -> GAAP EPS | B19: =Quarterly!E22 -> -18.564199 | C19: =Quarterly!J22 -> -4.4976163 | D19: =Quarterly!K22 -> -5.1537071 | E19: =Quarterly!L22 -> -5.4545455 | F19: =Quarterly!M22 -> -4.448445 | G19: =Quarterly!N22 -> -3.6503618 | H19: =Quarterly!O22 -> -0.19966702
A20: =Quarterly!A23 -> Diluted Shares Outstanding (MM) | B20: =Quarterly!E23 -> 8.680741 | C20: =Quarterly!J23 -> 44.468 | D20: =Quarterly!K23 -> 55.3 | E20: =Quarterly!L23 -> 57.75 | F20: =Quarterly!M23 -> 57.8 | G20: =Quarterly!N23 -> 58.7 | H20: =Quarterly!O23 -> 59

Sheet Schizophrenia
A1: ML-007C-MA Schizophrenia Model ($MM)
A2: U.S. Market | B2: 2029E | C2: 2030E | D2: 2031E | E2: 2032E | F2: 2033E | G2: 2034E | H2: 2035E | I2: 2036E | J2: 2037E | K2: 2038E | L2: 2039E | M2: 2040E
A3: Estimated # patients with schizophrenia ('000) | B3: 2000 | C3: =B3*1.005 -> 2010 | D3: =C3*1.005 -> 2020.05 | E3: =D3*1.005 -> 2030.1502 | F3: =E3*1.005 -> 2040.301 | G3: =F3*1.005 -> 2050.5025 | H3: =G3*1.005 -> 2060.755 | I3: =H3*1.005 -> 2071.0588 | J3: =I3*1.005 -> 2081.4141 | ... M3: =L3*1.005 -> 2112.7917
A4: % of diagnosed & treated patients | B4: 0.76 | C4: =B4+0.01 -> 0.77 | D4: =C4+0.01 -> 0.78 | E4: =D4+0.01 -> 0.79 | F4: =E4+0.01 -> 0.8 | G4: =F4+0.01 -> 0.81 | H4: =G4+0.01 -> 0.82 | I4: =H4+0.01 -> 0.83 | J4: =I4+0.01 -> 0.84 | ... M4: =L4+0.01 -> 0.87
A5: # diagnosed and treated schizophrenia patients | B5: =B3*B4 -> 1520 | C5: =C3*C4 -> 1547.7 | D5: =D3*D4 -> 1575.639 | E5: =E3*E4 -> 1603.8187 | F5: =F3*F4 -> 1632.2408 | G5: =G3*G4 -> 1660.907 | H5: =H3*H4 -> 1689.8191 | I5: =I3*I4 -> 1718.9788 | ... M5: =M3*M4 -> 1838.1287
A6: % of patients who could benefit from additional augmentation therapy | B6: 0.5 | C6: 0.5 | D6: 0.5 | E6: 0.5 | F6: 0.5 | G6: 0.5 | H6: 0.5 | I6: 0.5 | J6: 0.5 | K6: 0.5 | L6: 0.5 | M6: 0.5
A7: # patients who could benefit from additional augmentation therapy | B7: =B5*B6 -> 760 | C7: =C5*C6 -> 773.85 | D7: =D5*D6 -> 787.8195 | E7: =E5*E6 -> 801.90935 | F7: =F5*F6 -> 816.1204 | G7: =G5*G6 -> 830.45352 | H7: =H5*H6 -> 844.90956 | I7: =I5*I6 -> 859.4894 | ... M7: =M5*M6 -> 919.06437
A8: % penetration of 007 | B8: 0.0025 | C8: 0.013 | D8: 0.025 | E8: 0.035 | F8: 0.045 | G8: 0.05 | H8: 0.05 | I8: 0.05 | J8: 0.05 | K8: 0.05 | L8: 0.05 | M8: 0.05
A9: # patients on 007 as adjunctive therapy | B9: =B7*B8 -> 1.9 | C9: =C7*C8 -> 10.06005 | D9: =D7*D8 -> 19.695487 | E9: =E7*E8 -> 28.066827 | F9: =F7*F8 -> 36.725418 | G9: =G7*G8 -> 41.522676 | H9: =H7*H8 -> 42.245478 | I9: =I7*I8 -> 42.97447 | ... M9: =M7*M8 -> 45.953219
A10: % compliance | B10: 0.75 | C10: 0.75 | D10: 0.75 | E10: 0.75 | F10: 0.75 | G10: 0.75 | H10: 0.75 | I10: 0.75 | J10: 0.75 | K10: 0.75 | L10: 0.75 | M10: 0.75
A11: Price per patient | B11: 19000 | C11: 19000 | D11: 19000 | E11: =D11*1.02 -> 19380 | F11: =E11*1.02 -> 19767.6 | G11: =F11*1.02 -> 20162.952 | H11: =G11*1.02 -> 20566.211 | I11: =H11*1.02 -> 20977.535 | J11: =I11*1.02 -> 21397.086 | K11: =J11*1.02 -> 21825.028 | L11: =K11*1.02 -> 22261.528 | M11: =L11*1.02 -> 22706.759
A12: Price per patient after GTN | B12: =B11*0.6 -> 11400 | C12: =C11*0.6 -> 11400 | D12: =D11*0.7 -> 13300 | E12: =E11*0.7 -> 13566 | F12: =F11*0.7 -> 13837.32 | G12: =G11*0.7 -> 14114.066 | H12: =H11*0.7 -> 14396.348 | I12: =I11*0.7 -> 14684.275 | J12: =J11*0.7 -> 14977.96 | K12: =K11*0.7 -> 15277.519 | ... M12: =M11*0.7 -> 15894.731
A13: 007 adjunctive sales in schizophrenia ($MM) | B13: =B9*B10*B12/1000 -> 16.245 | C13: =C9*C10*C12/1000 -> 86.013427 | D13: =D9*D10*D12/1000 -> 196.46249 | E13: =E9*E10*E12/1000 -> 285.56593 | F13: =F9*F10*F12/1000 -> 381.13602 | G13: =G9*G10*G12/1000 -> 439.54035 | H13: =H9*H10*H12/1000 -> 456.13544 | I13: =I9*I10*I12/1000 -> 473.28669 | ... M13: =M9*M10*M12/1000 -> 547.81054
A14: # diagnosed and treated schizophrenia patients | B14: =B5 -> 1520 | C14: =C5 -> 1547.7 | D14: =D5 -> 1575.639 | E14: =E5 -> 1603.8187 | F14: =F5 -> 1632.2408 | G14: =G5 -> 1660.907 | H14: =H5 -> 1689.8191 | I14: =I5 -> 1718.9788 | ... M14: =M5 -> 1838.1287
A15: % of patients that don't respond to current treatments | B15: 0.3 | C15: 0.3 | D15: 0.3 | E15: 0.3 | F15: 0.3 | G15: 0.3 | H15: 0.3 | I15: 0.3 | J15: 0.3 | K15: 0.3 | L15: 0.3 | M15: 0.3
A16: # patients with insufficient response to current treatments | B16: =B14*B15 -> 456 | C16: =C14*C15 -> 464.31 | D16: =D14*D15 -> 472.6917 | E16: =E14*E15 -> 481.14561 | F16: =F14*F15 -> 489.67224 | G16: =G14*G15 -> 498.27211 | H16: =H14*H15 -> 506.94573 | I16: =I14*I15 -> 515.69364 | ... M16: =M14*M15 -> 551.43862
A17: # patients who received 007 in earlier line | B17: =0 -> 0 | C17: =B9 -> 1.9 | D17: =C9 -> 10.06005 | E17: =D9 -> 19.695487 | F17: =E9 -> 28.066827 | G17: =F9 -> 36.725418 | H17: =G9 -> 41.522676 | I17: =H9 -> 42.245478 | J17: =I9 -> 42.97447 | ... M17: =L9 -> 45.199026
A18: # patients who have not received 007 and need additional therapy | B18: =B16-B17 -> 456 | C18: =C16-C17 -> 462.41 | D18: =D16-D17 -> 462.63165 | E18: =E16-E17 -> 461.45012 | F18: =F16-F17 -> 461.60541 | G18: =G16-G17 -> 461.54669 | H18: =H16-H17 -> 465.42306 | I18: =I16-I17 -> 473.44816 | ... M18: =M16-M17 -> 506.2396
A19: % penetration of 007 | B19: 0.005 | C19: 0.02 | D19: 0.035 | E19: 0.07 | F19: 0.1 | G19: 0.125 | H19: 0.125 | I19: 0.125 | J19: 0.125 | K19: 0.125 | L19: 0.125 | M19: 0.125
A20: # patients on 007 as adjunctive therapy | B20: =B18*B19 -> 2.28 | C20: =C18*C19 -> 9.2482 | D20: =D18*D19 -> 16.192108 | E20: =E18*E19 -> 32.301509 | F20: =F18*F19 -> 46.160541 | G20: =G18*G19 -> 57.693336 | H20: =H18*H19 -> 58.177882 | I20: =I18*I19 -> 59.18102 | ... M20: =M18*M19 -> 63.27995
A21: % compliance | B21: 0.75 | C21: 0.75 | D21: 0.75 | E21: 0.75 | F21: 0.75 | G21: 0.75 | H21: 0.75 | I21: 0.75 | J21: 0.75 | K21: 0.75 | L21: 0.75 | M21: 0.75
A22: Price per patient | B22: =B11 -> 19000 | C22: =C11 -> 19000 | D22: =D11 -> 19000 | E22: =E11 -> 19380 | F22: =F11 -> 19767.6 | G22: =G11 -> 20162.952 | H22: =H11 -> 20566.211 | I22: =I11 -> 20977.535 | ... M22: =M11 -> 22706.759
A23: Price per patient after GTN | B23: =B12 -> 11400 | C23: =C12 -> 11400 | D23: =D12 -> 13300 | E23: =E12 -> 13566 | F23: =F12 -> 13837.32 | G23: =G12 -> 14114.066 | H23: =H12 -> 14396.348 | I23: =I12 -> 14684.275 | ... M23: =M12 -> 15894.731
A24: 007 monotherapy sales in schizophrenia ($MM) | B24: =B20*B21*B23/1000 -> 19.494 | C24: =C20*C21*C23/1000 -> 79.07211 | D24: =D20*D21*D23/1000 -> 161.51627 | E24: =E20*E21*E23/1000 -> 328.6517 | F24: =F20*F21*F23/1000 -> 479.05364 | G24: =G20*G21*G23/1000 -> 610.71569 | H24: =H20*H21*H23/1000 -> 628.16177 | I24: =I20*I21*I23/1000 -> 651.77277 | ... M24: =M20*M21*M23/1000 -> 754.36334
A25: Total U.S. 007 sales ($MM) | B25: =B13+B24 -> 35.739 | C25: =C13+C24 -> 165.08554 | D25: =D13+D24 -> 357.97876 | E25: =E13+E24 -> 614.21763 | F25: =F13+F24 -> 860.18966 | G25: =G13+G24 -> 1050.256 | H25: =H13+H24 -> 1084.2972 | I25: =I13+I24 -> 1125.0595 | ... M25: =M13+M24 -> 1302.1739
A27: E.U. Market | B27: 2029E | C27: 2030E | D27: 2031E | E27: 2032E | F27: 2033E | G27: 2034E | H27: 2035E | I27: 2036E | J27: 2037E | K27: 2038E | L27: 2039E | M27: 2040E
A28: Estimated # patients with schizophrenia ('000) | B28: 2350 | C28: =B28*1.005 -> 2361.75 | D28: =C28*1.005 -> 2373.5587 | E28: =D28*1.005 -> 2385.4265 | F28: =E28*1.005 -> 2397.3537 | G28: =F28*1.005 -> 2409.3404 | H28: =G28*1.005 -> 2421.3871 | I28: =H28*1.005 -> 2433.4941 | J28: =I28*1.005 -> 2445.6616 | ... M28: =L28*1.005 -> 2482.5302
A29: % of diagnosed & treated patients | B29: =B4 -> 0.76 | C29: =B29+0.01 -> 0.77 | D29: =C29+0.01 -> 0.78 | E29: =D29+0.01 -> 0.79 | F29: =E29+0.01 -> 0.8 | G29: =F29+0.01 -> 0.81 | H29: =G29+0.01 -> 0.82 | I29: =H29+0.01 -> 0.83 | J29: =I29+0.01 -> 0.84 | ... M29: =L29+0.01 -> 0.87
A30: # diagnosed and treated schizophrenia patients | B30: =B28*B29 -> 1786 | C30: =C28*C29 -> 1818.5475 | D30: =D28*D29 -> 1851.3758 | E30: =E28*E29 -> 1884.487 | F30: =F28*F29 -> 1917.8829 | G30: =G28*G29 -> 1951.5658 | H30: =H28*H29 -> 1985.5375 | I30: =I28*I29 -> 2019.8001 | ... M30: =M28*M29 -> 2159.8013
A31: % of patients who could benefit from additional augmentation therapy | B31: =B6 -> 0.5 | C31: =C6 -> 0.5 | D31: =D6 -> 0.5 | E31: =E6 -> 0.5 | F31: =F6 -> 0.5 | G31: =G6 -> 0.5 | H31: =H6 -> 0.5 | I31: =I6 -> 0.5 | ... M31: =M6 -> 0.5
A32: # patients who could benefit from additional augmentation therapy | B32: =B30*B31 -> 893 | C32: =C30*C31 -> 909.27375 | D32: =D30*D31 -> 925.68791 | E32: =E30*E31 -> 942.24348 | F32: =F30*F31 -> 958.94147 | G32: =G30*G31 -> 975.78288 | H32: =H30*H31 -> 992.76873 | I32: =I30*I31 -> 1009.9 | ... M32: =M30*M31 -> 1079.9006
A33: % penetration of 007 | B33: 0 | C33: 0.0035 | D33: 0.01 | E33: 0.03 | F33: 0.05 | G33: 0.05 | H33: 0.05 | I33: 0.05 | J33: 0.05 | K33: 0.05 | L33: 0.05 | M33: 0.05
A34: # patients on 007 | B34: =B32*B33 -> 0 | C34: =C32*C33 -> 3.1824581 | D34: =D32*D33 -> 9.2568791 | E34: =E32*E33 -> 28.267305 | F34: =F32*F33 -> 47.947074 | G34: =G32*G33 -> 48.789144 | H34: =H32*H33 -> 49.638437 | I34: =I32*I33 -> 50.495002 | ... M34: =M32*M33 -> 53.995032
A35: % compliance | B35: =B10 -> 0.75 | C35: =C10 -> 0.75 | D35: =D10 -> 0.75 | E35: =E10 -> 0.75 | F35: =F10 -> 0.75 | G35: =G10 -> 0.75 | H35: =H10 -> 0.75 | I35: =I10 -> 0.75 | ... M35: =M10 -> 0.75
A36: Price per patient | B36: =B11*0.7 -> 13300 | C36: =B36 -> 13300 | D36: =C36 -> 13300 | E36: =D36 -> 13300 | F36: =E36 -> 13300 | G36: =F36 -> 13300 | H36: =G36 -> 13300 | I36: =H36 -> 13300 | J36: =I36 -> 13300 | ... M36: =L36 -> 13300
A37: 007 adjunctive sales In schizophrenia ($MM) | B37: =B34*B35*B36/1000 -> 0 | C37: =C34*C35*C36/1000 -> 31.74502 | D37: =D34*D35*D36/1000 -> 92.337369 | E37: =E34*E35*E36/1000 -> 281.96636 | F37: =F34*F35*F36/1000 -> 478.27206 | G37: =G34*G35*G36/1000 -> 486.67171 | H37: =H34*H35*H36/1000 -> 495.1434 | I37: =I34*I35*I36/1000 -> 503.68765 | ... M37: =M34*M35*M36/1000 -> 538.60044
A38: # diagnosed and treated schizophrenia patients | B38: =B30 -> 1786 | C38: =C30 -> 1818.5475 | D38: =D30 -> 1851.3758 | E38: =E30 -> 1884.487 | F38: =F30 -> 1917.8829 | G38: =G30 -> 1951.5658 | H38: =H30 -> 1985.5375 | I38: =I30 -> 2019.8001 | ... M38: =M30 -> 2159.8013
A39: % of patients that don't respond to current treatments | B39: =B15 -> 0.3 | C39: =C15 -> 0.3 | D39: =D15 -> 0.3 | E39: =E15 -> 0.3 | F39: =F15 -> 0.3 | G39: =G15 -> 0.3 | H39: =H15 -> 0.3 | I39: =I15 -> 0.3 | ... M39: =M15 -> 0.3
A40: # patients with insufficient response to current treatments | B40: =B38*B39 -> 535.8 | C40: =C38*C39 -> 545.56425 | D40: =D38*D39 -> 555.41275 | E40: =E38*E39 -> 565.34609 | F40: =F38*F39 -> 575.36488 | G40: =G38*G39 -> 585.46973 | H40: =H38*H39 -> 595.66124 | I40: =I38*I39 -> 605.94003 | ... M40: =M38*M39 -> 647.94038
A41: # patients who received 007 in earlier line | B41: =0 -> 0 | C41: =B34 -> 0 | D41: =C34 -> 3.1824581 | E41: =D34 -> 9.2568791 | F41: =E34 -> 28.267305 | G41: =F34 -> 47.947074 | H41: =G34 -> 48.789144 | I41: =H34 -> 49.638437 | J41: =I34 -> 50.495002 | ... M41: =L34 -> 53.108855
...

Sheet 007 NPV
B2: Financial Year End | C2: 12/31
B3: Valuation Date | C3: =TODAY() -> 46118
B4: Discount Rate | C4: 0.1175
B5: Fampridine-SR price (2010) | C5: 10250
B7: $MM | D7: 2026E | E7: 2027E | F7: 2028E | G7: 2029E | H7: 2030E | I7: 2031E | J7: 2032E | K7: 2033E | L7: 2034E | M7: 2035E | N7: 2036E | O7: 2037E | P7: 2038E | Q7: 2039E | R7: 2040E
B8: $MM | D8: 45289.25 | E8: 45655.25 | F8: 46020.25 | G8: 46385.25 | H8: 46750.25 | I8: 47116.25 | J8: 47481.25 | K8: 47846.25 | L8: 48211.25 | M8: 48577.25 | N8: 48942.25 | O8: 49307.25 | P8: 49672.25 | Q8: 50038.25 | R8: 50403.25
B10: U.S. 007 Sales | D10: 0 | E10: 0 | F10: 0 | G10: =Schizophrenia!B25 -> 35.739 | H10: =Schizophrenia!C25 -> 165.08554 | I10: =Schizophrenia!D25 -> 357.97876 | J10: =Schizophrenia!E25 -> 614.21763 | K10: =Schizophrenia!F25 -> 860.18966 | L10: =Schizophrenia!G25 -> 1050.256 | M10: =Schizophrenia!H25 -> 1084.2972 | N10: =Schizophrenia!I25 -> 1125.0595 | ... R10: =Schizophrenia!M25 -> 1302.1739
B11: Growth (%) | E11: 0 | F11: 0 | G11: 0 | H11: =H10/G10-1 -> 3.6191986 | I11: =I10/H10-1 -> 1.1684441 | J11: =J10/I10-1 -> 0.71579349 | K11: =K10/J10-1 -> 0.40046396 | L11: =L10/K10-1 -> 0.22095869 | M11: =M10/L10-1 -> 0.032412261 | N11: =N10/M10-1 -> 0.037593243 | O11: =O10/N10-1 -> 0.037442817 | ... R11: =R10/Q10-1 -> 0.037012515
B12: Royalty Payments From Partners | D12: 0 | E12: 0 | F12: 0 | G12: 0 | H12: =Schizophrenia!C49 -> 9.614206 | I12: =Schizophrenia!D49 -> 32.238717 | J12: =Schizophrenia!E49 -> 78.581232 | K12: =Schizophrenia!F49 -> 133.8555 | L12: =Schizophrenia!G49 -> 150.95223 | M12: =Schizophrenia!H49 -> 153.57917 | N12: =Schizophrenia!I49 -> 156.22861 | O12: =Schizophrenia!J49 -> 158.90071 | ... R12: =Schizophrenia!M49 -> 167.05453
B13: Total Revenues | D13: =D10+D12 -> 0 | E13: =E10+E12 -> 0 | F13: =F10+F12 -> 0 | G13: =G10+G12 -> 35.739 | H13: =H10+H12 -> 174.69974 | I13: =I10+I12 -> 390.21748 | J13: =J10+J12 -> 692.79886 | K13: =K10+K12 -> 994.04516 | ... R13: =R10+R12 -> 1469.2284
B14: Growth (%) | E14: 0 | F14: 0 | G14: 0 | H14: =H13/G13-1 -> 3.8882102 | I14: =I13/H13-1 -> 1.2336465 | J14: =J13/I13-1 -> 0.7754173 | K14: =K13/J13-1 -> 0.43482504 | L14: =L13/K13-1 -> 0.20840412 | M14: =M13/L13-1 -> 0.030526029 | N14: =N13/M13-1 -> 0.035069486 | O14: =O13/N13-1 -> 0.034962856 | ... R14: =R13/Q13-1 -> 0.034659977
B15: COGS | D15: 0 | E15: 0 | F15: =(F10*0.1) -> 0 | G15: =(G10*0.1) -> 3.5739 | H15: =(H10*0.1) -> 16.508554 | I15: =(I10*0.1) -> 35.797876 | J15: =(J10*0.1) -> 61.421763 | K15: =(K10*0.1) -> 86.018966 | L15: =(L10*0.1) -> 105.0256 | M15: =(M10*0.1) -> 108.42972 | ... R15: =(R10*0.1) -> 130.21739
B16: COGS as a % of sales | D16: 0 | E16: 0 | F16: 0.1 | G16: 0.1 | H16: 0.1 | I16: 0.1 | J16: 0.1 | K16: 0.1 | L16: 0.1 | M16: 0.1 | N16: 0.1 | O16: 0.1 | P16: 0.1 | Q16: 0.1 | R16: 0.1
B17: R&D | D17: =Quarterly!J7 -> 153 | E17: =Quarterly!K7 -> 225 | F17: =Quarterly!L7 -> 250 | G17: =Quarterly!M7 -> 165 | H17: =Quarterly!N7 -> 125 | I17: =Quarterly!O7 -> 75 | J17: 50 | K17: 20 | L17: 10 | M17: 0 | N17: 0 | O17: 0 | P17: 0 | Q17: 0 | R17: 0
B18: R&D as a % of Revenues | D18: 0 | E18: 0 | F18: 0 | G18: =G17/G13 -> 4.6168052 | H18: =H17/H13 -> 0.71551336 | I18: =I17/I13 -> 0.19220051 | J18: =J17/J13 -> 0.072171019 | K18: =K17/K13 -> 0.02011981 | L18: =L17/L13 -> 0.008324951 | M18: =M17/M13 -> 0 | N18: =N17/N13 -> 0 | ... R18: =R17/R13 -> 0
B19: SG&A | D19: =Annual!C9 -> 47 | E19: =Annual!D9 -> 60 | F19: =Annual!E9 -> 65 | G19: =Annual!F9 -> 125 | H19: =Annual!G9 -> 250 | I19: =Annual!H9 -> 295 | J19: 305 | K19: 310 | L19: 315 | M19: 320 | N19: 325 | O19: 325 | P19: 325 | Q19: 325 | R19: 325
B20: SG&A as a % of Revenues | D20: 0 | E20: 0 | F20: 0 | G20: =G19/G13 -> 3.4975797 | H20: =H19/H13 -> 1.4310267 | I20: =I19/I13 -> 0.75598869 | J20: =J19/J13 -> 0.44024322 | K20: =K19/K13 -> 0.31185706 | L20: =L19/L13 -> 0.26223596 | M20: =M19/M13 -> 0.25850723 | N20: =N19/N13 -> 0.253651 | ... R20: =R19/R13 -> 0.22120454
B21: Operating Income | D21: =D13-(SUM(D15+D17+D19)) -> -200 | E21: =E13-(SUM(E15+E17+E19)) -> -285 | F21: =F13-(SUM(F15+F17+F19)) -> -315 | G21: =G13-(SUM(G15+G17+G19)) -> -257.8349 | H21: =H13-(SUM(H15+H17+H19)) -> -216.80881 | I21: =I13-(SUM(I15+I17+I19)) -> -15.580397 | J21: =J13-(SUM(J15+J17+J19)) -> 276.3771 | K21: =K13-(SUM(K15+K17+K19)) -> 578.02619 | ... R21: =R13-(SUM(R15+R17+R19)) -> 1014.011
B22: Tax | D22: 0 | E22: 0 | F22: 0 | G22: 0 | H22: =H21*H23 -> 0 | I22: 0 | J22: =J21*J23 -> 55.27542 | K22: =K21*K23 -> 115.60524 | L22: =L21*L23 -> 154.23653 | M22: =M21*M23 -> 161.88933 | N22: =N21*N23 -> 168.75643 | O22: =O21*O23 -> 176.87342 | P22: =P21*P23 -> 185.24803 | Q22: =Q21*Q23 -> 193.88823 | R22: =R21*R23 -> 202.80221
B23: Tax rate | D23: 0 | E23: 0 | F23: 0 | G23: 0 | H23: 0 | I23: 0.2 | J23: 0.2 | K23: 0.2 | L23: 0.2 | M23: 0.2 | N23: 0.2 | O23: 0.2 | P23: 0.2 | Q23: 0.2 | R23: 0.2
B24: Approx Free Cash Flow | D24: =D21-D22 -> -200 | E24: =E21-E22 -> -285 | F24: =F21-F22 -> -315 | G24: =G21-G22 -> -257.8349 | H24: =H21-H22 -> -216.80881 | I24: =I21-I22 -> -15.580397 | J24: =J21-J22 -> 221.10168 | K24: =K21-K22 -> 462.42095 | ... R24: =R21-R22 -> 811.20883
B25: Years | D25: =(D8-$C$3)/365.25 -> -2.2689938 | E25: =(E8-$C$3)/365.25 -> -1.2669405 | F25: =(F8-$C$3)/365.25 -> -0.26762491 | G25: =(G8-$C$3)/365.25 -> 0.73169062 | H25: =(H8-$C$3)/365.25 -> 1.7310062 | I25: =(I8-$C$3)/365.25 -> 2.7330595 | J25: =(J8-$C$3)/365.25 -> 3.7323751 | K25: =(K8-$C$3)/365.25 -> 4.7316906 | ... R25: =(R8-$C$3)/365.25 -> 11.732375
B26: Discount Factor | D26: =1/(1+$C$4)^D25 -> 1.2866883 | E26: =1/(1+$C$4)^E25 -> 1.1511363 | F26: =1/(1+$C$4)^F25 -> 1.0301779 | G26: =1/(1+$C$4)^G25 -> 0.92192955 | H26: =1/(1+$C$4)^H25 -> 0.82505562 | I26: =1/(1+$C$4)^I25 -> 0.7381364 | J26: =1/(1+$C$4)^J25 -> 0.66057497 | K26: =1/(1+$C$4)^K25 -> 0.59116349 | ... R26: =1/(1+$C$4)^R25 -> 0.27160756
B28: NPV of Cash flows | D28: =D24/(1+$C$4)^D25 -> -257.33766 | E28: =E24/(1+$C$4)^E25 -> -328.07385 | F28: =F24/(1+$C$4)^F25 -> -324.50605 | G28: =G24/(1+$C$4)^G25 -> -237.70561 | H28: =H24/(1+$C$4)^H25 -> -178.87933 | I28: =I24/(1+$C$4)^I25 -> -11.500458 | J28: =J24/(1+$C$4)^J25 -> 146.05424 | K28: =K24/(1+$C$4)^K25 -> 273.36639 | ... R28: =R24/(1+$C$4)^R25 -> 220.33045
B30: Terminal Value Calculation
B32: Final year FCF | D32: =$R24 -> 811.20883
B33: Perpetual Growth Rate | D33: -1
B34: Terminal Value | D34: =D32*(1+D33)/($C4-D33) -> 0
B35: Discount Factor | D35: =$R26 -> 0.27160756
B36: Present Value of Terminal Value | D36: =D34*D35 -> 0
B37: Present Value of Cash Flows | D37: =SUM(E28:R28)+(0.75*D28) -> 1039.8355
B38: Enterprise Value | D38: =D36+D37 -> 1039.8355
B39: Market Value | D39: =D38+Quarterly!D25 -> 1492.9315
B40: Fully Diluted Shares Outstanding | D40: =Quarterly!F23 -> 42.436
B41: Value per Fully Diluted Share | D41: =D39/D40 -> 35.180778

Sheet SOTP
A1: Sum Of The Parts Valuation
B2: Segment | C2: Value Per Share
B3: AXS-05 For Depression/ADA | C3: =#REF! -> #REF!
B4: AXS-07 For Acute Migraine | C4: ='007 NPV'!#REF! -> #REF!
B5: Sunosi For Narcolepsy/OSA | C5: =#REF! -> #REF!
B6: Sum-Of-The Parts Value | C6: =SUM(C3:C5) -> #REF!

Sheet BlueMatrix
A1: Ticker | B1: MPLT
A3: Market Data Grid Name | B3: Client Code | C3: Time Series Grid Name | D3: Client Code
A4: $0.50 Cu Leverage / Share | B4: CU_LVRG | C4: Cash | D4: CASH
A5: $100 Au Leverage / Share | B5: AU_LVRG | C5: Cash Flow | D5: CASHFLOW
A6: $5 Ag Leverage / Share | B6: AG_LVRG | C6: Cash Flow per Share | D6: CFPS
A7: 52-Week High | B7: 52 WK HIGH | C7: Discretionary Cash Flow | D7: DCF
A8: 52-Week Low | B8: 52 WK LOW | C8: Discretionary Cash Flow per Share | D8: DCFS
A9: Adjusted EV | B9: ADJEV | C9: Dividend | D9: DIV
A10: Average Daily Volume | B10: AVG DLY VOL | C10: Earnings Per Share | D10: EPS
A11: Book Value | B11: BV | C11: EBIT
A12: Daily Liquidity ($$MM) | B12: LIQPD | C12: EBITDA | D12: EBITDA
A13: Developed % | B13: DEVPCT | C13: EBITDA - Adjusted | D13: EBITDA_ADJ
A14: Dividend | B14: DIVIDEND | C14: EBITDAR | D14: EBITDAR
A15: Dividend Yield | B15: DIVIDEND_YIELD | C15: EBITDAX | D15: EBITDAX
A16: Enterprise Value (MM) | B16: Enterprise_Value | C16: FFO/Sh | D16: FFO
A17: European AP12 2009 | B17: Euro_AP12 | C17: Free Cash Flow | D17: FCF
A18: EV/Mcfe | B18: EVMCFE | C18: Free Cash Flow per share | D18: FCFPS
A19: EV/Mcfepd | B19: EVMCFEPD | C19: NA | D19: EPS_DIL
A20: Expected Return | B20: Expected_Return | C20: Net Cash/Debt ($M)
A21: Expected Total Return | B21: Expected_Total_Return | C21: Net Debt / Total Cap | D21: NETDEBT_TOTCAP
A22: Float | C22: Net Debt / Total Capitalization (MKT) | D22: NETDEBT_TOTCAPM
A23: FUND_NAV | C23: Operating Cash Flow | D23: OPCASHFLOW
A24: Gold | B24: Gold | C24: Production | D24: PRODUCTION
A25: Issue | B25: ISSUE | C25: Revenue ($M) | D25: Revenue
A26: Issue | B26: ISSUE_3
A27: Issue | B27: ISSUE_4
A28: Issue | B28: ISSUE_5
A29: Issue | B29: ISSUE_2
A30: Legacy Liabilities | B30: LEGLIA
A31: Long Term Debt ($MM) | B31: LT DEBT
A32: Market Cap (MM) | B32: MARKET_CAP
A33: Maturity | B33: MATURITY
A34: Maturity | B34: Maturity_3
A35: Maturity | B35: Maturity_4
A36: Maturity | B36: Maturity_5
A37: Maturity | B37: Maturity_2
... A41: Net Asset Value | B41: NAV
A42: Net Cash/Debt ($M)
A43: Net Debt | B43: NET_DEBT
A44: Net Debt/Total Cap | B44: DEBT TOT CAP
...
